[INFO]2021-04-23 15:55:39,248: log files at E:\projects_by_myself\backup\MeiWei_back_0421\remoteio\log
[INFO]2021-04-23 15:55:39,249: create lock <lock name:timer.lock_2792568574256,<unlocked _thread.RLock object owner=0 count=0 at 0x0000028A320ED150>>
[INFO]2021-04-23 15:55:39,252: create lock <lock name:runTasks.g_lock,<unlocked _thread.RLock object owner=0 count=0 at 0x0000028A32A328D0>>
[CRITICAL]2021-04-23 15:55:41,341: [modbusApi: 192.168.8.122] execute fcode=1, addr=16 exception:  cause a error: [WinError 10061] 由于目标计算机积极拒绝，无法连接。
pid=9160, ppid=12516, tid=9076
Traceback (most recent call last):
  File "E:\projects_by_myself\backup\MeiWei_back_0421\common\modbusapi.py", line 35, in __execute
    data = self.master.execute(self.__salveId, fcode, start, quantity_of_x=num, output_value=value)
  File "E:\Users\Administrator\AppData\Local\Programs\Python\Python38\lib\site-packages\modbus_tk\utils.py", line 39, in new
    raise excpt
  File "E:\Users\Administrator\AppData\Local\Programs\Python\Python38\lib\site-packages\modbus_tk\utils.py", line 37, in new
    ret = fcn(*args, **kwargs)
  File "E:\Users\Administrator\AppData\Local\Programs\Python\Python38\lib\site-packages\modbus_tk\modbus.py", line 152, in execute
    self.open()
  File "E:\Users\Administrator\AppData\Local\Programs\Python\Python38\lib\site-packages\modbus_tk\modbus.py", line 99, in open
    self._do_open()
  File "E:\Users\Administrator\AppData\Local\Programs\Python\Python38\lib\site-packages\modbus_tk\modbus_tcp.py", line 173, in _do_open
    self._sock.connect((self._host, self._port))
ConnectionRefusedError: [WinError 10061] 由于目标计算机积极拒绝，无法连接。

[CRITICAL]2021-04-23 15:55:41,357: ZLAN01 readDOList fail cause a error: [WinError 10061] 由于目标计算机积极拒绝，无法连接。
pid=9160, ppid=12516, tid=9076
Traceback (most recent call last):
  File "E:\projects_by_myself\backup\MeiWei_back_0421\remoteio\remoteioMgr.py", line 158, in readDOList
    return self._read(D10, IO_LENTH)
  File "E:\projects_by_myself\backup\MeiWei_back_0421\common\lock.py", line 120, in _call
    return func(*p,**pp)
  File "E:\projects_by_myself\backup\MeiWei_back_0421\remoteio\remoteioMgr.py", line 172, in _read
    s = self.master.read(mdef.READ_COILS,addr, length)
  File "E:\projects_by_myself\backup\MeiWei_back_0421\common\modbusapi.py", line 45, in read
    return self.__execute(fcode, start, num)
  File "E:\projects_by_myself\backup\MeiWei_back_0421\common\modbusapi.py", line 35, in __execute
    data = self.master.execute(self.__salveId, fcode, start, quantity_of_x=num, output_value=value)
  File "E:\Users\Administrator\AppData\Local\Programs\Python\Python38\lib\site-packages\modbus_tk\utils.py", line 39, in new
    raise excpt
  File "E:\Users\Administrator\AppData\Local\Programs\Python\Python38\lib\site-packages\modbus_tk\utils.py", line 37, in new
    ret = fcn(*args, **kwargs)
  File "E:\Users\Administrator\AppData\Local\Programs\Python\Python38\lib\site-packages\modbus_tk\modbus.py", line 152, in execute
    self.open()
  File "E:\Users\Administrator\AppData\Local\Programs\Python\Python38\lib\site-packages\modbus_tk\modbus.py", line 99, in open
    self._do_open()
  File "E:\Users\Administrator\AppData\Local\Programs\Python\Python38\lib\site-packages\modbus_tk\modbus_tcp.py", line 173, in _do_open
    self._sock.connect((self._host, self._port))
ConnectionRefusedError: [WinError 10061] 由于目标计算机积极拒绝，无法连接。

