[INFO]2021-05-08 15:42:41,323: log files at C:\Users\comba\Desktop\知识城地牛\knowledgeCity\common\log
[INFO]2021-05-08 15:42:41,324: find module agvCtrl.main_agv
[INFO]2021-05-08 15:42:41,324: find module agvDevice.main_agvDevice
[INFO]2021-05-08 15:42:41,324: find module alarm.main_alarm
[INFO]2021-05-08 15:42:41,325: find module auth.main_auth
[INFO]2021-05-08 15:42:41,325: find module autoCtrl.main_akmCtrl
[INFO]2021-05-08 15:42:41,325: find module door.main_door
[INFO]2021-05-08 15:42:41,325: find module elevator.main_elevator
[INFO]2021-05-08 15:42:41,326: find module feed.main_feed
[INFO]2021-05-08 15:42:41,331: find module remoteio.main_remoteio
[INFO]2021-05-08 15:42:41,331: import agvCtrl.main_agv
[INFO]2021-05-08 15:42:41,569: create lock <lock name:doorMgr.lock,<unlocked _thread.RLock object owner=0 count=0 at 0x0000027CD9C067B0>>
[INFO]2021-05-08 15:42:41,570: create lock <lock name:door.lock,<unlocked _thread.RLock object owner=0 count=0 at 0x0000027CD9C06918>>
[INFO]2021-05-08 15:42:41,621: create lock <lock name:timer.lock_2735254907592,<unlocked _thread.RLock object owner=0 count=0 at 0x0000027CD9E4F440>>
[ERROR]2021-05-08 15:42:41,629: mqtt is disabled
[INFO]2021-05-08 15:42:41,629: mqtt: subscribe [alarm/raise/+]
[INFO]2021-05-08 15:42:41,630: mqtt: subscribe [alarm/clear/+]
[INFO]2021-05-08 15:42:44,648: Mongodb connect to 127.0.0.1 port 27017
[INFO]2021-05-08 15:42:44,696: create lock <lock name:elevatorApi.tcp_lock,<unlocked _thread.RLock object owner=0 count=0 at 0x0000027CDA018B48>>
[INFO]2021-05-08 15:42:44,697: create lock <lock name:elevatorApi.g_lock,<unlocked _thread.RLock object owner=0 count=0 at 0x0000027CDA018788>>
[INFO]2021-05-08 15:42:44,698: create lock <lock name:elevatorMgr.lock,<unlocked _thread.RLock object owner=0 count=0 at 0x0000027CDA018300>>
[INFO]2021-05-08 15:42:44,706: create lock <lock name:agvserver,<unlocked _thread.RLock object owner=0 count=0 at 0x0000027CDA141760>>
[INFO]2021-05-08 15:42:44,857: create lock <lock name:mapMgr.lock,<unlocked _thread.RLock object owner=0 count=0 at 0x0000027CD83DC198>>
[INFO]2021-05-08 15:42:45,072: create lock <lock name:agvList.g_agvLock,<unlocked _thread.RLock object owner=0 count=0 at 0x0000027CDA1FDE40>>
[INFO]2021-05-08 15:42:45,075: create lock <lock name:taskList.lock,<unlocked _thread.RLock object owner=0 count=0 at 0x0000027CDA245F30>>
[INFO]2021-05-08 15:42:45,123: charge policy 0 , fix time
[INFO]2021-05-08 15:42:45,149: create lock <lock name:agvApi.g_lock,<unlocked _thread.RLock object owner=0 count=0 at 0x0000027CDA2BC1C0>>
[INFO]2021-05-08 15:42:45,572: start load map C:\Users\comba\Desktop\知识城地牛\knowledgeCity\agvCtrl\projects\knowledgeCity\comba-ZSC-3F_0419.smap
[DEBUG]2021-05-08 15:42:45,648: elevator thread start
[INFO]2021-05-08 15:42:45,663: load map C:\Users\comba\Desktop\知识城地牛\knowledgeCity\agvCtrl\projects\knowledgeCity\comba-ZSC-3F_0419.smap ,used 98 ms
[INFO]2021-05-08 15:42:45,671: start load map C:\Users\comba\Desktop\知识城地牛\knowledgeCity\agvCtrl\projects\knowledgeCity\comba-ZSC-F1-F3.smap
[INFO]2021-05-08 15:42:45,815: load map C:\Users\comba\Desktop\知识城地牛\knowledgeCity\agvCtrl\projects\knowledgeCity\comba-ZSC-F1-F3.smap ,used 151 ms
[INFO]2021-05-08 15:42:45,823: start load map C:\Users\comba\Desktop\知识城地牛\knowledgeCity\agvCtrl\projects\knowledgeCity\comba-ZXC-3F.smap
[INFO]2021-05-08 15:42:45,899: load map C:\Users\comba\Desktop\知识城地牛\knowledgeCity\agvCtrl\projects\knowledgeCity\comba-ZXC-3F.smap ,used 83 ms
[INFO]2021-05-08 15:42:45,907: start load map C:\Users\comba\Desktop\知识城地牛\knowledgeCity\agvCtrl\projects\knowledgeCity\comba-ZXC-F3.smap
[INFO]2021-05-08 15:42:45,957: load map C:\Users\comba\Desktop\知识城地牛\knowledgeCity\agvCtrl\projects\knowledgeCity\comba-ZXC-F3.smap ,used 57 ms
[INFO]2021-05-08 15:42:45,966: start load map C:\Users\comba\Desktop\知识城地牛\knowledgeCity\agvCtrl\projects\knowledgeCity\office.smap
[INFO]2021-05-08 15:42:45,999: load map C:\Users\comba\Desktop\知识城地牛\knowledgeCity\agvCtrl\projects\knowledgeCity\office.smap ,used 41 ms
[INFO]2021-05-08 15:42:46,004: import agvDevice.main_agvDevice
[INFO]2021-05-08 15:42:46,005: import alarm.main_alarm
[INFO]2021-05-08 15:42:46,006: import auth.main_auth
[INFO]2021-05-08 15:42:46,014: import autoCtrl.main_akmCtrl
[INFO]2021-05-08 15:42:46,023: create lock <lock name:agvApi.g_lock,<unlocked _thread.RLock object owner=0 count=0 at 0x0000027CDA6D3468>>
[INFO]2021-05-08 15:42:46,030: create lock <lock name:runTasks.pre_lock,<unlocked _thread.RLock object owner=0 count=0 at 0x0000027CDA6A8648>>
[INFO]2021-05-08 15:42:46,050: create lock <lock name:IOAlarm.s_lock,<unlocked _thread.RLock object owner=0 count=0 at 0x0000027CDA6A81C0>>
[INFO]2021-05-08 15:42:46,056: create lock <lock name:mapMgr.lock,<unlocked _thread.RLock object owner=0 count=0 at 0x0000027CDAE80120>>
[INFO]2021-05-08 15:42:46,563: import door.main_door
[INFO]2021-05-08 15:42:46,568: import elevator.main_elevator
[INFO]2021-05-08 15:42:46,569: import feed.main_feed
[INFO]2021-05-08 15:42:46,576: create lock <lock name:feedTask.g_lock,<unlocked _thread.RLock object owner=0 count=0 at 0x0000027CDB27D508>>
[INFO]2021-05-08 15:42:46,612: import remoteio.main_remoteio
[SUCC]2021-05-08 15:42:46,628: utility start, pid=13844, ppid=13780
[DEBUG]2021-05-08 15:42:46,628: create aliveObj upStation01 远程控制IO离线异常 timeout 120
[DEBUG]2021-05-08 15:42:46,628: start timer
[DEBUG]2021-05-08 15:42:46,629: create aliveObj downStation01 远程控制IO离线异常 timeout 120
[INFO]2021-05-08 15:42:46,637: load agv file: C:\Users\comba\Desktop\知识城地牛\knowledgeCity\agvCtrl/projects/knowledgeCity/agv.cfg
[INFO]2021-05-08 15:42:46,638: create lock <lock name:agvList.AGV01.lock,<unlocked _thread.RLock object owner=0 count=0 at 0x0000027CDB32E5A8>>
[DEBUG]2021-05-08 15:42:46,641: create aliveObj AGV01 AGV离线异常 timeout 300
[INFO]2021-05-08 15:42:46,642: AGV01 start agvList run thread
[INFO]2021-05-08 15:42:46,642: AGV01 start agvList run2 thread
[INFO]2021-05-08 15:42:46,643: create lock <lock name:agv.AGV01.lock_status,<unlocked _thread.RLock object owner=0 count=0 at 0x0000027CDB32E918>>
[DEBUG]2021-05-08 15:42:46,644: try connect AGV01 172.16.217.209:19204
[INFO]2021-05-08 15:42:46,645: create lock <lock name:agvList.AGV03.lock,<unlocked _thread.RLock object owner=0 count=0 at 0x0000027CDB32E968>>
[DEBUG]2021-05-08 15:42:46,647: create aliveObj AGV03 AGV离线异常 timeout 300
[INFO]2021-05-08 15:42:46,648: AGV03 start agvList run thread
[INFO]2021-05-08 15:42:46,648: AGV03 start agvList run2 thread
[INFO]2021-05-08 15:42:46,648: create lock <lock name:agvList.AGV04.lock,<unlocked _thread.RLock object owner=0 count=0 at 0x0000027CDB32EB98>>
[INFO]2021-05-08 15:42:46,648: create lock <lock name:agv.AGV03.lock_status,<unlocked _thread.RLock object owner=0 count=0 at 0x0000027CDB32EBE8>>
[DEBUG]2021-05-08 15:42:46,652: try connect AGV03 172.16.217.121:19204
[DEBUG]2021-05-08 15:42:46,653: create aliveObj AGV04 AGV离线异常 timeout 300
[INFO]2021-05-08 15:42:46,654: AGV04 start agvList run thread
[INFO]2021-05-08 15:42:46,654: AGV04 start agvList run2 thread
[INFO]2021-05-08 15:42:46,654: create lock <lock name:agvList.AGV02.lock,<unlocked _thread.RLock object owner=0 count=0 at 0x0000027CDB32EE18>>
[INFO]2021-05-08 15:42:46,654: create lock <lock name:agv.AGV04.lock_status,<unlocked _thread.RLock object owner=0 count=0 at 0x0000027CDB32EE68>>
[DEBUG]2021-05-08 15:42:46,656: try connect AGV04 172.16.217.211:19204
[DEBUG]2021-05-08 15:42:46,657: create aliveObj AGV02 AGV离线异常 timeout 300
[INFO]2021-05-08 15:42:46,657: AGV02 start agvList run thread
[INFO]2021-05-08 15:42:46,658: AGV02 start agvList run2 thread
[WARN]2021-05-08 15:42:46,658: Local server start! version 3.7.0, path C:\Users\comba\Desktop\知识城地牛\knowledgeCity\common, pid 13844
[INFO]2021-05-08 15:42:46,658: create lock <lock name:agv.AGV02.lock_status,<unlocked _thread.RLock object owner=0 count=0 at 0x0000027CDB32E418>>
[INFO]2021-05-08 15:42:46,659: add_ignore: taskStatus
[DEBUG]2021-05-08 15:42:46,661: try connect AGV02 172.16.217.213:19204
[INFO]2021-05-08 15:42:46,666: AGV04 connected 172.16.217.211 19204
[INFO]2021-05-08 15:42:46,667: create lock <lock name:agv.AGV04.lock_ctrl,<unlocked _thread.RLock object owner=0 count=0 at 0x0000027CDB32EFD0>>
[DEBUG]2021-05-08 15:42:46,667: try connect AGV04 172.16.217.211:19205
[INFO]2021-05-08 15:42:46,672: AGV04 connected 172.16.217.211 19205
[INFO]2021-05-08 15:42:46,673: create lock <lock name:agv.AGV04.lock_task,<unlocked _thread.RLock object owner=0 count=0 at 0x0000027CD91FCA58>>
[DEBUG]2021-05-08 15:42:46,673: try connect AGV04 172.16.217.211:19206
[INFO]2021-05-08 15:42:46,682: AGV04 connected 172.16.217.211 19206
[INFO]2021-05-08 15:42:46,687: create lock <lock name:agv.AGV04.lock_conf,<unlocked _thread.RLock object owner=0 count=0 at 0x0000027CD91FCB20>>
[DEBUG]2021-05-08 15:42:46,687: try connect AGV04 172.16.217.211:19207
[INFO]2021-05-08 15:42:46,692: AGV04 connected 172.16.217.211 19207
[INFO]2021-05-08 15:42:46,693: create lock <lock name:agv.AGV04.lock_core,<unlocked _thread.RLock object owner=0 count=0 at 0x0000027CD91FCAD0>>
[DEBUG]2021-05-08 15:42:46,694: try connect AGV04 172.16.217.211:19208
[INFO]2021-05-08 15:42:46,725: AGV04 connected 172.16.217.211 19208
[INFO]2021-05-08 15:42:46,725: create lock <lock name:agv.AGV04.lock_other,<unlocked _thread.RLock object owner=0 count=0 at 0x0000027CD91FCAF8>>
[DEBUG]2021-05-08 15:42:46,725: try connect AGV04 172.16.217.211:19210
[INFO]2021-05-08 15:42:46,751: AGV04 connected 172.16.217.211 19210
[INFO]2021-05-08 15:42:46,775: AGV04 current map comba-ZXC-F3
[INFO]2021-05-08 15:42:46,839: AGV04 is online
[WARN]2021-05-08 15:42:46,858: clear alarm obj=AGV04, typeId=54231, id=60964052697d98928ef141f9
[WARN]2021-05-08 15:42:46,864: clear alarm obj=AGV04, typeId=52200, id=60964054697d98928ef141fb
[DEBUG]2021-05-08 15:42:51,643: GET: http://127.0.0.1:8999/api/agv/init?appName=akmTask addr: 127.0.0.1
[INFO]2021-05-08 15:42:51,644: akmTask init client agvApi
[DEBUG]2021-05-08 15:42:51,646: used 2ms 200 OK application/json;charset=utf-8, GET: http://127.0.0.1:8999/api/agv/init?appName=akmTask
[DEBUG]2021-05-08 15:42:54,720: GET: http://127.0.0.1:8999/api/agv/startCharge?appName=akmTask addr: 127.0.0.1
[DEBUG]2021-05-08 15:42:54,754: used 34ms 200 OK application/json;charset=utf-8, GET: http://127.0.0.1:8999/api/agv/startCharge?appName=akmTask
[WARN]2021-05-08 15:42:54,861: timer_thread[tid:14132] <locked _thread.RLock object owner=14132 count=1 at 0x0000027CDA6A8620> ,hold 8231 ms
[INFO]2021-05-08 15:42:54,950: name=timer_thread, pid=13844, tid=14132
[01] File "C:/Users/comba/AppData/Local/Programs/Python/Python37/lib/threading.py", line 865, in run() 
[02] File "C:/Users/comba/Desktop/知识城地牛/knowledgeCity/common/mytimer.py", line 113, in _loop() 
[03] File "C:/Users/comba/Desktop/知识城地牛/knowledgeCity/common/lock.py", line 124, in _call() 
[04] File "C:/Users/comba/Desktop/知识城地牛/knowledgeCity/common/lock.py", line 102, in release() 
[05] File "C:/Users/comba/Desktop/知识城地牛/knowledgeCity/common/enhance.py", line 268, in getTrace() 
[06] File "C:/Users/comba/Desktop/知识城地牛/knowledgeCity/common/enhance.py", line 248, in getThreadStack()
[WARN]2021-05-08 15:42:56,067: AGV04 low battery charge,batteryLevel= 0.316 start charge level= 0.400
[WARN]2021-05-08 15:42:56,097: AGV04 battery 0.316 check failed: no_idle_9.442
[DEBUG]2021-05-08 15:42:56,418: send http_get: http://127.0.0.1:8999/api/remoteio/readDOList?id=upStation01
[ERROR]2021-05-08 15:42:56,650: connect AGV01 failed timed out
[ERROR]2021-05-08 15:42:56,668: connect AGV02 failed timed out
[ERROR]2021-05-08 15:42:56,668: connect AGV03 failed timed out
[DEBUG]2021-05-08 15:42:56,686: try connect AGV01 172.16.217.209:19204
[DEBUG]2021-05-08 15:42:56,704: try connect AGV02 172.16.217.213:19204
[DEBUG]2021-05-08 15:42:56,768: try connect AGV03 172.16.217.121:19204
[ERROR]2021-05-08 15:43:06,852: connect AGV01 failed timed out
[INFO]2021-05-08 15:43:06,886: AGV01 checkLink failed 172.16.217.209 19204
[WARN]2021-05-08 15:43:06,915: agvThread.AGV01[tid:14152] <lock name:agv.AGV01.lock_status,<locked _thread.RLock object owner=14152 count=1 at 0x0000027CDB32E918>> ,hold 20271 ms
[ERROR]2021-05-08 15:43:06,933: connect AGV02 failed timed out
[ERROR]2021-05-08 15:43:06,969: connect AGV03 failed timed out
[INFO]2021-05-08 15:43:06,980: AGV02 checkLink failed 172.16.217.213 19204
[INFO]2021-05-08 15:43:07,028: name=agvThread.AGV01, pid=13844, tid=14152
[01] File "C:/Users/comba/AppData/Local/Programs/Python/Python37/lib/threading.py", line 865, in run() 
[02] File "C:/Users/comba/Desktop/知识城地牛/knowledgeCity/agvCtrl/agvList.py", line 565, in run() 
[03] File "../driver/seerAgv/agvCtrl.py", line 36, in checkLink() 
[04] File "../driver/seerAgv/agvApi.py", line 184, in checkLink() 
[05] File "C:/Users/comba/Desktop/知识城地牛/knowledgeCity/common/lock.py", line 102, in release() 
[06] File "C:/Users/comba/Desktop/知识城地牛/knowledgeCity/common/enhance.py", line 268, in getTrace() 
[07] File "C:/Users/comba/Desktop/知识城地牛/knowledgeCity/common/enhance.py", line 248, in getThreadStack()
[INFO]2021-05-08 15:43:07,034: AGV03 checkLink failed 172.16.217.121 19204
[WARN]2021-05-08 15:43:07,046: agvThread.AGV02[tid:14204] <lock name:agv.AGV02.lock_status,<locked _thread.RLock object owner=14204 count=1 at 0x0000027CDB32E418>> ,hold 20385 ms
[WARN]2021-05-08 15:43:07,127: agvThread.AGV03[tid:14168] <lock name:agv.AGV03.lock_status,<locked _thread.RLock object owner=14168 count=1 at 0x0000027CDB32EBE8>> ,hold 20475 ms
[INFO]2021-05-08 15:43:07,191: name=agvThread.AGV02, pid=13844, tid=14204
[01] File "C:/Users/comba/AppData/Local/Programs/Python/Python37/lib/threading.py", line 865, in run() 
[02] File "C:/Users/comba/Desktop/知识城地牛/knowledgeCity/agvCtrl/agvList.py", line 565, in run() 
[03] File "../driver/seerAgv/agvCtrl.py", line 36, in checkLink() 
[04] File "../driver/seerAgv/agvApi.py", line 184, in checkLink() 
[05] File "C:/Users/comba/Desktop/知识城地牛/knowledgeCity/common/lock.py", line 102, in release() 
[06] File "C:/Users/comba/Desktop/知识城地牛/knowledgeCity/common/enhance.py", line 268, in getTrace() 
[07] File "C:/Users/comba/Desktop/知识城地牛/knowledgeCity/common/enhance.py", line 248, in getThreadStack()
[INFO]2021-05-08 15:43:07,247: name=agvThread.AGV03, pid=13844, tid=14168
[01] File "C:/Users/comba/AppData/Local/Programs/Python/Python37/lib/threading.py", line 865, in run() 
[02] File "C:/Users/comba/Desktop/知识城地牛/knowledgeCity/agvCtrl/agvList.py", line 565, in run() 
[03] File "../driver/seerAgv/agvCtrl.py", line 36, in checkLink() 
[04] File "../driver/seerAgv/agvApi.py", line 184, in checkLink() 
[05] File "C:/Users/comba/Desktop/知识城地牛/knowledgeCity/common/lock.py", line 102, in release() 
[06] File "C:/Users/comba/Desktop/知识城地牛/knowledgeCity/common/enhance.py", line 268, in getTrace() 
[07] File "C:/Users/comba/Desktop/知识城地牛/knowledgeCity/common/enhance.py", line 248, in getThreadStack()
[DEBUG]2021-05-08 15:43:09,092: try connect AGV01 172.16.217.209:19204
[DEBUG]2021-05-08 15:43:09,231: try connect AGV02 172.16.217.213:19204
[DEBUG]2021-05-08 15:43:09,283: try connect AGV03 172.16.217.121:19204
[CRITICAL]2021-05-08 15:43:11,851: upStation01 init failed cause a error: ('http get', 'http://127.0.0.1:8999/api/remoteio/readDOList', {'id': 'upStation01'}, 'error:', 'timed out')
pid=13844, ppid=13780, tid=14132
Traceback (most recent call last):
  File "C:\Users\comba\Desktop\知识城地牛\knowledgeCity\common\webutility.py", line 103, in http_get
    f = urllib.request.urlopen(u,timeout=timeout)
  File "C:\Users\comba\AppData\Local\Programs\Python\Python37\lib\urllib\request.py", line 222, in urlopen
    return opener.open(url, data, timeout)
  File "C:\Users\comba\AppData\Local\Programs\Python\Python37\lib\urllib\request.py", line 525, in open
    response = self._open(req, data)
  File "C:\Users\comba\AppData\Local\Programs\Python\Python37\lib\urllib\request.py", line 543, in _open
    '_open', req)
  File "C:\Users\comba\AppData\Local\Programs\Python\Python37\lib\urllib\request.py", line 503, in _call_chain
    result = func(*args)
  File "C:\Users\comba\AppData\Local\Programs\Python\Python37\lib\urllib\request.py", line 1345, in http_open
    return self.do_open(http.client.HTTPConnection, req)
  File "C:\Users\comba\AppData\Local\Programs\Python\Python37\lib\urllib\request.py", line 1320, in do_open
    r = h.getresponse()
  File "C:\Users\comba\AppData\Local\Programs\Python\Python37\lib\http\client.py", line 1321, in getresponse
    response.begin()
  File "C:\Users\comba\AppData\Local\Programs\Python\Python37\lib\http\client.py", line 296, in begin
    version, status, reason = self._read_status()
  File "C:\Users\comba\AppData\Local\Programs\Python\Python37\lib\http\client.py", line 257, in _read_status
    line = str(self.fp.readline(_MAXLINE + 1), "iso-8859-1")
  File "C:\Users\comba\AppData\Local\Programs\Python\Python37\lib\socket.py", line 589, in readinto
    return self._sock.recv_into(b)
socket.timeout: timed out

During handling of the above exception, another exception occurred:

Traceback (most recent call last):
  File "C:\Users\comba\Desktop\知识城地牛\knowledgeCity\autoCtrl\deviceCtrl.py", line 175, in _checkInit
    s = ioApi.readDOList(devices[d][ioId])["status"]
  File "..\remoteio\remoteioApi.py", line 73, in readDOList
    return _remoteio('/api/remoteio/readDOList', id, param)
  File "..\remoteio\remoteioApi.py", line 100, in _remoteio
    return http_get(url + apiurl, param)
  File "..\remoteio\remoteioApi.py", line 16, in http_get
    r = webutility.http_get(url, param)
  File "C:\Users\comba\Desktop\知识城地牛\knowledgeCity\common\webutility.py", line 105, in http_get
    raise Exception("http get",url,params,"error:",str(e))
Exception: ('http get', 'http://127.0.0.1:8999/api/remoteio/readDOList', {'id': 'upStation01'}, 'error:', 'timed out')

[DEBUG]2021-05-08 15:43:12,940: send http_get: http://127.0.0.1:8999/api/remoteio/readDOList?id=downStation01
[DEBUG]2021-05-08 15:43:13,134: GET: http://127.0.0.1:8999/api/scada/addTask?source=%E4%B8%89%E6%A5%BC%E5%A4%B9%E5%85%B7%E7%82%B9A&target=%E4%B8%89%E6%A5%BC%E5%A4%B9%E5%85%B7%E7%82%B9C addr: 127.0.0.1
[INFO]2021-05-08 15:43:13,156: Scada send a task to the server from 三楼夹具点A to 三楼夹具点C payloadId: None
[INFO]2021-05-08 15:43:13,196: create task[6096411173dabd3614753481]: type= scadaTask , 从三楼夹具点A运送货架到三楼夹具点C {'source': '三楼夹具点A', 'target': '三楼夹具点C', 'payloadId': None, 'priority': 1, 'type': 'scadaTask', 'taskName': '从三楼夹具点A运送货架到三楼夹具点C', 'createTime': datetime.datetime(2021, 5, 8, 15, 43, 13, 178113), 'updateTime': datetime.datetime(2021, 5, 8, 15, 43, 13, 178113), 'startTime': None, 'endTime': None, 'status': 'waiting', 'step': 'waiting', 'msg': None, 'history': [], '_id': ObjectId('6096411173dabd3614753481')}
[INFO]2021-05-08 15:43:13,225: 三楼夹具点C 三楼夹具点A
[INFO]2021-05-08 15:43:13,310: task[6096411173dabd3614753481][-] AP22(LM17) -> AP25(LM24) [waiting] is inside False
[INFO]2021-05-08 15:43:13,340: task cmd: got a task from scada task[6096411173dabd3614753481][-] AP22(LM17) -> AP25(LM24) [waiting]
[DEBUG]2021-05-08 15:43:13,369: used 235ms 200 OK application/json;charset=utf-8, GET: http://127.0.0.1:8999/api/scada/addTask?source=%E4%B8%89%E6%A5%BC%E5%A4%B9%E5%85%B7%E7%82%B9A&target=%E4%B8%89%E6%A5%BC%E5%A4%B9%E5%85%B7%E7%82%B9C
[DEBUG]2021-05-08 15:43:13,450: GET: http://127.0.0.1:8999/favicon.ico addr: 127.0.0.1
[DEBUG]2021-05-08 15:43:13,474: used 24ms 200 OK , GET: http://127.0.0.1:8999/favicon.ico
[CRITICAL]2021-05-08 15:43:17,828: [modbusApi: 172.16.167.221] execute fcode=1, addr=8256 exception:  cause a error: [WinError 10060] 由于连接方在一段时间后没有正确答复或连接的主机没有反应，连接尝试失败。
pid=13844, ppid=13780, tid=14232
Traceback (most recent call last):
  File "C:\Users\comba\Desktop\知识城地牛\knowledgeCity\common\modbusapi.py", line 35, in __execute
    data = self.master.execute(self.__salveId, fcode, start, quantity_of_x=num, output_value=value)
  File "C:\Users\comba\AppData\Local\Programs\Python\Python37\lib\site-packages\modbus_tk\utils.py", line 39, in new
    raise excpt
  File "C:\Users\comba\AppData\Local\Programs\Python\Python37\lib\site-packages\modbus_tk\utils.py", line 37, in new
    ret = fcn(*args, **kwargs)
  File "C:\Users\comba\AppData\Local\Programs\Python\Python37\lib\site-packages\modbus_tk\modbus.py", line 152, in execute
    self.open()
  File "C:\Users\comba\AppData\Local\Programs\Python\Python37\lib\site-packages\modbus_tk\modbus.py", line 99, in open
    self._do_open()
  File "C:\Users\comba\AppData\Local\Programs\Python\Python37\lib\site-packages\modbus_tk\modbus_tcp.py", line 173, in _do_open
    self._sock.connect((self._host, self._port))
TimeoutError: [WinError 10060] 由于连接方在一段时间后没有正确答复或连接的主机没有反应，连接尝试失败。

[WARN]2021-05-08 15:43:17,904: worker 2[tid:14232] <locked _thread.RLock object owner=14232 count=1 at 0x0000027CDA680800> ,hold 21361 ms
[INFO]2021-05-08 15:43:18,389: name=worker 2, pid=13844, tid=14232
[01] File "C:/Users/comba/AppData/Local/Programs/Python/Python37/lib/threading.py", line 865, in run() 
[02] File "C:/Users/comba/AppData/Local/Programs/Python/Python37/lib/site-packages/paste/httpserver.py", line 895, in worker_thread_callback() 
[03] File "C:/Users/comba/AppData/Local/Programs/Python/Python37/lib/site-packages/paste/httpserver.py", line 1069, in <lambda>() 
[04] File "C:/Users/comba/AppData/Local/Programs/Python/Python37/lib/site-packages/paste/httpserver.py", line 1085, in process_request_in_thread() 
[05] File "C:/Users/comba/AppData/Local/Programs/Python/Python37/lib/socketserver.py", line 357, in finish_request() 
[06] File "C:/Users/comba/AppData/Local/Programs/Python/Python37/lib/socketserver.py", line 717, in __init__() 
[07] File "C:/Users/comba/AppData/Local/Programs/Python/Python37/lib/site-packages/paste/httpserver.py", line 459, in handle() 
[08] File "C:/Users/comba/AppData/Local/Programs/Python/Python37/lib/http/server.py", line 426, in handle() 
[09] File "C:/Users/comba/AppData/Local/Programs/Python/Python37/lib/site-packages/paste/httpserver.py", line 454, in handle_one_request() 
[10] File "C:/Users/comba/AppData/Local/Programs/Python/Python37/lib/site-packages/paste/httpserver.py", line 304, in wsgi_execute() 
[11] File "C:/Users/comba/AppData/Local/Programs/Python/Python37/lib/site-packages/paste/translogger.py", line 69, in __call__() 
[12] File "C:/Users/comba/AppData/Local/Programs/Python/Python37/lib/site-packages/bottle.py", line 979, in __call__() 
[13] File "C:/Users/comba/AppData/Local/Programs/Python/Python37/lib/site-packages/bottle.py", line 954, in wsgi() 
[14] File "C:/Users/comba/AppData/Local/Programs/Python/Python37/lib/site-packages/bottle.py", line 862, in _handle() 
[15] File "C:/Users/comba/AppData/Local/Programs/Python/Python37/lib/site-packages/bottle.py", line 1742, in wrapper() 
[16] File "C:/Users/comba/Desktop/知识城地牛/knowledgeCity/common/webutility.py", line 465, in _enable_cors() 
[17] File "C:/Users/comba/Desktop/知识城地牛/knowledgeCity/common/webutility.py", line 481, in _enable_cors() 
[18] File "C:/Users/comba/Desktop/知识城地牛/knowledgeCity/common/scadaUtility.py", line 45, in __call() 
[19] File "C:/Users/comba/Desktop/知识城地牛/knowledgeCity/remoteio/main_remoteio.py", line 87, in urlReadDOList() 
[20] File "../remoteio/remoteioMgr.py", line 158, in readDOList() 
[21] File "../remoteio/remoteioMgr.py", line 262, in readDOList() 
[22] File "C:/Users/comba/Desktop/知识城地牛/knowledgeCity/common/lock.py", line 124, in _call() 
[23] File "C:/Users/comba/Desktop/知识城地牛/knowledgeCity/common/lock.py", line 102, in release() 
[24] File "C:/Users/comba/Desktop/知识城地牛/knowledgeCity/common/enhance.py", line 268, in getTrace() 
[25] File "C:/Users/comba/Desktop/知识城地牛/knowledgeCity/common/enhance.py", line 248, in getThreadStack()
[CRITICAL]2021-05-08 15:43:18,491: upStation01 readDIList fail cause a error: [WinError 10060] 由于连接方在一段时间后没有正确答复或连接的主机没有反应，连接尝试失败。
pid=13844, ppid=13780, tid=14232
Traceback (most recent call last):
  File "..\remoteio\remoteioMgr.py", line 262, in readDOList
    return self._read(M30, IO_LENTH)
  File "C:\Users\comba\Desktop\知识城地牛\knowledgeCity\common\lock.py", line 122, in _call
    return func(*p,**pp)
  File "..\remoteio\remoteioMgr.py", line 314, in _read
    s = self.master.read(mdef.READ_COILS,addr, length)
  File "C:\Users\comba\Desktop\知识城地牛\knowledgeCity\common\modbusapi.py", line 45, in read
    return self.__execute(fcode, start, num)
  File "C:\Users\comba\Desktop\知识城地牛\knowledgeCity\common\modbusapi.py", line 35, in __execute
    data = self.master.execute(self.__salveId, fcode, start, quantity_of_x=num, output_value=value)
  File "C:\Users\comba\AppData\Local\Programs\Python\Python37\lib\site-packages\modbus_tk\utils.py", line 39, in new
    raise excpt
  File "C:\Users\comba\AppData\Local\Programs\Python\Python37\lib\site-packages\modbus_tk\utils.py", line 37, in new
    ret = fcn(*args, **kwargs)
  File "C:\Users\comba\AppData\Local\Programs\Python\Python37\lib\site-packages\modbus_tk\modbus.py", line 152, in execute
    self.open()
  File "C:\Users\comba\AppData\Local\Programs\Python\Python37\lib\site-packages\modbus_tk\modbus.py", line 99, in open
    self._do_open()
  File "C:\Users\comba\AppData\Local\Programs\Python\Python37\lib\site-packages\modbus_tk\modbus_tcp.py", line 173, in _do_open
    self._sock.connect((self._host, self._port))
TimeoutError: [WinError 10060] 由于连接方在一段时间后没有正确答复或连接的主机没有反应，连接尝试失败。

[CRITICAL]2021-05-08 15:43:18,614: invoke <function urlReadDOList at 0x0000027CD91C1D08> cause a error: [WinError 10060] 由于连接方在一段时间后没有正确答复或连接的主机没有反应，连接尝试失败。
pid=13844, ppid=13780, tid=14232
Traceback (most recent call last):
  File "C:\Users\comba\Desktop\知识城地牛\knowledgeCity\common\scadaUtility.py", line 45, in __call
    ret = func(*p,**pp)
  File "C:\Users\comba\Desktop\知识城地牛\knowledgeCity\remoteio\main_remoteio.py", line 87, in urlReadDOList
    return ioMgr.readDOList(id)
  File "..\remoteio\remoteioMgr.py", line 158, in readDOList
    result=remoteioInfo.readDOList()
  File "..\remoteio\remoteioMgr.py", line 262, in readDOList
    return self._read(M30, IO_LENTH)
  File "C:\Users\comba\Desktop\知识城地牛\knowledgeCity\common\lock.py", line 122, in _call
    return func(*p,**pp)
  File "..\remoteio\remoteioMgr.py", line 314, in _read
    s = self.master.read(mdef.READ_COILS,addr, length)
  File "C:\Users\comba\Desktop\知识城地牛\knowledgeCity\common\modbusapi.py", line 45, in read
    return self.__execute(fcode, start, num)
  File "C:\Users\comba\Desktop\知识城地牛\knowledgeCity\common\modbusapi.py", line 35, in __execute
    data = self.master.execute(self.__salveId, fcode, start, quantity_of_x=num, output_value=value)
  File "C:\Users\comba\AppData\Local\Programs\Python\Python37\lib\site-packages\modbus_tk\utils.py", line 39, in new
    raise excpt
  File "C:\Users\comba\AppData\Local\Programs\Python\Python37\lib\site-packages\modbus_tk\utils.py", line 37, in new
    ret = fcn(*args, **kwargs)
  File "C:\Users\comba\AppData\Local\Programs\Python\Python37\lib\site-packages\modbus_tk\modbus.py", line 152, in execute
    self.open()
  File "C:\Users\comba\AppData\Local\Programs\Python\Python37\lib\site-packages\modbus_tk\modbus.py", line 99, in open
    self._do_open()
  File "C:\Users\comba\AppData\Local\Programs\Python\Python37\lib\site-packages\modbus_tk\modbus_tcp.py", line 173, in _do_open
    self._sock.connect((self._host, self._port))
TimeoutError: [WinError 10060] 由于连接方在一段时间后没有正确答复或连接的主机没有反应，连接尝试失败。

[ERROR]2021-05-08 15:43:19,187: connect AGV01 failed timed out
[INFO]2021-05-08 15:43:19,209: AGV01 checkLink failed 172.16.217.209 19204
[WARN]2021-05-08 15:43:19,251: agvThread.AGV01[tid:14152] <lock name:agv.AGV01.lock_status,<locked _thread.RLock object owner=14152 count=1 at 0x0000027CDB32E918>> ,hold 10159 ms
[ERROR]2021-05-08 15:43:19,297: connect AGV02 failed timed out
[ERROR]2021-05-08 15:43:19,321: connect AGV03 failed timed out
[INFO]2021-05-08 15:43:19,321: name=agvThread.AGV01, pid=13844, tid=14152
[01] File "C:/Users/comba/AppData/Local/Programs/Python/Python37/lib/threading.py", line 865, in run() 
[02] File "C:/Users/comba/Desktop/知识城地牛/knowledgeCity/agvCtrl/agvList.py", line 565, in run() 
[03] File "../driver/seerAgv/agvCtrl.py", line 36, in checkLink() 
[04] File "../driver/seerAgv/agvApi.py", line 184, in checkLink() 
[05] File "C:/Users/comba/Desktop/知识城地牛/knowledgeCity/common/lock.py", line 102, in release() 
[06] File "C:/Users/comba/Desktop/知识城地牛/knowledgeCity/common/enhance.py", line 268, in getTrace() 
[07] File "C:/Users/comba/Desktop/知识城地牛/knowledgeCity/common/enhance.py", line 248, in getThreadStack()
[INFO]2021-05-08 15:43:19,321: AGV02 checkLink failed 172.16.217.213 19204
[INFO]2021-05-08 15:43:19,338: AGV03 checkLink failed 172.16.217.121 19204
[WARN]2021-05-08 15:43:19,415: agvThread.AGV02[tid:14204] <lock name:agv.AGV02.lock_status,<locked _thread.RLock object owner=14204 count=1 at 0x0000027CDB32E418>> ,hold 10184 ms
[WARN]2021-05-08 15:43:19,444: agvThread.AGV03[tid:14168] <lock name:agv.AGV03.lock_status,<locked _thread.RLock object owner=14168 count=1 at 0x0000027CDB32EBE8>> ,hold 10161 ms
[INFO]2021-05-08 15:43:19,580: name=agvThread.AGV02, pid=13844, tid=14204
[01] File "C:/Users/comba/AppData/Local/Programs/Python/Python37/lib/threading.py", line 865, in run() 
[02] File "C:/Users/comba/Desktop/知识城地牛/knowledgeCity/agvCtrl/agvList.py", line 565, in run() 
[03] File "../driver/seerAgv/agvCtrl.py", line 36, in checkLink() 
[04] File "../driver/seerAgv/agvApi.py", line 184, in checkLink() 
[05] File "C:/Users/comba/Desktop/知识城地牛/knowledgeCity/common/lock.py", line 102, in release() 
[06] File "C:/Users/comba/Desktop/知识城地牛/knowledgeCity/common/enhance.py", line 268, in getTrace() 
[07] File "C:/Users/comba/Desktop/知识城地牛/knowledgeCity/common/enhance.py", line 248, in getThreadStack()
[INFO]2021-05-08 15:43:19,620: name=agvThread.AGV03, pid=13844, tid=14168
[01] File "C:/Users/comba/AppData/Local/Programs/Python/Python37/lib/threading.py", line 865, in run() 
[02] File "C:/Users/comba/Desktop/知识城地牛/knowledgeCity/agvCtrl/agvList.py", line 565, in run() 
[03] File "../driver/seerAgv/agvCtrl.py", line 36, in checkLink() 
[04] File "../driver/seerAgv/agvApi.py", line 184, in checkLink() 
[05] File "C:/Users/comba/Desktop/知识城地牛/knowledgeCity/common/lock.py", line 102, in release() 
[06] File "C:/Users/comba/Desktop/知识城地牛/knowledgeCity/common/enhance.py", line 268, in getTrace() 
[07] File "C:/Users/comba/Desktop/知识城地牛/knowledgeCity/common/enhance.py", line 248, in getThreadStack()
[DEBUG]2021-05-08 15:43:21,379: try connect AGV01 172.16.217.209:19204
[DEBUG]2021-05-08 15:43:21,646: try connect AGV02 172.16.217.213:19204
[DEBUG]2021-05-08 15:43:21,694: try connect AGV03 172.16.217.121:19204
[CRITICAL]2021-05-08 15:43:28,104: downStation01 init failed cause a error: ('http get', 'http://127.0.0.1:8999/api/remoteio/readDOList', {'id': 'downStation01'}, 'error:', 'timed out')
pid=13844, ppid=13780, tid=14132
Traceback (most recent call last):
  File "C:\Users\comba\Desktop\知识城地牛\knowledgeCity\common\webutility.py", line 103, in http_get
    f = urllib.request.urlopen(u,timeout=timeout)
  File "C:\Users\comba\AppData\Local\Programs\Python\Python37\lib\urllib\request.py", line 222, in urlopen
    return opener.open(url, data, timeout)
  File "C:\Users\comba\AppData\Local\Programs\Python\Python37\lib\urllib\request.py", line 525, in open
    response = self._open(req, data)
  File "C:\Users\comba\AppData\Local\Programs\Python\Python37\lib\urllib\request.py", line 543, in _open
    '_open', req)
  File "C:\Users\comba\AppData\Local\Programs\Python\Python37\lib\urllib\request.py", line 503, in _call_chain
    result = func(*args)
  File "C:\Users\comba\AppData\Local\Programs\Python\Python37\lib\urllib\request.py", line 1345, in http_open
    return self.do_open(http.client.HTTPConnection, req)
  File "C:\Users\comba\AppData\Local\Programs\Python\Python37\lib\urllib\request.py", line 1320, in do_open
    r = h.getresponse()
  File "C:\Users\comba\AppData\Local\Programs\Python\Python37\lib\http\client.py", line 1321, in getresponse
    response.begin()
  File "C:\Users\comba\AppData\Local\Programs\Python\Python37\lib\http\client.py", line 296, in begin
    version, status, reason = self._read_status()
  File "C:\Users\comba\AppData\Local\Programs\Python\Python37\lib\http\client.py", line 257, in _read_status
    line = str(self.fp.readline(_MAXLINE + 1), "iso-8859-1")
  File "C:\Users\comba\AppData\Local\Programs\Python\Python37\lib\socket.py", line 589, in readinto
    return self._sock.recv_into(b)
socket.timeout: timed out

During handling of the above exception, another exception occurred:

Traceback (most recent call last):
  File "C:\Users\comba\Desktop\知识城地牛\knowledgeCity\autoCtrl\deviceCtrl.py", line 175, in _checkInit
    s = ioApi.readDOList(devices[d][ioId])["status"]
  File "..\remoteio\remoteioApi.py", line 73, in readDOList
    return _remoteio('/api/remoteio/readDOList', id, param)
  File "..\remoteio\remoteioApi.py", line 100, in _remoteio
    return http_get(url + apiurl, param)
  File "..\remoteio\remoteioApi.py", line 16, in http_get
    r = webutility.http_get(url, param)
  File "C:\Users\comba\Desktop\知识城地牛\knowledgeCity\common\webutility.py", line 105, in http_get
    raise Exception("http get",url,params,"error:",str(e))
Exception: ('http get', 'http://127.0.0.1:8999/api/remoteio/readDOList', {'id': 'downStation01'}, 'error:', 'timed out')

[INFO]2021-05-08 15:43:29,151: init IO success
[DEBUG]2021-05-08 15:43:29,175: send http_get: http://127.0.0.1:8999/api/remoteio/readDOList?id=upStation01
[ERROR]2021-05-08 15:43:31,452: connect AGV01 failed timed out
[INFO]2021-05-08 15:43:31,470: AGV01 checkLink failed 172.16.217.209 19204
[WARN]2021-05-08 15:43:31,543: agvThread.AGV01[tid:14152] <lock name:agv.AGV01.lock_status,<locked _thread.RLock object owner=14152 count=1 at 0x0000027CDB32E918>> ,hold 10164 ms
[INFO]2021-05-08 15:43:31,607: name=agvThread.AGV01, pid=13844, tid=14152
[01] File "C:/Users/comba/AppData/Local/Programs/Python/Python37/lib/threading.py", line 865, in run() 
[02] File "C:/Users/comba/Desktop/知识城地牛/knowledgeCity/agvCtrl/agvList.py", line 565, in run() 
[03] File "../driver/seerAgv/agvCtrl.py", line 36, in checkLink() 
[04] File "../driver/seerAgv/agvApi.py", line 184, in checkLink() 
[05] File "C:/Users/comba/Desktop/知识城地牛/knowledgeCity/common/lock.py", line 102, in release() 
[06] File "C:/Users/comba/Desktop/知识城地牛/knowledgeCity/common/enhance.py", line 268, in getTrace() 
[07] File "C:/Users/comba/Desktop/知识城地牛/knowledgeCity/common/enhance.py", line 248, in getThreadStack()
[ERROR]2021-05-08 15:43:31,689: connect AGV02 failed timed out
[INFO]2021-05-08 15:43:31,736: AGV02 checkLink failed 172.16.217.213 19204
[WARN]2021-05-08 15:43:31,760: agvThread.AGV02[tid:14204] <lock name:agv.AGV02.lock_status,<locked _thread.RLock object owner=14204 count=1 at 0x0000027CDB32E418>> ,hold 10114 ms
[ERROR]2021-05-08 15:43:31,782: connect AGV03 failed timed out
[INFO]2021-05-08 15:43:31,824: name=agvThread.AGV02, pid=13844, tid=14204
[01] File "C:/Users/comba/AppData/Local/Programs/Python/Python37/lib/threading.py", line 865, in run() 
[02] File "C:/Users/comba/Desktop/知识城地牛/knowledgeCity/agvCtrl/agvList.py", line 565, in run() 
[03] File "../driver/seerAgv/agvCtrl.py", line 36, in checkLink() 
[04] File "../driver/seerAgv/agvApi.py", line 184, in checkLink() 
[05] File "C:/Users/comba/Desktop/知识城地牛/knowledgeCity/common/lock.py", line 102, in release() 
[06] File "C:/Users/comba/Desktop/知识城地牛/knowledgeCity/common/enhance.py", line 268, in getTrace() 
[07] File "C:/Users/comba/Desktop/知识城地牛/knowledgeCity/common/enhance.py", line 248, in getThreadStack()
[INFO]2021-05-08 15:43:31,829: AGV03 checkLink failed 172.16.217.121 19204
[WARN]2021-05-08 15:43:31,898: agvThread.AGV03[tid:14168] <lock name:agv.AGV03.lock_status,<locked _thread.RLock object owner=14168 count=1 at 0x0000027CDB32EBE8>> ,hold 10204 ms
[INFO]2021-05-08 15:43:32,016: name=agvThread.AGV03, pid=13844, tid=14168
[01] File "C:/Users/comba/AppData/Local/Programs/Python/Python37/lib/threading.py", line 865, in run() 
[02] File "C:/Users/comba/Desktop/知识城地牛/knowledgeCity/agvCtrl/agvList.py", line 565, in run() 
[03] File "../driver/seerAgv/agvCtrl.py", line 36, in checkLink() 
[04] File "../driver/seerAgv/agvApi.py", line 184, in checkLink() 
[05] File "C:/Users/comba/Desktop/知识城地牛/knowledgeCity/common/lock.py", line 102, in release() 
[06] File "C:/Users/comba/Desktop/知识城地牛/knowledgeCity/common/enhance.py", line 268, in getTrace() 
[07] File "C:/Users/comba/Desktop/知识城地牛/knowledgeCity/common/enhance.py", line 248, in getThreadStack()
[DEBUG]2021-05-08 15:43:33,637: try connect AGV01 172.16.217.209:19204
[DEBUG]2021-05-08 15:43:33,880: try connect AGV02 172.16.217.213:19204
[DEBUG]2021-05-08 15:43:34,042: try connect AGV03 172.16.217.121:19204
[CRITICAL]2021-05-08 15:43:38,711: [modbusApi: 172.16.167.220] execute fcode=1, addr=8256 exception:  cause a error: [WinError 10060] 由于连接方在一段时间后没有正确答复或连接的主机没有反应，连接尝试失败。
pid=13844, ppid=13780, tid=14236
Traceback (most recent call last):
  File "C:\Users\comba\Desktop\知识城地牛\knowledgeCity\common\modbusapi.py", line 35, in __execute
    data = self.master.execute(self.__salveId, fcode, start, quantity_of_x=num, output_value=value)
  File "C:\Users\comba\AppData\Local\Programs\Python\Python37\lib\site-packages\modbus_tk\utils.py", line 39, in new
    raise excpt
  File "C:\Users\comba\AppData\Local\Programs\Python\Python37\lib\site-packages\modbus_tk\utils.py", line 37, in new
    ret = fcn(*args, **kwargs)
  File "C:\Users\comba\AppData\Local\Programs\Python\Python37\lib\site-packages\modbus_tk\modbus.py", line 152, in execute
    self.open()
  File "C:\Users\comba\AppData\Local\Programs\Python\Python37\lib\site-packages\modbus_tk\modbus.py", line 99, in open
    self._do_open()
  File "C:\Users\comba\AppData\Local\Programs\Python\Python37\lib\site-packages\modbus_tk\modbus_tcp.py", line 173, in _do_open
    self._sock.connect((self._host, self._port))
TimeoutError: [WinError 10060] 由于连接方在一段时间后没有正确答复或连接的主机没有反应，连接尝试失败。

[WARN]2021-05-08 15:43:38,740: worker 3[tid:14236] <locked _thread.RLock object owner=14236 count=1 at 0x0000027CDA680B20> ,hold 25687 ms
[INFO]2021-05-08 15:43:38,840: name=worker 3, pid=13844, tid=14236
[01] File "C:/Users/comba/AppData/Local/Programs/Python/Python37/lib/threading.py", line 865, in run() 
[02] File "C:/Users/comba/AppData/Local/Programs/Python/Python37/lib/site-packages/paste/httpserver.py", line 895, in worker_thread_callback() 
[03] File "C:/Users/comba/AppData/Local/Programs/Python/Python37/lib/site-packages/paste/httpserver.py", line 1069, in <lambda>() 
[04] File "C:/Users/comba/AppData/Local/Programs/Python/Python37/lib/site-packages/paste/httpserver.py", line 1085, in process_request_in_thread() 
[05] File "C:/Users/comba/AppData/Local/Programs/Python/Python37/lib/socketserver.py", line 357, in finish_request() 
[06] File "C:/Users/comba/AppData/Local/Programs/Python/Python37/lib/socketserver.py", line 717, in __init__() 
[07] File "C:/Users/comba/AppData/Local/Programs/Python/Python37/lib/site-packages/paste/httpserver.py", line 459, in handle() 
[08] File "C:/Users/comba/AppData/Local/Programs/Python/Python37/lib/http/server.py", line 426, in handle() 
[09] File "C:/Users/comba/AppData/Local/Programs/Python/Python37/lib/site-packages/paste/httpserver.py", line 454, in handle_one_request() 
[10] File "C:/Users/comba/AppData/Local/Programs/Python/Python37/lib/site-packages/paste/httpserver.py", line 304, in wsgi_execute() 
[11] File "C:/Users/comba/AppData/Local/Programs/Python/Python37/lib/site-packages/paste/translogger.py", line 69, in __call__() 
[12] File "C:/Users/comba/AppData/Local/Programs/Python/Python37/lib/site-packages/bottle.py", line 979, in __call__() 
[13] File "C:/Users/comba/AppData/Local/Programs/Python/Python37/lib/site-packages/bottle.py", line 954, in wsgi() 
[14] File "C:/Users/comba/AppData/Local/Programs/Python/Python37/lib/site-packages/bottle.py", line 862, in _handle() 
[15] File "C:/Users/comba/AppData/Local/Programs/Python/Python37/lib/site-packages/bottle.py", line 1742, in wrapper() 
[16] File "C:/Users/comba/Desktop/知识城地牛/knowledgeCity/common/webutility.py", line 465, in _enable_cors() 
[17] File "C:/Users/comba/Desktop/知识城地牛/knowledgeCity/common/webutility.py", line 481, in _enable_cors() 
[18] File "C:/Users/comba/Desktop/知识城地牛/knowledgeCity/common/scadaUtility.py", line 45, in __call() 
[19] File "C:/Users/comba/Desktop/知识城地牛/knowledgeCity/remoteio/main_remoteio.py", line 87, in urlReadDOList() 
[20] File "../remoteio/remoteioMgr.py", line 158, in readDOList() 
[21] File "../remoteio/remoteioMgr.py", line 262, in readDOList() 
[22] File "C:/Users/comba/Desktop/知识城地牛/knowledgeCity/common/lock.py", line 124, in _call() 
[23] File "C:/Users/comba/Desktop/知识城地牛/knowledgeCity/common/lock.py", line 102, in release() 
[24] File "C:/Users/comba/Desktop/知识城地牛/knowledgeCity/common/enhance.py", line 268, in getTrace() 
[25] File "C:/Users/comba/Desktop/知识城地牛/knowledgeCity/common/enhance.py", line 248, in getThreadStack()
[CRITICAL]2021-05-08 15:43:38,925: downStation01 readDIList fail cause a error: [WinError 10060] 由于连接方在一段时间后没有正确答复或连接的主机没有反应，连接尝试失败。
pid=13844, ppid=13780, tid=14236
Traceback (most recent call last):
  File "..\remoteio\remoteioMgr.py", line 262, in readDOList
    return self._read(M30, IO_LENTH)
  File "C:\Users\comba\Desktop\知识城地牛\knowledgeCity\common\lock.py", line 122, in _call
    return func(*p,**pp)
  File "..\remoteio\remoteioMgr.py", line 314, in _read
    s = self.master.read(mdef.READ_COILS,addr, length)
  File "C:\Users\comba\Desktop\知识城地牛\knowledgeCity\common\modbusapi.py", line 45, in read
    return self.__execute(fcode, start, num)
  File "C:\Users\comba\Desktop\知识城地牛\knowledgeCity\common\modbusapi.py", line 35, in __execute
    data = self.master.execute(self.__salveId, fcode, start, quantity_of_x=num, output_value=value)
  File "C:\Users\comba\AppData\Local\Programs\Python\Python37\lib\site-packages\modbus_tk\utils.py", line 39, in new
    raise excpt
  File "C:\Users\comba\AppData\Local\Programs\Python\Python37\lib\site-packages\modbus_tk\utils.py", line 37, in new
    ret = fcn(*args, **kwargs)
  File "C:\Users\comba\AppData\Local\Programs\Python\Python37\lib\site-packages\modbus_tk\modbus.py", line 152, in execute
    self.open()
  File "C:\Users\comba\AppData\Local\Programs\Python\Python37\lib\site-packages\modbus_tk\modbus.py", line 99, in open
    self._do_open()
  File "C:\Users\comba\AppData\Local\Programs\Python\Python37\lib\site-packages\modbus_tk\modbus_tcp.py", line 173, in _do_open
    self._sock.connect((self._host, self._port))
TimeoutError: [WinError 10060] 由于连接方在一段时间后没有正确答复或连接的主机没有反应，连接尝试失败。

[CRITICAL]2021-05-08 15:43:39,019: invoke <function urlReadDOList at 0x0000027CD91C1D08> cause a error: [WinError 10060] 由于连接方在一段时间后没有正确答复或连接的主机没有反应，连接尝试失败。
pid=13844, ppid=13780, tid=14236
Traceback (most recent call last):
  File "C:\Users\comba\Desktop\知识城地牛\knowledgeCity\common\scadaUtility.py", line 45, in __call
    ret = func(*p,**pp)
  File "C:\Users\comba\Desktop\知识城地牛\knowledgeCity\remoteio\main_remoteio.py", line 87, in urlReadDOList
    return ioMgr.readDOList(id)
  File "..\remoteio\remoteioMgr.py", line 158, in readDOList
    result=remoteioInfo.readDOList()
  File "..\remoteio\remoteioMgr.py", line 262, in readDOList
    return self._read(M30, IO_LENTH)
  File "C:\Users\comba\Desktop\知识城地牛\knowledgeCity\common\lock.py", line 122, in _call
    return func(*p,**pp)
  File "..\remoteio\remoteioMgr.py", line 314, in _read
    s = self.master.read(mdef.READ_COILS,addr, length)
  File "C:\Users\comba\Desktop\知识城地牛\knowledgeCity\common\modbusapi.py", line 45, in read
    return self.__execute(fcode, start, num)
  File "C:\Users\comba\Desktop\知识城地牛\knowledgeCity\common\modbusapi.py", line 35, in __execute
    data = self.master.execute(self.__salveId, fcode, start, quantity_of_x=num, output_value=value)
  File "C:\Users\comba\AppData\Local\Programs\Python\Python37\lib\site-packages\modbus_tk\utils.py", line 39, in new
    raise excpt
  File "C:\Users\comba\AppData\Local\Programs\Python\Python37\lib\site-packages\modbus_tk\utils.py", line 37, in new
    ret = fcn(*args, **kwargs)
  File "C:\Users\comba\AppData\Local\Programs\Python\Python37\lib\site-packages\modbus_tk\modbus.py", line 152, in execute
    self.open()
  File "C:\Users\comba\AppData\Local\Programs\Python\Python37\lib\site-packages\modbus_tk\modbus.py", line 99, in open
    self._do_open()
  File "C:\Users\comba\AppData\Local\Programs\Python\Python37\lib\site-packages\modbus_tk\modbus_tcp.py", line 173, in _do_open
    self._sock.connect((self._host, self._port))
TimeoutError: [WinError 10060] 由于连接方在一段时间后没有正确答复或连接的主机没有反应，连接尝试失败。

[ERROR]2021-05-08 15:43:43,697: connect AGV01 failed timed out
[INFO]2021-05-08 15:43:43,744: AGV01 checkLink failed 172.16.217.209 19204
[WARN]2021-05-08 15:43:43,779: agvThread.AGV01[tid:14152] <lock name:agv.AGV01.lock_status,<locked _thread.RLock object owner=14152 count=1 at 0x0000027CDB32E918>> ,hold 10142 ms
[INFO]2021-05-08 15:43:43,902: name=agvThread.AGV01, pid=13844, tid=14152
[01] File "C:/Users/comba/AppData/Local/Programs/Python/Python37/lib/threading.py", line 865, in run() 
[02] File "C:/Users/comba/Desktop/知识城地牛/knowledgeCity/agvCtrl/agvList.py", line 565, in run() 
[03] File "../driver/seerAgv/agvCtrl.py", line 36, in checkLink() 
[04] File "../driver/seerAgv/agvApi.py", line 184, in checkLink() 
[05] File "C:/Users/comba/Desktop/知识城地牛/knowledgeCity/common/lock.py", line 102, in release() 
[06] File "C:/Users/comba/Desktop/知识城地牛/knowledgeCity/common/enhance.py", line 268, in getTrace() 
[07] File "C:/Users/comba/Desktop/知识城地牛/knowledgeCity/common/enhance.py", line 248, in getThreadStack()
[ERROR]2021-05-08 15:43:43,968: connect AGV02 failed timed out
[INFO]2021-05-08 15:43:44,003: AGV02 checkLink failed 172.16.217.213 19204
[WARN]2021-05-08 15:43:44,033: agvThread.AGV02[tid:14204] <lock name:agv.AGV02.lock_status,<locked _thread.RLock object owner=14204 count=1 at 0x0000027CDB32E418>> ,hold 10153 ms
[ERROR]2021-05-08 15:43:44,092: connect AGV03 failed timed out
[INFO]2021-05-08 15:43:44,127: AGV03 checkLink failed 172.16.217.121 19204
[WARN]2021-05-08 15:43:44,157: agvThread.AGV03[tid:14168] <lock name:agv.AGV03.lock_status,<locked _thread.RLock object owner=14168 count=1 at 0x0000027CDB32EBE8>> ,hold 10115 ms
[INFO]2021-05-08 15:43:44,180: name=agvThread.AGV02, pid=13844, tid=14204
[01] File "C:/Users/comba/AppData/Local/Programs/Python/Python37/lib/threading.py", line 865, in run() 
[02] File "C:/Users/comba/Desktop/知识城地牛/knowledgeCity/agvCtrl/agvList.py", line 565, in run() 
[03] File "../driver/seerAgv/agvCtrl.py", line 36, in checkLink() 
[04] File "../driver/seerAgv/agvApi.py", line 184, in checkLink() 
[05] File "C:/Users/comba/Desktop/知识城地牛/knowledgeCity/common/lock.py", line 102, in release() 
[06] File "C:/Users/comba/Desktop/知识城地牛/knowledgeCity/common/enhance.py", line 268, in getTrace() 
[07] File "C:/Users/comba/Desktop/知识城地牛/knowledgeCity/common/enhance.py", line 248, in getThreadStack()
[INFO]2021-05-08 15:43:44,250: name=agvThread.AGV03, pid=13844, tid=14168
[01] File "C:/Users/comba/AppData/Local/Programs/Python/Python37/lib/threading.py", line 865, in run() 
[02] File "C:/Users/comba/Desktop/知识城地牛/knowledgeCity/agvCtrl/agvList.py", line 565, in run() 
[03] File "../driver/seerAgv/agvCtrl.py", line 36, in checkLink() 
[04] File "../driver/seerAgv/agvApi.py", line 184, in checkLink() 
[05] File "C:/Users/comba/Desktop/知识城地牛/knowledgeCity/common/lock.py", line 102, in release() 
[06] File "C:/Users/comba/Desktop/知识城地牛/knowledgeCity/common/enhance.py", line 268, in getTrace() 
[07] File "C:/Users/comba/Desktop/知识城地牛/knowledgeCity/common/enhance.py", line 248, in getThreadStack()
[CRITICAL]2021-05-08 15:43:44,363: readDIList error cause a error: ('http get', 'http://127.0.0.1:8999/api/remoteio/readDOList', {'id': 'upStation01'}, 'error:', 'timed out')
pid=13844, ppid=13780, tid=14132
Traceback (most recent call last):
  File "C:\Users\comba\Desktop\知识城地牛\knowledgeCity\common\webutility.py", line 103, in http_get
    f = urllib.request.urlopen(u,timeout=timeout)
  File "C:\Users\comba\AppData\Local\Programs\Python\Python37\lib\urllib\request.py", line 222, in urlopen
    return opener.open(url, data, timeout)
  File "C:\Users\comba\AppData\Local\Programs\Python\Python37\lib\urllib\request.py", line 525, in open
    response = self._open(req, data)
  File "C:\Users\comba\AppData\Local\Programs\Python\Python37\lib\urllib\request.py", line 543, in _open
    '_open', req)
  File "C:\Users\comba\AppData\Local\Programs\Python\Python37\lib\urllib\request.py", line 503, in _call_chain
    result = func(*args)
  File "C:\Users\comba\AppData\Local\Programs\Python\Python37\lib\urllib\request.py", line 1345, in http_open
    return self.do_open(http.client.HTTPConnection, req)
  File "C:\Users\comba\AppData\Local\Programs\Python\Python37\lib\urllib\request.py", line 1320, in do_open
    r = h.getresponse()
  File "C:\Users\comba\AppData\Local\Programs\Python\Python37\lib\http\client.py", line 1321, in getresponse
    response.begin()
  File "C:\Users\comba\AppData\Local\Programs\Python\Python37\lib\http\client.py", line 296, in begin
    version, status, reason = self._read_status()
  File "C:\Users\comba\AppData\Local\Programs\Python\Python37\lib\http\client.py", line 257, in _read_status
    line = str(self.fp.readline(_MAXLINE + 1), "iso-8859-1")
  File "C:\Users\comba\AppData\Local\Programs\Python\Python37\lib\socket.py", line 589, in readinto
    return self._sock.recv_into(b)
socket.timeout: timed out

During handling of the above exception, another exception occurred:

Traceback (most recent call last):
  File "C:\Users\comba\Desktop\知识城地牛\knowledgeCity\autoCtrl\deviceCtrl.py", line 71, in _monitorDevices
    s1 = ioApi.readDOList(devices[d]["io1"])["status"] #上板机
  File "..\remoteio\remoteioApi.py", line 73, in readDOList
    return _remoteio('/api/remoteio/readDOList', id, param)
  File "..\remoteio\remoteioApi.py", line 100, in _remoteio
    return http_get(url + apiurl, param)
  File "..\remoteio\remoteioApi.py", line 16, in http_get
    r = webutility.http_get(url, param)
  File "C:\Users\comba\Desktop\知识城地牛\knowledgeCity\common\webutility.py", line 105, in http_get
    raise Exception("http get",url,params,"error:",str(e))
Exception: ('http get', 'http://127.0.0.1:8999/api/remoteio/readDOList', {'id': 'upStation01'}, 'error:', 'timed out')

[DEBUG]2021-05-08 15:43:45,941: try connect AGV01 172.16.217.209:19204
[DEBUG]2021-05-08 15:43:46,271: try connect AGV02 172.16.217.213:19204
[DEBUG]2021-05-08 15:43:46,331: try connect AGV03 172.16.217.121:19204
[WARN]2021-05-08 15:43:46,895: AGV04 low battery charge,batteryLevel= 0.316 start charge level= 0.400
[INFO]2021-05-08 15:43:46,929: AGV04 battery 0.316 check success
[WARN]2021-05-08 15:43:47,123: AGV04 Can't find charge point at comba-ZXC-F3 battery: 0.316
[INFO]2021-05-08 15:43:47,170: task[6096411173dabd3614753481]:  start {'failMsg': '任务等待执行', 'startTime': datetime.datetime(2021, 5, 8, 15, 43, 47, 158061), 'updateTime': datetime.datetime(2021, 5, 8, 15, 43, 47, 158061), 'status': 'running'}
[INFO]2021-05-08 15:43:47,204: task: start task[6096411173dabd3614753481][-] AP22(LM17) -> AP25(LM24) [waiting]
[INFO]2021-05-08 15:43:47,216: this is handle taskStep=============>waiting
[INFO]2021-05-08 15:43:47,263: task[6096411173dabd3614753481] update info: {'failMsg': '等待分配小车', 'updateTime': datetime.datetime(2021, 5, 8, 15, 43, 47, 240811)}
[DEBUG]2021-05-08 15:43:47,298: task[6096411173dabd3614753481][-] AP22(LM17) -> AP25(LM24) [waitForAgv] waiting -> waitForAgv
[DEBUG]2021-05-08 15:43:48,215: send http_get: http://127.0.0.1:8999/api/remoteio/readDOList?id=upStation01
[INFO]2021-05-08 15:43:48,553: this is handle taskStep=============>waitForAgv
[DEBUG]2021-05-08 15:43:48,671: GET: http://127.0.0.1:8999/api/agv/apply?appName=akmTask&autoLock=False&exclude&loc=AP22&mapId=comba-ZXC-F3&taskId=6096411173dabd3614753481&timeout=10 addr: 127.0.0.1
[INFO]2021-05-08 15:43:48,700: agvControl中的_apply进去
[INFO]2021-05-08 15:43:48,753: [('comba-ZXC-F3.LM20', 'AGV04')]
[INFO]2021-05-08 15:43:49,663: apply AGV04 ,taskId: 6096411173dabd3614753481 ,loc comba-ZXC-F3.AP22 ,autoLock False , used 910 ms
[INFO]2021-05-08 15:43:49,693: AGV04
[INFO]2021-05-08 15:43:49,716: 5555555555555555555555555
[INFO]2021-05-08 15:43:49,751: 6666666666666666666666666
[INFO]2021-05-08 15:43:49,804: AGV04
[DEBUG]2021-05-08 15:43:49,883: used 1212ms 200 OK application/json;charset=utf-8, GET: http://127.0.0.1:8999/api/agv/apply?appName=akmTask&autoLock=False&exclude&loc=AP22&mapId=comba-ZXC-F3&taskId=6096411173dabd3614753481&timeout=10
[INFO]2021-05-08 15:43:49,969: comba-ZXC-F3.AP22 comba-ZXC-F3.AP25
[INFO]2021-05-08 15:43:49,998: AGV04
[INFO]2021-05-08 15:43:50,021: 判断类型
[INFO]2021-05-08 15:43:50,056: 1111111111111111111111
[DEBUG]2021-05-08 15:43:50,108: GET: http://127.0.0.1:8999/api/agv/lock?agv=AGV04&appName=akmTask&taskId=6096411173dabd3614753481 addr: 127.0.0.1
[DEBUG]2021-05-08 15:43:50,132: lock:  AGV04 taskId 6096411173dabd3614753481 app akmTask
[WARN]2021-05-08 15:43:50,301: worker 6[tid:14248] <locked _thread.RLock object owner=14248 count=1 at 0x0000027CDA680800> ,hold 21009 ms
[INFO]2021-05-08 15:43:50,407: name=worker 6, pid=13844, tid=14248
[01] File "C:/Users/comba/AppData/Local/Programs/Python/Python37/lib/threading.py", line 865, in run() 
[02] File "C:/Users/comba/AppData/Local/Programs/Python/Python37/lib/site-packages/paste/httpserver.py", line 895, in worker_thread_callback() 
[03] File "C:/Users/comba/AppData/Local/Programs/Python/Python37/lib/site-packages/paste/httpserver.py", line 1069, in <lambda>() 
[04] File "C:/Users/comba/AppData/Local/Programs/Python/Python37/lib/site-packages/paste/httpserver.py", line 1085, in process_request_in_thread() 
[05] File "C:/Users/comba/AppData/Local/Programs/Python/Python37/lib/socketserver.py", line 357, in finish_request() 
[06] File "C:/Users/comba/AppData/Local/Programs/Python/Python37/lib/socketserver.py", line 717, in __init__() 
[07] File "C:/Users/comba/AppData/Local/Programs/Python/Python37/lib/site-packages/paste/httpserver.py", line 459, in handle() 
[08] File "C:/Users/comba/AppData/Local/Programs/Python/Python37/lib/http/server.py", line 426, in handle() 
[09] File "C:/Users/comba/AppData/Local/Programs/Python/Python37/lib/site-packages/paste/httpserver.py", line 454, in handle_one_request() 
[10] File "C:/Users/comba/AppData/Local/Programs/Python/Python37/lib/site-packages/paste/httpserver.py", line 304, in wsgi_execute() 
[11] File "C:/Users/comba/AppData/Local/Programs/Python/Python37/lib/site-packages/paste/translogger.py", line 69, in __call__() 
[12] File "C:/Users/comba/AppData/Local/Programs/Python/Python37/lib/site-packages/bottle.py", line 979, in __call__() 
[13] File "C:/Users/comba/AppData/Local/Programs/Python/Python37/lib/site-packages/bottle.py", line 954, in wsgi() 
[14] File "C:/Users/comba/AppData/Local/Programs/Python/Python37/lib/site-packages/bottle.py", line 862, in _handle() 
[15] File "C:/Users/comba/AppData/Local/Programs/Python/Python37/lib/site-packages/bottle.py", line 1742, in wrapper() 
[16] File "C:/Users/comba/Desktop/知识城地牛/knowledgeCity/common/webutility.py", line 465, in _enable_cors() 
[17] File "C:/Users/comba/Desktop/知识城地牛/knowledgeCity/common/webutility.py", line 481, in _enable_cors() 
[18] File "C:/Users/comba/Desktop/知识城地牛/knowledgeCity/common/scadaUtility.py", line 45, in __call() 
[19] File "C:/Users/comba/Desktop/知识城地牛/knowledgeCity/remoteio/main_remoteio.py", line 87, in urlReadDOList() 
[20] File "../remoteio/remoteioMgr.py", line 158, in readDOList() 
[21] File "../remoteio/remoteioMgr.py", line 262, in readDOList() 
[22] File "C:/Users/comba/Desktop/知识城地牛/knowledgeCity/common/lock.py", line 124, in _call() 
[23] File "C:/Users/comba/Desktop/知识城地牛/knowledgeCity/common/lock.py", line 102, in release() 
[24] File "C:/Users/comba/Desktop/知识城地牛/knowledgeCity/common/enhance.py", line 268, in getTrace() 
[25] File "C:/Users/comba/Desktop/知识城地牛/knowledgeCity/common/enhance.py", line 248, in getThreadStack()
[CRITICAL]2021-05-08 15:43:50,496: upStation01 readDIList fail cause a error: [WinError 10060] 由于连接方在一段时间后没有正确答复或连接的主机没有反应，连接尝试失败。
pid=13844, ppid=13780, tid=14248
Traceback (most recent call last):
  File "..\remoteio\remoteioMgr.py", line 262, in readDOList
    return self._read(M30, IO_LENTH)
  File "C:\Users\comba\Desktop\知识城地牛\knowledgeCity\common\lock.py", line 122, in _call
    return func(*p,**pp)
  File "..\remoteio\remoteioMgr.py", line 311, in _read
    self.master.open()
  File "C:\Users\comba\Desktop\知识城地牛\knowledgeCity\common\modbusapi.py", line 60, in open
    self.master.open()
  File "C:\Users\comba\AppData\Local\Programs\Python\Python37\lib\site-packages\modbus_tk\modbus.py", line 99, in open
    self._do_open()
  File "C:\Users\comba\AppData\Local\Programs\Python\Python37\lib\site-packages\modbus_tk\modbus_tcp.py", line 173, in _do_open
    self._sock.connect((self._host, self._port))
TimeoutError: [WinError 10060] 由于连接方在一段时间后没有正确答复或连接的主机没有反应，连接尝试失败。

[CRITICAL]2021-05-08 15:43:50,589: invoke <function urlReadDOList at 0x0000027CD91C1D08> cause a error: [WinError 10060] 由于连接方在一段时间后没有正确答复或连接的主机没有反应，连接尝试失败。
pid=13844, ppid=13780, tid=14248
Traceback (most recent call last):
  File "C:\Users\comba\Desktop\知识城地牛\knowledgeCity\common\scadaUtility.py", line 45, in __call
    ret = func(*p,**pp)
  File "C:\Users\comba\Desktop\知识城地牛\knowledgeCity\remoteio\main_remoteio.py", line 87, in urlReadDOList
    return ioMgr.readDOList(id)
  File "..\remoteio\remoteioMgr.py", line 158, in readDOList
    result=remoteioInfo.readDOList()
  File "..\remoteio\remoteioMgr.py", line 262, in readDOList
    return self._read(M30, IO_LENTH)
  File "C:\Users\comba\Desktop\知识城地牛\knowledgeCity\common\lock.py", line 122, in _call
    return func(*p,**pp)
  File "..\remoteio\remoteioMgr.py", line 311, in _read
    self.master.open()
  File "C:\Users\comba\Desktop\知识城地牛\knowledgeCity\common\modbusapi.py", line 60, in open
    self.master.open()
  File "C:\Users\comba\AppData\Local\Programs\Python\Python37\lib\site-packages\modbus_tk\modbus.py", line 99, in open
    self._do_open()
  File "C:\Users\comba\AppData\Local\Programs\Python\Python37\lib\site-packages\modbus_tk\modbus_tcp.py", line 173, in _do_open
    self._sock.connect((self._host, self._port))
TimeoutError: [WinError 10060] 由于连接方在一段时间后没有正确答复或连接的主机没有反应，连接尝试失败。

[WARN]2021-05-08 15:43:51,177: AGV04 clear task finish, cur= comba-ZXC-F3.LM20 task_status= 4
[INFO]2021-05-08 15:43:51,263: 22222222222222222222222
[INFO]2021-05-08 15:43:51,334: AGV04
[INFO]2021-05-08 15:43:51,362: task[6096411173dabd3614753481][-] AP22(LM17) -> AP25(LM24) [waitForAgv] apply AGV04
[INFO]2021-05-08 15:43:51,407: task[6096411173dabd3614753481] update info: {'agvId': 'AGV04', 'failMsg': '成功分配小车AGV04', 'updateTime': datetime.datetime(2021, 5, 8, 15, 43, 51, 384734)}
[DEBUG]2021-05-08 15:43:51,472: task[6096411173dabd3614753481][AGV04] AP22(LM17) -> AP25(LM24) [initAGV] waitForAgv -> initAGV
[INFO]2021-05-08 15:43:51,863: this is handle taskStep=============>initAGV
[INFO]2021-05-08 15:43:51,887: task[6096411173dabd3614753481] update info: {'failMsg': '前往三楼夹具点A工位点', 'updateTime': datetime.datetime(2021, 5, 8, 15, 43, 51, 881400)}
[DEBUG]2021-05-08 15:43:51,899: task[6096411173dabd3614753481][AGV04] AP22(LM17) -> AP25(LM24) [startMoveAGV] initAGV -> startMoveAGV
[INFO]2021-05-08 15:43:52,363: this is handle taskStep=============>startMoveAGV
[DEBUG]2021-05-08 15:43:52,383: GET: http://127.0.0.1:8999/api/agv/move?WorkPlace=true&agv=AGV04&agvId=AGV04&appName=akmTask&direction=None&floorId=comba-ZXC-F3&isRotate&loc=comba-ZXC-F3.AP22&location=AP22&p_direction=0.0&pgv_type=1&recognize=False&seer_jackup=JackLoad&taskId=6096411173dabd3614753481_2&taskType=scadaTask&timeoutSec=86400&use_pgv=False addr: 127.0.0.1
[INFO]2021-05-08 15:43:52,388: Begin: AGV04 move from comba-ZXC-F3.LM20 to comba-ZXC-F3.AP22 by paths: [('comba-ZXC-F3', ['LM20', 'LM21', 'LM17', 'AP18', 'AP22'], 5.569704036667539)] task: 6096411173dabd3614753481_2 timeout 86400 used 4 ms
[DEBUG]2021-05-08 15:43:52,389: used 6ms 200 OK application/json;charset=utf-8, GET: http://127.0.0.1:8999/api/agv/move?WorkPlace=true&agv=AGV04&agvId=AGV04&appName=akmTask&direction=None&floorId=comba-ZXC-F3&isRotate&loc=comba-ZXC-F3.AP22&location=AP22&p_direction=0.0&pgv_type=1&recognize=False&seer_jackup=JackLoad&taskId=6096411173dabd3614753481_2&taskType=scadaTask&timeoutSec=86400&use_pgv=False
[DEBUG]2021-05-08 15:43:52,391: task[6096411173dabd3614753481][AGV04] AP22(LM17) -> AP25(LM24) [loadPlayload] startMoveAGV -> loadPlayload
[INFO]2021-05-08 15:43:52,694: this is handle taskStep=============>loadPlayload
[INFO]2021-05-08 15:43:53,001: this is handle taskStep=============>loadPlayload
[DEBUG]2021-05-08 15:43:53,293: agvInfo: AGV04 comba-ZXC-F3.LM20 move to comba-ZXC-F3.LM21 ,taskId 6096411173dabd3614753481_2
[INFO]2021-05-08 15:43:53,303: this is handle taskStep=============>loadPlayload
[INFO]2021-05-08 15:43:53,605: this is handle taskStep=============>loadPlayload
[INFO]2021-05-08 15:43:53,910: this is handle taskStep=============>loadPlayload
[INFO]2021-05-08 15:43:54,212: this is handle taskStep=============>loadPlayload
[INFO]2021-05-08 15:43:54,514: this is handle taskStep=============>loadPlayload
[INFO]2021-05-08 15:43:54,816: this is handle taskStep=============>loadPlayload
[INFO]2021-05-08 15:43:55,123: this is handle taskStep=============>loadPlayload
[INFO]2021-05-08 15:43:55,431: this is handle taskStep=============>loadPlayload
[INFO]2021-05-08 15:43:55,737: this is handle taskStep=============>loadPlayload
[ERROR]2021-05-08 15:43:56,012: connect AGV01 failed timed out
[INFO]2021-05-08 15:43:56,013: AGV01 checkLink failed 172.16.217.209 19204
[WARN]2021-05-08 15:43:56,014: agvThread.AGV01[tid:14152] <lock name:agv.AGV01.lock_status,<locked _thread.RLock object owner=14152 count=1 at 0x0000027CDB32E918>> ,hold 10073 ms
[INFO]2021-05-08 15:43:56,015: name=agvThread.AGV01, pid=13844, tid=14152
[01] File "C:/Users/comba/AppData/Local/Programs/Python/Python37/lib/threading.py", line 865, in run() 
[02] File "C:/Users/comba/Desktop/知识城地牛/knowledgeCity/agvCtrl/agvList.py", line 565, in run() 
[03] File "../driver/seerAgv/agvCtrl.py", line 36, in checkLink() 
[04] File "../driver/seerAgv/agvApi.py", line 184, in checkLink() 
[05] File "C:/Users/comba/Desktop/知识城地牛/knowledgeCity/common/lock.py", line 102, in release() 
[06] File "C:/Users/comba/Desktop/知识城地牛/knowledgeCity/common/enhance.py", line 268, in getTrace() 
[07] File "C:/Users/comba/Desktop/知识城地牛/knowledgeCity/common/enhance.py", line 248, in getThreadStack()
[INFO]2021-05-08 15:43:56,040: this is handle taskStep=============>loadPlayload
[INFO]2021-05-08 15:43:56,343: this is handle taskStep=============>loadPlayload
[ERROR]2021-05-08 15:43:56,348: connect AGV02 failed timed out
[INFO]2021-05-08 15:43:56,352: AGV02 checkLink failed 172.16.217.213 19204
[WARN]2021-05-08 15:43:56,354: agvThread.AGV02[tid:14204] <lock name:agv.AGV02.lock_status,<locked _thread.RLock object owner=14204 count=1 at 0x0000027CDB32E418>> ,hold 10083 ms
[INFO]2021-05-08 15:43:56,364: name=agvThread.AGV02, pid=13844, tid=14204
[01] File "C:/Users/comba/AppData/Local/Programs/Python/Python37/lib/threading.py", line 865, in run() 
[02] File "C:/Users/comba/Desktop/知识城地牛/knowledgeCity/agvCtrl/agvList.py", line 565, in run() 
[03] File "../driver/seerAgv/agvCtrl.py", line 36, in checkLink() 
[04] File "../driver/seerAgv/agvApi.py", line 184, in checkLink() 
[05] File "C:/Users/comba/Desktop/知识城地牛/knowledgeCity/common/lock.py", line 102, in release() 
[06] File "C:/Users/comba/Desktop/知识城地牛/knowledgeCity/common/enhance.py", line 268, in getTrace() 
[07] File "C:/Users/comba/Desktop/知识城地牛/knowledgeCity/common/enhance.py", line 248, in getThreadStack()
[ERROR]2021-05-08 15:43:56,394: connect AGV03 failed timed out
[INFO]2021-05-08 15:43:56,398: AGV03 checkLink failed 172.16.217.121 19204
[WARN]2021-05-08 15:43:56,399: agvThread.AGV03[tid:14168] <lock name:agv.AGV03.lock_status,<locked _thread.RLock object owner=14168 count=1 at 0x0000027CDB32EBE8>> ,hold 10068 ms
[INFO]2021-05-08 15:43:56,402: name=agvThread.AGV03, pid=13844, tid=14168
[01] File "C:/Users/comba/AppData/Local/Programs/Python/Python37/lib/threading.py", line 865, in run() 
[02] File "C:/Users/comba/Desktop/知识城地牛/knowledgeCity/agvCtrl/agvList.py", line 565, in run() 
[03] File "../driver/seerAgv/agvCtrl.py", line 36, in checkLink() 
[04] File "../driver/seerAgv/agvApi.py", line 184, in checkLink() 
[05] File "C:/Users/comba/Desktop/知识城地牛/knowledgeCity/common/lock.py", line 102, in release() 
[06] File "C:/Users/comba/Desktop/知识城地牛/knowledgeCity/common/enhance.py", line 268, in getTrace() 
[07] File "C:/Users/comba/Desktop/知识城地牛/knowledgeCity/common/enhance.py", line 248, in getThreadStack()
[INFO]2021-05-08 15:43:56,651: this is handle taskStep=============>loadPlayload
[INFO]2021-05-08 15:43:56,953: this is handle taskStep=============>loadPlayload
[INFO]2021-05-08 15:43:57,261: this is handle taskStep=============>loadPlayload
[INFO]2021-05-08 15:43:57,568: this is handle taskStep=============>loadPlayload
[INFO]2021-05-08 15:43:57,870: this is handle taskStep=============>loadPlayload
[DEBUG]2021-05-08 15:43:58,017: try connect AGV01 172.16.217.209:19204
[INFO]2021-05-08 15:43:58,190: this is handle taskStep=============>loadPlayload
[DEBUG]2021-05-08 15:43:58,372: try connect AGV02 172.16.217.213:19204
[DEBUG]2021-05-08 15:43:58,406: try connect AGV03 172.16.217.121:19204
[INFO]2021-05-08 15:43:58,497: this is handle taskStep=============>loadPlayload
[INFO]2021-05-08 15:43:58,801: this is handle taskStep=============>loadPlayload
[INFO]2021-05-08 15:43:59,104: this is handle taskStep=============>loadPlayload
[INFO]2021-05-08 15:43:59,405: this is handle taskStep=============>loadPlayload
[DEBUG]2021-05-08 15:43:59,531: AGV04 turn to wait check cur LM20 next LM17 0.608 False
[INFO]2021-05-08 15:43:59,710: this is handle taskStep=============>loadPlayload
[INFO]2021-05-08 15:44:00,019: this is handle taskStep=============>loadPlayload
[DEBUG]2021-05-08 15:44:00,043: agvInfo: AGV04 comba-ZXC-F3.LM20 move to comba-ZXC-F3.LM17 ,taskId 6096411173dabd3614753481_2
[DEBUG]2021-05-08 15:44:00,290: AGV04 set loc comba-ZXC-F3.LM21 ,old LM20 (9.05,6.17)
[INFO]2021-05-08 15:44:00,322: this is handle taskStep=============>loadPlayload
[INFO]2021-05-08 15:44:00,625: this is handle taskStep=============>loadPlayload
[DEBUG]2021-05-08 15:44:00,764: AGV04 turn to wait check cur LM21 next AP18 0.452 False
[INFO]2021-05-08 15:44:00,928: this is handle taskStep=============>loadPlayload
[INFO]2021-05-08 15:44:01,230: this is handle taskStep=============>loadPlayload
[DEBUG]2021-05-08 15:44:01,275: agvInfo: AGV04 comba-ZXC-F3.LM21 move to comba-ZXC-F3.AP18 ,taskId 6096411173dabd3614753481_2
[INFO]2021-05-08 15:44:01,533: this is handle taskStep=============>loadPlayload
[INFO]2021-05-08 15:44:01,835: this is handle taskStep=============>loadPlayload
[INFO]2021-05-08 15:44:02,139: this is handle taskStep=============>loadPlayload
[INFO]2021-05-08 15:44:02,446: this is handle taskStep=============>loadPlayload
[INFO]2021-05-08 15:44:02,754: this is handle taskStep=============>loadPlayload
[INFO]2021-05-08 15:44:03,057: this is handle taskStep=============>loadPlayload
[CRITICAL]2021-05-08 15:44:03,335: readDIList error cause a error: ('http get', 'http://127.0.0.1:8999/api/remoteio/readDOList', {'id': 'upStation01'}, 'error:', 'timed out')
pid=13844, ppid=13780, tid=14132
Traceback (most recent call last):
  File "C:\Users\comba\Desktop\知识城地牛\knowledgeCity\common\webutility.py", line 103, in http_get
    f = urllib.request.urlopen(u,timeout=timeout)
  File "C:\Users\comba\AppData\Local\Programs\Python\Python37\lib\urllib\request.py", line 222, in urlopen
    return opener.open(url, data, timeout)
  File "C:\Users\comba\AppData\Local\Programs\Python\Python37\lib\urllib\request.py", line 525, in open
    response = self._open(req, data)
  File "C:\Users\comba\AppData\Local\Programs\Python\Python37\lib\urllib\request.py", line 543, in _open
    '_open', req)
  File "C:\Users\comba\AppData\Local\Programs\Python\Python37\lib\urllib\request.py", line 503, in _call_chain
    result = func(*args)
  File "C:\Users\comba\AppData\Local\Programs\Python\Python37\lib\urllib\request.py", line 1345, in http_open
    return self.do_open(http.client.HTTPConnection, req)
  File "C:\Users\comba\AppData\Local\Programs\Python\Python37\lib\urllib\request.py", line 1320, in do_open
    r = h.getresponse()
  File "C:\Users\comba\AppData\Local\Programs\Python\Python37\lib\http\client.py", line 1321, in getresponse
    response.begin()
  File "C:\Users\comba\AppData\Local\Programs\Python\Python37\lib\http\client.py", line 296, in begin
    version, status, reason = self._read_status()
  File "C:\Users\comba\AppData\Local\Programs\Python\Python37\lib\http\client.py", line 257, in _read_status
    line = str(self.fp.readline(_MAXLINE + 1), "iso-8859-1")
  File "C:\Users\comba\AppData\Local\Programs\Python\Python37\lib\socket.py", line 589, in readinto
    return self._sock.recv_into(b)
socket.timeout: timed out

During handling of the above exception, another exception occurred:

Traceback (most recent call last):
  File "C:\Users\comba\Desktop\知识城地牛\knowledgeCity\autoCtrl\deviceCtrl.py", line 71, in _monitorDevices
    s1 = ioApi.readDOList(devices[d]["io1"])["status"] #上板机
  File "..\remoteio\remoteioApi.py", line 73, in readDOList
    return _remoteio('/api/remoteio/readDOList', id, param)
  File "..\remoteio\remoteioApi.py", line 100, in _remoteio
    return http_get(url + apiurl, param)
  File "..\remoteio\remoteioApi.py", line 16, in http_get
    r = webutility.http_get(url, param)
  File "C:\Users\comba\Desktop\知识城地牛\knowledgeCity\common\webutility.py", line 105, in http_get
    raise Exception("http get",url,params,"error:",str(e))
Exception: ('http get', 'http://127.0.0.1:8999/api/remoteio/readDOList', {'id': 'upStation01'}, 'error:', 'timed out')

[INFO]2021-05-08 15:44:03,360: this is handle taskStep=============>loadPlayload
[INFO]2021-05-08 15:44:03,664: this is handle taskStep=============>loadPlayload
[INFO]2021-05-08 15:44:03,967: this is handle taskStep=============>loadPlayload
[INFO]2021-05-08 15:44:04,275: this is handle taskStep=============>loadPlayload
[INFO]2021-05-08 15:44:04,342: remoteio is alarm: []
[INFO]2021-05-08 15:44:04,578: this is handle taskStep=============>loadPlayload
[INFO]2021-05-08 15:44:04,886: this is handle taskStep=============>loadPlayload
[INFO]2021-05-08 15:44:05,195: this is handle taskStep=============>loadPlayload
[WARN]2021-05-08 15:44:05,348: AGV04 low battery charge,batteryLevel= 0.316 start charge level= 0.400
[WARN]2021-05-08 15:44:05,350: AGV04 battery 0.316 check failed: isLocked
[DEBUG]2021-05-08 15:44:05,351: send http_get: http://127.0.0.1:8999/api/remoteio/readDOList?id=upStation01
[INFO]2021-05-08 15:44:05,501: this is handle taskStep=============>loadPlayload
[INFO]2021-05-08 15:44:05,804: this is handle taskStep=============>loadPlayload
[INFO]2021-05-08 15:44:06,110: this is handle taskStep=============>loadPlayload
[INFO]2021-05-08 15:44:06,422: this is handle taskStep=============>loadPlayload
[INFO]2021-05-08 15:44:06,724: this is handle taskStep=============>loadPlayload
[INFO]2021-05-08 15:44:07,032: this is handle taskStep=============>loadPlayload
[INFO]2021-05-08 15:44:07,335: this is handle taskStep=============>loadPlayload
[INFO]2021-05-08 15:44:07,639: this is handle taskStep=============>loadPlayload
[INFO]2021-05-08 15:44:07,942: this is handle taskStep=============>loadPlayload
[ERROR]2021-05-08 15:44:08,018: connect AGV01 failed timed out
[INFO]2021-05-08 15:44:08,023: AGV01 checkLink failed 172.16.217.209 19204
[WARN]2021-05-08 15:44:08,025: agvThread.AGV01[tid:14152] <lock name:agv.AGV01.lock_status,<locked _thread.RLock object owner=14152 count=1 at 0x0000027CDB32E918>> ,hold 10008 ms
[INFO]2021-05-08 15:44:08,029: name=agvThread.AGV01, pid=13844, tid=14152
[01] File "C:/Users/comba/AppData/Local/Programs/Python/Python37/lib/threading.py", line 865, in run() 
[02] File "C:/Users/comba/Desktop/知识城地牛/knowledgeCity/agvCtrl/agvList.py", line 565, in run() 
[03] File "../driver/seerAgv/agvCtrl.py", line 36, in checkLink() 
[04] File "../driver/seerAgv/agvApi.py", line 184, in checkLink() 
[05] File "C:/Users/comba/Desktop/知识城地牛/knowledgeCity/common/lock.py", line 102, in release() 
[06] File "C:/Users/comba/Desktop/知识城地牛/knowledgeCity/common/enhance.py", line 268, in getTrace() 
[07] File "C:/Users/comba/Desktop/知识城地牛/knowledgeCity/common/enhance.py", line 248, in getThreadStack()
[INFO]2021-05-08 15:44:08,244: this is handle taskStep=============>loadPlayload
[ERROR]2021-05-08 15:44:08,377: connect AGV02 failed timed out
[INFO]2021-05-08 15:44:08,378: AGV02 checkLink failed 172.16.217.213 19204
[WARN]2021-05-08 15:44:08,379: agvThread.AGV02[tid:14204] <lock name:agv.AGV02.lock_status,<locked _thread.RLock object owner=14204 count=1 at 0x0000027CDB32E418>> ,hold 10007 ms
[INFO]2021-05-08 15:44:08,381: name=agvThread.AGV02, pid=13844, tid=14204
[01] File "C:/Users/comba/AppData/Local/Programs/Python/Python37/lib/threading.py", line 865, in run() 
[02] File "C:/Users/comba/Desktop/知识城地牛/knowledgeCity/agvCtrl/agvList.py", line 565, in run() 
[03] File "../driver/seerAgv/agvCtrl.py", line 36, in checkLink() 
[04] File "../driver/seerAgv/agvApi.py", line 184, in checkLink() 
[05] File "C:/Users/comba/Desktop/知识城地牛/knowledgeCity/common/lock.py", line 102, in release() 
[06] File "C:/Users/comba/Desktop/知识城地牛/knowledgeCity/common/enhance.py", line 268, in getTrace() 
[07] File "C:/Users/comba/Desktop/知识城地牛/knowledgeCity/common/enhance.py", line 248, in getThreadStack()
[ERROR]2021-05-08 15:44:08,412: connect AGV03 failed timed out
[INFO]2021-05-08 15:44:08,413: AGV03 checkLink failed 172.16.217.121 19204
[WARN]2021-05-08 15:44:08,414: agvThread.AGV03[tid:14168] <lock name:agv.AGV03.lock_status,<locked _thread.RLock object owner=14168 count=1 at 0x0000027CDB32EBE8>> ,hold 10008 ms
[INFO]2021-05-08 15:44:08,415: name=agvThread.AGV03, pid=13844, tid=14168
[01] File "C:/Users/comba/AppData/Local/Programs/Python/Python37/lib/threading.py", line 865, in run() 
[02] File "C:/Users/comba/Desktop/知识城地牛/knowledgeCity/agvCtrl/agvList.py", line 565, in run() 
[03] File "../driver/seerAgv/agvCtrl.py", line 36, in checkLink() 
[04] File "../driver/seerAgv/agvApi.py", line 184, in checkLink() 
[05] File "C:/Users/comba/Desktop/知识城地牛/knowledgeCity/common/lock.py", line 102, in release() 
[06] File "C:/Users/comba/Desktop/知识城地牛/knowledgeCity/common/enhance.py", line 268, in getTrace() 
[07] File "C:/Users/comba/Desktop/知识城地牛/knowledgeCity/common/enhance.py", line 248, in getThreadStack()
[INFO]2021-05-08 15:44:08,552: this is handle taskStep=============>loadPlayload
[INFO]2021-05-08 15:44:08,860: this is handle taskStep=============>loadPlayload
[INFO]2021-05-08 15:44:09,167: this is handle taskStep=============>loadPlayload
[DEBUG]2021-05-08 15:44:09,192: AGV04 set loc comba-ZXC-F3.LM17 ,old LM21 (9.19,5.73)
[INFO]2021-05-08 15:44:09,475: this is handle taskStep=============>loadPlayload
[DEBUG]2021-05-08 15:44:09,507: AGV04 choise next pos cur LM17 next AP22 pre AP18 1.977 False
[DEBUG]2021-05-08 15:44:09,508: AGV04 turn to wait check cur LM17 next AP22 1.977 False
[INFO]2021-05-08 15:44:09,783: this is handle taskStep=============>loadPlayload
[DEBUG]2021-05-08 15:44:10,025: agvInfo: AGV04 comba-ZXC-F3.LM17 move jackup to comba-ZXC-F3.AP22 ,taskId 6096411173dabd3614753481_2
[INFO]2021-05-08 15:44:10,026: --------------------跳转到driver下的seerAgv下的agcCtrl.py中的goTargetAndDoWork函数中-----------------10---------
[INFO]2021-05-08 15:44:10,027: 1
[INFO]2021-05-08 15:44:10,028: {'id': 'AP22', 'operation': 'JackLoad', 'recognize': False, 'use_pgv': False}
[INFO]2021-05-08 15:44:10,028: --------------------------准备进去driver中的seerAgv.py下的task函数-----------------（11）--------------
[DEBUG]2021-05-08 15:44:10,035: try connect AGV01 172.16.217.209:19204
[INFO]2021-05-08 15:44:10,086: this is handle taskStep=============>loadPlayload
[DEBUG]2021-05-08 15:44:10,384: try connect AGV02 172.16.217.213:19204
[INFO]2021-05-08 15:44:10,391: this is handle taskStep=============>loadPlayload
[DEBUG]2021-05-08 15:44:10,417: try connect AGV03 172.16.217.121:19204
[INFO]2021-05-08 15:44:10,694: this is handle taskStep=============>loadPlayload
[INFO]2021-05-08 15:44:11,002: this is handle taskStep=============>loadPlayload
[INFO]2021-05-08 15:44:11,304: this is handle taskStep=============>loadPlayload
[WARN]2021-05-08 15:44:11,471: worker 7[tid:14252] <locked _thread.RLock object owner=14252 count=1 at 0x0000027CDA680800> ,hold 23144 ms
[INFO]2021-05-08 15:44:11,472: name=worker 7, pid=13844, tid=14252
[01] File "C:/Users/comba/AppData/Local/Programs/Python/Python37/lib/threading.py", line 865, in run() 
[02] File "C:/Users/comba/AppData/Local/Programs/Python/Python37/lib/site-packages/paste/httpserver.py", line 895, in worker_thread_callback() 
[03] File "C:/Users/comba/AppData/Local/Programs/Python/Python37/lib/site-packages/paste/httpserver.py", line 1069, in <lambda>() 
[04] File "C:/Users/comba/AppData/Local/Programs/Python/Python37/lib/site-packages/paste/httpserver.py", line 1085, in process_request_in_thread() 
[05] File "C:/Users/comba/AppData/Local/Programs/Python/Python37/lib/socketserver.py", line 357, in finish_request() 
[06] File "C:/Users/comba/AppData/Local/Programs/Python/Python37/lib/socketserver.py", line 717, in __init__() 
[07] File "C:/Users/comba/AppData/Local/Programs/Python/Python37/lib/site-packages/paste/httpserver.py", line 459, in handle() 
[08] File "C:/Users/comba/AppData/Local/Programs/Python/Python37/lib/http/server.py", line 426, in handle() 
[09] File "C:/Users/comba/AppData/Local/Programs/Python/Python37/lib/site-packages/paste/httpserver.py", line 454, in handle_one_request() 
[10] File "C:/Users/comba/AppData/Local/Programs/Python/Python37/lib/site-packages/paste/httpserver.py", line 304, in wsgi_execute() 
[11] File "C:/Users/comba/AppData/Local/Programs/Python/Python37/lib/site-packages/paste/translogger.py", line 69, in __call__() 
[12] File "C:/Users/comba/AppData/Local/Programs/Python/Python37/lib/site-packages/bottle.py", line 979, in __call__() 
[13] File "C:/Users/comba/AppData/Local/Programs/Python/Python37/lib/site-packages/bottle.py", line 954, in wsgi() 
[14] File "C:/Users/comba/AppData/Local/Programs/Python/Python37/lib/site-packages/bottle.py", line 862, in _handle() 
[15] File "C:/Users/comba/AppData/Local/Programs/Python/Python37/lib/site-packages/bottle.py", line 1742, in wrapper() 
[16] File "C:/Users/comba/Desktop/知识城地牛/knowledgeCity/common/webutility.py", line 465, in _enable_cors() 
[17] File "C:/Users/comba/Desktop/知识城地牛/knowledgeCity/common/webutility.py", line 481, in _enable_cors() 
[18] File "C:/Users/comba/Desktop/知识城地牛/knowledgeCity/common/scadaUtility.py", line 45, in __call() 
[19] File "C:/Users/comba/Desktop/知识城地牛/knowledgeCity/remoteio/main_remoteio.py", line 87, in urlReadDOList() 
[20] File "../remoteio/remoteioMgr.py", line 158, in readDOList() 
[21] File "../remoteio/remoteioMgr.py", line 262, in readDOList() 
[22] File "C:/Users/comba/Desktop/知识城地牛/knowledgeCity/common/lock.py", line 124, in _call() 
[23] File "C:/Users/comba/Desktop/知识城地牛/knowledgeCity/common/lock.py", line 102, in release() 
[24] File "C:/Users/comba/Desktop/知识城地牛/knowledgeCity/common/enhance.py", line 268, in getTrace() 
[25] File "C:/Users/comba/Desktop/知识城地牛/knowledgeCity/common/enhance.py", line 248, in getThreadStack()
[CRITICAL]2021-05-08 15:44:11,478: upStation01 readDIList fail cause a error: [WinError 10060] 由于连接方在一段时间后没有正确答复或连接的主机没有反应，连接尝试失败。
pid=13844, ppid=13780, tid=14252
Traceback (most recent call last):
  File "..\remoteio\remoteioMgr.py", line 262, in readDOList
    return self._read(M30, IO_LENTH)
  File "C:\Users\comba\Desktop\知识城地牛\knowledgeCity\common\lock.py", line 122, in _call
    return func(*p,**pp)
  File "..\remoteio\remoteioMgr.py", line 311, in _read
    self.master.open()
  File "C:\Users\comba\Desktop\知识城地牛\knowledgeCity\common\modbusapi.py", line 60, in open
    self.master.open()
  File "C:\Users\comba\AppData\Local\Programs\Python\Python37\lib\site-packages\modbus_tk\modbus.py", line 99, in open
    self._do_open()
  File "C:\Users\comba\AppData\Local\Programs\Python\Python37\lib\site-packages\modbus_tk\modbus_tcp.py", line 173, in _do_open
    self._sock.connect((self._host, self._port))
TimeoutError: [WinError 10060] 由于连接方在一段时间后没有正确答复或连接的主机没有反应，连接尝试失败。

[CRITICAL]2021-05-08 15:44:11,484: invoke <function urlReadDOList at 0x0000027CD91C1D08> cause a error: [WinError 10060] 由于连接方在一段时间后没有正确答复或连接的主机没有反应，连接尝试失败。
pid=13844, ppid=13780, tid=14252
Traceback (most recent call last):
  File "C:\Users\comba\Desktop\知识城地牛\knowledgeCity\common\scadaUtility.py", line 45, in __call
    ret = func(*p,**pp)
  File "C:\Users\comba\Desktop\知识城地牛\knowledgeCity\remoteio\main_remoteio.py", line 87, in urlReadDOList
    return ioMgr.readDOList(id)
  File "..\remoteio\remoteioMgr.py", line 158, in readDOList
    result=remoteioInfo.readDOList()
  File "..\remoteio\remoteioMgr.py", line 262, in readDOList
    return self._read(M30, IO_LENTH)
  File "C:\Users\comba\Desktop\知识城地牛\knowledgeCity\common\lock.py", line 122, in _call
    return func(*p,**pp)
  File "..\remoteio\remoteioMgr.py", line 311, in _read
    self.master.open()
  File "C:\Users\comba\Desktop\知识城地牛\knowledgeCity\common\modbusapi.py", line 60, in open
    self.master.open()
  File "C:\Users\comba\AppData\Local\Programs\Python\Python37\lib\site-packages\modbus_tk\modbus.py", line 99, in open
    self._do_open()
  File "C:\Users\comba\AppData\Local\Programs\Python\Python37\lib\site-packages\modbus_tk\modbus_tcp.py", line 173, in _do_open
    self._sock.connect((self._host, self._port))
TimeoutError: [WinError 10060] 由于连接方在一段时间后没有正确答复或连接的主机没有反应，连接尝试失败。

[INFO]2021-05-08 15:44:11,606: this is handle taskStep=============>loadPlayload
[INFO]2021-05-08 15:44:11,926: this is handle taskStep=============>loadPlayload
[INFO]2021-05-08 15:44:12,229: this is handle taskStep=============>loadPlayload
[INFO]2021-05-08 15:44:12,537: this is handle taskStep=============>loadPlayload
[INFO]2021-05-08 15:44:12,839: this is handle taskStep=============>loadPlayload
[INFO]2021-05-08 15:44:13,142: this is handle taskStep=============>loadPlayload
[INFO]2021-05-08 15:44:13,449: this is handle taskStep=============>loadPlayload
[INFO]2021-05-08 15:44:13,764: this is handle taskStep=============>loadPlayload
[INFO]2021-05-08 15:44:14,067: this is handle taskStep=============>loadPlayload
[INFO]2021-05-08 15:44:14,372: this is handle taskStep=============>loadPlayload
[INFO]2021-05-08 15:44:14,674: this is handle taskStep=============>loadPlayload
[INFO]2021-05-08 15:44:14,976: this is handle taskStep=============>loadPlayload
[INFO]2021-05-08 15:44:15,284: this is handle taskStep=============>loadPlayload
[INFO]2021-05-08 15:44:15,594: this is handle taskStep=============>loadPlayload
[INFO]2021-05-08 15:44:15,903: this is handle taskStep=============>loadPlayload
[INFO]2021-05-08 15:44:16,206: this is handle taskStep=============>loadPlayload
[INFO]2021-05-08 15:44:16,509: this is handle taskStep=============>loadPlayload
[INFO]2021-05-08 15:44:16,811: this is handle taskStep=============>loadPlayload
[INFO]2021-05-08 15:44:17,113: this is handle taskStep=============>loadPlayload
[INFO]2021-05-08 15:44:17,421: this is handle taskStep=============>loadPlayload
[INFO]2021-05-08 15:44:17,723: this is handle taskStep=============>loadPlayload
[INFO]2021-05-08 15:44:18,026: this is handle taskStep=============>loadPlayload
[INFO]2021-05-08 15:44:18,335: this is handle taskStep=============>loadPlayload
[INFO]2021-05-08 15:44:18,643: this is handle taskStep=============>loadPlayload
[DEBUG]2021-05-08 15:44:18,901: AGV04 set loc comba-ZXC-F3.AP18 ,old LM17 (7.83,5.73)
[INFO]2021-05-08 15:44:18,950: this is handle taskStep=============>loadPlayload
[INFO]2021-05-08 15:44:19,253: this is handle taskStep=============>loadPlayload
[INFO]2021-05-08 15:44:19,563: this is handle taskStep=============>loadPlayload
[INFO]2021-05-08 15:44:19,872: this is handle taskStep=============>loadPlayload
[ERROR]2021-05-08 15:44:20,037: connect AGV01 failed timed out
[INFO]2021-05-08 15:44:20,037: AGV01 checkLink failed 172.16.217.209 19204
[WARN]2021-05-08 15:44:20,038: agvThread.AGV01[tid:14152] <lock name:agv.AGV01.lock_status,<locked _thread.RLock object owner=14152 count=1 at 0x0000027CDB32E918>> ,hold 10003 ms
[INFO]2021-05-08 15:44:20,040: name=agvThread.AGV01, pid=13844, tid=14152
[01] File "C:/Users/comba/AppData/Local/Programs/Python/Python37/lib/threading.py", line 865, in run() 
[02] File "C:/Users/comba/Desktop/知识城地牛/knowledgeCity/agvCtrl/agvList.py", line 565, in run() 
[03] File "../driver/seerAgv/agvCtrl.py", line 36, in checkLink() 
[04] File "../driver/seerAgv/agvApi.py", line 184, in checkLink() 
[05] File "C:/Users/comba/Desktop/知识城地牛/knowledgeCity/common/lock.py", line 102, in release() 
[06] File "C:/Users/comba/Desktop/知识城地牛/knowledgeCity/common/enhance.py", line 268, in getTrace() 
[07] File "C:/Users/comba/Desktop/知识城地牛/knowledgeCity/common/enhance.py", line 248, in getThreadStack()
[INFO]2021-05-08 15:44:20,181: this is handle taskStep=============>loadPlayload
[CRITICAL]2021-05-08 15:44:20,368: readDIList error cause a error: ('http get', 'http://127.0.0.1:8999/api/remoteio/readDOList', {'id': 'upStation01'}, 'error:', 'timed out')
pid=13844, ppid=13780, tid=14132
Traceback (most recent call last):
  File "C:\Users\comba\Desktop\知识城地牛\knowledgeCity\common\webutility.py", line 103, in http_get
    f = urllib.request.urlopen(u,timeout=timeout)
  File "C:\Users\comba\AppData\Local\Programs\Python\Python37\lib\urllib\request.py", line 222, in urlopen
    return opener.open(url, data, timeout)
  File "C:\Users\comba\AppData\Local\Programs\Python\Python37\lib\urllib\request.py", line 525, in open
    response = self._open(req, data)
  File "C:\Users\comba\AppData\Local\Programs\Python\Python37\lib\urllib\request.py", line 543, in _open
    '_open', req)
  File "C:\Users\comba\AppData\Local\Programs\Python\Python37\lib\urllib\request.py", line 503, in _call_chain
    result = func(*args)
  File "C:\Users\comba\AppData\Local\Programs\Python\Python37\lib\urllib\request.py", line 1345, in http_open
    return self.do_open(http.client.HTTPConnection, req)
  File "C:\Users\comba\AppData\Local\Programs\Python\Python37\lib\urllib\request.py", line 1320, in do_open
    r = h.getresponse()
  File "C:\Users\comba\AppData\Local\Programs\Python\Python37\lib\http\client.py", line 1321, in getresponse
    response.begin()
  File "C:\Users\comba\AppData\Local\Programs\Python\Python37\lib\http\client.py", line 296, in begin
    version, status, reason = self._read_status()
  File "C:\Users\comba\AppData\Local\Programs\Python\Python37\lib\http\client.py", line 257, in _read_status
    line = str(self.fp.readline(_MAXLINE + 1), "iso-8859-1")
  File "C:\Users\comba\AppData\Local\Programs\Python\Python37\lib\socket.py", line 589, in readinto
    return self._sock.recv_into(b)
socket.timeout: timed out

During handling of the above exception, another exception occurred:

Traceback (most recent call last):
  File "C:\Users\comba\Desktop\知识城地牛\knowledgeCity\autoCtrl\deviceCtrl.py", line 71, in _monitorDevices
    s1 = ioApi.readDOList(devices[d]["io1"])["status"] #上板机
  File "..\remoteio\remoteioApi.py", line 73, in readDOList
    return _remoteio('/api/remoteio/readDOList', id, param)
  File "..\remoteio\remoteioApi.py", line 100, in _remoteio
    return http_get(url + apiurl, param)
  File "..\remoteio\remoteioApi.py", line 16, in http_get
    r = webutility.http_get(url, param)
  File "C:\Users\comba\Desktop\知识城地牛\knowledgeCity\common\webutility.py", line 105, in http_get
    raise Exception("http get",url,params,"error:",str(e))
Exception: ('http get', 'http://127.0.0.1:8999/api/remoteio/readDOList', {'id': 'upStation01'}, 'error:', 'timed out')

[ERROR]2021-05-08 15:44:20,387: connect AGV02 failed timed out
[INFO]2021-05-08 15:44:20,395: AGV02 checkLink failed 172.16.217.213 19204
[WARN]2021-05-08 15:44:20,395: agvThread.AGV02[tid:14204] <lock name:agv.AGV02.lock_status,<locked _thread.RLock object owner=14204 count=1 at 0x0000027CDB32E418>> ,hold 10011 ms
[INFO]2021-05-08 15:44:20,397: name=agvThread.AGV02, pid=13844, tid=14204
[01] File "C:/Users/comba/AppData/Local/Programs/Python/Python37/lib/threading.py", line 865, in run() 
[02] File "C:/Users/comba/Desktop/知识城地牛/knowledgeCity/agvCtrl/agvList.py", line 565, in run() 
[03] File "../driver/seerAgv/agvCtrl.py", line 36, in checkLink() 
[04] File "../driver/seerAgv/agvApi.py", line 184, in checkLink() 
[05] File "C:/Users/comba/Desktop/知识城地牛/knowledgeCity/common/lock.py", line 102, in release() 
[06] File "C:/Users/comba/Desktop/知识城地牛/knowledgeCity/common/enhance.py", line 268, in getTrace() 
[07] File "C:/Users/comba/Desktop/知识城地牛/knowledgeCity/common/enhance.py", line 248, in getThreadStack()
[ERROR]2021-05-08 15:44:20,418: connect AGV03 failed timed out
[INFO]2021-05-08 15:44:20,419: AGV03 checkLink failed 172.16.217.121 19204
[WARN]2021-05-08 15:44:20,420: agvThread.AGV03[tid:14168] <lock name:agv.AGV03.lock_status,<locked _thread.RLock object owner=14168 count=1 at 0x0000027CDB32EBE8>> ,hold 10003 ms
[INFO]2021-05-08 15:44:20,421: name=agvThread.AGV03, pid=13844, tid=14168
[01] File "C:/Users/comba/AppData/Local/Programs/Python/Python37/lib/threading.py", line 865, in run() 
[02] File "C:/Users/comba/Desktop/知识城地牛/knowledgeCity/agvCtrl/agvList.py", line 565, in run() 
[03] File "../driver/seerAgv/agvCtrl.py", line 36, in checkLink() 
[04] File "../driver/seerAgv/agvApi.py", line 184, in checkLink() 
[05] File "C:/Users/comba/Desktop/知识城地牛/knowledgeCity/common/lock.py", line 102, in release() 
[06] File "C:/Users/comba/Desktop/知识城地牛/knowledgeCity/common/enhance.py", line 268, in getTrace() 
[07] File "C:/Users/comba/Desktop/知识城地牛/knowledgeCity/common/enhance.py", line 248, in getThreadStack()
[INFO]2021-05-08 15:44:20,488: this is handle taskStep=============>loadPlayload
[INFO]2021-05-08 15:44:20,791: this is handle taskStep=============>loadPlayload
[INFO]2021-05-08 15:44:21,098: this is handle taskStep=============>loadPlayload
[DEBUG]2021-05-08 15:44:21,250: AGV04 set loc comba-ZXC-F3.AP22 ,old AP18 (7.38,5.75)
[WARN]2021-05-08 15:44:21,267: AGV04 waitFinish status error: AP22 ,target= AP22 task_status= 2
[INFO]2021-05-08 15:44:21,374: remoteio is alarm: []
[INFO]2021-05-08 15:44:21,401: this is handle taskStep=============>loadPlayload
[INFO]2021-05-08 15:44:21,705: this is handle taskStep=============>loadPlayload
[WARN]2021-05-08 15:44:21,772: AGV04 waitFinish status error: AP22 ,target= AP22 task_status= 2
[INFO]2021-05-08 15:44:22,012: this is handle taskStep=============>loadPlayload
[DEBUG]2021-05-08 15:44:22,042: try connect AGV01 172.16.217.209:19204
[WARN]2021-05-08 15:44:22,274: AGV04 waitFinish status error: AP22 ,target= AP22 task_status= 2
[INFO]2021-05-08 15:44:22,319: this is handle taskStep=============>loadPlayload
[WARN]2021-05-08 15:44:22,379: AGV04 low battery charge,batteryLevel= 0.312 start charge level= 0.400
[WARN]2021-05-08 15:44:22,380: AGV04 battery 0.312 check failed: isLocked
[DEBUG]2021-05-08 15:44:22,381: send http_get: http://127.0.0.1:8999/api/remoteio/readDOList?id=upStation01
[DEBUG]2021-05-08 15:44:22,399: try connect AGV02 172.16.217.213:19204
[DEBUG]2021-05-08 15:44:22,424: try connect AGV03 172.16.217.121:19204
[INFO]2021-05-08 15:44:22,625: this is handle taskStep=============>loadPlayload
[WARN]2021-05-08 15:44:22,779: AGV04 waitFinish status error: AP22 ,target= AP22 task_status= 2
[INFO]2021-05-08 15:44:22,932: this is handle taskStep=============>loadPlayload
[INFO]2021-05-08 15:44:23,235: this is handle taskStep=============>loadPlayload
[WARN]2021-05-08 15:44:23,285: AGV04 waitFinish status error: AP22 ,target= AP22 task_status= 2
[INFO]2021-05-08 15:44:23,539: this is handle taskStep=============>loadPlayload
[WARN]2021-05-08 15:44:23,789: AGV04 waitFinish status error: AP22 ,target= AP22 task_status= 2
[INFO]2021-05-08 15:44:23,846: this is handle taskStep=============>loadPlayload
[INFO]2021-05-08 15:44:24,154: this is handle taskStep=============>loadPlayload
[INFO]2021-05-08 15:44:24,463: this is handle taskStep=============>loadPlayload
[INFO]2021-05-08 15:44:24,766: this is handle taskStep=============>loadPlayload
[INFO]2021-05-08 15:44:25,073: this is handle taskStep=============>loadPlayload
[SUCC]2021-05-08 15:44:25,292: Finish:  AGV04 arrived comba-ZXC-F3.AP22 ,task: 6096411173dabd3614753481_2
[INFO]2021-05-08 15:44:25,384: this is handle taskStep=============>loadPlayload
[INFO]2021-05-08 15:44:25,407: task: move finish callback task[6096411173dabd3614753481][AGV04] AP22(LM17) -> AP25(LM24) [loadPlayload]
[INFO]2021-05-08 15:44:25,410: task[6096411173dabd3614753481] update info: {'failMsg': 'AGV二层出料', 'updateTime': datetime.datetime(2021, 5, 8, 15, 44, 25, 409583)}
[INFO]2021-05-08 15:44:25,688: this is handle taskStep=============>loadPlayload_readqr
[DEBUG]2021-05-08 15:44:25,689: send http_get: http://127.0.0.1:8999/api/agv/rollerRobotUnLoad?agv=AGV04&timeoutSec=30&unitId=2
[DEBUG]2021-05-08 15:44:25,703: GET: http://127.0.0.1:8999/api/agv/rollerRobotUnLoad?agv=AGV04&timeoutSec=30&unitId=2 addr: 127.0.0.1
[INFO]2021-05-08 15:44:25,704: AGV04 rollerRobotUnLoad unitId: 2
[DEBUG]2021-05-08 15:44:25,781: used 78ms 200 OK application/json;charset=utf-8, GET: http://127.0.0.1:8999/api/agv/rollerRobotUnLoad?agv=AGV04&timeoutSec=30&unitId=2
[DEBUG]2021-05-08 15:44:25,784: [return] use 95 ms,http_get: http://127.0.0.1:8999/api/agv/rollerRobotUnLoad?agv=AGV04&timeoutSec=30&unitId=2
[INFO]2021-05-08 15:44:25,785: task[6096411173dabd3614753481] update info: {'failMsg': '二层滚筒出料三楼夹具点C', 'updateTime': datetime.datetime(2021, 5, 8, 15, 44, 25, 785492)}
[DEBUG]2021-05-08 15:44:25,786: task[6096411173dabd3614753481][AGV04] AP22(LM17) -> AP25(LM24) [checkTwoLayerGoing] loadPlayload_readqr -> checkTwoLayerGoing
[INFO]2021-05-08 15:44:26,094: this is handle taskStep=============>checkTwoLayerGoing
[DEBUG]2021-05-08 15:44:26,118: send http_get: http://127.0.0.1:8999/api/agv/checkUnitUnloadStatus?agv=AGV04&timeoutSec=30&unitId=2
[DEBUG]2021-05-08 15:44:26,217: GET: http://127.0.0.1:8999/api/agv/checkUnitUnloadStatus?agv=AGV04&timeoutSec=30&unitId=2 addr: 127.0.0.1
[INFO]2021-05-08 15:44:26,363: AGV04 checkUnitUnloadStatus unitId: 2
[DEBUG]2021-05-08 15:44:26,387: used 170ms 200 OK application/json;charset=utf-8, GET: http://127.0.0.1:8999/api/agv/checkUnitUnloadStatus?agv=AGV04&timeoutSec=30&unitId=2
[DEBUG]2021-05-08 15:44:26,449: [return] use 331 ms,http_get: http://127.0.0.1:8999/api/agv/checkUnitUnloadStatus?agv=AGV04&timeoutSec=30&unitId=2
[DEBUG]2021-05-08 15:44:28,485: send http_get: http://127.0.0.1:8999/api/agv/checkUnitUnloadStatus?agv=AGV04&timeoutSec=30&unitId=2
[DEBUG]2021-05-08 15:44:28,557: GET: http://127.0.0.1:8999/api/agv/checkUnitUnloadStatus?agv=AGV04&timeoutSec=30&unitId=2 addr: 127.0.0.1
[INFO]2021-05-08 15:44:28,626: AGV04 checkUnitUnloadStatus unitId: 2
[DEBUG]2021-05-08 15:44:28,662: used 105ms 200 OK application/json;charset=utf-8, GET: http://127.0.0.1:8999/api/agv/checkUnitUnloadStatus?agv=AGV04&timeoutSec=30&unitId=2
[DEBUG]2021-05-08 15:44:28,726: [return] use 241 ms,http_get: http://127.0.0.1:8999/api/agv/checkUnitUnloadStatus?agv=AGV04&timeoutSec=30&unitId=2
[INFO]2021-05-08 15:44:30,808: task[6096411173dabd3614753481] update info: {'step': 'checkTwoLayerFinish', 'msg': '检测2层设置出料完成信号', 'updateTime': datetime.datetime(2021, 5, 8, 15, 44, 30, 796089)}
[WARN]2021-05-08 15:44:30,836: scada.6096411173dabd3614753481[tid:2260] <locked _thread.RLock object owner=2260 count=1 at 0x0000027CDE6873C8> ,hold 4742 ms
[INFO]2021-05-08 15:44:30,972: name=scada.6096411173dabd3614753481, pid=13844, tid=2260
[01] File "C:/Users/comba/AppData/Local/Programs/Python/Python37/lib/threading.py", line 865, in run() 
[02] File "C:/Users/comba/Desktop/知识城地牛/knowledgeCity/common/utility.py", line 167, in __call() 
[03] File "C:/Users/comba/Desktop/知识城地牛/knowledgeCity/autoCtrl/runTasks.py", line 916, in _taskFunc() 
[04] File "C:/Users/comba/Desktop/知识城地牛/knowledgeCity/common/lock.py", line 124, in _call() 
[05] File "C:/Users/comba/Desktop/知识城地牛/knowledgeCity/common/lock.py", line 102, in release() 
[06] File "C:/Users/comba/Desktop/知识城地牛/knowledgeCity/common/enhance.py", line 268, in getTrace() 
[07] File "C:/Users/comba/Desktop/知识城地牛/knowledgeCity/common/enhance.py", line 248, in getThreadStack()
[DEBUG]2021-05-08 15:44:31,018: task[6096411173dabd3614753481][AGV04] AP22(LM17) -> AP25(LM24) [checkTwoLayerFinish] checkTwoLayerGoing -> checkTwoLayerFinish
[INFO]2021-05-08 15:44:31,392: this is handle taskStep=============>checkTwoLayerFinish
[DEBUG]2021-05-08 15:44:31,415: send http_get: http://127.0.0.1:8999/api/agv/rollerRobotLoad?agv=AGV04&timeoutSec=30&unitId=1
[DEBUG]2021-05-08 15:44:31,584: GET: http://127.0.0.1:8999/api/agv/rollerRobotLoad?agv=AGV04&timeoutSec=30&unitId=1 addr: 127.0.0.1
[INFO]2021-05-08 15:44:31,632: AGV04 rollerRobotLoad unitId: 1
[ERROR]2021-05-08 15:44:32,047: connect AGV01 failed timed out
[INFO]2021-05-08 15:44:32,088: AGV01 checkLink failed 172.16.217.209 19204
[WARN]2021-05-08 15:44:32,129: agvThread.AGV01[tid:14152] <lock name:agv.AGV01.lock_status,<locked _thread.RLock object owner=14152 count=1 at 0x0000027CDB32E918>> ,hold 10087 ms
[INFO]2021-05-08 15:44:32,202: name=agvThread.AGV01, pid=13844, tid=14152
[01] File "C:/Users/comba/AppData/Local/Programs/Python/Python37/lib/threading.py", line 865, in run() 
[02] File "C:/Users/comba/Desktop/知识城地牛/knowledgeCity/agvCtrl/agvList.py", line 565, in run() 
[03] File "../driver/seerAgv/agvCtrl.py", line 36, in checkLink() 
[04] File "../driver/seerAgv/agvApi.py", line 184, in checkLink() 
[05] File "C:/Users/comba/Desktop/知识城地牛/knowledgeCity/common/lock.py", line 102, in release() 
[06] File "C:/Users/comba/Desktop/知识城地牛/knowledgeCity/common/enhance.py", line 268, in getTrace() 
[07] File "C:/Users/comba/Desktop/知识城地牛/knowledgeCity/common/enhance.py", line 248, in getThreadStack()
[DEBUG]2021-05-08 15:44:32,380: used 796ms 200 OK application/json;charset=utf-8, GET: http://127.0.0.1:8999/api/agv/rollerRobotLoad?agv=AGV04&timeoutSec=30&unitId=1
[ERROR]2021-05-08 15:44:32,404: connect AGV02 failed timed out
[DEBUG]2021-05-08 15:44:32,410: [return] use 995 ms,http_get: http://127.0.0.1:8999/api/agv/rollerRobotLoad?agv=AGV04&timeoutSec=30&unitId=1
[INFO]2021-05-08 15:44:32,416: AGV02 checkLink failed 172.16.217.213 19204
[ERROR]2021-05-08 15:44:32,427: connect AGV03 failed timed out
[WARN]2021-05-08 15:44:32,491: worker 0[tid:14224] <locked _thread.RLock object owner=14224 count=1 at 0x0000027CDA680800> ,hold 27128 ms
[INFO]2021-05-08 15:44:32,497: task[6096411173dabd3614753481] update info: {'failMsg': '一层滚筒进料三楼夹具点C', 'updateTime': datetime.datetime(2021, 5, 8, 15, 44, 32, 462622)}
[WARN]2021-05-08 15:44:32,533: agvThread.AGV02[tid:14204] <lock name:agv.AGV02.lock_status,<locked _thread.RLock object owner=14204 count=1 at 0x0000027CDB32E418>> ,hold 10134 ms
[INFO]2021-05-08 15:44:32,574: AGV03 checkLink failed 172.16.217.121 19204
[DEBUG]2021-05-08 15:44:32,631: task[6096411173dabd3614753481][AGV04] AP22(LM17) -> AP25(LM24) [waitPushrodPush] checkTwoLayerFinish -> waitPushrodPush
[INFO]2021-05-08 15:44:32,654: name=worker 0, pid=13844, tid=14224
[01] File "C:/Users/comba/AppData/Local/Programs/Python/Python37/lib/threading.py", line 865, in run() 
[02] File "C:/Users/comba/AppData/Local/Programs/Python/Python37/lib/site-packages/paste/httpserver.py", line 895, in worker_thread_callback() 
[03] File "C:/Users/comba/AppData/Local/Programs/Python/Python37/lib/site-packages/paste/httpserver.py", line 1069, in <lambda>() 
[04] File "C:/Users/comba/AppData/Local/Programs/Python/Python37/lib/site-packages/paste/httpserver.py", line 1085, in process_request_in_thread() 
[05] File "C:/Users/comba/AppData/Local/Programs/Python/Python37/lib/socketserver.py", line 357, in finish_request() 
[06] File "C:/Users/comba/AppData/Local/Programs/Python/Python37/lib/socketserver.py", line 717, in __init__() 
[07] File "C:/Users/comba/AppData/Local/Programs/Python/Python37/lib/site-packages/paste/httpserver.py", line 459, in handle() 
[08] File "C:/Users/comba/AppData/Local/Programs/Python/Python37/lib/http/server.py", line 426, in handle() 
[09] File "C:/Users/comba/AppData/Local/Programs/Python/Python37/lib/site-packages/paste/httpserver.py", line 454, in handle_one_request() 
[10] File "C:/Users/comba/AppData/Local/Programs/Python/Python37/lib/site-packages/paste/httpserver.py", line 304, in wsgi_execute() 
[11] File "C:/Users/comba/AppData/Local/Programs/Python/Python37/lib/site-packages/paste/translogger.py", line 69, in __call__() 
[12] File "C:/Users/comba/AppData/Local/Programs/Python/Python37/lib/site-packages/bottle.py", line 979, in __call__() 
[13] File "C:/Users/comba/AppData/Local/Programs/Python/Python37/lib/site-packages/bottle.py", line 954, in wsgi() 
[14] File "C:/Users/comba/AppData/Local/Programs/Python/Python37/lib/site-packages/bottle.py", line 862, in _handle() 
[15] File "C:/Users/comba/AppData/Local/Programs/Python/Python37/lib/site-packages/bottle.py", line 1742, in wrapper() 
[16] File "C:/Users/comba/Desktop/知识城地牛/knowledgeCity/common/webutility.py", line 465, in _enable_cors() 
[17] File "C:/Users/comba/Desktop/知识城地牛/knowledgeCity/common/webutility.py", line 481, in _enable_cors() 
[18] File "C:/Users/comba/Desktop/知识城地牛/knowledgeCity/common/scadaUtility.py", line 45, in __call() 
[19] File "C:/Users/comba/Desktop/知识城地牛/knowledgeCity/remoteio/main_remoteio.py", line 87, in urlReadDOList() 
[20] File "../remoteio/remoteioMgr.py", line 158, in readDOList() 
[21] File "../remoteio/remoteioMgr.py", line 262, in readDOList() 
[22] File "C:/Users/comba/Desktop/知识城地牛/knowledgeCity/common/lock.py", line 124, in _call() 
[23] File "C:/Users/comba/Desktop/知识城地牛/knowledgeCity/common/lock.py", line 102, in release() 
[24] File "C:/Users/comba/Desktop/知识城地牛/knowledgeCity/common/enhance.py", line 268, in getTrace() 
[25] File "C:/Users/comba/Desktop/知识城地牛/knowledgeCity/common/enhance.py", line 248, in getThreadStack()
[INFO]2021-05-08 15:44:32,707: name=agvThread.AGV02, pid=13844, tid=14204
[01] File "C:/Users/comba/AppData/Local/Programs/Python/Python37/lib/threading.py", line 865, in run() 
[02] File "C:/Users/comba/Desktop/知识城地牛/knowledgeCity/agvCtrl/agvList.py", line 565, in run() 
[03] File "../driver/seerAgv/agvCtrl.py", line 36, in checkLink() 
[04] File "../driver/seerAgv/agvApi.py", line 184, in checkLink() 
[05] File "C:/Users/comba/Desktop/知识城地牛/knowledgeCity/common/lock.py", line 102, in release() 
[06] File "C:/Users/comba/Desktop/知识城地牛/knowledgeCity/common/enhance.py", line 268, in getTrace() 
[07] File "C:/Users/comba/Desktop/知识城地牛/knowledgeCity/common/enhance.py", line 248, in getThreadStack()
[WARN]2021-05-08 15:44:32,725: agvThread.AGV03[tid:14168] <lock name:agv.AGV03.lock_status,<locked _thread.RLock object owner=14168 count=1 at 0x0000027CDB32EBE8>> ,hold 10301 ms
[CRITICAL]2021-05-08 15:44:32,841: upStation01 readDIList fail cause a error: [WinError 10060] 由于连接方在一段时间后没有正确答复或连接的主机没有反应，连接尝试失败。
pid=13844, ppid=13780, tid=14224
Traceback (most recent call last):
  File "..\remoteio\remoteioMgr.py", line 262, in readDOList
    return self._read(M30, IO_LENTH)
  File "C:\Users\comba\Desktop\知识城地牛\knowledgeCity\common\lock.py", line 122, in _call
    return func(*p,**pp)
  File "..\remoteio\remoteioMgr.py", line 311, in _read
    self.master.open()
  File "C:\Users\comba\Desktop\知识城地牛\knowledgeCity\common\modbusapi.py", line 60, in open
    self.master.open()
  File "C:\Users\comba\AppData\Local\Programs\Python\Python37\lib\site-packages\modbus_tk\modbus.py", line 99, in open
    self._do_open()
  File "C:\Users\comba\AppData\Local\Programs\Python\Python37\lib\site-packages\modbus_tk\modbus_tcp.py", line 173, in _do_open
    self._sock.connect((self._host, self._port))
TimeoutError: [WinError 10060] 由于连接方在一段时间后没有正确答复或连接的主机没有反应，连接尝试失败。

[INFO]2021-05-08 15:44:32,950: name=agvThread.AGV03, pid=13844, tid=14168
[01] File "C:/Users/comba/AppData/Local/Programs/Python/Python37/lib/threading.py", line 865, in run() 
[02] File "C:/Users/comba/Desktop/知识城地牛/knowledgeCity/agvCtrl/agvList.py", line 565, in run() 
[03] File "../driver/seerAgv/agvCtrl.py", line 36, in checkLink() 
[04] File "../driver/seerAgv/agvApi.py", line 184, in checkLink() 
[05] File "C:/Users/comba/Desktop/知识城地牛/knowledgeCity/common/lock.py", line 102, in release() 
[06] File "C:/Users/comba/Desktop/知识城地牛/knowledgeCity/common/enhance.py", line 268, in getTrace() 
[07] File "C:/Users/comba/Desktop/知识城地牛/knowledgeCity/common/enhance.py", line 248, in getThreadStack()
[CRITICAL]2021-05-08 15:44:32,980: invoke <function urlReadDOList at 0x0000027CD91C1D08> cause a error: [WinError 10060] 由于连接方在一段时间后没有正确答复或连接的主机没有反应，连接尝试失败。
pid=13844, ppid=13780, tid=14224
Traceback (most recent call last):
  File "C:\Users\comba\Desktop\知识城地牛\knowledgeCity\common\scadaUtility.py", line 45, in __call
    ret = func(*p,**pp)
  File "C:\Users\comba\Desktop\知识城地牛\knowledgeCity\remoteio\main_remoteio.py", line 87, in urlReadDOList
    return ioMgr.readDOList(id)
  File "..\remoteio\remoteioMgr.py", line 158, in readDOList
    result=remoteioInfo.readDOList()
  File "..\remoteio\remoteioMgr.py", line 262, in readDOList
    return self._read(M30, IO_LENTH)
  File "C:\Users\comba\Desktop\知识城地牛\knowledgeCity\common\lock.py", line 122, in _call
    return func(*p,**pp)
  File "..\remoteio\remoteioMgr.py", line 311, in _read
    self.master.open()
  File "C:\Users\comba\Desktop\知识城地牛\knowledgeCity\common\modbusapi.py", line 60, in open
    self.master.open()
  File "C:\Users\comba\AppData\Local\Programs\Python\Python37\lib\site-packages\modbus_tk\modbus.py", line 99, in open
    self._do_open()
  File "C:\Users\comba\AppData\Local\Programs\Python\Python37\lib\site-packages\modbus_tk\modbus_tcp.py", line 173, in _do_open
    self._sock.connect((self._host, self._port))
TimeoutError: [WinError 10060] 由于连接方在一段时间后没有正确答复或连接的主机没有反应，连接尝试失败。

[INFO]2021-05-08 15:44:33,094: this is handle taskStep=============>waitPushrodPush
[CRITICAL]2021-05-08 15:44:33,164: taskFunc2:task[6096411173dabd3614753481][AGV04] AP22(LM17) -> AP25(LM24) [waitPushrodPush] cause a error: rollerRobotPush() missing 1 required positional argument: 'unitId'
pid=13844, ppid=13780, tid=2260
Traceback (most recent call last):
  File "C:\Users\comba\Desktop\知识城地牛\knowledgeCity\autoCtrl\runTasks.py", line 916, in _taskFunc
    elif not self.handle():
  File "C:\Users\comba\Desktop\知识城地牛\knowledgeCity\common\lock.py", line 122, in _call
    return func(*p,**pp)
  File "C:\Users\comba\Desktop\知识城地牛\knowledgeCity\autoCtrl\runTasks.py", line 724, in handle
    if not self.rollerRobotPush(): #推杆
TypeError: rollerRobotPush() missing 1 required positional argument: 'unitId'

[WARN]2021-05-08 15:44:33,228: task[6096411173dabd3614753481]:  error {'failMsg': "rollerRobotPush() missing 1 required positional argument: 'unitId'", 'endTime': datetime.datetime(2021, 5, 8, 15, 44, 33, 206630), 'status': 'error'}
[INFO]2021-05-08 15:44:33,251: task[6096411173dabd3614753481][AGV04] AP22(LM17) -> AP25(LM24) [waitPushrodPush] AGV04 release task, release agv False False False
[INFO]2021-05-08 15:44:33,285: task: stop task[6096411173dabd3614753481][AGV04] AP22(LM17) -> AP25(LM24) [waitPushrodPush]
[DEBUG]2021-05-08 15:44:34,250: try connect AGV01 172.16.217.209:19204
[DEBUG]2021-05-08 15:44:34,863: try connect AGV02 172.16.217.213:19204
[DEBUG]2021-05-08 15:44:35,014: try connect AGV03 172.16.217.121:19204
[CRITICAL]2021-05-08 15:44:37,435: readDIList error cause a error: ('http get', 'http://127.0.0.1:8999/api/remoteio/readDOList', {'id': 'upStation01'}, 'error:', 'timed out')
pid=13844, ppid=13780, tid=14132
Traceback (most recent call last):
  File "C:\Users\comba\Desktop\知识城地牛\knowledgeCity\common\webutility.py", line 103, in http_get
    f = urllib.request.urlopen(u,timeout=timeout)
  File "C:\Users\comba\AppData\Local\Programs\Python\Python37\lib\urllib\request.py", line 222, in urlopen
    return opener.open(url, data, timeout)
  File "C:\Users\comba\AppData\Local\Programs\Python\Python37\lib\urllib\request.py", line 525, in open
    response = self._open(req, data)
  File "C:\Users\comba\AppData\Local\Programs\Python\Python37\lib\urllib\request.py", line 543, in _open
    '_open', req)
  File "C:\Users\comba\AppData\Local\Programs\Python\Python37\lib\urllib\request.py", line 503, in _call_chain
    result = func(*args)
  File "C:\Users\comba\AppData\Local\Programs\Python\Python37\lib\urllib\request.py", line 1345, in http_open
    return self.do_open(http.client.HTTPConnection, req)
  File "C:\Users\comba\AppData\Local\Programs\Python\Python37\lib\urllib\request.py", line 1320, in do_open
    r = h.getresponse()
  File "C:\Users\comba\AppData\Local\Programs\Python\Python37\lib\http\client.py", line 1321, in getresponse
    response.begin()
  File "C:\Users\comba\AppData\Local\Programs\Python\Python37\lib\http\client.py", line 296, in begin
    version, status, reason = self._read_status()
  File "C:\Users\comba\AppData\Local\Programs\Python\Python37\lib\http\client.py", line 257, in _read_status
    line = str(self.fp.readline(_MAXLINE + 1), "iso-8859-1")
  File "C:\Users\comba\AppData\Local\Programs\Python\Python37\lib\socket.py", line 589, in readinto
    return self._sock.recv_into(b)
socket.timeout: timed out

During handling of the above exception, another exception occurred:

Traceback (most recent call last):
  File "C:\Users\comba\Desktop\知识城地牛\knowledgeCity\autoCtrl\deviceCtrl.py", line 71, in _monitorDevices
    s1 = ioApi.readDOList(devices[d]["io1"])["status"] #上板机
  File "..\remoteio\remoteioApi.py", line 73, in readDOList
    return _remoteio('/api/remoteio/readDOList', id, param)
  File "..\remoteio\remoteioApi.py", line 100, in _remoteio
    return http_get(url + apiurl, param)
  File "..\remoteio\remoteioApi.py", line 16, in http_get
    r = webutility.http_get(url, param)
  File "C:\Users\comba\Desktop\知识城地牛\knowledgeCity\common\webutility.py", line 105, in http_get
    raise Exception("http get",url,params,"error:",str(e))
Exception: ('http get', 'http://127.0.0.1:8999/api/remoteio/readDOList', {'id': 'upStation01'}, 'error:', 'timed out')

[INFO]2021-05-08 15:44:38,507: remoteio is alarm: []
[WARN]2021-05-08 15:44:39,608: AGV04 low battery charge,batteryLevel= 0.312 start charge level= 0.400
[WARN]2021-05-08 15:44:39,632: AGV04 battery 0.312 check failed: isLocked
[DEBUG]2021-05-08 15:44:39,703: task: delete task 6096411173dabd3614753481
[DEBUG]2021-05-08 15:44:39,781: send http_get: http://127.0.0.1:8999/api/remoteio/readDOList?id=upStation01
[ERROR]2021-05-08 15:44:44,298: connect AGV01 failed timed out
[INFO]2021-05-08 15:44:44,334: AGV01 checkLink failed 172.16.217.209 19204
[WARN]2021-05-08 15:44:44,382: agvThread.AGV01[tid:14152] <lock name:agv.AGV01.lock_status,<locked _thread.RLock object owner=14152 count=1 at 0x0000027CDB32E918>> ,hold 10132 ms
[INFO]2021-05-08 15:44:44,464: name=agvThread.AGV01, pid=13844, tid=14152
[01] File "C:/Users/comba/AppData/Local/Programs/Python/Python37/lib/threading.py", line 865, in run() 
[02] File "C:/Users/comba/Desktop/知识城地牛/knowledgeCity/agvCtrl/agvList.py", line 565, in run() 
[03] File "../driver/seerAgv/agvCtrl.py", line 36, in checkLink() 
[04] File "../driver/seerAgv/agvApi.py", line 184, in checkLink() 
[05] File "C:/Users/comba/Desktop/知识城地牛/knowledgeCity/common/lock.py", line 102, in release() 
[06] File "C:/Users/comba/Desktop/知识城地牛/knowledgeCity/common/enhance.py", line 268, in getTrace() 
[07] File "C:/Users/comba/Desktop/知识城地牛/knowledgeCity/common/enhance.py", line 248, in getThreadStack()
[ERROR]2021-05-08 15:44:44,952: connect AGV02 failed timed out
[INFO]2021-05-08 15:44:44,988: AGV02 checkLink failed 172.16.217.213 19204
[WARN]2021-05-08 15:44:45,006: agvThread.AGV02[tid:14204] <lock name:agv.AGV02.lock_status,<locked _thread.RLock object owner=14204 count=1 at 0x0000027CDB32E418>> ,hold 10143 ms
[INFO]2021-05-08 15:44:45,081: name=agvThread.AGV02, pid=13844, tid=14204
[01] File "C:/Users/comba/AppData/Local/Programs/Python/Python37/lib/threading.py", line 865, in run() 
[02] File "C:/Users/comba/Desktop/知识城地牛/knowledgeCity/agvCtrl/agvList.py", line 565, in run() 
[03] File "../driver/seerAgv/agvCtrl.py", line 36, in checkLink() 
[04] File "../driver/seerAgv/agvApi.py", line 184, in checkLink() 
[05] File "C:/Users/comba/Desktop/知识城地牛/knowledgeCity/common/lock.py", line 102, in release() 
[06] File "C:/Users/comba/Desktop/知识城地牛/knowledgeCity/common/enhance.py", line 268, in getTrace() 
[07] File "C:/Users/comba/Desktop/知识城地牛/knowledgeCity/common/enhance.py", line 248, in getThreadStack()
[ERROR]2021-05-08 15:44:45,093: connect AGV03 failed timed out
[INFO]2021-05-08 15:44:45,158: AGV03 checkLink failed 172.16.217.121 19204
[WARN]2021-05-08 15:44:45,187: agvThread.AGV03[tid:14168] <lock name:agv.AGV03.lock_status,<locked _thread.RLock object owner=14168 count=1 at 0x0000027CDB32EBE8>> ,hold 10173 ms
[INFO]2021-05-08 15:44:45,257: name=agvThread.AGV03, pid=13844, tid=14168
[01] File "C:/Users/comba/AppData/Local/Programs/Python/Python37/lib/threading.py", line 865, in run() 
[02] File "C:/Users/comba/Desktop/知识城地牛/knowledgeCity/agvCtrl/agvList.py", line 565, in run() 
[03] File "../driver/seerAgv/agvCtrl.py", line 36, in checkLink() 
[04] File "../driver/seerAgv/agvApi.py", line 184, in checkLink() 
[05] File "C:/Users/comba/Desktop/知识城地牛/knowledgeCity/common/lock.py", line 102, in release() 
[06] File "C:/Users/comba/Desktop/知识城地牛/knowledgeCity/common/enhance.py", line 268, in getTrace() 
[07] File "C:/Users/comba/Desktop/知识城地牛/knowledgeCity/common/enhance.py", line 248, in getThreadStack()
[DEBUG]2021-05-08 15:44:46,542: try connect AGV01 172.16.217.209:19204
[DEBUG]2021-05-08 15:44:47,134: try connect AGV02 172.16.217.213:19204
[DEBUG]2021-05-08 15:44:47,292: try connect AGV03 172.16.217.121:19204
[WARN]2021-05-08 15:44:53,871: worker 9[tid:14260] <locked _thread.RLock object owner=14260 count=1 at 0x0000027CDA680800> ,hold 31478 ms
[INFO]2021-05-08 15:44:53,997: name=worker 9, pid=13844, tid=14260
[01] File "C:/Users/comba/AppData/Local/Programs/Python/Python37/lib/threading.py", line 865, in run() 
[02] File "C:/Users/comba/AppData/Local/Programs/Python/Python37/lib/site-packages/paste/httpserver.py", line 895, in worker_thread_callback() 
[03] File "C:/Users/comba/AppData/Local/Programs/Python/Python37/lib/site-packages/paste/httpserver.py", line 1069, in <lambda>() 
[04] File "C:/Users/comba/AppData/Local/Programs/Python/Python37/lib/site-packages/paste/httpserver.py", line 1085, in process_request_in_thread() 
[05] File "C:/Users/comba/AppData/Local/Programs/Python/Python37/lib/socketserver.py", line 357, in finish_request() 
[06] File "C:/Users/comba/AppData/Local/Programs/Python/Python37/lib/socketserver.py", line 717, in __init__() 
[07] File "C:/Users/comba/AppData/Local/Programs/Python/Python37/lib/site-packages/paste/httpserver.py", line 459, in handle() 
[08] File "C:/Users/comba/AppData/Local/Programs/Python/Python37/lib/http/server.py", line 426, in handle() 
[09] File "C:/Users/comba/AppData/Local/Programs/Python/Python37/lib/site-packages/paste/httpserver.py", line 454, in handle_one_request() 
[10] File "C:/Users/comba/AppData/Local/Programs/Python/Python37/lib/site-packages/paste/httpserver.py", line 304, in wsgi_execute() 
[11] File "C:/Users/comba/AppData/Local/Programs/Python/Python37/lib/site-packages/paste/translogger.py", line 69, in __call__() 
[12] File "C:/Users/comba/AppData/Local/Programs/Python/Python37/lib/site-packages/bottle.py", line 979, in __call__() 
[13] File "C:/Users/comba/AppData/Local/Programs/Python/Python37/lib/site-packages/bottle.py", line 954, in wsgi() 
[14] File "C:/Users/comba/AppData/Local/Programs/Python/Python37/lib/site-packages/bottle.py", line 862, in _handle() 
[15] File "C:/Users/comba/AppData/Local/Programs/Python/Python37/lib/site-packages/bottle.py", line 1742, in wrapper() 
[16] File "C:/Users/comba/Desktop/知识城地牛/knowledgeCity/common/webutility.py", line 465, in _enable_cors() 
[17] File "C:/Users/comba/Desktop/知识城地牛/knowledgeCity/common/webutility.py", line 481, in _enable_cors() 
[18] File "C:/Users/comba/Desktop/知识城地牛/knowledgeCity/common/scadaUtility.py", line 45, in __call() 
[19] File "C:/Users/comba/Desktop/知识城地牛/knowledgeCity/remoteio/main_remoteio.py", line 87, in urlReadDOList() 
[20] File "../remoteio/remoteioMgr.py", line 158, in readDOList() 
[21] File "../remoteio/remoteioMgr.py", line 262, in readDOList() 
[22] File "C:/Users/comba/Desktop/知识城地牛/knowledgeCity/common/lock.py", line 124, in _call() 
[23] File "C:/Users/comba/Desktop/知识城地牛/knowledgeCity/common/lock.py", line 102, in release() 
[24] File "C:/Users/comba/Desktop/知识城地牛/knowledgeCity/common/enhance.py", line 268, in getTrace() 
[25] File "C:/Users/comba/Desktop/知识城地牛/knowledgeCity/common/enhance.py", line 248, in getThreadStack()
[CRITICAL]2021-05-08 15:44:54,043: upStation01 readDIList fail cause a error: [WinError 10060] 由于连接方在一段时间后没有正确答复或连接的主机没有反应，连接尝试失败。
pid=13844, ppid=13780, tid=14260
Traceback (most recent call last):
  File "..\remoteio\remoteioMgr.py", line 262, in readDOList
    return self._read(M30, IO_LENTH)
  File "C:\Users\comba\Desktop\知识城地牛\knowledgeCity\common\lock.py", line 122, in _call
    return func(*p,**pp)
  File "..\remoteio\remoteioMgr.py", line 311, in _read
    self.master.open()
  File "C:\Users\comba\Desktop\知识城地牛\knowledgeCity\common\modbusapi.py", line 60, in open
    self.master.open()
  File "C:\Users\comba\AppData\Local\Programs\Python\Python37\lib\site-packages\modbus_tk\modbus.py", line 99, in open
    self._do_open()
  File "C:\Users\comba\AppData\Local\Programs\Python\Python37\lib\site-packages\modbus_tk\modbus_tcp.py", line 173, in _do_open
    self._sock.connect((self._host, self._port))
TimeoutError: [WinError 10060] 由于连接方在一段时间后没有正确答复或连接的主机没有反应，连接尝试失败。

[CRITICAL]2021-05-08 15:44:54,174: invoke <function urlReadDOList at 0x0000027CD91C1D08> cause a error: [WinError 10060] 由于连接方在一段时间后没有正确答复或连接的主机没有反应，连接尝试失败。
pid=13844, ppid=13780, tid=14260
Traceback (most recent call last):
  File "C:\Users\comba\Desktop\知识城地牛\knowledgeCity\common\scadaUtility.py", line 45, in __call
    ret = func(*p,**pp)
  File "C:\Users\comba\Desktop\知识城地牛\knowledgeCity\remoteio\main_remoteio.py", line 87, in urlReadDOList
    return ioMgr.readDOList(id)
  File "..\remoteio\remoteioMgr.py", line 158, in readDOList
    result=remoteioInfo.readDOList()
  File "..\remoteio\remoteioMgr.py", line 262, in readDOList
    return self._read(M30, IO_LENTH)
  File "C:\Users\comba\Desktop\知识城地牛\knowledgeCity\common\lock.py", line 122, in _call
    return func(*p,**pp)
  File "..\remoteio\remoteioMgr.py", line 311, in _read
    self.master.open()
  File "C:\Users\comba\Desktop\知识城地牛\knowledgeCity\common\modbusapi.py", line 60, in open
    self.master.open()
  File "C:\Users\comba\AppData\Local\Programs\Python\Python37\lib\site-packages\modbus_tk\modbus.py", line 99, in open
    self._do_open()
  File "C:\Users\comba\AppData\Local\Programs\Python\Python37\lib\site-packages\modbus_tk\modbus_tcp.py", line 173, in _do_open
    self._sock.connect((self._host, self._port))
TimeoutError: [WinError 10060] 由于连接方在一段时间后没有正确答复或连接的主机没有反应，连接尝试失败。

[CRITICAL]2021-05-08 15:44:54,914: readDIList error cause a error: ('http get', 'http://127.0.0.1:8999/api/remoteio/readDOList', {'id': 'upStation01'}, 'error:', 'timed out')
pid=13844, ppid=13780, tid=14132
Traceback (most recent call last):
  File "C:\Users\comba\Desktop\知识城地牛\knowledgeCity\common\webutility.py", line 103, in http_get
    f = urllib.request.urlopen(u,timeout=timeout)
  File "C:\Users\comba\AppData\Local\Programs\Python\Python37\lib\urllib\request.py", line 222, in urlopen
    return opener.open(url, data, timeout)
  File "C:\Users\comba\AppData\Local\Programs\Python\Python37\lib\urllib\request.py", line 525, in open
    response = self._open(req, data)
  File "C:\Users\comba\AppData\Local\Programs\Python\Python37\lib\urllib\request.py", line 543, in _open
    '_open', req)
  File "C:\Users\comba\AppData\Local\Programs\Python\Python37\lib\urllib\request.py", line 503, in _call_chain
    result = func(*args)
  File "C:\Users\comba\AppData\Local\Programs\Python\Python37\lib\urllib\request.py", line 1345, in http_open
    return self.do_open(http.client.HTTPConnection, req)
  File "C:\Users\comba\AppData\Local\Programs\Python\Python37\lib\urllib\request.py", line 1320, in do_open
    r = h.getresponse()
  File "C:\Users\comba\AppData\Local\Programs\Python\Python37\lib\http\client.py", line 1321, in getresponse
    response.begin()
  File "C:\Users\comba\AppData\Local\Programs\Python\Python37\lib\http\client.py", line 296, in begin
    version, status, reason = self._read_status()
  File "C:\Users\comba\AppData\Local\Programs\Python\Python37\lib\http\client.py", line 257, in _read_status
    line = str(self.fp.readline(_MAXLINE + 1), "iso-8859-1")
  File "C:\Users\comba\AppData\Local\Programs\Python\Python37\lib\socket.py", line 589, in readinto
    return self._sock.recv_into(b)
socket.timeout: timed out

During handling of the above exception, another exception occurred:

Traceback (most recent call last):
  File "C:\Users\comba\Desktop\知识城地牛\knowledgeCity\autoCtrl\deviceCtrl.py", line 71, in _monitorDevices
    s1 = ioApi.readDOList(devices[d]["io1"])["status"] #上板机
  File "..\remoteio\remoteioApi.py", line 73, in readDOList
    return _remoteio('/api/remoteio/readDOList', id, param)
  File "..\remoteio\remoteioApi.py", line 100, in _remoteio
    return http_get(url + apiurl, param)
  File "..\remoteio\remoteioApi.py", line 16, in http_get
    r = webutility.http_get(url, param)
  File "C:\Users\comba\Desktop\知识城地牛\knowledgeCity\common\webutility.py", line 105, in http_get
    raise Exception("http get",url,params,"error:",str(e))
Exception: ('http get', 'http://127.0.0.1:8999/api/remoteio/readDOList', {'id': 'upStation01'}, 'error:', 'timed out')

[INFO]2021-05-08 15:44:55,976: remoteio is alarm: []
[ERROR]2021-05-08 15:44:56,018: raise alarm obj=upStation01, typeId=39998, desc=远程控制IO离线异常, id=60964178697d98928ef142aa
[ERROR]2021-05-08 15:44:56,048: raise alarm obj=downStation01, typeId=39998, desc=远程控制IO离线异常, id=60964178697d98928ef142ac
[ERROR]2021-05-08 15:44:56,666: connect AGV01 failed timed out
[INFO]2021-05-08 15:44:56,701: AGV01 checkLink failed 172.16.217.209 19204
[WARN]2021-05-08 15:44:56,735: agvThread.AGV01[tid:14152] <lock name:agv.AGV01.lock_status,<locked _thread.RLock object owner=14152 count=1 at 0x0000027CDB32E918>> ,hold 10193 ms
[INFO]2021-05-08 15:44:56,806: name=agvThread.AGV01, pid=13844, tid=14152
[01] File "C:/Users/comba/AppData/Local/Programs/Python/Python37/lib/threading.py", line 865, in run() 
[02] File "C:/Users/comba/Desktop/知识城地牛/knowledgeCity/agvCtrl/agvList.py", line 565, in run() 
[03] File "../driver/seerAgv/agvCtrl.py", line 36, in checkLink() 
[04] File "../driver/seerAgv/agvApi.py", line 184, in checkLink() 
[05] File "C:/Users/comba/Desktop/知识城地牛/knowledgeCity/common/lock.py", line 102, in release() 
[06] File "C:/Users/comba/Desktop/知识城地牛/knowledgeCity/common/enhance.py", line 268, in getTrace() 
[07] File "C:/Users/comba/Desktop/知识城地牛/knowledgeCity/common/enhance.py", line 248, in getThreadStack()
[ERROR]2021-05-08 15:44:57,185: connect AGV02 failed timed out
[WARN]2021-05-08 15:44:57,191: AGV04 low battery charge,batteryLevel= 0.312 start charge level= 0.400
[INFO]2021-05-08 15:44:57,247: AGV02 checkLink failed 172.16.217.213 19204
[WARN]2021-05-08 15:44:57,270: AGV04 battery 0.312 check failed: isLocked
[WARN]2021-05-08 15:44:57,300: agvThread.AGV02[tid:14204] <lock name:agv.AGV02.lock_status,<locked _thread.RLock object owner=14204 count=1 at 0x0000027CDB32E418>> ,hold 10166 ms
[DEBUG]2021-05-08 15:44:57,333: send http_get: http://127.0.0.1:8999/api/remoteio/readDOList?id=upStation01
[ERROR]2021-05-08 15:44:57,363: connect AGV03 failed timed out
[INFO]2021-05-08 15:44:57,438: name=agvThread.AGV02, pid=13844, tid=14204
[01] File "C:/Users/comba/AppData/Local/Programs/Python/Python37/lib/threading.py", line 865, in run() 
[02] File "C:/Users/comba/Desktop/知识城地牛/knowledgeCity/agvCtrl/agvList.py", line 565, in run() 
[03] File "../driver/seerAgv/agvCtrl.py", line 36, in checkLink() 
[04] File "../driver/seerAgv/agvApi.py", line 184, in checkLink() 
[05] File "C:/Users/comba/Desktop/知识城地牛/knowledgeCity/common/lock.py", line 102, in release() 
[06] File "C:/Users/comba/Desktop/知识城地牛/knowledgeCity/common/enhance.py", line 268, in getTrace() 
[07] File "C:/Users/comba/Desktop/知识城地牛/knowledgeCity/common/enhance.py", line 248, in getThreadStack()
[INFO]2021-05-08 15:44:57,485: AGV03 checkLink failed 172.16.217.121 19204
[WARN]2021-05-08 15:44:57,549: agvThread.AGV03[tid:14168] <lock name:agv.AGV03.lock_status,<locked _thread.RLock object owner=14168 count=1 at 0x0000027CDB32EBE8>> ,hold 10257 ms
[INFO]2021-05-08 15:44:57,613: name=agvThread.AGV03, pid=13844, tid=14168
[01] File "C:/Users/comba/AppData/Local/Programs/Python/Python37/lib/threading.py", line 865, in run() 
[02] File "C:/Users/comba/Desktop/知识城地牛/knowledgeCity/agvCtrl/agvList.py", line 565, in run() 
[03] File "../driver/seerAgv/agvCtrl.py", line 36, in checkLink() 
[04] File "../driver/seerAgv/agvApi.py", line 184, in checkLink() 
[05] File "C:/Users/comba/Desktop/知识城地牛/knowledgeCity/common/lock.py", line 102, in release() 
[06] File "C:/Users/comba/Desktop/知识城地牛/knowledgeCity/common/enhance.py", line 268, in getTrace() 
[07] File "C:/Users/comba/Desktop/知识城地牛/knowledgeCity/common/enhance.py", line 248, in getThreadStack()
[DEBUG]2021-05-08 15:44:58,846: try connect AGV01 172.16.217.209:19204
[DEBUG]2021-05-08 15:44:59,518: try connect AGV02 172.16.217.213:19204
[DEBUG]2021-05-08 15:44:59,677: try connect AGV03 172.16.217.121:19204
[ERROR]2021-05-08 15:45:08,912: connect AGV01 failed timed out
[INFO]2021-05-08 15:45:08,947: AGV01 checkLink failed 172.16.217.209 19204
[WARN]2021-05-08 15:45:08,977: agvThread.AGV01[tid:14152] <lock name:agv.AGV01.lock_status,<locked _thread.RLock object owner=14152 count=1 at 0x0000027CDB32E918>> ,hold 10131 ms
[INFO]2021-05-08 15:45:09,083: name=agvThread.AGV01, pid=13844, tid=14152
[01] File "C:/Users/comba/AppData/Local/Programs/Python/Python37/lib/threading.py", line 865, in run() 
[02] File "C:/Users/comba/Desktop/知识城地牛/knowledgeCity/agvCtrl/agvList.py", line 565, in run() 
[03] File "../driver/seerAgv/agvCtrl.py", line 36, in checkLink() 
[04] File "../driver/seerAgv/agvApi.py", line 184, in checkLink() 
[05] File "C:/Users/comba/Desktop/知识城地牛/knowledgeCity/common/lock.py", line 102, in release() 
[06] File "C:/Users/comba/Desktop/知识城地牛/knowledgeCity/common/enhance.py", line 268, in getTrace() 
[07] File "C:/Users/comba/Desktop/知识城地牛/knowledgeCity/common/enhance.py", line 248, in getThreadStack()
[ERROR]2021-05-08 15:45:09,586: connect AGV02 failed timed out
[INFO]2021-05-08 15:45:09,634: AGV02 checkLink failed 172.16.217.213 19204
[WARN]2021-05-08 15:45:09,664: agvThread.AGV02[tid:14204] <lock name:agv.AGV02.lock_status,<locked _thread.RLock object owner=14204 count=1 at 0x0000027CDB32E418>> ,hold 10146 ms
[INFO]2021-05-08 15:45:09,725: name=agvThread.AGV02, pid=13844, tid=14204
[01] File "C:/Users/comba/AppData/Local/Programs/Python/Python37/lib/threading.py", line 865, in run() 
[02] File "C:/Users/comba/Desktop/知识城地牛/knowledgeCity/agvCtrl/agvList.py", line 565, in run() 
[03] File "../driver/seerAgv/agvCtrl.py", line 36, in checkLink() 
[04] File "../driver/seerAgv/agvApi.py", line 184, in checkLink() 
[05] File "C:/Users/comba/Desktop/知识城地牛/knowledgeCity/common/lock.py", line 102, in release() 
[06] File "C:/Users/comba/Desktop/知识城地牛/knowledgeCity/common/enhance.py", line 268, in getTrace() 
[07] File "C:/Users/comba/Desktop/知识城地牛/knowledgeCity/common/enhance.py", line 248, in getThreadStack()
[ERROR]2021-05-08 15:45:09,760: connect AGV03 failed timed out
[INFO]2021-05-08 15:45:09,843: AGV03 checkLink failed 172.16.217.121 19204
[WARN]2021-05-08 15:45:09,862: agvThread.AGV03[tid:14168] <lock name:agv.AGV03.lock_status,<locked _thread.RLock object owner=14168 count=1 at 0x0000027CDB32EBE8>> ,hold 10185 ms
[INFO]2021-05-08 15:45:09,956: name=agvThread.AGV03, pid=13844, tid=14168
[01] File "C:/Users/comba/AppData/Local/Programs/Python/Python37/lib/threading.py", line 865, in run() 
[02] File "C:/Users/comba/Desktop/知识城地牛/knowledgeCity/agvCtrl/agvList.py", line 565, in run() 
[03] File "../driver/seerAgv/agvCtrl.py", line 36, in checkLink() 
[04] File "../driver/seerAgv/agvApi.py", line 184, in checkLink() 
[05] File "C:/Users/comba/Desktop/知识城地牛/knowledgeCity/common/lock.py", line 102, in release() 
[06] File "C:/Users/comba/Desktop/知识城地牛/knowledgeCity/common/enhance.py", line 268, in getTrace() 
[07] File "C:/Users/comba/Desktop/知识城地牛/knowledgeCity/common/enhance.py", line 248, in getThreadStack()
[DEBUG]2021-05-08 15:45:11,146: try connect AGV01 172.16.217.209:19204
[DEBUG]2021-05-08 15:45:11,786: try connect AGV02 172.16.217.213:19204
[DEBUG]2021-05-08 15:45:11,985: try connect AGV03 172.16.217.121:19204
[CRITICAL]2021-05-08 15:45:12,519: readDIList error cause a error: ('http get', 'http://127.0.0.1:8999/api/remoteio/readDOList', {'id': 'upStation01'}, 'error:', 'timed out')
pid=13844, ppid=13780, tid=14132
Traceback (most recent call last):
  File "C:\Users\comba\Desktop\知识城地牛\knowledgeCity\common\webutility.py", line 103, in http_get
    f = urllib.request.urlopen(u,timeout=timeout)
  File "C:\Users\comba\AppData\Local\Programs\Python\Python37\lib\urllib\request.py", line 222, in urlopen
    return opener.open(url, data, timeout)
  File "C:\Users\comba\AppData\Local\Programs\Python\Python37\lib\urllib\request.py", line 525, in open
    response = self._open(req, data)
  File "C:\Users\comba\AppData\Local\Programs\Python\Python37\lib\urllib\request.py", line 543, in _open
    '_open', req)
  File "C:\Users\comba\AppData\Local\Programs\Python\Python37\lib\urllib\request.py", line 503, in _call_chain
    result = func(*args)
  File "C:\Users\comba\AppData\Local\Programs\Python\Python37\lib\urllib\request.py", line 1345, in http_open
    return self.do_open(http.client.HTTPConnection, req)
  File "C:\Users\comba\AppData\Local\Programs\Python\Python37\lib\urllib\request.py", line 1320, in do_open
    r = h.getresponse()
  File "C:\Users\comba\AppData\Local\Programs\Python\Python37\lib\http\client.py", line 1321, in getresponse
    response.begin()
  File "C:\Users\comba\AppData\Local\Programs\Python\Python37\lib\http\client.py", line 296, in begin
    version, status, reason = self._read_status()
  File "C:\Users\comba\AppData\Local\Programs\Python\Python37\lib\http\client.py", line 257, in _read_status
    line = str(self.fp.readline(_MAXLINE + 1), "iso-8859-1")
  File "C:\Users\comba\AppData\Local\Programs\Python\Python37\lib\socket.py", line 589, in readinto
    return self._sock.recv_into(b)
socket.timeout: timed out

During handling of the above exception, another exception occurred:

Traceback (most recent call last):
  File "C:\Users\comba\Desktop\知识城地牛\knowledgeCity\autoCtrl\deviceCtrl.py", line 71, in _monitorDevices
    s1 = ioApi.readDOList(devices[d]["io1"])["status"] #上板机
  File "..\remoteio\remoteioApi.py", line 73, in readDOList
    return _remoteio('/api/remoteio/readDOList', id, param)
  File "..\remoteio\remoteioApi.py", line 100, in _remoteio
    return http_get(url + apiurl, param)
  File "..\remoteio\remoteioApi.py", line 16, in http_get
    r = webutility.http_get(url, param)
  File "C:\Users\comba\Desktop\知识城地牛\knowledgeCity\common\webutility.py", line 105, in http_get
    raise Exception("http get",url,params,"error:",str(e))
Exception: ('http get', 'http://127.0.0.1:8999/api/remoteio/readDOList', {'id': 'upStation01'}, 'error:', 'timed out')

[INFO]2021-05-08 15:45:13,615: remoteio is alarm: ['upStation01', 'downStation01']
[WARN]2021-05-08 15:45:14,765: AGV04 low battery charge,batteryLevel= 0.312 start charge level= 0.400
[WARN]2021-05-08 15:45:14,800: AGV04 battery 0.312 check failed: isLocked
[WARN]2021-05-08 15:45:15,049: worker 5[tid:14244] <locked _thread.RLock object owner=14244 count=1 at 0x0000027CDA680800> ,hold 35197 ms
[INFO]2021-05-08 15:45:15,159: name=worker 5, pid=13844, tid=14244
[01] File "C:/Users/comba/AppData/Local/Programs/Python/Python37/lib/threading.py", line 865, in run() 
[02] File "C:/Users/comba/AppData/Local/Programs/Python/Python37/lib/site-packages/paste/httpserver.py", line 895, in worker_thread_callback() 
[03] File "C:/Users/comba/AppData/Local/Programs/Python/Python37/lib/site-packages/paste/httpserver.py", line 1069, in <lambda>() 
[04] File "C:/Users/comba/AppData/Local/Programs/Python/Python37/lib/site-packages/paste/httpserver.py", line 1085, in process_request_in_thread() 
[05] File "C:/Users/comba/AppData/Local/Programs/Python/Python37/lib/socketserver.py", line 357, in finish_request() 
[06] File "C:/Users/comba/AppData/Local/Programs/Python/Python37/lib/socketserver.py", line 717, in __init__() 
[07] File "C:/Users/comba/AppData/Local/Programs/Python/Python37/lib/site-packages/paste/httpserver.py", line 459, in handle() 
[08] File "C:/Users/comba/AppData/Local/Programs/Python/Python37/lib/http/server.py", line 426, in handle() 
[09] File "C:/Users/comba/AppData/Local/Programs/Python/Python37/lib/site-packages/paste/httpserver.py", line 454, in handle_one_request() 
[10] File "C:/Users/comba/AppData/Local/Programs/Python/Python37/lib/site-packages/paste/httpserver.py", line 304, in wsgi_execute() 
[11] File "C:/Users/comba/AppData/Local/Programs/Python/Python37/lib/site-packages/paste/translogger.py", line 69, in __call__() 
[12] File "C:/Users/comba/AppData/Local/Programs/Python/Python37/lib/site-packages/bottle.py", line 979, in __call__() 
[13] File "C:/Users/comba/AppData/Local/Programs/Python/Python37/lib/site-packages/bottle.py", line 954, in wsgi() 
[14] File "C:/Users/comba/AppData/Local/Programs/Python/Python37/lib/site-packages/bottle.py", line 862, in _handle() 
[15] File "C:/Users/comba/AppData/Local/Programs/Python/Python37/lib/site-packages/bottle.py", line 1742, in wrapper() 
[16] File "C:/Users/comba/Desktop/知识城地牛/knowledgeCity/common/webutility.py", line 465, in _enable_cors() 
[17] File "C:/Users/comba/Desktop/知识城地牛/knowledgeCity/common/webutility.py", line 481, in _enable_cors() 
[18] File "C:/Users/comba/Desktop/知识城地牛/knowledgeCity/common/scadaUtility.py", line 45, in __call() 
[19] File "C:/Users/comba/Desktop/知识城地牛/knowledgeCity/remoteio/main_remoteio.py", line 87, in urlReadDOList() 
[20] File "../remoteio/remoteioMgr.py", line 158, in readDOList() 
[21] File "../remoteio/remoteioMgr.py", line 262, in readDOList() 
[22] File "C:/Users/comba/Desktop/知识城地牛/knowledgeCity/common/lock.py", line 124, in _call() 
[23] File "C:/Users/comba/Desktop/知识城地牛/knowledgeCity/common/lock.py", line 102, in release() 
[24] File "C:/Users/comba/Desktop/知识城地牛/knowledgeCity/common/enhance.py", line 268, in getTrace() 
[25] File "C:/Users/comba/Desktop/知识城地牛/knowledgeCity/common/enhance.py", line 248, in getThreadStack()
[CRITICAL]2021-05-08 15:45:15,279: upStation01 readDIList fail cause a error: [WinError 10060] 由于连接方在一段时间后没有正确答复或连接的主机没有反应，连接尝试失败。
pid=13844, ppid=13780, tid=14244
Traceback (most recent call last):
  File "..\remoteio\remoteioMgr.py", line 262, in readDOList
    return self._read(M30, IO_LENTH)
  File "C:\Users\comba\Desktop\知识城地牛\knowledgeCity\common\lock.py", line 122, in _call
    return func(*p,**pp)
  File "..\remoteio\remoteioMgr.py", line 311, in _read
    self.master.open()
  File "C:\Users\comba\Desktop\知识城地牛\knowledgeCity\common\modbusapi.py", line 60, in open
    self.master.open()
  File "C:\Users\comba\AppData\Local\Programs\Python\Python37\lib\site-packages\modbus_tk\modbus.py", line 99, in open
    self._do_open()
  File "C:\Users\comba\AppData\Local\Programs\Python\Python37\lib\site-packages\modbus_tk\modbus_tcp.py", line 173, in _do_open
    self._sock.connect((self._host, self._port))
TimeoutError: [WinError 10060] 由于连接方在一段时间后没有正确答复或连接的主机没有反应，连接尝试失败。

[CRITICAL]2021-05-08 15:45:15,425: invoke <function urlReadDOList at 0x0000027CD91C1D08> cause a error: [WinError 10060] 由于连接方在一段时间后没有正确答复或连接的主机没有反应，连接尝试失败。
pid=13844, ppid=13780, tid=14244
Traceback (most recent call last):
  File "C:\Users\comba\Desktop\知识城地牛\knowledgeCity\common\scadaUtility.py", line 45, in __call
    ret = func(*p,**pp)
  File "C:\Users\comba\Desktop\知识城地牛\knowledgeCity\remoteio\main_remoteio.py", line 87, in urlReadDOList
    return ioMgr.readDOList(id)
  File "..\remoteio\remoteioMgr.py", line 158, in readDOList
    result=remoteioInfo.readDOList()
  File "..\remoteio\remoteioMgr.py", line 262, in readDOList
    return self._read(M30, IO_LENTH)
  File "C:\Users\comba\Desktop\知识城地牛\knowledgeCity\common\lock.py", line 122, in _call
    return func(*p,**pp)
  File "..\remoteio\remoteioMgr.py", line 311, in _read
    self.master.open()
  File "C:\Users\comba\Desktop\知识城地牛\knowledgeCity\common\modbusapi.py", line 60, in open
    self.master.open()
  File "C:\Users\comba\AppData\Local\Programs\Python\Python37\lib\site-packages\modbus_tk\modbus.py", line 99, in open
    self._do_open()
  File "C:\Users\comba\AppData\Local\Programs\Python\Python37\lib\site-packages\modbus_tk\modbus_tcp.py", line 173, in _do_open
    self._sock.connect((self._host, self._port))
TimeoutError: [WinError 10060] 由于连接方在一段时间后没有正确答复或连接的主机没有反应，连接尝试失败。

[INFO]2021-05-08 15:45:15,973: remoteio is alarm: ['upStation01', 'downStation01']
[ERROR]2021-05-08 15:45:21,229: connect AGV01 failed timed out
[INFO]2021-05-08 15:45:21,287: AGV01 checkLink failed 172.16.217.209 19204
[WARN]2021-05-08 15:45:21,321: agvThread.AGV01[tid:14152] <lock name:agv.AGV01.lock_status,<locked _thread.RLock object owner=14152 count=1 at 0x0000027CDB32E918>> ,hold 10175 ms
[INFO]2021-05-08 15:45:21,420: name=agvThread.AGV01, pid=13844, tid=14152
[01] File "C:/Users/comba/AppData/Local/Programs/Python/Python37/lib/threading.py", line 865, in run() 
[02] File "C:/Users/comba/Desktop/知识城地牛/knowledgeCity/agvCtrl/agvList.py", line 565, in run() 
[03] File "../driver/seerAgv/agvCtrl.py", line 36, in checkLink() 
[04] File "../driver/seerAgv/agvApi.py", line 184, in checkLink() 
[05] File "C:/Users/comba/Desktop/知识城地牛/knowledgeCity/common/lock.py", line 102, in release() 
[06] File "C:/Users/comba/Desktop/知识城地牛/knowledgeCity/common/enhance.py", line 268, in getTrace() 
[07] File "C:/Users/comba/Desktop/知识城地牛/knowledgeCity/common/enhance.py", line 248, in getThreadStack()
[ERROR]2021-05-08 15:45:21,838: connect AGV02 failed timed out
[INFO]2021-05-08 15:45:21,856: AGV02 checkLink failed 172.16.217.213 19204
[WARN]2021-05-08 15:45:21,891: agvThread.AGV02[tid:14204] <lock name:agv.AGV02.lock_status,<locked _thread.RLock object owner=14204 count=1 at 0x0000027CDB32E418>> ,hold 10105 ms
[INFO]2021-05-08 15:45:21,975: name=agvThread.AGV02, pid=13844, tid=14204
[01] File "C:/Users/comba/AppData/Local/Programs/Python/Python37/lib/threading.py", line 865, in run() 
[02] File "C:/Users/comba/Desktop/知识城地牛/knowledgeCity/agvCtrl/agvList.py", line 565, in run() 
[03] File "../driver/seerAgv/agvCtrl.py", line 36, in checkLink() 
[04] File "../driver/seerAgv/agvApi.py", line 184, in checkLink() 
[05] File "C:/Users/comba/Desktop/知识城地牛/knowledgeCity/common/lock.py", line 102, in release() 
[06] File "C:/Users/comba/Desktop/知识城地牛/knowledgeCity/common/enhance.py", line 268, in getTrace() 
[07] File "C:/Users/comba/Desktop/知识城地牛/knowledgeCity/common/enhance.py", line 248, in getThreadStack()
[ERROR]2021-05-08 15:45:22,033: connect AGV03 failed timed out
[INFO]2021-05-08 15:45:22,062: AGV03 checkLink failed 172.16.217.121 19204
[WARN]2021-05-08 15:45:22,101: agvThread.AGV03[tid:14168] <lock name:agv.AGV03.lock_status,<locked _thread.RLock object owner=14168 count=1 at 0x0000027CDB32EBE8>> ,hold 10116 ms
[INFO]2021-05-08 15:45:22,157: name=agvThread.AGV03, pid=13844, tid=14168
[01] File "C:/Users/comba/AppData/Local/Programs/Python/Python37/lib/threading.py", line 865, in run() 
[02] File "C:/Users/comba/Desktop/知识城地牛/knowledgeCity/agvCtrl/agvList.py", line 565, in run() 
[03] File "../driver/seerAgv/agvCtrl.py", line 36, in checkLink() 
[04] File "../driver/seerAgv/agvApi.py", line 184, in checkLink() 
[05] File "C:/Users/comba/Desktop/知识城地牛/knowledgeCity/common/lock.py", line 102, in release() 
[06] File "C:/Users/comba/Desktop/知识城地牛/knowledgeCity/common/enhance.py", line 268, in getTrace() 
[07] File "C:/Users/comba/Desktop/知识城地牛/knowledgeCity/common/enhance.py", line 248, in getThreadStack()
[DEBUG]2021-05-08 15:45:23,463: try connect AGV01 172.16.217.209:19204
[DEBUG]2021-05-08 15:45:24,017: try connect AGV02 172.16.217.213:19204
[DEBUG]2021-05-08 15:45:24,205: try connect AGV03 172.16.217.121:19204
