[INFO]2021-05-08 16:04:36,242: log files at C:\Users\comba\Desktop\知识城地牛\knowledgeCity\common\log
[INFO]2021-05-08 16:04:36,242: find module agvCtrl.main_agv
[INFO]2021-05-08 16:04:36,243: find module agvDevice.main_agvDevice
[INFO]2021-05-08 16:04:36,243: find module alarm.main_alarm
[INFO]2021-05-08 16:04:36,243: find module auth.main_auth
[INFO]2021-05-08 16:04:36,243: find module autoCtrl.main_akmCtrl
[INFO]2021-05-08 16:04:36,244: find module door.main_door
[INFO]2021-05-08 16:04:36,244: find module elevator.main_elevator
[INFO]2021-05-08 16:04:36,244: find module feed.main_feed
[INFO]2021-05-08 16:04:36,247: find module remoteio.main_remoteio
[INFO]2021-05-08 16:04:36,247: import agvCtrl.main_agv
[INFO]2021-05-08 16:04:36,487: create lock <lock name:doorMgr.lock,<unlocked _thread.RLock object owner=0 count=0 at 0x000001B9596147B0>>
[INFO]2021-05-08 16:04:36,489: create lock <lock name:door.lock,<unlocked _thread.RLock object owner=0 count=0 at 0x000001B959614918>>
[INFO]2021-05-08 16:04:36,542: create lock <lock name:timer.lock_1895582574744,<unlocked _thread.RLock object owner=0 count=0 at 0x000001B95985F440>>
[ERROR]2021-05-08 16:04:36,550: mqtt is disabled
[INFO]2021-05-08 16:04:36,552: mqtt: subscribe [alarm/raise/+]
[INFO]2021-05-08 16:04:36,553: mqtt: subscribe [alarm/clear/+]
[INFO]2021-05-08 16:04:39,571: Mongodb connect to 127.0.0.1 port 27017
[INFO]2021-05-08 16:04:39,607: create lock <lock name:elevatorApi.tcp_lock,<unlocked _thread.RLock object owner=0 count=0 at 0x000001B959A28B48>>
[INFO]2021-05-08 16:04:39,609: create lock <lock name:elevatorApi.g_lock,<unlocked _thread.RLock object owner=0 count=0 at 0x000001B959A28788>>
[INFO]2021-05-08 16:04:39,610: create lock <lock name:elevatorMgr.lock,<unlocked _thread.RLock object owner=0 count=0 at 0x000001B959A28300>>
[INFO]2021-05-08 16:04:39,619: create lock <lock name:agvserver,<unlocked _thread.RLock object owner=0 count=0 at 0x000001B959B31760>>
[INFO]2021-05-08 16:04:39,771: create lock <lock name:mapMgr.lock,<unlocked _thread.RLock object owner=0 count=0 at 0x000001B957DEC198>>
[INFO]2021-05-08 16:04:39,986: create lock <lock name:agvList.g_agvLock,<unlocked _thread.RLock object owner=0 count=0 at 0x000001B959C0DE40>>
[INFO]2021-05-08 16:04:39,989: create lock <lock name:taskList.lock,<unlocked _thread.RLock object owner=0 count=0 at 0x000001B959C55F30>>
[INFO]2021-05-08 16:04:40,039: charge policy 0 , fix time
[INFO]2021-05-08 16:04:40,065: create lock <lock name:agvApi.g_lock,<unlocked _thread.RLock object owner=0 count=0 at 0x000001B959CCB1C0>>
[INFO]2021-05-08 16:04:40,487: start load map C:\Users\comba\Desktop\知识城地牛\knowledgeCity\agvCtrl\projects\knowledgeCity\comba-ZSC-3F_0419.smap
[DEBUG]2021-05-08 16:04:40,565: elevator thread start
[INFO]2021-05-08 16:04:40,581: load map C:\Users\comba\Desktop\知识城地牛\knowledgeCity\agvCtrl\projects\knowledgeCity\comba-ZSC-3F_0419.smap ,used 101 ms
[INFO]2021-05-08 16:04:40,588: start load map C:\Users\comba\Desktop\知识城地牛\knowledgeCity\agvCtrl\projects\knowledgeCity\comba-ZSC-F1-F3.smap
[INFO]2021-05-08 16:04:40,733: load map C:\Users\comba\Desktop\知识城地牛\knowledgeCity\agvCtrl\projects\knowledgeCity\comba-ZSC-F1-F3.smap ,used 151 ms
[INFO]2021-05-08 16:04:40,742: start load map C:\Users\comba\Desktop\知识城地牛\knowledgeCity\agvCtrl\projects\knowledgeCity\comba-ZXC-3F.smap
[INFO]2021-05-08 16:04:40,818: load map C:\Users\comba\Desktop\知识城地牛\knowledgeCity\agvCtrl\projects\knowledgeCity\comba-ZXC-3F.smap ,used 83 ms
[INFO]2021-05-08 16:04:40,826: start load map C:\Users\comba\Desktop\知识城地牛\knowledgeCity\agvCtrl\projects\knowledgeCity\comba-ZXC-F3.smap
[INFO]2021-05-08 16:04:40,875: load map C:\Users\comba\Desktop\知识城地牛\knowledgeCity\agvCtrl\projects\knowledgeCity\comba-ZXC-F3.smap ,used 56 ms
[INFO]2021-05-08 16:04:40,886: start load map C:\Users\comba\Desktop\知识城地牛\knowledgeCity\agvCtrl\projects\knowledgeCity\office.smap
[INFO]2021-05-08 16:04:40,920: load map C:\Users\comba\Desktop\知识城地牛\knowledgeCity\agvCtrl\projects\knowledgeCity\office.smap ,used 42 ms
[INFO]2021-05-08 16:04:40,924: import agvDevice.main_agvDevice
[INFO]2021-05-08 16:04:40,925: import alarm.main_alarm
[INFO]2021-05-08 16:04:40,926: import auth.main_auth
[INFO]2021-05-08 16:04:40,933: import autoCtrl.main_akmCtrl
[INFO]2021-05-08 16:04:40,943: create lock <lock name:agvApi.g_lock,<unlocked _thread.RLock object owner=0 count=0 at 0x000001B95A0E3468>>
[INFO]2021-05-08 16:04:40,951: create lock <lock name:runTasks.pre_lock,<unlocked _thread.RLock object owner=0 count=0 at 0x000001B95A0B9648>>
[INFO]2021-05-08 16:04:40,972: create lock <lock name:IOAlarm.s_lock,<unlocked _thread.RLock object owner=0 count=0 at 0x000001B95A0B9148>>
[INFO]2021-05-08 16:04:40,977: create lock <lock name:mapMgr.lock,<unlocked _thread.RLock object owner=0 count=0 at 0x000001B95A8920F8>>
[INFO]2021-05-08 16:04:41,506: import door.main_door
[INFO]2021-05-08 16:04:41,509: import elevator.main_elevator
[INFO]2021-05-08 16:04:41,509: import feed.main_feed
[INFO]2021-05-08 16:04:41,516: create lock <lock name:feedTask.g_lock,<unlocked _thread.RLock object owner=0 count=0 at 0x000001B95AC8D508>>
[INFO]2021-05-08 16:04:41,549: import remoteio.main_remoteio
[SUCC]2021-05-08 16:04:41,568: utility start, pid=10292, ppid=13624
[DEBUG]2021-05-08 16:04:41,568: create aliveObj upStation01 远程控制IO离线异常 timeout 120
[DEBUG]2021-05-08 16:04:41,569: start timer
[DEBUG]2021-05-08 16:04:41,570: create aliveObj downStation01 远程控制IO离线异常 timeout 120
[INFO]2021-05-08 16:04:41,578: load agv file: C:\Users\comba\Desktop\知识城地牛\knowledgeCity\agvCtrl/projects/knowledgeCity/agv.cfg
[INFO]2021-05-08 16:04:41,579: create lock <lock name:agvList.AGV01.lock,<unlocked _thread.RLock object owner=0 count=0 at 0x000001B95AD3D468>>
[DEBUG]2021-05-08 16:04:41,581: create aliveObj AGV01 AGV离线异常 timeout 300
[INFO]2021-05-08 16:04:41,583: AGV01 start agvList run thread
[INFO]2021-05-08 16:04:41,583: AGV01 start agvList run2 thread
[INFO]2021-05-08 16:04:41,583: create lock <lock name:agv.AGV01.lock_status,<unlocked _thread.RLock object owner=0 count=0 at 0x000001B95AD3D940>>
[DEBUG]2021-05-08 16:04:41,585: try connect AGV01 172.16.217.209:19204
[INFO]2021-05-08 16:04:41,586: create lock <lock name:agvList.AGV03.lock,<unlocked _thread.RLock object owner=0 count=0 at 0x000001B95AD3D9E0>>
[DEBUG]2021-05-08 16:04:41,588: create aliveObj AGV03 AGV离线异常 timeout 300
[INFO]2021-05-08 16:04:41,589: AGV03 start agvList run thread
[INFO]2021-05-08 16:04:41,589: AGV03 start agvList run2 thread
[INFO]2021-05-08 16:04:41,589: create lock <lock name:agvList.AGV04.lock,<unlocked _thread.RLock object owner=0 count=0 at 0x000001B95AD3DBC0>>
[INFO]2021-05-08 16:04:41,590: create lock <lock name:agv.AGV03.lock_status,<unlocked _thread.RLock object owner=0 count=0 at 0x000001B95AD3DC10>>
[DEBUG]2021-05-08 16:04:41,591: try connect AGV03 172.16.217.121:19204
[DEBUG]2021-05-08 16:04:41,592: create aliveObj AGV04 AGV离线异常 timeout 300
[INFO]2021-05-08 16:04:41,593: AGV04 start agvList run thread
[INFO]2021-05-08 16:04:41,594: AGV04 start agvList run2 thread
[INFO]2021-05-08 16:04:41,594: create lock <lock name:agvList.AGV02.lock,<unlocked _thread.RLock object owner=0 count=0 at 0x000001B95AD3DE40>>
[INFO]2021-05-08 16:04:41,594: create lock <lock name:agv.AGV04.lock_status,<unlocked _thread.RLock object owner=0 count=0 at 0x000001B95AD3DE90>>
[DEBUG]2021-05-08 16:04:41,595: try connect AGV04 172.16.217.211:19204
[DEBUG]2021-05-08 16:04:41,597: create aliveObj AGV02 AGV离线异常 timeout 300
[INFO]2021-05-08 16:04:41,597: AGV02 start agvList run thread
[INFO]2021-05-08 16:04:41,598: AGV02 start agvList run2 thread
[WARN]2021-05-08 16:04:41,598: Local server start! version 3.7.0, path C:\Users\comba\Desktop\知识城地牛\knowledgeCity\common, pid 10292
[INFO]2021-05-08 16:04:41,598: create lock <lock name:agv.AGV02.lock_status,<unlocked _thread.RLock object owner=0 count=0 at 0x000001B95AD3D418>>
[INFO]2021-05-08 16:04:41,599: add_ignore: taskStatus
[DEBUG]2021-05-08 16:04:41,599: try connect AGV02 172.16.217.213:19204
[INFO]2021-05-08 16:04:41,606: AGV04 connected 172.16.217.211 19204
[INFO]2021-05-08 16:04:41,606: create lock <lock name:agv.AGV04.lock_ctrl,<unlocked _thread.RLock object owner=0 count=0 at 0x000001B95AD3DFA8>>
[DEBUG]2021-05-08 16:04:41,607: try connect AGV04 172.16.217.211:19205
[INFO]2021-05-08 16:04:41,633: AGV04 connected 172.16.217.211 19205
[INFO]2021-05-08 16:04:41,634: create lock <lock name:agv.AGV04.lock_task,<unlocked _thread.RLock object owner=0 count=0 at 0x000001B958C0CAF8>>
[DEBUG]2021-05-08 16:04:41,635: try connect AGV04 172.16.217.211:19206
[INFO]2021-05-08 16:04:41,659: AGV04 connected 172.16.217.211 19206
[INFO]2021-05-08 16:04:41,660: create lock <lock name:agv.AGV04.lock_conf,<unlocked _thread.RLock object owner=0 count=0 at 0x000001B958C0CB20>>
[DEBUG]2021-05-08 16:04:41,661: try connect AGV04 172.16.217.211:19207
[INFO]2021-05-08 16:04:41,669: AGV04 connected 172.16.217.211 19207
[INFO]2021-05-08 16:04:41,670: create lock <lock name:agv.AGV04.lock_core,<unlocked _thread.RLock object owner=0 count=0 at 0x000001B958C0CBC0>>
[DEBUG]2021-05-08 16:04:41,670: try connect AGV04 172.16.217.211:19208
[INFO]2021-05-08 16:04:41,685: AGV04 connected 172.16.217.211 19208
[INFO]2021-05-08 16:04:41,685: create lock <lock name:agv.AGV04.lock_other,<unlocked _thread.RLock object owner=0 count=0 at 0x000001B958C0CBE8>>
[DEBUG]2021-05-08 16:04:41,686: try connect AGV04 172.16.217.211:19210
[INFO]2021-05-08 16:04:41,693: AGV04 connected 172.16.217.211 19210
[INFO]2021-05-08 16:04:41,727: AGV04 current map comba-ZXC-F3
[INFO]2021-05-08 16:04:41,773: AGV04 is online
[WARN]2021-05-08 16:04:41,781: clear alarm obj=AGV04, typeId=54004, id=609645a8697d98928ef14496
[WARN]2021-05-08 16:04:41,784: clear alarm obj=AGV04, typeId=54013, id=609645a8697d98928ef1449d
[ERROR]2021-05-08 16:04:41,785: raise alarm obj=AGV04, typeId=49997, desc=小车置信度小于最低阈值,当前值:0.6029
[WARN]2021-05-08 16:04:41,789: clear alarm obj=AGV04, typeId=4002, id=609645a8697d98928ef1449b
[DEBUG]2021-05-08 16:04:46,587: GET: http://127.0.0.1:8999/api/agv/init?appName=akmTask addr: 127.0.0.1
[INFO]2021-05-08 16:04:46,590: akmTask init client agvApi
[DEBUG]2021-05-08 16:04:46,592: used 5ms 200 OK application/json;charset=utf-8, GET: http://127.0.0.1:8999/api/agv/init?appName=akmTask
[DEBUG]2021-05-08 16:04:49,641: GET: http://127.0.0.1:8999/api/agv/startCharge?appName=akmTask addr: 127.0.0.1
[DEBUG]2021-05-08 16:04:49,653: used 12ms 200 OK application/json;charset=utf-8, GET: http://127.0.0.1:8999/api/agv/startCharge?appName=akmTask
[WARN]2021-05-08 16:04:49,717: timer_thread[tid:13572] <locked _thread.RLock object owner=13572 count=1 at 0x000001B95A0B9620> ,hold 8145 ms
[INFO]2021-05-08 16:04:49,788: name=timer_thread, pid=10292, tid=13572
[01] File "C:/Users/comba/AppData/Local/Programs/Python/Python37/lib/threading.py", line 865, in run() 
[02] File "C:/Users/comba/Desktop/知识城地牛/knowledgeCity/common/mytimer.py", line 113, in _loop() 
[03] File "C:/Users/comba/Desktop/知识城地牛/knowledgeCity/common/lock.py", line 124, in _call() 
[04] File "C:/Users/comba/Desktop/知识城地牛/knowledgeCity/common/lock.py", line 102, in release() 
[05] File "C:/Users/comba/Desktop/知识城地牛/knowledgeCity/common/enhance.py", line 268, in getTrace() 
[06] File "C:/Users/comba/Desktop/知识城地牛/knowledgeCity/common/enhance.py", line 248, in getThreadStack()
[WARN]2021-05-08 16:04:50,993: AGV04 low battery charge,batteryLevel= 0.288 start charge level= 0.400
[WARN]2021-05-08 16:04:51,022: AGV04 battery 0.288 check failed: no_idle_9.428
[DEBUG]2021-05-08 16:04:51,388: send http_get: http://127.0.0.1:8999/api/remoteio/readDOList?id=upStation01
[ERROR]2021-05-08 16:04:51,593: connect AGV01 failed timed out
[ERROR]2021-05-08 16:04:51,599: connect AGV03 failed timed out
[ERROR]2021-05-08 16:04:51,634: connect AGV02 failed timed out
[DEBUG]2021-05-08 16:04:51,674: try connect AGV01 172.16.217.209:19204
[DEBUG]2021-05-08 16:04:51,680: try connect AGV03 172.16.217.121:19204
[DEBUG]2021-05-08 16:04:51,709: try connect AGV02 172.16.217.213:19204
[ERROR]2021-05-08 16:05:01,769: connect AGV01 failed timed out
[INFO]2021-05-08 16:05:01,797: AGV01 checkLink failed 172.16.217.209 19204
[ERROR]2021-05-08 16:05:01,803: connect AGV03 failed timed out
[WARN]2021-05-08 16:05:01,837: agvThread.AGV01[tid:7308] <lock name:agv.AGV01.lock_status,<locked _thread.RLock object owner=7308 count=1 at 0x000001B95AD3D940>> ,hold 20252 ms
[ERROR]2021-05-08 16:05:01,866: connect AGV02 failed timed out
[INFO]2021-05-08 16:05:01,895: AGV03 checkLink failed 172.16.217.121 19204
[INFO]2021-05-08 16:05:01,971: AGV02 checkLink failed 172.16.217.213 19204
[INFO]2021-05-08 16:05:01,995: name=agvThread.AGV01, pid=10292, tid=7308
[01] File "C:/Users/comba/AppData/Local/Programs/Python/Python37/lib/threading.py", line 865, in run() 
[02] File "C:/Users/comba/Desktop/知识城地牛/knowledgeCity/agvCtrl/agvList.py", line 565, in run() 
[03] File "../driver/seerAgv/agvCtrl.py", line 36, in checkLink() 
[04] File "../driver/seerAgv/agvApi.py", line 184, in checkLink() 
[05] File "C:/Users/comba/Desktop/知识城地牛/knowledgeCity/common/lock.py", line 102, in release() 
[06] File "C:/Users/comba/Desktop/知识城地牛/knowledgeCity/common/enhance.py", line 268, in getTrace() 
[07] File "C:/Users/comba/Desktop/知识城地牛/knowledgeCity/common/enhance.py", line 248, in getThreadStack()
[WARN]2021-05-08 16:05:02,012: agvThread.AGV03[tid:1072] <lock name:agv.AGV03.lock_status,<locked _thread.RLock object owner=1072 count=1 at 0x000001B95AD3DC10>> ,hold 20421 ms
[WARN]2021-05-08 16:05:02,065: agvThread.AGV02[tid:13448] <lock name:agv.AGV02.lock_status,<locked _thread.RLock object owner=13448 count=1 at 0x000001B95AD3D418>> ,hold 20466 ms
[INFO]2021-05-08 16:05:02,170: name=agvThread.AGV03, pid=10292, tid=1072
[01] File "C:/Users/comba/AppData/Local/Programs/Python/Python37/lib/threading.py", line 865, in run() 
[02] File "C:/Users/comba/Desktop/知识城地牛/knowledgeCity/agvCtrl/agvList.py", line 565, in run() 
[03] File "../driver/seerAgv/agvCtrl.py", line 36, in checkLink() 
[04] File "../driver/seerAgv/agvApi.py", line 184, in checkLink() 
[05] File "C:/Users/comba/Desktop/知识城地牛/knowledgeCity/common/lock.py", line 102, in release() 
[06] File "C:/Users/comba/Desktop/知识城地牛/knowledgeCity/common/enhance.py", line 268, in getTrace() 
[07] File "C:/Users/comba/Desktop/知识城地牛/knowledgeCity/common/enhance.py", line 248, in getThreadStack()
[INFO]2021-05-08 16:05:02,204: name=agvThread.AGV02, pid=10292, tid=13448
[01] File "C:/Users/comba/AppData/Local/Programs/Python/Python37/lib/threading.py", line 865, in run() 
[02] File "C:/Users/comba/Desktop/知识城地牛/knowledgeCity/agvCtrl/agvList.py", line 565, in run() 
[03] File "../driver/seerAgv/agvCtrl.py", line 36, in checkLink() 
[04] File "../driver/seerAgv/agvApi.py", line 184, in checkLink() 
[05] File "C:/Users/comba/Desktop/知识城地牛/knowledgeCity/common/lock.py", line 102, in release() 
[06] File "C:/Users/comba/Desktop/知识城地牛/knowledgeCity/common/enhance.py", line 268, in getTrace() 
[07] File "C:/Users/comba/Desktop/知识城地牛/knowledgeCity/common/enhance.py", line 248, in getThreadStack()
[DEBUG]2021-05-08 16:05:04,089: try connect AGV01 172.16.217.209:19204
[DEBUG]2021-05-08 16:05:04,231: try connect AGV03 172.16.217.121:19204
[DEBUG]2021-05-08 16:05:04,276: try connect AGV02 172.16.217.213:19204
[CRITICAL]2021-05-08 16:05:06,826: upStation01 init failed cause a error: ('http get', 'http://127.0.0.1:8999/api/remoteio/readDOList', {'id': 'upStation01'}, 'error:', 'timed out')
pid=10292, ppid=13624, tid=13572
Traceback (most recent call last):
  File "C:\Users\comba\Desktop\知识城地牛\knowledgeCity\common\webutility.py", line 103, in http_get
    f = urllib.request.urlopen(u,timeout=timeout)
  File "C:\Users\comba\AppData\Local\Programs\Python\Python37\lib\urllib\request.py", line 222, in urlopen
    return opener.open(url, data, timeout)
  File "C:\Users\comba\AppData\Local\Programs\Python\Python37\lib\urllib\request.py", line 525, in open
    response = self._open(req, data)
  File "C:\Users\comba\AppData\Local\Programs\Python\Python37\lib\urllib\request.py", line 543, in _open
    '_open', req)
  File "C:\Users\comba\AppData\Local\Programs\Python\Python37\lib\urllib\request.py", line 503, in _call_chain
    result = func(*args)
  File "C:\Users\comba\AppData\Local\Programs\Python\Python37\lib\urllib\request.py", line 1345, in http_open
    return self.do_open(http.client.HTTPConnection, req)
  File "C:\Users\comba\AppData\Local\Programs\Python\Python37\lib\urllib\request.py", line 1320, in do_open
    r = h.getresponse()
  File "C:\Users\comba\AppData\Local\Programs\Python\Python37\lib\http\client.py", line 1321, in getresponse
    response.begin()
  File "C:\Users\comba\AppData\Local\Programs\Python\Python37\lib\http\client.py", line 296, in begin
    version, status, reason = self._read_status()
  File "C:\Users\comba\AppData\Local\Programs\Python\Python37\lib\http\client.py", line 257, in _read_status
    line = str(self.fp.readline(_MAXLINE + 1), "iso-8859-1")
  File "C:\Users\comba\AppData\Local\Programs\Python\Python37\lib\socket.py", line 589, in readinto
    return self._sock.recv_into(b)
socket.timeout: timed out

During handling of the above exception, another exception occurred:

Traceback (most recent call last):
  File "C:\Users\comba\Desktop\知识城地牛\knowledgeCity\autoCtrl\deviceCtrl.py", line 175, in _checkInit
    s = ioApi.readDOList(devices[d][ioId])["status"]
  File "..\remoteio\remoteioApi.py", line 73, in readDOList
    return _remoteio('/api/remoteio/readDOList', id, param)
  File "..\remoteio\remoteioApi.py", line 100, in _remoteio
    return http_get(url + apiurl, param)
  File "..\remoteio\remoteioApi.py", line 16, in http_get
    r = webutility.http_get(url, param)
  File "C:\Users\comba\Desktop\知识城地牛\knowledgeCity\common\webutility.py", line 105, in http_get
    raise Exception("http get",url,params,"error:",str(e))
Exception: ('http get', 'http://127.0.0.1:8999/api/remoteio/readDOList', {'id': 'upStation01'}, 'error:', 'timed out')

[DEBUG]2021-05-08 16:05:07,896: send http_get: http://127.0.0.1:8999/api/remoteio/readDOList?id=downStation01
[DEBUG]2021-05-08 16:05:11,832: GET: http://127.0.0.1:8999/api/scada/addTask?source=%E4%B8%89%E6%A5%BC%E5%A4%B9%E5%85%B7%E7%82%B9A&target=%E4%B8%89%E6%A5%BC%E5%A4%B9%E5%85%B7%E7%82%B9C addr: 127.0.0.1
[INFO]2021-05-08 16:05:11,857: Scada send a task to the server from 三楼夹具点A to 三楼夹具点C payloadId: None
[INFO]2021-05-08 16:05:11,899: create task[6096463773dabd283420de74]: type= scadaTask , 从三楼夹具点A运送货架到三楼夹具点C {'source': '三楼夹具点A', 'target': '三楼夹具点C', 'payloadId': None, 'priority': 1, 'type': 'scadaTask', 'taskName': '从三楼夹具点A运送货架到三楼夹具点C', 'createTime': datetime.datetime(2021, 5, 8, 16, 5, 11, 893833), 'updateTime': datetime.datetime(2021, 5, 8, 16, 5, 11, 893833), 'startTime': None, 'endTime': None, 'status': 'waiting', 'step': 'waiting', 'msg': None, 'history': [], '_id': ObjectId('6096463773dabd283420de74')}
[INFO]2021-05-08 16:05:11,928: 三楼夹具点C 三楼夹具点A
[INFO]2021-05-08 16:05:12,010: task[6096463773dabd283420de74][-] AP22(LM17) -> AP25(LM24) [waiting] is inside False
[INFO]2021-05-08 16:05:12,045: task cmd: got a task from scada task[6096463773dabd283420de74][-] AP22(LM17) -> AP25(LM24) [waiting]
[DEBUG]2021-05-08 16:05:12,080: used 248ms 200 OK application/json;charset=utf-8, GET: http://127.0.0.1:8999/api/scada/addTask?source=%E4%B8%89%E6%A5%BC%E5%A4%B9%E5%85%B7%E7%82%B9A&target=%E4%B8%89%E6%A5%BC%E5%A4%B9%E5%85%B7%E7%82%B9C
[CRITICAL]2021-05-08 16:05:12,816: [modbusApi: 172.16.167.221] execute fcode=1, addr=8256 exception:  cause a error: [WinError 10060] 由于连接方在一段时间后没有正确答复或连接的主机没有反应，连接尝试失败。
pid=10292, ppid=13624, tid=13976
Traceback (most recent call last):
  File "C:\Users\comba\Desktop\知识城地牛\knowledgeCity\common\modbusapi.py", line 35, in __execute
    data = self.master.execute(self.__salveId, fcode, start, quantity_of_x=num, output_value=value)
  File "C:\Users\comba\AppData\Local\Programs\Python\Python37\lib\site-packages\modbus_tk\utils.py", line 39, in new
    raise excpt
  File "C:\Users\comba\AppData\Local\Programs\Python\Python37\lib\site-packages\modbus_tk\utils.py", line 37, in new
    ret = fcn(*args, **kwargs)
  File "C:\Users\comba\AppData\Local\Programs\Python\Python37\lib\site-packages\modbus_tk\modbus.py", line 152, in execute
    self.open()
  File "C:\Users\comba\AppData\Local\Programs\Python\Python37\lib\site-packages\modbus_tk\modbus.py", line 99, in open
    self._do_open()
  File "C:\Users\comba\AppData\Local\Programs\Python\Python37\lib\site-packages\modbus_tk\modbus_tcp.py", line 173, in _do_open
    self._sock.connect((self._host, self._port))
TimeoutError: [WinError 10060] 由于连接方在一段时间后没有正确答复或连接的主机没有反应，连接尝试失败。

[WARN]2021-05-08 16:05:12,909: worker 2[tid:13976] <locked _thread.RLock object owner=13976 count=1 at 0x000001B95A08E670> ,hold 21368 ms
[INFO]2021-05-08 16:05:13,473: name=worker 2, pid=10292, tid=13976
[01] File "C:/Users/comba/AppData/Local/Programs/Python/Python37/lib/threading.py", line 865, in run() 
[02] File "C:/Users/comba/AppData/Local/Programs/Python/Python37/lib/site-packages/paste/httpserver.py", line 895, in worker_thread_callback() 
[03] File "C:/Users/comba/AppData/Local/Programs/Python/Python37/lib/site-packages/paste/httpserver.py", line 1069, in <lambda>() 
[04] File "C:/Users/comba/AppData/Local/Programs/Python/Python37/lib/site-packages/paste/httpserver.py", line 1085, in process_request_in_thread() 
[05] File "C:/Users/comba/AppData/Local/Programs/Python/Python37/lib/socketserver.py", line 357, in finish_request() 
[06] File "C:/Users/comba/AppData/Local/Programs/Python/Python37/lib/socketserver.py", line 717, in __init__() 
[07] File "C:/Users/comba/AppData/Local/Programs/Python/Python37/lib/site-packages/paste/httpserver.py", line 459, in handle() 
[08] File "C:/Users/comba/AppData/Local/Programs/Python/Python37/lib/http/server.py", line 426, in handle() 
[09] File "C:/Users/comba/AppData/Local/Programs/Python/Python37/lib/site-packages/paste/httpserver.py", line 454, in handle_one_request() 
[10] File "C:/Users/comba/AppData/Local/Programs/Python/Python37/lib/site-packages/paste/httpserver.py", line 304, in wsgi_execute() 
[11] File "C:/Users/comba/AppData/Local/Programs/Python/Python37/lib/site-packages/paste/translogger.py", line 69, in __call__() 
[12] File "C:/Users/comba/AppData/Local/Programs/Python/Python37/lib/site-packages/bottle.py", line 979, in __call__() 
[13] File "C:/Users/comba/AppData/Local/Programs/Python/Python37/lib/site-packages/bottle.py", line 954, in wsgi() 
[14] File "C:/Users/comba/AppData/Local/Programs/Python/Python37/lib/site-packages/bottle.py", line 862, in _handle() 
[15] File "C:/Users/comba/AppData/Local/Programs/Python/Python37/lib/site-packages/bottle.py", line 1742, in wrapper() 
[16] File "C:/Users/comba/Desktop/知识城地牛/knowledgeCity/common/webutility.py", line 465, in _enable_cors() 
[17] File "C:/Users/comba/Desktop/知识城地牛/knowledgeCity/common/webutility.py", line 481, in _enable_cors() 
[18] File "C:/Users/comba/Desktop/知识城地牛/knowledgeCity/common/scadaUtility.py", line 45, in __call() 
[19] File "C:/Users/comba/Desktop/知识城地牛/knowledgeCity/remoteio/main_remoteio.py", line 87, in urlReadDOList() 
[20] File "../remoteio/remoteioMgr.py", line 158, in readDOList() 
[21] File "../remoteio/remoteioMgr.py", line 262, in readDOList() 
[22] File "C:/Users/comba/Desktop/知识城地牛/knowledgeCity/common/lock.py", line 124, in _call() 
[23] File "C:/Users/comba/Desktop/知识城地牛/knowledgeCity/common/lock.py", line 102, in release() 
[24] File "C:/Users/comba/Desktop/知识城地牛/knowledgeCity/common/enhance.py", line 268, in getTrace() 
[25] File "C:/Users/comba/Desktop/知识城地牛/knowledgeCity/common/enhance.py", line 248, in getThreadStack()
[CRITICAL]2021-05-08 16:05:13,565: upStation01 readDIList fail cause a error: [WinError 10060] 由于连接方在一段时间后没有正确答复或连接的主机没有反应，连接尝试失败。
pid=10292, ppid=13624, tid=13976
Traceback (most recent call last):
  File "..\remoteio\remoteioMgr.py", line 262, in readDOList
    return self._read(M30, IO_LENTH)
  File "C:\Users\comba\Desktop\知识城地牛\knowledgeCity\common\lock.py", line 122, in _call
    return func(*p,**pp)
  File "..\remoteio\remoteioMgr.py", line 314, in _read
    s = self.master.read(mdef.READ_COILS,addr, length)
  File "C:\Users\comba\Desktop\知识城地牛\knowledgeCity\common\modbusapi.py", line 45, in read
    return self.__execute(fcode, start, num)
  File "C:\Users\comba\Desktop\知识城地牛\knowledgeCity\common\modbusapi.py", line 35, in __execute
    data = self.master.execute(self.__salveId, fcode, start, quantity_of_x=num, output_value=value)
  File "C:\Users\comba\AppData\Local\Programs\Python\Python37\lib\site-packages\modbus_tk\utils.py", line 39, in new
    raise excpt
  File "C:\Users\comba\AppData\Local\Programs\Python\Python37\lib\site-packages\modbus_tk\utils.py", line 37, in new
    ret = fcn(*args, **kwargs)
  File "C:\Users\comba\AppData\Local\Programs\Python\Python37\lib\site-packages\modbus_tk\modbus.py", line 152, in execute
    self.open()
  File "C:\Users\comba\AppData\Local\Programs\Python\Python37\lib\site-packages\modbus_tk\modbus.py", line 99, in open
    self._do_open()
  File "C:\Users\comba\AppData\Local\Programs\Python\Python37\lib\site-packages\modbus_tk\modbus_tcp.py", line 173, in _do_open
    self._sock.connect((self._host, self._port))
TimeoutError: [WinError 10060] 由于连接方在一段时间后没有正确答复或连接的主机没有反应，连接尝试失败。

[CRITICAL]2021-05-08 16:05:13,669: invoke <function urlReadDOList at 0x000001B958BCFD08> cause a error: [WinError 10060] 由于连接方在一段时间后没有正确答复或连接的主机没有反应，连接尝试失败。
pid=10292, ppid=13624, tid=13976
Traceback (most recent call last):
  File "C:\Users\comba\Desktop\知识城地牛\knowledgeCity\common\scadaUtility.py", line 45, in __call
    ret = func(*p,**pp)
  File "C:\Users\comba\Desktop\知识城地牛\knowledgeCity\remoteio\main_remoteio.py", line 87, in urlReadDOList
    return ioMgr.readDOList(id)
  File "..\remoteio\remoteioMgr.py", line 158, in readDOList
    result=remoteioInfo.readDOList()
  File "..\remoteio\remoteioMgr.py", line 262, in readDOList
    return self._read(M30, IO_LENTH)
  File "C:\Users\comba\Desktop\知识城地牛\knowledgeCity\common\lock.py", line 122, in _call
    return func(*p,**pp)
  File "..\remoteio\remoteioMgr.py", line 314, in _read
    s = self.master.read(mdef.READ_COILS,addr, length)
  File "C:\Users\comba\Desktop\知识城地牛\knowledgeCity\common\modbusapi.py", line 45, in read
    return self.__execute(fcode, start, num)
  File "C:\Users\comba\Desktop\知识城地牛\knowledgeCity\common\modbusapi.py", line 35, in __execute
    data = self.master.execute(self.__salveId, fcode, start, quantity_of_x=num, output_value=value)
  File "C:\Users\comba\AppData\Local\Programs\Python\Python37\lib\site-packages\modbus_tk\utils.py", line 39, in new
    raise excpt
  File "C:\Users\comba\AppData\Local\Programs\Python\Python37\lib\site-packages\modbus_tk\utils.py", line 37, in new
    ret = fcn(*args, **kwargs)
  File "C:\Users\comba\AppData\Local\Programs\Python\Python37\lib\site-packages\modbus_tk\modbus.py", line 152, in execute
    self.open()
  File "C:\Users\comba\AppData\Local\Programs\Python\Python37\lib\site-packages\modbus_tk\modbus.py", line 99, in open
    self._do_open()
  File "C:\Users\comba\AppData\Local\Programs\Python\Python37\lib\site-packages\modbus_tk\modbus_tcp.py", line 173, in _do_open
    self._sock.connect((self._host, self._port))
TimeoutError: [WinError 10060] 由于连接方在一段时间后没有正确答复或连接的主机没有反应，连接尝试失败。

[ERROR]2021-05-08 16:05:14,156: connect AGV01 failed timed out
[INFO]2021-05-08 16:05:14,185: AGV01 checkLink failed 172.16.217.209 19204
[WARN]2021-05-08 16:05:14,208: agvThread.AGV01[tid:7308] <lock name:agv.AGV01.lock_status,<locked _thread.RLock object owner=7308 count=1 at 0x000001B95AD3D940>> ,hold 10119 ms
[INFO]2021-05-08 16:05:14,271: name=agvThread.AGV01, pid=10292, tid=7308
[01] File "C:/Users/comba/AppData/Local/Programs/Python/Python37/lib/threading.py", line 865, in run() 
[02] File "C:/Users/comba/Desktop/知识城地牛/knowledgeCity/agvCtrl/agvList.py", line 565, in run() 
[03] File "../driver/seerAgv/agvCtrl.py", line 36, in checkLink() 
[04] File "../driver/seerAgv/agvApi.py", line 184, in checkLink() 
[05] File "C:/Users/comba/Desktop/知识城地牛/knowledgeCity/common/lock.py", line 102, in release() 
[06] File "C:/Users/comba/Desktop/知识城地牛/knowledgeCity/common/enhance.py", line 268, in getTrace() 
[07] File "C:/Users/comba/Desktop/知识城地牛/knowledgeCity/common/enhance.py", line 248, in getThreadStack()
[ERROR]2021-05-08 16:05:14,277: connect AGV03 failed timed out
[ERROR]2021-05-08 16:05:14,339: connect AGV02 failed timed out
[INFO]2021-05-08 16:05:14,345: AGV03 checkLink failed 172.16.217.121 19204
[INFO]2021-05-08 16:05:14,389: AGV02 checkLink failed 172.16.217.213 19204
[WARN]2021-05-08 16:05:14,394: agvThread.AGV03[tid:1072] <lock name:agv.AGV03.lock_status,<locked _thread.RLock object owner=1072 count=1 at 0x000001B95AD3DC10>> ,hold 10163 ms
[WARN]2021-05-08 16:05:14,420: agvThread.AGV02[tid:13448] <lock name:agv.AGV02.lock_status,<locked _thread.RLock object owner=13448 count=1 at 0x000001B95AD3D418>> ,hold 10144 ms
[INFO]2021-05-08 16:05:14,513: name=agvThread.AGV03, pid=10292, tid=1072
[01] File "C:/Users/comba/AppData/Local/Programs/Python/Python37/lib/threading.py", line 865, in run() 
[02] File "C:/Users/comba/Desktop/知识城地牛/knowledgeCity/agvCtrl/agvList.py", line 565, in run() 
[03] File "../driver/seerAgv/agvCtrl.py", line 36, in checkLink() 
[04] File "../driver/seerAgv/agvApi.py", line 184, in checkLink() 
[05] File "C:/Users/comba/Desktop/知识城地牛/knowledgeCity/common/lock.py", line 102, in release() 
[06] File "C:/Users/comba/Desktop/知识城地牛/knowledgeCity/common/enhance.py", line 268, in getTrace() 
[07] File "C:/Users/comba/Desktop/知识城地牛/knowledgeCity/common/enhance.py", line 248, in getThreadStack()
[INFO]2021-05-08 16:05:14,569: name=agvThread.AGV02, pid=10292, tid=13448
[01] File "C:/Users/comba/AppData/Local/Programs/Python/Python37/lib/threading.py", line 865, in run() 
[02] File "C:/Users/comba/Desktop/知识城地牛/knowledgeCity/agvCtrl/agvList.py", line 565, in run() 
[03] File "../driver/seerAgv/agvCtrl.py", line 36, in checkLink() 
[04] File "../driver/seerAgv/agvApi.py", line 184, in checkLink() 
[05] File "C:/Users/comba/Desktop/知识城地牛/knowledgeCity/common/lock.py", line 102, in release() 
[06] File "C:/Users/comba/Desktop/知识城地牛/knowledgeCity/common/enhance.py", line 268, in getTrace() 
[07] File "C:/Users/comba/Desktop/知识城地牛/knowledgeCity/common/enhance.py", line 248, in getThreadStack()
[DEBUG]2021-05-08 16:05:16,302: try connect AGV01 172.16.217.209:19204
[DEBUG]2021-05-08 16:05:16,566: try connect AGV03 172.16.217.121:19204
[DEBUG]2021-05-08 16:05:16,618: try connect AGV02 172.16.217.213:19204
[CRITICAL]2021-05-08 16:05:23,043: downStation01 init failed cause a error: ('http get', 'http://127.0.0.1:8999/api/remoteio/readDOList', {'id': 'downStation01'}, 'error:', 'timed out')
pid=10292, ppid=13624, tid=13572
Traceback (most recent call last):
  File "C:\Users\comba\Desktop\知识城地牛\knowledgeCity\common\webutility.py", line 103, in http_get
    f = urllib.request.urlopen(u,timeout=timeout)
  File "C:\Users\comba\AppData\Local\Programs\Python\Python37\lib\urllib\request.py", line 222, in urlopen
    return opener.open(url, data, timeout)
  File "C:\Users\comba\AppData\Local\Programs\Python\Python37\lib\urllib\request.py", line 525, in open
    response = self._open(req, data)
  File "C:\Users\comba\AppData\Local\Programs\Python\Python37\lib\urllib\request.py", line 543, in _open
    '_open', req)
  File "C:\Users\comba\AppData\Local\Programs\Python\Python37\lib\urllib\request.py", line 503, in _call_chain
    result = func(*args)
  File "C:\Users\comba\AppData\Local\Programs\Python\Python37\lib\urllib\request.py", line 1345, in http_open
    return self.do_open(http.client.HTTPConnection, req)
  File "C:\Users\comba\AppData\Local\Programs\Python\Python37\lib\urllib\request.py", line 1320, in do_open
    r = h.getresponse()
  File "C:\Users\comba\AppData\Local\Programs\Python\Python37\lib\http\client.py", line 1321, in getresponse
    response.begin()
  File "C:\Users\comba\AppData\Local\Programs\Python\Python37\lib\http\client.py", line 296, in begin
    version, status, reason = self._read_status()
  File "C:\Users\comba\AppData\Local\Programs\Python\Python37\lib\http\client.py", line 257, in _read_status
    line = str(self.fp.readline(_MAXLINE + 1), "iso-8859-1")
  File "C:\Users\comba\AppData\Local\Programs\Python\Python37\lib\socket.py", line 589, in readinto
    return self._sock.recv_into(b)
socket.timeout: timed out

During handling of the above exception, another exception occurred:

Traceback (most recent call last):
  File "C:\Users\comba\Desktop\知识城地牛\knowledgeCity\autoCtrl\deviceCtrl.py", line 175, in _checkInit
    s = ioApi.readDOList(devices[d][ioId])["status"]
  File "..\remoteio\remoteioApi.py", line 73, in readDOList
    return _remoteio('/api/remoteio/readDOList', id, param)
  File "..\remoteio\remoteioApi.py", line 100, in _remoteio
    return http_get(url + apiurl, param)
  File "..\remoteio\remoteioApi.py", line 16, in http_get
    r = webutility.http_get(url, param)
  File "C:\Users\comba\Desktop\知识城地牛\knowledgeCity\common\webutility.py", line 105, in http_get
    raise Exception("http get",url,params,"error:",str(e))
Exception: ('http get', 'http://127.0.0.1:8999/api/remoteio/readDOList', {'id': 'downStation01'}, 'error:', 'timed out')

[INFO]2021-05-08 16:05:24,087: init IO success
[DEBUG]2021-05-08 16:05:24,111: send http_get: http://127.0.0.1:8999/api/remoteio/readDOList?id=upStation01
[ERROR]2021-05-08 16:05:26,368: connect AGV01 failed timed out
[INFO]2021-05-08 16:05:26,385: AGV01 checkLink failed 172.16.217.209 19204
[WARN]2021-05-08 16:05:26,411: agvThread.AGV01[tid:7308] <lock name:agv.AGV01.lock_status,<locked _thread.RLock object owner=7308 count=1 at 0x000001B95AD3D940>> ,hold 10109 ms
[INFO]2021-05-08 16:05:26,488: name=agvThread.AGV01, pid=10292, tid=7308
[01] File "C:/Users/comba/AppData/Local/Programs/Python/Python37/lib/threading.py", line 865, in run() 
[02] File "C:/Users/comba/Desktop/知识城地牛/knowledgeCity/agvCtrl/agvList.py", line 565, in run() 
[03] File "../driver/seerAgv/agvCtrl.py", line 36, in checkLink() 
[04] File "../driver/seerAgv/agvApi.py", line 184, in checkLink() 
[05] File "C:/Users/comba/Desktop/知识城地牛/knowledgeCity/common/lock.py", line 102, in release() 
[06] File "C:/Users/comba/Desktop/知识城地牛/knowledgeCity/common/enhance.py", line 268, in getTrace() 
[07] File "C:/Users/comba/Desktop/知识城地牛/knowledgeCity/common/enhance.py", line 248, in getThreadStack()
[ERROR]2021-05-08 16:05:26,665: connect AGV03 failed timed out
[ERROR]2021-05-08 16:05:26,671: connect AGV02 failed timed out
[INFO]2021-05-08 16:05:26,735: AGV03 checkLink failed 172.16.217.121 19204
[INFO]2021-05-08 16:05:26,781: AGV02 checkLink failed 172.16.217.213 19204
[WARN]2021-05-08 16:05:26,804: agvThread.AGV03[tid:1072] <lock name:agv.AGV03.lock_status,<locked _thread.RLock object owner=1072 count=1 at 0x000001B95AD3DC10>> ,hold 10238 ms
[WARN]2021-05-08 16:05:26,857: agvThread.AGV02[tid:13448] <lock name:agv.AGV02.lock_status,<locked _thread.RLock object owner=13448 count=1 at 0x000001B95AD3D418>> ,hold 10239 ms
[INFO]2021-05-08 16:05:26,957: name=agvThread.AGV03, pid=10292, tid=1072
[01] File "C:/Users/comba/AppData/Local/Programs/Python/Python37/lib/threading.py", line 865, in run() 
[02] File "C:/Users/comba/Desktop/知识城地牛/knowledgeCity/agvCtrl/agvList.py", line 565, in run() 
[03] File "../driver/seerAgv/agvCtrl.py", line 36, in checkLink() 
[04] File "../driver/seerAgv/agvApi.py", line 184, in checkLink() 
[05] File "C:/Users/comba/Desktop/知识城地牛/knowledgeCity/common/lock.py", line 102, in release() 
[06] File "C:/Users/comba/Desktop/知识城地牛/knowledgeCity/common/enhance.py", line 268, in getTrace() 
[07] File "C:/Users/comba/Desktop/知识城地牛/knowledgeCity/common/enhance.py", line 248, in getThreadStack()
[INFO]2021-05-08 16:05:27,017: name=agvThread.AGV02, pid=10292, tid=13448
[01] File "C:/Users/comba/AppData/Local/Programs/Python/Python37/lib/threading.py", line 865, in run() 
[02] File "C:/Users/comba/Desktop/知识城地牛/knowledgeCity/agvCtrl/agvList.py", line 565, in run() 
[03] File "../driver/seerAgv/agvCtrl.py", line 36, in checkLink() 
[04] File "../driver/seerAgv/agvApi.py", line 184, in checkLink() 
[05] File "C:/Users/comba/Desktop/知识城地牛/knowledgeCity/common/lock.py", line 102, in release() 
[06] File "C:/Users/comba/Desktop/知识城地牛/knowledgeCity/common/enhance.py", line 268, in getTrace() 
[07] File "C:/Users/comba/Desktop/知识城地牛/knowledgeCity/common/enhance.py", line 248, in getThreadStack()
[DEBUG]2021-05-08 16:05:28,558: try connect AGV01 172.16.217.209:19204
[DEBUG]2021-05-08 16:05:29,029: try connect AGV03 172.16.217.121:19204
[DEBUG]2021-05-08 16:05:29,076: try connect AGV02 172.16.217.213:19204
[CRITICAL]2021-05-08 16:05:33,721: [modbusApi: 172.16.167.220] execute fcode=1, addr=8256 exception:  cause a error: [WinError 10060] 由于连接方在一段时间后没有正确答复或连接的主机没有反应，连接尝试失败。
pid=10292, ppid=13624, tid=8296
Traceback (most recent call last):
  File "C:\Users\comba\Desktop\知识城地牛\knowledgeCity\common\modbusapi.py", line 35, in __execute
    data = self.master.execute(self.__salveId, fcode, start, quantity_of_x=num, output_value=value)
  File "C:\Users\comba\AppData\Local\Programs\Python\Python37\lib\site-packages\modbus_tk\utils.py", line 39, in new
    raise excpt
  File "C:\Users\comba\AppData\Local\Programs\Python\Python37\lib\site-packages\modbus_tk\utils.py", line 37, in new
    ret = fcn(*args, **kwargs)
  File "C:\Users\comba\AppData\Local\Programs\Python\Python37\lib\site-packages\modbus_tk\modbus.py", line 152, in execute
    self.open()
  File "C:\Users\comba\AppData\Local\Programs\Python\Python37\lib\site-packages\modbus_tk\modbus.py", line 99, in open
    self._do_open()
  File "C:\Users\comba\AppData\Local\Programs\Python\Python37\lib\site-packages\modbus_tk\modbus_tcp.py", line 173, in _do_open
    self._sock.connect((self._host, self._port))
TimeoutError: [WinError 10060] 由于连接方在一段时间后没有正确答复或连接的主机没有反应，连接尝试失败。

[WARN]2021-05-08 16:05:33,781: worker 3[tid:8296] <locked _thread.RLock object owner=8296 count=1 at 0x000001B95A08E7B0> ,hold 25827 ms
[INFO]2021-05-08 16:05:33,889: name=worker 3, pid=10292, tid=8296
[01] File "C:/Users/comba/AppData/Local/Programs/Python/Python37/lib/threading.py", line 865, in run() 
[02] File "C:/Users/comba/AppData/Local/Programs/Python/Python37/lib/site-packages/paste/httpserver.py", line 895, in worker_thread_callback() 
[03] File "C:/Users/comba/AppData/Local/Programs/Python/Python37/lib/site-packages/paste/httpserver.py", line 1069, in <lambda>() 
[04] File "C:/Users/comba/AppData/Local/Programs/Python/Python37/lib/site-packages/paste/httpserver.py", line 1085, in process_request_in_thread() 
[05] File "C:/Users/comba/AppData/Local/Programs/Python/Python37/lib/socketserver.py", line 357, in finish_request() 
[06] File "C:/Users/comba/AppData/Local/Programs/Python/Python37/lib/socketserver.py", line 717, in __init__() 
[07] File "C:/Users/comba/AppData/Local/Programs/Python/Python37/lib/site-packages/paste/httpserver.py", line 459, in handle() 
[08] File "C:/Users/comba/AppData/Local/Programs/Python/Python37/lib/http/server.py", line 426, in handle() 
[09] File "C:/Users/comba/AppData/Local/Programs/Python/Python37/lib/site-packages/paste/httpserver.py", line 454, in handle_one_request() 
[10] File "C:/Users/comba/AppData/Local/Programs/Python/Python37/lib/site-packages/paste/httpserver.py", line 304, in wsgi_execute() 
[11] File "C:/Users/comba/AppData/Local/Programs/Python/Python37/lib/site-packages/paste/translogger.py", line 69, in __call__() 
[12] File "C:/Users/comba/AppData/Local/Programs/Python/Python37/lib/site-packages/bottle.py", line 979, in __call__() 
[13] File "C:/Users/comba/AppData/Local/Programs/Python/Python37/lib/site-packages/bottle.py", line 954, in wsgi() 
[14] File "C:/Users/comba/AppData/Local/Programs/Python/Python37/lib/site-packages/bottle.py", line 862, in _handle() 
[15] File "C:/Users/comba/AppData/Local/Programs/Python/Python37/lib/site-packages/bottle.py", line 1742, in wrapper() 
[16] File "C:/Users/comba/Desktop/知识城地牛/knowledgeCity/common/webutility.py", line 465, in _enable_cors() 
[17] File "C:/Users/comba/Desktop/知识城地牛/knowledgeCity/common/webutility.py", line 481, in _enable_cors() 
[18] File "C:/Users/comba/Desktop/知识城地牛/knowledgeCity/common/scadaUtility.py", line 45, in __call() 
[19] File "C:/Users/comba/Desktop/知识城地牛/knowledgeCity/remoteio/main_remoteio.py", line 87, in urlReadDOList() 
[20] File "../remoteio/remoteioMgr.py", line 158, in readDOList() 
[21] File "../remoteio/remoteioMgr.py", line 262, in readDOList() 
[22] File "C:/Users/comba/Desktop/知识城地牛/knowledgeCity/common/lock.py", line 124, in _call() 
[23] File "C:/Users/comba/Desktop/知识城地牛/knowledgeCity/common/lock.py", line 102, in release() 
[24] File "C:/Users/comba/Desktop/知识城地牛/knowledgeCity/common/enhance.py", line 268, in getTrace() 
[25] File "C:/Users/comba/Desktop/知识城地牛/knowledgeCity/common/enhance.py", line 248, in getThreadStack()
[CRITICAL]2021-05-08 16:05:33,981: downStation01 readDIList fail cause a error: [WinError 10060] 由于连接方在一段时间后没有正确答复或连接的主机没有反应，连接尝试失败。
pid=10292, ppid=13624, tid=8296
Traceback (most recent call last):
  File "..\remoteio\remoteioMgr.py", line 262, in readDOList
    return self._read(M30, IO_LENTH)
  File "C:\Users\comba\Desktop\知识城地牛\knowledgeCity\common\lock.py", line 122, in _call
    return func(*p,**pp)
  File "..\remoteio\remoteioMgr.py", line 314, in _read
    s = self.master.read(mdef.READ_COILS,addr, length)
  File "C:\Users\comba\Desktop\知识城地牛\knowledgeCity\common\modbusapi.py", line 45, in read
    return self.__execute(fcode, start, num)
  File "C:\Users\comba\Desktop\知识城地牛\knowledgeCity\common\modbusapi.py", line 35, in __execute
    data = self.master.execute(self.__salveId, fcode, start, quantity_of_x=num, output_value=value)
  File "C:\Users\comba\AppData\Local\Programs\Python\Python37\lib\site-packages\modbus_tk\utils.py", line 39, in new
    raise excpt
  File "C:\Users\comba\AppData\Local\Programs\Python\Python37\lib\site-packages\modbus_tk\utils.py", line 37, in new
    ret = fcn(*args, **kwargs)
  File "C:\Users\comba\AppData\Local\Programs\Python\Python37\lib\site-packages\modbus_tk\modbus.py", line 152, in execute
    self.open()
  File "C:\Users\comba\AppData\Local\Programs\Python\Python37\lib\site-packages\modbus_tk\modbus.py", line 99, in open
    self._do_open()
  File "C:\Users\comba\AppData\Local\Programs\Python\Python37\lib\site-packages\modbus_tk\modbus_tcp.py", line 173, in _do_open
    self._sock.connect((self._host, self._port))
TimeoutError: [WinError 10060] 由于连接方在一段时间后没有正确答复或连接的主机没有反应，连接尝试失败。

[CRITICAL]2021-05-08 16:05:34,087: invoke <function urlReadDOList at 0x000001B958BCFD08> cause a error: [WinError 10060] 由于连接方在一段时间后没有正确答复或连接的主机没有反应，连接尝试失败。
pid=10292, ppid=13624, tid=8296
Traceback (most recent call last):
  File "C:\Users\comba\Desktop\知识城地牛\knowledgeCity\common\scadaUtility.py", line 45, in __call
    ret = func(*p,**pp)
  File "C:\Users\comba\Desktop\知识城地牛\knowledgeCity\remoteio\main_remoteio.py", line 87, in urlReadDOList
    return ioMgr.readDOList(id)
  File "..\remoteio\remoteioMgr.py", line 158, in readDOList
    result=remoteioInfo.readDOList()
  File "..\remoteio\remoteioMgr.py", line 262, in readDOList
    return self._read(M30, IO_LENTH)
  File "C:\Users\comba\Desktop\知识城地牛\knowledgeCity\common\lock.py", line 122, in _call
    return func(*p,**pp)
  File "..\remoteio\remoteioMgr.py", line 314, in _read
    s = self.master.read(mdef.READ_COILS,addr, length)
  File "C:\Users\comba\Desktop\知识城地牛\knowledgeCity\common\modbusapi.py", line 45, in read
    return self.__execute(fcode, start, num)
  File "C:\Users\comba\Desktop\知识城地牛\knowledgeCity\common\modbusapi.py", line 35, in __execute
    data = self.master.execute(self.__salveId, fcode, start, quantity_of_x=num, output_value=value)
  File "C:\Users\comba\AppData\Local\Programs\Python\Python37\lib\site-packages\modbus_tk\utils.py", line 39, in new
    raise excpt
  File "C:\Users\comba\AppData\Local\Programs\Python\Python37\lib\site-packages\modbus_tk\utils.py", line 37, in new
    ret = fcn(*args, **kwargs)
  File "C:\Users\comba\AppData\Local\Programs\Python\Python37\lib\site-packages\modbus_tk\modbus.py", line 152, in execute
    self.open()
  File "C:\Users\comba\AppData\Local\Programs\Python\Python37\lib\site-packages\modbus_tk\modbus.py", line 99, in open
    self._do_open()
  File "C:\Users\comba\AppData\Local\Programs\Python\Python37\lib\site-packages\modbus_tk\modbus_tcp.py", line 173, in _do_open
    self._sock.connect((self._host, self._port))
TimeoutError: [WinError 10060] 由于连接方在一段时间后没有正确答复或连接的主机没有反应，连接尝试失败。

[ERROR]2021-05-08 16:05:38,609: connect AGV01 failed timed out
[INFO]2021-05-08 16:05:38,667: AGV01 checkLink failed 172.16.217.209 19204
[WARN]2021-05-08 16:05:38,690: agvThread.AGV01[tid:7308] <lock name:agv.AGV01.lock_status,<locked _thread.RLock object owner=7308 count=1 at 0x000001B95AD3D940>> ,hold 10132 ms
[INFO]2021-05-08 16:05:38,743: name=agvThread.AGV01, pid=10292, tid=7308
[01] File "C:/Users/comba/AppData/Local/Programs/Python/Python37/lib/threading.py", line 865, in run() 
[02] File "C:/Users/comba/Desktop/知识城地牛/knowledgeCity/agvCtrl/agvList.py", line 565, in run() 
[03] File "../driver/seerAgv/agvCtrl.py", line 36, in checkLink() 
[04] File "../driver/seerAgv/agvApi.py", line 184, in checkLink() 
[05] File "C:/Users/comba/Desktop/知识城地牛/knowledgeCity/common/lock.py", line 102, in release() 
[06] File "C:/Users/comba/Desktop/知识城地牛/knowledgeCity/common/enhance.py", line 268, in getTrace() 
[07] File "C:/Users/comba/Desktop/知识城地牛/knowledgeCity/common/enhance.py", line 248, in getThreadStack()
[ERROR]2021-05-08 16:05:39,091: connect AGV03 failed timed out
[INFO]2021-05-08 16:05:39,127: AGV03 checkLink failed 172.16.217.121 19204
[ERROR]2021-05-08 16:05:39,143: connect AGV02 failed timed out
[WARN]2021-05-08 16:05:39,161: agvThread.AGV03[tid:1072] <lock name:agv.AGV03.lock_status,<locked _thread.RLock object owner=1072 count=1 at 0x000001B95AD3DC10>> ,hold 10132 ms
[INFO]2021-05-08 16:05:39,197: AGV02 checkLink failed 172.16.217.213 19204
[WARN]2021-05-08 16:05:39,298: agvThread.AGV02[tid:13448] <lock name:agv.AGV02.lock_status,<locked _thread.RLock object owner=13448 count=1 at 0x000001B95AD3D418>> ,hold 10222 ms
[INFO]2021-05-08 16:05:39,310: name=agvThread.AGV03, pid=10292, tid=1072
[01] File "C:/Users/comba/AppData/Local/Programs/Python/Python37/lib/threading.py", line 865, in run() 
[02] File "C:/Users/comba/Desktop/知识城地牛/knowledgeCity/agvCtrl/agvList.py", line 565, in run() 
[03] File "../driver/seerAgv/agvCtrl.py", line 36, in checkLink() 
[04] File "../driver/seerAgv/agvApi.py", line 184, in checkLink() 
[05] File "C:/Users/comba/Desktop/知识城地牛/knowledgeCity/common/lock.py", line 102, in release() 
[06] File "C:/Users/comba/Desktop/知识城地牛/knowledgeCity/common/enhance.py", line 268, in getTrace() 
[07] File "C:/Users/comba/Desktop/知识城地牛/knowledgeCity/common/enhance.py", line 248, in getThreadStack()
[CRITICAL]2021-05-08 16:05:39,345: readDIList error cause a error: ('http get', 'http://127.0.0.1:8999/api/remoteio/readDOList', {'id': 'upStation01'}, 'error:', 'timed out')
pid=10292, ppid=13624, tid=13572
Traceback (most recent call last):
  File "C:\Users\comba\Desktop\知识城地牛\knowledgeCity\common\webutility.py", line 103, in http_get
    f = urllib.request.urlopen(u,timeout=timeout)
  File "C:\Users\comba\AppData\Local\Programs\Python\Python37\lib\urllib\request.py", line 222, in urlopen
    return opener.open(url, data, timeout)
  File "C:\Users\comba\AppData\Local\Programs\Python\Python37\lib\urllib\request.py", line 525, in open
    response = self._open(req, data)
  File "C:\Users\comba\AppData\Local\Programs\Python\Python37\lib\urllib\request.py", line 543, in _open
    '_open', req)
  File "C:\Users\comba\AppData\Local\Programs\Python\Python37\lib\urllib\request.py", line 503, in _call_chain
    result = func(*args)
  File "C:\Users\comba\AppData\Local\Programs\Python\Python37\lib\urllib\request.py", line 1345, in http_open
    return self.do_open(http.client.HTTPConnection, req)
  File "C:\Users\comba\AppData\Local\Programs\Python\Python37\lib\urllib\request.py", line 1320, in do_open
    r = h.getresponse()
  File "C:\Users\comba\AppData\Local\Programs\Python\Python37\lib\http\client.py", line 1321, in getresponse
    response.begin()
  File "C:\Users\comba\AppData\Local\Programs\Python\Python37\lib\http\client.py", line 296, in begin
    version, status, reason = self._read_status()
  File "C:\Users\comba\AppData\Local\Programs\Python\Python37\lib\http\client.py", line 257, in _read_status
    line = str(self.fp.readline(_MAXLINE + 1), "iso-8859-1")
  File "C:\Users\comba\AppData\Local\Programs\Python\Python37\lib\socket.py", line 589, in readinto
    return self._sock.recv_into(b)
socket.timeout: timed out

During handling of the above exception, another exception occurred:

Traceback (most recent call last):
  File "C:\Users\comba\Desktop\知识城地牛\knowledgeCity\autoCtrl\deviceCtrl.py", line 71, in _monitorDevices
    s1 = ioApi.readDOList(devices[d]["io1"])["status"] #上板机
  File "..\remoteio\remoteioApi.py", line 73, in readDOList
    return _remoteio('/api/remoteio/readDOList', id, param)
  File "..\remoteio\remoteioApi.py", line 100, in _remoteio
    return http_get(url + apiurl, param)
  File "..\remoteio\remoteioApi.py", line 16, in http_get
    r = webutility.http_get(url, param)
  File "C:\Users\comba\Desktop\知识城地牛\knowledgeCity\common\webutility.py", line 105, in http_get
    raise Exception("http get",url,params,"error:",str(e))
Exception: ('http get', 'http://127.0.0.1:8999/api/remoteio/readDOList', {'id': 'upStation01'}, 'error:', 'timed out')

[INFO]2021-05-08 16:05:39,414: name=agvThread.AGV02, pid=10292, tid=13448
[01] File "C:/Users/comba/AppData/Local/Programs/Python/Python37/lib/threading.py", line 865, in run() 
[02] File "C:/Users/comba/Desktop/知识城地牛/knowledgeCity/agvCtrl/agvList.py", line 565, in run() 
[03] File "../driver/seerAgv/agvCtrl.py", line 36, in checkLink() 
[04] File "../driver/seerAgv/agvApi.py", line 184, in checkLink() 
[05] File "C:/Users/comba/Desktop/知识城地牛/knowledgeCity/common/lock.py", line 102, in release() 
[06] File "C:/Users/comba/Desktop/知识城地牛/knowledgeCity/common/enhance.py", line 268, in getTrace() 
[07] File "C:/Users/comba/Desktop/知识城地牛/knowledgeCity/common/enhance.py", line 248, in getThreadStack()
[DEBUG]2021-05-08 16:05:40,783: try connect AGV01 172.16.217.209:19204
[DEBUG]2021-05-08 16:05:41,385: try connect AGV03 172.16.217.121:19204
[DEBUG]2021-05-08 16:05:41,482: try connect AGV02 172.16.217.213:19204
[WARN]2021-05-08 16:05:41,712: AGV04 low battery charge,batteryLevel= 0.288 start charge level= 0.400
[INFO]2021-05-08 16:05:41,759: AGV04 battery 0.288 check success
[WARN]2021-05-08 16:05:41,930: AGV04 Can't find charge point at comba-ZXC-F3 battery: 0.288
[INFO]2021-05-08 16:05:41,977: task[6096463773dabd283420de74]:  start {'failMsg': '任务等待执行', 'startTime': datetime.datetime(2021, 5, 8, 16, 5, 41, 960217), 'updateTime': datetime.datetime(2021, 5, 8, 16, 5, 41, 960217), 'status': 'running'}
[INFO]2021-05-08 16:05:42,018: task: start task[6096463773dabd283420de74][-] AP22(LM17) -> AP25(LM24) [waiting]
[INFO]2021-05-08 16:05:42,040: this is handle taskStep=============>waiting
[INFO]2021-05-08 16:05:42,073: task[6096463773dabd283420de74] update info: {'failMsg': '等待分配小车', 'updateTime': datetime.datetime(2021, 5, 8, 16, 5, 42, 62942)}
[DEBUG]2021-05-08 16:05:42,084: task[6096463773dabd283420de74][-] AP22(LM17) -> AP25(LM24) [waitForAgv] waiting -> waitForAgv
[DEBUG]2021-05-08 16:05:43,027: send http_get: http://127.0.0.1:8999/api/remoteio/readDOList?id=upStation01
[INFO]2021-05-08 16:05:43,359: this is handle taskStep=============>waitForAgv
[DEBUG]2021-05-08 16:05:43,441: GET: http://127.0.0.1:8999/api/agv/apply?appName=akmTask&autoLock=False&exclude&loc=AP22&mapId=comba-ZXC-F3&taskId=6096463773dabd283420de74&timeout=10 addr: 127.0.0.1
[INFO]2021-05-08 16:05:43,453: agvControl中的_apply进去
[INFO]2021-05-08 16:05:43,476: [('comba-ZXC-F3.LM20', 'AGV04')]
[INFO]2021-05-08 16:05:44,310: apply AGV04 ,taskId: 6096463773dabd283420de74 ,loc comba-ZXC-F3.AP22 ,autoLock False , used 834 ms
[INFO]2021-05-08 16:05:44,352: AGV04
[INFO]2021-05-08 16:05:44,374: 5555555555555555555555555
[INFO]2021-05-08 16:05:44,413: 6666666666666666666666666
[INFO]2021-05-08 16:05:44,465: AGV04
[DEBUG]2021-05-08 16:05:44,476: used 1035ms 200 OK application/json;charset=utf-8, GET: http://127.0.0.1:8999/api/agv/apply?appName=akmTask&autoLock=False&exclude&loc=AP22&mapId=comba-ZXC-F3&taskId=6096463773dabd283420de74&timeout=10
[INFO]2021-05-08 16:05:44,522: comba-ZXC-F3.AP22 comba-ZXC-F3.AP25
[INFO]2021-05-08 16:05:44,551: AGV04
[INFO]2021-05-08 16:05:44,574: 判断类型
[INFO]2021-05-08 16:05:44,644: 1111111111111111111111
[DEBUG]2021-05-08 16:05:44,749: GET: http://127.0.0.1:8999/api/agv/lock?agv=AGV04&appName=akmTask&taskId=6096463773dabd283420de74 addr: 127.0.0.1
[DEBUG]2021-05-08 16:05:44,801: lock:  AGV04 taskId 6096463773dabd283420de74 app akmTask
[WARN]2021-05-08 16:05:45,289: worker 6[tid:1456] <locked _thread.RLock object owner=1456 count=1 at 0x000001B95A08E670> ,hold 21021 ms
[INFO]2021-05-08 16:05:45,418: name=worker 6, pid=10292, tid=1456
[01] File "C:/Users/comba/AppData/Local/Programs/Python/Python37/lib/threading.py", line 865, in run() 
[02] File "C:/Users/comba/AppData/Local/Programs/Python/Python37/lib/site-packages/paste/httpserver.py", line 895, in worker_thread_callback() 
[03] File "C:/Users/comba/AppData/Local/Programs/Python/Python37/lib/site-packages/paste/httpserver.py", line 1069, in <lambda>() 
[04] File "C:/Users/comba/AppData/Local/Programs/Python/Python37/lib/site-packages/paste/httpserver.py", line 1085, in process_request_in_thread() 
[05] File "C:/Users/comba/AppData/Local/Programs/Python/Python37/lib/socketserver.py", line 357, in finish_request() 
[06] File "C:/Users/comba/AppData/Local/Programs/Python/Python37/lib/socketserver.py", line 717, in __init__() 
[07] File "C:/Users/comba/AppData/Local/Programs/Python/Python37/lib/site-packages/paste/httpserver.py", line 459, in handle() 
[08] File "C:/Users/comba/AppData/Local/Programs/Python/Python37/lib/http/server.py", line 426, in handle() 
[09] File "C:/Users/comba/AppData/Local/Programs/Python/Python37/lib/site-packages/paste/httpserver.py", line 454, in handle_one_request() 
[10] File "C:/Users/comba/AppData/Local/Programs/Python/Python37/lib/site-packages/paste/httpserver.py", line 304, in wsgi_execute() 
[11] File "C:/Users/comba/AppData/Local/Programs/Python/Python37/lib/site-packages/paste/translogger.py", line 69, in __call__() 
[12] File "C:/Users/comba/AppData/Local/Programs/Python/Python37/lib/site-packages/bottle.py", line 979, in __call__() 
[13] File "C:/Users/comba/AppData/Local/Programs/Python/Python37/lib/site-packages/bottle.py", line 954, in wsgi() 
[14] File "C:/Users/comba/AppData/Local/Programs/Python/Python37/lib/site-packages/bottle.py", line 862, in _handle() 
[15] File "C:/Users/comba/AppData/Local/Programs/Python/Python37/lib/site-packages/bottle.py", line 1742, in wrapper() 
[16] File "C:/Users/comba/Desktop/知识城地牛/knowledgeCity/common/webutility.py", line 465, in _enable_cors() 
[17] File "C:/Users/comba/Desktop/知识城地牛/knowledgeCity/common/webutility.py", line 481, in _enable_cors() 
[18] File "C:/Users/comba/Desktop/知识城地牛/knowledgeCity/common/scadaUtility.py", line 45, in __call() 
[19] File "C:/Users/comba/Desktop/知识城地牛/knowledgeCity/remoteio/main_remoteio.py", line 87, in urlReadDOList() 
[20] File "../remoteio/remoteioMgr.py", line 158, in readDOList() 
[21] File "../remoteio/remoteioMgr.py", line 262, in readDOList() 
[22] File "C:/Users/comba/Desktop/知识城地牛/knowledgeCity/common/lock.py", line 124, in _call() 
[23] File "C:/Users/comba/Desktop/知识城地牛/knowledgeCity/common/lock.py", line 102, in release() 
[24] File "C:/Users/comba/Desktop/知识城地牛/knowledgeCity/common/enhance.py", line 268, in getTrace() 
[25] File "C:/Users/comba/Desktop/知识城地牛/knowledgeCity/common/enhance.py", line 248, in getThreadStack()
[CRITICAL]2021-05-08 16:05:45,488: upStation01 readDIList fail cause a error: [WinError 10060] 由于连接方在一段时间后没有正确答复或连接的主机没有反应，连接尝试失败。
pid=10292, ppid=13624, tid=1456
Traceback (most recent call last):
  File "..\remoteio\remoteioMgr.py", line 262, in readDOList
    return self._read(M30, IO_LENTH)
  File "C:\Users\comba\Desktop\知识城地牛\knowledgeCity\common\lock.py", line 122, in _call
    return func(*p,**pp)
  File "..\remoteio\remoteioMgr.py", line 311, in _read
    self.master.open()
  File "C:\Users\comba\Desktop\知识城地牛\knowledgeCity\common\modbusapi.py", line 60, in open
    self.master.open()
  File "C:\Users\comba\AppData\Local\Programs\Python\Python37\lib\site-packages\modbus_tk\modbus.py", line 99, in open
    self._do_open()
  File "C:\Users\comba\AppData\Local\Programs\Python\Python37\lib\site-packages\modbus_tk\modbus_tcp.py", line 173, in _do_open
    self._sock.connect((self._host, self._port))
TimeoutError: [WinError 10060] 由于连接方在一段时间后没有正确答复或连接的主机没有反应，连接尝试失败。

[CRITICAL]2021-05-08 16:05:45,613: invoke <function urlReadDOList at 0x000001B958BCFD08> cause a error: [WinError 10060] 由于连接方在一段时间后没有正确答复或连接的主机没有反应，连接尝试失败。
pid=10292, ppid=13624, tid=1456
Traceback (most recent call last):
  File "C:\Users\comba\Desktop\知识城地牛\knowledgeCity\common\scadaUtility.py", line 45, in __call
    ret = func(*p,**pp)
  File "C:\Users\comba\Desktop\知识城地牛\knowledgeCity\remoteio\main_remoteio.py", line 87, in urlReadDOList
    return ioMgr.readDOList(id)
  File "..\remoteio\remoteioMgr.py", line 158, in readDOList
    result=remoteioInfo.readDOList()
  File "..\remoteio\remoteioMgr.py", line 262, in readDOList
    return self._read(M30, IO_LENTH)
  File "C:\Users\comba\Desktop\知识城地牛\knowledgeCity\common\lock.py", line 122, in _call
    return func(*p,**pp)
  File "..\remoteio\remoteioMgr.py", line 311, in _read
    self.master.open()
  File "C:\Users\comba\Desktop\知识城地牛\knowledgeCity\common\modbusapi.py", line 60, in open
    self.master.open()
  File "C:\Users\comba\AppData\Local\Programs\Python\Python37\lib\site-packages\modbus_tk\modbus.py", line 99, in open
    self._do_open()
  File "C:\Users\comba\AppData\Local\Programs\Python\Python37\lib\site-packages\modbus_tk\modbus_tcp.py", line 173, in _do_open
    self._sock.connect((self._host, self._port))
TimeoutError: [WinError 10060] 由于连接方在一段时间后没有正确答复或连接的主机没有反应，连接尝试失败。

[WARN]2021-05-08 16:05:45,834: AGV04 clear task finish, cur= comba-ZXC-F3.LM20 task_status= 4
[INFO]2021-05-08 16:05:45,892: 22222222222222222222222
[INFO]2021-05-08 16:05:45,904: AGV04
[INFO]2021-05-08 16:05:45,934: task[6096463773dabd283420de74][-] AP22(LM17) -> AP25(LM24) [waitForAgv] apply AGV04
[INFO]2021-05-08 16:05:45,982: task[6096463773dabd283420de74] update info: {'agvId': 'AGV04', 'failMsg': '成功分配小车AGV04', 'updateTime': datetime.datetime(2021, 5, 8, 16, 5, 45, 970469)}
[DEBUG]2021-05-08 16:05:46,011: task[6096463773dabd283420de74][AGV04] AP22(LM17) -> AP25(LM24) [initAGV] waitForAgv -> initAGV
[INFO]2021-05-08 16:05:46,447: this is handle taskStep=============>initAGV
[INFO]2021-05-08 16:05:46,489: task[6096463773dabd283420de74] update info: {'failMsg': '前往三楼夹具点A工位点', 'updateTime': datetime.datetime(2021, 5, 8, 16, 5, 46, 477111)}
[DEBUG]2021-05-08 16:05:46,515: task[6096463773dabd283420de74][AGV04] AP22(LM17) -> AP25(LM24) [startMoveAGV] initAGV -> startMoveAGV
[INFO]2021-05-08 16:05:46,923: this is handle taskStep=============>startMoveAGV
[DEBUG]2021-05-08 16:05:46,942: GET: http://127.0.0.1:8999/api/agv/move?WorkPlace=true&agv=AGV04&agvId=AGV04&appName=akmTask&direction=None&floorId=comba-ZXC-F3&isRotate&loc=comba-ZXC-F3.AP22&location=AP22&p_direction=0.0&pgv_type=1&recognize=False&seer_jackup=JackLoad&taskId=6096463773dabd283420de74_2&taskType=scadaTask&timeoutSec=86400&use_pgv=False addr: 127.0.0.1
[INFO]2021-05-08 16:05:46,948: Begin: AGV04 move from comba-ZXC-F3.LM20 to comba-ZXC-F3.AP22 by paths: [('comba-ZXC-F3', ['LM20', 'LM21', 'LM17', 'AP18', 'AP22'], 5.569704036667539)] task: 6096463773dabd283420de74_2 timeout 86400 used 5 ms
[DEBUG]2021-05-08 16:05:46,949: used 7ms 200 OK application/json;charset=utf-8, GET: http://127.0.0.1:8999/api/agv/move?WorkPlace=true&agv=AGV04&agvId=AGV04&appName=akmTask&direction=None&floorId=comba-ZXC-F3&isRotate&loc=comba-ZXC-F3.AP22&location=AP22&p_direction=0.0&pgv_type=1&recognize=False&seer_jackup=JackLoad&taskId=6096463773dabd283420de74_2&taskType=scadaTask&timeoutSec=86400&use_pgv=False
[DEBUG]2021-05-08 16:05:46,951: task[6096463773dabd283420de74][AGV04] AP22(LM17) -> AP25(LM24) [loadPlayload] startMoveAGV -> loadPlayload
[INFO]2021-05-08 16:05:47,253: this is handle taskStep=============>loadPlayload
[INFO]2021-05-08 16:05:47,560: this is handle taskStep=============>loadPlayload
[DEBUG]2021-05-08 16:05:47,694: agvInfo: AGV04 comba-ZXC-F3.LM20 move to comba-ZXC-F3.LM21 ,taskId 6096463773dabd283420de74_2
[INFO]2021-05-08 16:05:47,863: this is handle taskStep=============>loadPlayload
[INFO]2021-05-08 16:05:48,169: this is handle taskStep=============>loadPlayload
[INFO]2021-05-08 16:05:48,471: this is handle taskStep=============>loadPlayload
[INFO]2021-05-08 16:05:48,778: this is handle taskStep=============>loadPlayload
[INFO]2021-05-08 16:05:49,081: this is handle taskStep=============>loadPlayload
[INFO]2021-05-08 16:05:49,384: this is handle taskStep=============>loadPlayload
[INFO]2021-05-08 16:05:49,691: this is handle taskStep=============>loadPlayload
[INFO]2021-05-08 16:05:49,994: this is handle taskStep=============>loadPlayload
[INFO]2021-05-08 16:05:50,301: this is handle taskStep=============>loadPlayload
[INFO]2021-05-08 16:05:50,604: this is handle taskStep=============>loadPlayload
[ERROR]2021-05-08 16:05:50,861: connect AGV01 failed timed out
[INFO]2021-05-08 16:05:50,862: AGV01 checkLink failed 172.16.217.209 19204
[WARN]2021-05-08 16:05:50,863: agvThread.AGV01[tid:7308] <lock name:agv.AGV01.lock_status,<locked _thread.RLock object owner=7308 count=1 at 0x000001B95AD3D940>> ,hold 10080 ms
[INFO]2021-05-08 16:05:50,864: name=agvThread.AGV01, pid=10292, tid=7308
[01] File "C:/Users/comba/AppData/Local/Programs/Python/Python37/lib/threading.py", line 865, in run() 
[02] File "C:/Users/comba/Desktop/知识城地牛/knowledgeCity/agvCtrl/agvList.py", line 565, in run() 
[03] File "../driver/seerAgv/agvCtrl.py", line 36, in checkLink() 
[04] File "../driver/seerAgv/agvApi.py", line 184, in checkLink() 
[05] File "C:/Users/comba/Desktop/知识城地牛/knowledgeCity/common/lock.py", line 102, in release() 
[06] File "C:/Users/comba/Desktop/知识城地牛/knowledgeCity/common/enhance.py", line 268, in getTrace() 
[07] File "C:/Users/comba/Desktop/知识城地牛/knowledgeCity/common/enhance.py", line 248, in getThreadStack()
[INFO]2021-05-08 16:05:50,911: this is handle taskStep=============>loadPlayload
[INFO]2021-05-08 16:05:51,213: this is handle taskStep=============>loadPlayload
[ERROR]2021-05-08 16:05:51,442: connect AGV03 failed timed out
[INFO]2021-05-08 16:05:51,443: AGV03 checkLink failed 172.16.217.121 19204
[WARN]2021-05-08 16:05:51,444: agvThread.AGV03[tid:1072] <lock name:agv.AGV03.lock_status,<locked _thread.RLock object owner=1072 count=1 at 0x000001B95AD3DC10>> ,hold 10059 ms
[INFO]2021-05-08 16:05:51,446: name=agvThread.AGV03, pid=10292, tid=1072
[01] File "C:/Users/comba/AppData/Local/Programs/Python/Python37/lib/threading.py", line 865, in run() 
[02] File "C:/Users/comba/Desktop/知识城地牛/knowledgeCity/agvCtrl/agvList.py", line 565, in run() 
[03] File "../driver/seerAgv/agvCtrl.py", line 36, in checkLink() 
[04] File "../driver/seerAgv/agvApi.py", line 184, in checkLink() 
[05] File "C:/Users/comba/Desktop/知识城地牛/knowledgeCity/common/lock.py", line 102, in release() 
[06] File "C:/Users/comba/Desktop/知识城地牛/knowledgeCity/common/enhance.py", line 268, in getTrace() 
[07] File "C:/Users/comba/Desktop/知识城地牛/knowledgeCity/common/enhance.py", line 248, in getThreadStack()
[INFO]2021-05-08 16:05:51,515: this is handle taskStep=============>loadPlayload
[ERROR]2021-05-08 16:05:51,554: connect AGV02 failed timed out
[INFO]2021-05-08 16:05:51,556: AGV02 checkLink failed 172.16.217.213 19204
[WARN]2021-05-08 16:05:51,557: agvThread.AGV02[tid:13448] <lock name:agv.AGV02.lock_status,<locked _thread.RLock object owner=13448 count=1 at 0x000001B95AD3D418>> ,hold 10075 ms
[INFO]2021-05-08 16:05:51,558: name=agvThread.AGV02, pid=10292, tid=13448
[01] File "C:/Users/comba/AppData/Local/Programs/Python/Python37/lib/threading.py", line 865, in run() 
[02] File "C:/Users/comba/Desktop/知识城地牛/knowledgeCity/agvCtrl/agvList.py", line 565, in run() 
[03] File "../driver/seerAgv/agvCtrl.py", line 36, in checkLink() 
[04] File "../driver/seerAgv/agvApi.py", line 184, in checkLink() 
[05] File "C:/Users/comba/Desktop/知识城地牛/knowledgeCity/common/lock.py", line 102, in release() 
[06] File "C:/Users/comba/Desktop/知识城地牛/knowledgeCity/common/enhance.py", line 268, in getTrace() 
[07] File "C:/Users/comba/Desktop/知识城地牛/knowledgeCity/common/enhance.py", line 248, in getThreadStack()
[INFO]2021-05-08 16:05:51,818: this is handle taskStep=============>loadPlayload
[INFO]2021-05-08 16:05:52,123: this is handle taskStep=============>loadPlayload
[INFO]2021-05-08 16:05:52,429: this is handle taskStep=============>loadPlayload
[INFO]2021-05-08 16:05:52,731: this is handle taskStep=============>loadPlayload
[DEBUG]2021-05-08 16:05:52,867: try connect AGV01 172.16.217.209:19204
[INFO]2021-05-08 16:05:53,033: this is handle taskStep=============>loadPlayload
[INFO]2021-05-08 16:05:53,336: this is handle taskStep=============>loadPlayload
[DEBUG]2021-05-08 16:05:53,449: try connect AGV03 172.16.217.121:19204
[DEBUG]2021-05-08 16:05:53,561: try connect AGV02 172.16.217.213:19204
[INFO]2021-05-08 16:05:53,641: this is handle taskStep=============>loadPlayload
[ERROR]2021-05-08 16:05:53,889: raise alarm obj=AGV04, typeId=54004, desc=AGV异常, id=60964661697d98928ef14582
[ERROR]2021-05-08 16:05:53,891: raise alarm obj=AGV04, typeId=54013, desc=AGV异常, id=60964661697d98928ef14584
[ERROR]2021-05-08 16:05:53,893: raise alarm obj=AGV04, typeId=54025, desc=AGV异常
[INFO]2021-05-08 16:05:53,944: this is handle taskStep=============>loadPlayload
[INFO]2021-05-08 16:05:54,248: this is handle taskStep=============>loadPlayload
[ERROR]2021-05-08 16:05:54,451: raise alarm obj=AGV04, typeId=4002, desc=急停按钮处于激活状态, id=60964662697d98928ef14587
[INFO]2021-05-08 16:05:54,551: this is handle taskStep=============>loadPlayload
[INFO]2021-05-08 16:05:54,853: this is handle taskStep=============>loadPlayload
[INFO]2021-05-08 16:05:55,155: this is handle taskStep=============>loadPlayload
[INFO]2021-05-08 16:05:55,458: this is handle taskStep=============>loadPlayload
[INFO]2021-05-08 16:05:55,765: this is handle taskStep=============>loadPlayload
[INFO]2021-05-08 16:05:56,067: this is handle taskStep=============>loadPlayload
[INFO]2021-05-08 16:05:56,375: this is handle taskStep=============>loadPlayload
[INFO]2021-05-08 16:05:56,683: this is handle taskStep=============>loadPlayload
[INFO]2021-05-08 16:05:56,986: this is handle taskStep=============>loadPlayload
[INFO]2021-05-08 16:05:57,294: this is handle taskStep=============>loadPlayload
[INFO]2021-05-08 16:05:57,597: this is handle taskStep=============>loadPlayload
[INFO]2021-05-08 16:05:57,904: this is handle taskStep=============>loadPlayload
[CRITICAL]2021-05-08 16:05:58,082: readDIList error cause a error: ('http get', 'http://127.0.0.1:8999/api/remoteio/readDOList', {'id': 'upStation01'}, 'error:', 'timed out')
pid=10292, ppid=13624, tid=13572
Traceback (most recent call last):
  File "C:\Users\comba\Desktop\知识城地牛\knowledgeCity\common\webutility.py", line 103, in http_get
    f = urllib.request.urlopen(u,timeout=timeout)
  File "C:\Users\comba\AppData\Local\Programs\Python\Python37\lib\urllib\request.py", line 222, in urlopen
    return opener.open(url, data, timeout)
  File "C:\Users\comba\AppData\Local\Programs\Python\Python37\lib\urllib\request.py", line 525, in open
    response = self._open(req, data)
  File "C:\Users\comba\AppData\Local\Programs\Python\Python37\lib\urllib\request.py", line 543, in _open
    '_open', req)
  File "C:\Users\comba\AppData\Local\Programs\Python\Python37\lib\urllib\request.py", line 503, in _call_chain
    result = func(*args)
  File "C:\Users\comba\AppData\Local\Programs\Python\Python37\lib\urllib\request.py", line 1345, in http_open
    return self.do_open(http.client.HTTPConnection, req)
  File "C:\Users\comba\AppData\Local\Programs\Python\Python37\lib\urllib\request.py", line 1320, in do_open
    r = h.getresponse()
  File "C:\Users\comba\AppData\Local\Programs\Python\Python37\lib\http\client.py", line 1321, in getresponse
    response.begin()
  File "C:\Users\comba\AppData\Local\Programs\Python\Python37\lib\http\client.py", line 296, in begin
    version, status, reason = self._read_status()
  File "C:\Users\comba\AppData\Local\Programs\Python\Python37\lib\http\client.py", line 257, in _read_status
    line = str(self.fp.readline(_MAXLINE + 1), "iso-8859-1")
  File "C:\Users\comba\AppData\Local\Programs\Python\Python37\lib\socket.py", line 589, in readinto
    return self._sock.recv_into(b)
socket.timeout: timed out

During handling of the above exception, another exception occurred:

Traceback (most recent call last):
  File "C:\Users\comba\Desktop\知识城地牛\knowledgeCity\autoCtrl\deviceCtrl.py", line 71, in _monitorDevices
    s1 = ioApi.readDOList(devices[d]["io1"])["status"] #上板机
  File "..\remoteio\remoteioApi.py", line 73, in readDOList
    return _remoteio('/api/remoteio/readDOList', id, param)
  File "..\remoteio\remoteioApi.py", line 100, in _remoteio
    return http_get(url + apiurl, param)
  File "..\remoteio\remoteioApi.py", line 16, in http_get
    r = webutility.http_get(url, param)
  File "C:\Users\comba\Desktop\知识城地牛\knowledgeCity\common\webutility.py", line 105, in http_get
    raise Exception("http get",url,params,"error:",str(e))
Exception: ('http get', 'http://127.0.0.1:8999/api/remoteio/readDOList', {'id': 'upStation01'}, 'error:', 'timed out')

[INFO]2021-05-08 16:05:58,209: this is handle taskStep=============>loadPlayload
[INFO]2021-05-08 16:05:58,512: this is handle taskStep=============>loadPlayload
[INFO]2021-05-08 16:05:58,815: this is handle taskStep=============>loadPlayload
[INFO]2021-05-08 16:05:59,092: remoteio is alarm: []
[INFO]2021-05-08 16:05:59,117: this is handle taskStep=============>loadPlayload
[INFO]2021-05-08 16:05:59,424: this is handle taskStep=============>loadPlayload
[INFO]2021-05-08 16:05:59,726: this is handle taskStep=============>loadPlayload
[INFO]2021-05-08 16:06:00,029: this is handle taskStep=============>loadPlayload
[WARN]2021-05-08 16:06:00,106: AGV04 low battery charge,batteryLevel= 0.288 start charge level= 0.400
[WARN]2021-05-08 16:06:00,110: AGV04 battery 0.288 check failed: emergency
[DEBUG]2021-05-08 16:06:00,113: send http_get: http://127.0.0.1:8999/api/remoteio/readDOList?id=upStation01
[INFO]2021-05-08 16:06:00,332: this is handle taskStep=============>loadPlayload
[INFO]2021-05-08 16:06:00,643: this is handle taskStep=============>loadPlayload
[INFO]2021-05-08 16:06:00,945: this is handle taskStep=============>loadPlayload
[INFO]2021-05-08 16:06:01,247: this is handle taskStep=============>loadPlayload
[INFO]2021-05-08 16:06:01,549: this is handle taskStep=============>loadPlayload
[INFO]2021-05-08 16:06:01,853: this is handle taskStep=============>loadPlayload
[INFO]2021-05-08 16:06:02,158: this is handle taskStep=============>loadPlayload
[INFO]2021-05-08 16:06:02,465: this is handle taskStep=============>loadPlayload
[INFO]2021-05-08 16:06:02,768: this is handle taskStep=============>loadPlayload
[ERROR]2021-05-08 16:06:02,869: connect AGV01 failed timed out
[INFO]2021-05-08 16:06:02,871: AGV01 checkLink failed 172.16.217.209 19204
[WARN]2021-05-08 16:06:02,872: agvThread.AGV01[tid:7308] <lock name:agv.AGV01.lock_status,<locked _thread.RLock object owner=7308 count=1 at 0x000001B95AD3D940>> ,hold 10005 ms
[INFO]2021-05-08 16:06:02,873: name=agvThread.AGV01, pid=10292, tid=7308
[01] File "C:/Users/comba/AppData/Local/Programs/Python/Python37/lib/threading.py", line 865, in run() 
[02] File "C:/Users/comba/Desktop/知识城地牛/knowledgeCity/agvCtrl/agvList.py", line 565, in run() 
[03] File "../driver/seerAgv/agvCtrl.py", line 36, in checkLink() 
[04] File "../driver/seerAgv/agvApi.py", line 184, in checkLink() 
[05] File "C:/Users/comba/Desktop/知识城地牛/knowledgeCity/common/lock.py", line 102, in release() 
[06] File "C:/Users/comba/Desktop/知识城地牛/knowledgeCity/common/enhance.py", line 268, in getTrace() 
[07] File "C:/Users/comba/Desktop/知识城地牛/knowledgeCity/common/enhance.py", line 248, in getThreadStack()
[INFO]2021-05-08 16:06:03,070: this is handle taskStep=============>loadPlayload
[INFO]2021-05-08 16:06:03,373: this is handle taskStep=============>loadPlayload
[ERROR]2021-05-08 16:06:03,451: connect AGV03 failed timed out
[INFO]2021-05-08 16:06:03,452: AGV03 checkLink failed 172.16.217.121 19204
[WARN]2021-05-08 16:06:03,453: agvThread.AGV03[tid:1072] <lock name:agv.AGV03.lock_status,<locked _thread.RLock object owner=1072 count=1 at 0x000001B95AD3DC10>> ,hold 10004 ms
[INFO]2021-05-08 16:06:03,454: name=agvThread.AGV03, pid=10292, tid=1072
[01] File "C:/Users/comba/AppData/Local/Programs/Python/Python37/lib/threading.py", line 865, in run() 
[02] File "C:/Users/comba/Desktop/知识城地牛/knowledgeCity/agvCtrl/agvList.py", line 565, in run() 
[03] File "../driver/seerAgv/agvCtrl.py", line 36, in checkLink() 
[04] File "../driver/seerAgv/agvApi.py", line 184, in checkLink() 
[05] File "C:/Users/comba/Desktop/知识城地牛/knowledgeCity/common/lock.py", line 102, in release() 
[06] File "C:/Users/comba/Desktop/知识城地牛/knowledgeCity/common/enhance.py", line 268, in getTrace() 
[07] File "C:/Users/comba/Desktop/知识城地牛/knowledgeCity/common/enhance.py", line 248, in getThreadStack()
[ERROR]2021-05-08 16:06:03,565: connect AGV02 failed timed out
[INFO]2021-05-08 16:06:03,569: AGV02 checkLink failed 172.16.217.213 19204
[WARN]2021-05-08 16:06:03,571: agvThread.AGV02[tid:13448] <lock name:agv.AGV02.lock_status,<locked _thread.RLock object owner=13448 count=1 at 0x000001B95AD3D418>> ,hold 10010 ms
[INFO]2021-05-08 16:06:03,575: name=agvThread.AGV02, pid=10292, tid=13448
[01] File "C:/Users/comba/AppData/Local/Programs/Python/Python37/lib/threading.py", line 865, in run() 
[02] File "C:/Users/comba/Desktop/知识城地牛/knowledgeCity/agvCtrl/agvList.py", line 565, in run() 
[03] File "../driver/seerAgv/agvCtrl.py", line 36, in checkLink() 
[04] File "../driver/seerAgv/agvApi.py", line 184, in checkLink() 
[05] File "C:/Users/comba/Desktop/知识城地牛/knowledgeCity/common/lock.py", line 102, in release() 
[06] File "C:/Users/comba/Desktop/知识城地牛/knowledgeCity/common/enhance.py", line 268, in getTrace() 
[07] File "C:/Users/comba/Desktop/知识城地牛/knowledgeCity/common/enhance.py", line 248, in getThreadStack()
[INFO]2021-05-08 16:06:03,681: this is handle taskStep=============>loadPlayload
[INFO]2021-05-08 16:06:03,983: this is handle taskStep=============>loadPlayload
[INFO]2021-05-08 16:06:04,290: this is handle taskStep=============>loadPlayload
[INFO]2021-05-08 16:06:04,592: this is handle taskStep=============>loadPlayload
[DEBUG]2021-05-08 16:06:04,874: try connect AGV01 172.16.217.209:19204
[INFO]2021-05-08 16:06:04,895: this is handle taskStep=============>loadPlayload
[INFO]2021-05-08 16:06:05,197: this is handle taskStep=============>loadPlayload
[DEBUG]2021-05-08 16:06:05,456: try connect AGV03 172.16.217.121:19204
[INFO]2021-05-08 16:06:05,501: this is handle taskStep=============>loadPlayload
[DEBUG]2021-05-08 16:06:05,583: try connect AGV02 172.16.217.213:19204
[INFO]2021-05-08 16:06:05,807: this is handle taskStep=============>loadPlayload
[INFO]2021-05-08 16:06:06,110: this is handle taskStep=============>loadPlayload
[INFO]2021-05-08 16:06:06,412: this is handle taskStep=============>loadPlayload
[WARN]2021-05-08 16:06:06,473: worker 7[tid:12652] <locked _thread.RLock object owner=12652 count=1 at 0x000001B95A08E670> ,hold 23376 ms
[INFO]2021-05-08 16:06:06,477: name=worker 7, pid=10292, tid=12652
[01] File "C:/Users/comba/AppData/Local/Programs/Python/Python37/lib/threading.py", line 865, in run() 
[02] File "C:/Users/comba/AppData/Local/Programs/Python/Python37/lib/site-packages/paste/httpserver.py", line 895, in worker_thread_callback() 
[03] File "C:/Users/comba/AppData/Local/Programs/Python/Python37/lib/site-packages/paste/httpserver.py", line 1069, in <lambda>() 
[04] File "C:/Users/comba/AppData/Local/Programs/Python/Python37/lib/site-packages/paste/httpserver.py", line 1085, in process_request_in_thread() 
[05] File "C:/Users/comba/AppData/Local/Programs/Python/Python37/lib/socketserver.py", line 357, in finish_request() 
[06] File "C:/Users/comba/AppData/Local/Programs/Python/Python37/lib/socketserver.py", line 717, in __init__() 
[07] File "C:/Users/comba/AppData/Local/Programs/Python/Python37/lib/site-packages/paste/httpserver.py", line 459, in handle() 
[08] File "C:/Users/comba/AppData/Local/Programs/Python/Python37/lib/http/server.py", line 426, in handle() 
[09] File "C:/Users/comba/AppData/Local/Programs/Python/Python37/lib/site-packages/paste/httpserver.py", line 454, in handle_one_request() 
[10] File "C:/Users/comba/AppData/Local/Programs/Python/Python37/lib/site-packages/paste/httpserver.py", line 304, in wsgi_execute() 
[11] File "C:/Users/comba/AppData/Local/Programs/Python/Python37/lib/site-packages/paste/translogger.py", line 69, in __call__() 
[12] File "C:/Users/comba/AppData/Local/Programs/Python/Python37/lib/site-packages/bottle.py", line 979, in __call__() 
[13] File "C:/Users/comba/AppData/Local/Programs/Python/Python37/lib/site-packages/bottle.py", line 954, in wsgi() 
[14] File "C:/Users/comba/AppData/Local/Programs/Python/Python37/lib/site-packages/bottle.py", line 862, in _handle() 
[15] File "C:/Users/comba/AppData/Local/Programs/Python/Python37/lib/site-packages/bottle.py", line 1742, in wrapper() 
[16] File "C:/Users/comba/Desktop/知识城地牛/knowledgeCity/common/webutility.py", line 465, in _enable_cors() 
[17] File "C:/Users/comba/Desktop/知识城地牛/knowledgeCity/common/webutility.py", line 481, in _enable_cors() 
[18] File "C:/Users/comba/Desktop/知识城地牛/knowledgeCity/common/scadaUtility.py", line 45, in __call() 
[19] File "C:/Users/comba/Desktop/知识城地牛/knowledgeCity/remoteio/main_remoteio.py", line 87, in urlReadDOList() 
[20] File "../remoteio/remoteioMgr.py", line 158, in readDOList() 
[21] File "../remoteio/remoteioMgr.py", line 262, in readDOList() 
[22] File "C:/Users/comba/Desktop/知识城地牛/knowledgeCity/common/lock.py", line 124, in _call() 
[23] File "C:/Users/comba/Desktop/知识城地牛/knowledgeCity/common/lock.py", line 102, in release() 
[24] File "C:/Users/comba/Desktop/知识城地牛/knowledgeCity/common/enhance.py", line 268, in getTrace() 
[25] File "C:/Users/comba/Desktop/知识城地牛/knowledgeCity/common/enhance.py", line 248, in getThreadStack()
[CRITICAL]2021-05-08 16:06:06,487: upStation01 readDIList fail cause a error: [WinError 10060] 由于连接方在一段时间后没有正确答复或连接的主机没有反应，连接尝试失败。
pid=10292, ppid=13624, tid=12652
Traceback (most recent call last):
  File "..\remoteio\remoteioMgr.py", line 262, in readDOList
    return self._read(M30, IO_LENTH)
  File "C:\Users\comba\Desktop\知识城地牛\knowledgeCity\common\lock.py", line 122, in _call
    return func(*p,**pp)
  File "..\remoteio\remoteioMgr.py", line 311, in _read
    self.master.open()
  File "C:\Users\comba\Desktop\知识城地牛\knowledgeCity\common\modbusapi.py", line 60, in open
    self.master.open()
  File "C:\Users\comba\AppData\Local\Programs\Python\Python37\lib\site-packages\modbus_tk\modbus.py", line 99, in open
    self._do_open()
  File "C:\Users\comba\AppData\Local\Programs\Python\Python37\lib\site-packages\modbus_tk\modbus_tcp.py", line 173, in _do_open
    self._sock.connect((self._host, self._port))
TimeoutError: [WinError 10060] 由于连接方在一段时间后没有正确答复或连接的主机没有反应，连接尝试失败。

[CRITICAL]2021-05-08 16:06:06,495: invoke <function urlReadDOList at 0x000001B958BCFD08> cause a error: [WinError 10060] 由于连接方在一段时间后没有正确答复或连接的主机没有反应，连接尝试失败。
pid=10292, ppid=13624, tid=12652
Traceback (most recent call last):
  File "C:\Users\comba\Desktop\知识城地牛\knowledgeCity\common\scadaUtility.py", line 45, in __call
    ret = func(*p,**pp)
  File "C:\Users\comba\Desktop\知识城地牛\knowledgeCity\remoteio\main_remoteio.py", line 87, in urlReadDOList
    return ioMgr.readDOList(id)
  File "..\remoteio\remoteioMgr.py", line 158, in readDOList
    result=remoteioInfo.readDOList()
  File "..\remoteio\remoteioMgr.py", line 262, in readDOList
    return self._read(M30, IO_LENTH)
  File "C:\Users\comba\Desktop\知识城地牛\knowledgeCity\common\lock.py", line 122, in _call
    return func(*p,**pp)
  File "..\remoteio\remoteioMgr.py", line 311, in _read
    self.master.open()
  File "C:\Users\comba\Desktop\知识城地牛\knowledgeCity\common\modbusapi.py", line 60, in open
    self.master.open()
  File "C:\Users\comba\AppData\Local\Programs\Python\Python37\lib\site-packages\modbus_tk\modbus.py", line 99, in open
    self._do_open()
  File "C:\Users\comba\AppData\Local\Programs\Python\Python37\lib\site-packages\modbus_tk\modbus_tcp.py", line 173, in _do_open
    self._sock.connect((self._host, self._port))
TimeoutError: [WinError 10060] 由于连接方在一段时间后没有正确答复或连接的主机没有反应，连接尝试失败。

[INFO]2021-05-08 16:06:06,715: this is handle taskStep=============>loadPlayload
[INFO]2021-05-08 16:06:07,020: this is handle taskStep=============>loadPlayload
[INFO]2021-05-08 16:06:07,322: this is handle taskStep=============>loadPlayload
[INFO]2021-05-08 16:06:07,624: this is handle taskStep=============>loadPlayload
[INFO]2021-05-08 16:06:07,928: this is handle taskStep=============>loadPlayload
[INFO]2021-05-08 16:06:08,235: this is handle taskStep=============>loadPlayload
