[INFO]2021-05-26 12:07:18,632: log files at C:\Users\comba\Desktop\KLC\knowledgeCity\common\log
[INFO]2021-05-26 12:07:18,632: find module agvCtrl.main_agv
[INFO]2021-05-26 12:07:18,633: find module agvDevice.main_agvDevice
[INFO]2021-05-26 12:07:18,633: find module alarm.main_alarm
[INFO]2021-05-26 12:07:18,633: find module auth.main_auth
[INFO]2021-05-26 12:07:18,634: find module autoCtrl.main_akmCtrl
[INFO]2021-05-26 12:07:18,634: find module door.main_door
[INFO]2021-05-26 12:07:18,634: find module elevator.main_elevator
[INFO]2021-05-26 12:07:18,634: find module feed.main_feed
[INFO]2021-05-26 12:07:18,639: find module remoteio.main_remoteio
[INFO]2021-05-26 12:07:18,639: import agvCtrl.main_agv
[INFO]2021-05-26 12:07:18,870: create lock <lock name:doorMgr.lock,<unlocked _thread.RLock object owner=0 count=0 at 0x00000239F7B647B0>>
[INFO]2021-05-26 12:07:18,872: create lock <lock name:door.lock,<unlocked _thread.RLock object owner=0 count=0 at 0x00000239F7B64918>>
[INFO]2021-05-26 12:07:18,919: create lock <lock name:timer.lock_2447994747200,<unlocked _thread.RLock object owner=0 count=0 at 0x00000239F7DAE440>>
[ERROR]2021-05-26 12:07:18,926: mqtt is disabled
[INFO]2021-05-26 12:07:18,926: mqtt: subscribe [alarm/raise/+]
[INFO]2021-05-26 12:07:18,927: mqtt: subscribe [alarm/clear/+]
[INFO]2021-05-26 12:07:21,945: Mongodb connect to 127.0.0.1 port 27017
[INFO]2021-05-26 12:07:21,990: create lock <lock name:elevatorApi.tcp_lock,<unlocked _thread.RLock object owner=0 count=0 at 0x00000239F7F77B48>>
[INFO]2021-05-26 12:07:21,991: create lock <lock name:elevatorApi.g_lock,<unlocked _thread.RLock object owner=0 count=0 at 0x00000239F7F77788>>
[INFO]2021-05-26 12:07:21,993: create lock <lock name:elevatorMgr.lock,<unlocked _thread.RLock object owner=0 count=0 at 0x00000239F7F77300>>
[INFO]2021-05-26 12:07:22,001: create lock <lock name:agvserver,<unlocked _thread.RLock object owner=0 count=0 at 0x00000239F807E710>>
[INFO]2021-05-26 12:07:22,142: create lock <lock name:mapMgr.lock,<unlocked _thread.RLock object owner=0 count=0 at 0x00000239F633C198>>
[INFO]2021-05-26 12:07:22,353: create lock <lock name:agvList.g_agvLock,<unlocked _thread.RLock object owner=0 count=0 at 0x00000239F813FDF0>>
[INFO]2021-05-26 12:07:22,356: create lock <lock name:taskList.lock,<unlocked _thread.RLock object owner=0 count=0 at 0x00000239F8188EE0>>
[INFO]2021-05-26 12:07:22,403: charge policy 0 , fix time
[INFO]2021-05-26 12:07:22,429: create lock <lock name:agvApi.g_lock,<unlocked _thread.RLock object owner=0 count=0 at 0x00000239F823C210>>
[INFO]2021-05-26 12:07:22,849: start load map C:\Users\comba\Desktop\KLC\knowledgeCity\agvCtrl\projects\knowledgeCity\comba-ZSC-3F_0419.smap
[DEBUG]2021-05-26 12:07:22,926: elevator thread start
[INFO]2021-05-26 12:07:22,940: load map C:\Users\comba\Desktop\KLC\knowledgeCity\agvCtrl\projects\knowledgeCity\comba-ZSC-3F_0419.smap ,used 98 ms
[INFO]2021-05-26 12:07:22,947: start load map C:\Users\comba\Desktop\KLC\knowledgeCity\agvCtrl\projects\knowledgeCity\comba-ZSC-F1-F3.smap
[INFO]2021-05-26 12:07:23,091: load map C:\Users\comba\Desktop\KLC\knowledgeCity\agvCtrl\projects\knowledgeCity\comba-ZSC-F1-F3.smap ,used 150 ms
[INFO]2021-05-26 12:07:23,098: start load map C:\Users\comba\Desktop\KLC\knowledgeCity\agvCtrl\projects\knowledgeCity\comba-ZXC-3F.smap
[INFO]2021-05-26 12:07:23,173: load map C:\Users\comba\Desktop\KLC\knowledgeCity\agvCtrl\projects\knowledgeCity\comba-ZXC-3F.smap ,used 82 ms
[INFO]2021-05-26 12:07:23,180: start load map C:\Users\comba\Desktop\KLC\knowledgeCity\agvCtrl\projects\knowledgeCity\comba-ZXC-F3.smap
[INFO]2021-05-26 12:07:23,229: load map C:\Users\comba\Desktop\KLC\knowledgeCity\agvCtrl\projects\knowledgeCity\comba-ZXC-F3.smap ,used 55 ms
[INFO]2021-05-26 12:07:23,237: start load map C:\Users\comba\Desktop\KLC\knowledgeCity\agvCtrl\projects\knowledgeCity\office.smap
[INFO]2021-05-26 12:07:23,269: load map C:\Users\comba\Desktop\KLC\knowledgeCity\agvCtrl\projects\knowledgeCity\office.smap ,used 39 ms
[INFO]2021-05-26 12:07:23,272: import agvDevice.main_agvDevice
[INFO]2021-05-26 12:07:23,273: import alarm.main_alarm
[INFO]2021-05-26 12:07:23,274: import auth.main_auth
[INFO]2021-05-26 12:07:23,281: import autoCtrl.main_akmCtrl
[INFO]2021-05-26 12:07:23,302: create lock <lock name:agvApi.g_lock,<unlocked _thread.RLock object owner=0 count=0 at 0x00000239F89BA670>>
[INFO]2021-05-26 12:07:23,311: create lock <lock name:runTasks.pre_lock,<unlocked _thread.RLock object owner=0 count=0 at 0x00000239F862AE90>>
[INFO]2021-05-26 12:07:23,334: create lock <lock name:IOAlarm.s_lock,<unlocked _thread.RLock object owner=0 count=0 at 0x00000239F862A170>>
[INFO]2021-05-26 12:07:23,337: create lock <lock name:mapMgr.lock,<unlocked _thread.RLock object owner=0 count=0 at 0x00000239F87E4120>>
[INFO]2021-05-26 12:07:23,827: import door.main_door
[INFO]2021-05-26 12:07:23,829: import elevator.main_elevator
[INFO]2021-05-26 12:07:23,830: import feed.main_feed
[INFO]2021-05-26 12:07:23,835: create lock <lock name:feedTask.g_lock,<unlocked _thread.RLock object owner=0 count=0 at 0x00000239F9B024E0>>
[INFO]2021-05-26 12:07:23,867: import remoteio.main_remoteio
[SUCC]2021-05-26 12:07:23,881: utility start, pid=1764, ppid=10836
[DEBUG]2021-05-26 12:07:23,881: create aliveObj upStation01 远程控制IO离线异常 timeout 120
[DEBUG]2021-05-26 12:07:23,882: start timer
[DEBUG]2021-05-26 12:07:23,882: create aliveObj downStation01 远程控制IO离线异常 timeout 120
[DEBUG]2021-05-26 12:07:23,883: create aliveObj 3FLamp 远程控制IO离线异常 timeout 120
[INFO]2021-05-26 12:07:23,889: load agv file: C:\Users\comba\Desktop\KLC\knowledgeCity\agvCtrl/projects/knowledgeCity/agv.cfg
[INFO]2021-05-26 12:07:23,889: create lock <lock name:agvList.AGV01.lock,<unlocked _thread.RLock object owner=0 count=0 at 0x00000239F9BB1530>>
[DEBUG]2021-05-26 12:07:23,891: create aliveObj AGV01 AGV离线异常 timeout 300
[INFO]2021-05-26 12:07:23,893: AGV01 start agvList run thread
[INFO]2021-05-26 12:07:23,893: AGV01 start agvList run2 thread
[INFO]2021-05-26 12:07:23,894: create lock <lock name:agv.AGV01.lock_status,<unlocked _thread.RLock object owner=0 count=0 at 0x00000239F9BB1A80>>
[DEBUG]2021-05-26 12:07:23,895: try connect AGV01 172.16.217.209:19204
[INFO]2021-05-26 12:07:23,896: create lock <lock name:agvList.AGVdiniu.lock,<unlocked _thread.RLock object owner=0 count=0 at 0x00000239F9BB1A08>>
[DEBUG]2021-05-26 12:07:23,898: create aliveObj AGVdiniu AGV离线异常 timeout 300
[INFO]2021-05-26 12:07:23,898: AGVdiniu start agvList run thread
[INFO]2021-05-26 12:07:23,898: AGVdiniu start agvList run2 thread
[INFO]2021-05-26 12:07:23,898: create lock <lock name:agvList.AGVwuliao.lock,<unlocked _thread.RLock object owner=0 count=0 at 0x00000239F9BB1C38>>
[INFO]2021-05-26 12:07:23,899: create lock <lock name:agv.AGVdiniu.lock_status,<unlocked _thread.RLock object owner=0 count=0 at 0x00000239F9BB1C88>>
[DEBUG]2021-05-26 12:07:23,900: try connect AGVdiniu 172.16.217.121:19204
[DEBUG]2021-05-26 12:07:23,901: create aliveObj AGVwuliao AGV离线异常 timeout 300
[INFO]2021-05-26 12:07:23,901: AGV01 connected 172.16.217.209 19204
[INFO]2021-05-26 12:07:23,902: AGVwuliao start agvList run thread
[INFO]2021-05-26 12:07:23,902: AGVwuliao start agvList run2 thread
[INFO]2021-05-26 12:07:23,902: create lock <lock name:agvList.AGVchache.lock,<unlocked _thread.RLock object owner=0 count=0 at 0x00000239F9BB1EE0>>
[INFO]2021-05-26 12:07:23,902: create lock <lock name:agv.AGV01.lock_ctrl,<unlocked _thread.RLock object owner=0 count=0 at 0x00000239F9BB1A58>>
[INFO]2021-05-26 12:07:23,903: create lock <lock name:agv.AGVwuliao.lock_status,<unlocked _thread.RLock object owner=0 count=0 at 0x00000239F9BB1F30>>
[DEBUG]2021-05-26 12:07:23,904: try connect AGV01 172.16.217.209:19205
[DEBUG]2021-05-26 12:07:23,904: try connect AGVwuliao 172.16.217.211:19204
[DEBUG]2021-05-26 12:07:23,905: create aliveObj AGVchache AGV离线异常 timeout 300
[INFO]2021-05-26 12:07:23,905: AGVchache start agvList run thread
[INFO]2021-05-26 12:07:23,906: AGVchache start agvList run2 thread
[WARN]2021-05-26 12:07:23,906: Local server start! version 3.7.0, path C:\Users\comba\Desktop\KLC\knowledgeCity\common, pid 1764
[INFO]2021-05-26 12:07:23,906: create lock <lock name:agv.AGVchache.lock_status,<unlocked _thread.RLock object owner=0 count=0 at 0x00000239F9BB1440>>
[INFO]2021-05-26 12:07:23,907: add_ignore: taskStatus
[DEBUG]2021-05-26 12:07:23,907: try connect AGVchache 172.16.217.213:19204
[INFO]2021-05-26 12:07:23,916: AGV01 connected 172.16.217.209 19205
[INFO]2021-05-26 12:07:23,918: create lock <lock name:agv.AGV01.lock_task,<unlocked _thread.RLock object owner=0 count=0 at 0x00000239F715B0A8>>
[DEBUG]2021-05-26 12:07:23,919: try connect AGV01 172.16.217.209:19206
[INFO]2021-05-26 12:07:23,923: AGV01 connected 172.16.217.209 19206
[INFO]2021-05-26 12:07:23,924: create lock <lock name:agv.AGV01.lock_conf,<unlocked _thread.RLock object owner=0 count=0 at 0x00000239F715BB98>>
[DEBUG]2021-05-26 12:07:23,924: try connect AGV01 172.16.217.209:19207
[INFO]2021-05-26 12:07:23,926: AGVchache connected 172.16.217.213 19204
[INFO]2021-05-26 12:07:23,926: create lock <lock name:agv.AGVchache.lock_ctrl,<unlocked _thread.RLock object owner=0 count=0 at 0x00000239F9BB15A8>>
[DEBUG]2021-05-26 12:07:23,926: try connect AGVchache 172.16.217.213:19205
[INFO]2021-05-26 12:07:23,932: AGV01 connected 172.16.217.209 19207
[INFO]2021-05-26 12:07:23,933: create lock <lock name:agv.AGV01.lock_core,<unlocked _thread.RLock object owner=0 count=0 at 0x00000239F715BB70>>
[DEBUG]2021-05-26 12:07:23,933: try connect AGV01 172.16.217.209:19208
[INFO]2021-05-26 12:07:23,934: AGVchache connected 172.16.217.213 19205
[INFO]2021-05-26 12:07:23,934: create lock <lock name:agv.AGVchache.lock_task,<unlocked _thread.RLock object owner=0 count=0 at 0x00000239F715BB48>>
[DEBUG]2021-05-26 12:07:23,934: try connect AGVchache 172.16.217.213:19206
[INFO]2021-05-26 12:07:23,937: AGV01 connected 172.16.217.209 19208
[INFO]2021-05-26 12:07:23,938: create lock <lock name:agv.AGV01.lock_other,<unlocked _thread.RLock object owner=0 count=0 at 0x00000239F715BBE8>>
[DEBUG]2021-05-26 12:07:23,938: try connect AGV01 172.16.217.209:19210
[INFO]2021-05-26 12:07:23,939: AGVchache connected 172.16.217.213 19206
[INFO]2021-05-26 12:07:23,940: create lock <lock name:agv.AGVchache.lock_conf,<unlocked _thread.RLock object owner=0 count=0 at 0x00000239F715BC60>>
[DEBUG]2021-05-26 12:07:23,940: try connect AGVchache 172.16.217.213:19207
[INFO]2021-05-26 12:07:23,944: AGVchache connected 172.16.217.213 19207
[INFO]2021-05-26 12:07:23,945: create lock <lock name:agv.AGVchache.lock_core,<unlocked _thread.RLock object owner=0 count=0 at 0x00000239F715BC88>>
[DEBUG]2021-05-26 12:07:23,945: try connect AGVchache 172.16.217.213:19208
[INFO]2021-05-26 12:07:23,954: AGV01 connected 172.16.217.209 19210
[INFO]2021-05-26 12:07:23,960: AGVchache connected 172.16.217.213 19208
[INFO]2021-05-26 12:07:23,960: create lock <lock name:agv.AGVchache.lock_other,<unlocked _thread.RLock object owner=0 count=0 at 0x00000239F715BC38>>
[DEBUG]2021-05-26 12:07:23,960: try connect AGVchache 172.16.217.213:19210
[INFO]2021-05-26 12:07:23,978: AGVchache connected 172.16.217.213 19210
[INFO]2021-05-26 12:07:23,989: AGV01 current map comba-ZXC-F3
[INFO]2021-05-26 12:07:23,990: AGVchache current map comba-ZSC-F1-F3
[INFO]2021-05-26 12:07:24,008: AGVchache is online
[INFO]2021-05-26 12:07:24,018: AGV01 is online
[DEBUG]2021-05-26 12:07:28,899: GET: http://127.0.0.1:8999/api/agv/init?appName=akmTask addr: 127.0.0.1
[INFO]2021-05-26 12:07:28,900: akmTask init client agvApi
[DEBUG]2021-05-26 12:07:28,902: used 3ms 200 OK application/json;charset=utf-8, GET: http://127.0.0.1:8999/api/agv/init?appName=akmTask
[DEBUG]2021-05-26 12:07:31,970: GET: http://127.0.0.1:8999/api/agv/startCharge?appName=akmTask addr: 127.0.0.1
[DEBUG]2021-05-26 12:07:32,000: used 30ms 200 OK application/json;charset=utf-8, GET: http://127.0.0.1:8999/api/agv/startCharge?appName=akmTask
[WARN]2021-05-26 12:07:32,089: timer_thread[tid:1296] <locked _thread.RLock object owner=1296 count=1 at 0x00000239F862AEB8> ,hold 8206 ms
[INFO]2021-05-26 12:07:32,197: name=timer_thread, pid=1764, tid=1296
[01] File "C:/Users/comba/AppData/Local/Programs/Python/Python37/lib/threading.py", line 865, in run() 
[02] File "C:/Users/comba/Desktop/KLC/knowledgeCity/common/mytimer.py", line 113, in _loop() 
[03] File "C:/Users/comba/Desktop/KLC/knowledgeCity/common/lock.py", line 124, in _call() 
[04] File "C:/Users/comba/Desktop/KLC/knowledgeCity/common/lock.py", line 102, in release() 
[05] File "C:/Users/comba/Desktop/KLC/knowledgeCity/common/enhance.py", line 268, in getTrace() 
[06] File "C:/Users/comba/Desktop/KLC/knowledgeCity/common/enhance.py", line 248, in getThreadStack()
[DEBUG]2021-05-26 12:07:33,542: send http_get: http://127.0.0.1:8999/api/remoteio/readDOList?id=upStation01
[DEBUG]2021-05-26 12:07:33,746: [return] use 204 ms,http_get: http://127.0.0.1:8999/api/remoteio/readDOList?id=upStation01
[DEBUG]2021-05-26 12:07:33,770: send http_get: http://127.0.0.1:8999/api/remoteio/readDOList?id=downStation01
[ERROR]2021-05-26 12:07:33,903: connect AGVdiniu failed timed out
[ERROR]2021-05-26 12:07:33,909: connect AGVwuliao failed timed out
[DEBUG]2021-05-26 12:07:33,940: try connect AGVdiniu 172.16.217.121:19204
[DEBUG]2021-05-26 12:07:33,970: try connect AGVwuliao 172.16.217.211:19204
[DEBUG]2021-05-26 12:07:34,494: [return] use 724 ms,http_get: http://127.0.0.1:8999/api/remoteio/readDOList?id=downStation01
[INFO]2021-05-26 12:07:34,512: init IO success
[DEBUG]2021-05-26 12:07:34,559: send http_get: http://127.0.0.1:8999/api/remoteio/readDOList?id=upStation01
[DEBUG]2021-05-26 12:07:34,671: [return] use 112 ms,http_get: http://127.0.0.1:8999/api/remoteio/readDOList?id=upStation01
[DEBUG]2021-05-26 12:07:34,721: send http_get: http://127.0.0.1:8999/api/remoteio/readDOList?id=downStation01
[DEBUG]2021-05-26 12:07:34,876: [return] use 155 ms,http_get: http://127.0.0.1:8999/api/remoteio/readDOList?id=downStation01
[INFO]2021-05-26 12:07:34,900: AAS产线 upStation01 [0, 0, 0, 0, 0, 0, 0, 0] downStation01 [1, 0, 0, 0, 1, 0, 0, 0]
[DEBUG]2021-05-26 12:07:37,066: send http_get: http://127.0.0.1:8999/api/remoteio/readDOList?id=upStation01
[DEBUG]2021-05-26 12:07:37,426: [return] use 360 ms,http_get: http://127.0.0.1:8999/api/remoteio/readDOList?id=upStation01
[DEBUG]2021-05-26 12:07:37,450: send http_get: http://127.0.0.1:8999/api/remoteio/readDOList?id=downStation01
[DEBUG]2021-05-26 12:07:37,610: [return] use 160 ms,http_get: http://127.0.0.1:8999/api/remoteio/readDOList?id=downStation01
[INFO]2021-05-26 12:07:37,634: AAS产线 upStation01 [0, 0, 0, 0, 0, 0, 0, 0] downStation01 [1, 0, 0, 0, 1, 0, 0, 0]
[INFO]2021-05-26 12:07:38,686: remoteio is alarm: []
[DEBUG]2021-05-26 12:07:39,765: send http_get: http://127.0.0.1:8999/api/remoteio/readDOList?id=upStation01
[WARN]2021-05-26 12:07:43,786: agvThread.AGV01[tid:864] <lock name:agv.AGV01.lock_status,<locked _thread.RLock object owner=864 count=1 at 0x00000239F9BB1A80>> ,hold 5801 ms
[INFO]2021-05-26 12:07:43,871: name=agvThread.AGV01, pid=1764, tid=864
[01] File "C:/Users/comba/AppData/Local/Programs/Python/Python37/lib/threading.py", line 865, in run() 
[02] File "C:/Users/comba/Desktop/KLC/knowledgeCity/agvCtrl/agvList.py", line 574, in run() 
[03] File "C:/Users/comba/Desktop/KLC/knowledgeCity/agvCtrl/agvList.py", line 865, in readStatus1() 
[04] File "C:/Users/comba/Desktop/KLC/knowledgeCity/agvCtrl/agvList.py", line 845, in _readStatus1() 
[05] File "../driver/seerAgv/agvCtrl.py", line 846, in readStatus1() 
[06] File "../driver/seerAgv/agvApi.py", line 196, in status() 
[07] File "../driver/seerAgv/agvApi.py", line 255, in _handle() 
[08] File "C:/Users/comba/Desktop/KLC/knowledgeCity/common/lock.py", line 102, in release() 
[09] File "C:/Users/comba/Desktop/KLC/knowledgeCity/common/enhance.py", line 268, in getTrace() 
[10] File "C:/Users/comba/Desktop/KLC/knowledgeCity/common/enhance.py", line 248, in getThreadStack()
[ERROR]2021-05-26 12:07:44,032: connect AGVdiniu failed timed out
[ERROR]2021-05-26 12:07:44,062: connect AGVwuliao failed timed out
[INFO]2021-05-26 12:07:44,068: AGVdiniu checkLink failed 172.16.217.121 19204
[INFO]2021-05-26 12:07:44,104: AGVwuliao checkLink failed 172.16.217.211 19204
[WARN]2021-05-26 12:07:44,116: agvThread.AGVdiniu[tid:11840] <lock name:agv.AGVdiniu.lock_status,<locked _thread.RLock object owner=11840 count=1 at 0x00000239F9BB1C88>> ,hold 20216 ms
[WARN]2021-05-26 12:07:44,158: agvThread.AGVwuliao[tid:6388] <lock name:agv.AGVwuliao.lock_status,<locked _thread.RLock object owner=6388 count=1 at 0x00000239F9BB1F30>> ,hold 20254 ms
[INFO]2021-05-26 12:07:44,248: name=agvThread.AGVdiniu, pid=1764, tid=11840
[01] File "C:/Users/comba/AppData/Local/Programs/Python/Python37/lib/threading.py", line 865, in run() 
[02] File "C:/Users/comba/Desktop/KLC/knowledgeCity/agvCtrl/agvList.py", line 566, in run() 
[03] File "../driver/seerAgv/agvCtrl.py", line 36, in checkLink() 
[04] File "../driver/seerAgv/agvApi.py", line 185, in checkLink() 
[05] File "C:/Users/comba/Desktop/KLC/knowledgeCity/common/lock.py", line 102, in release() 
[06] File "C:/Users/comba/Desktop/KLC/knowledgeCity/common/enhance.py", line 268, in getTrace() 
[07] File "C:/Users/comba/Desktop/KLC/knowledgeCity/common/enhance.py", line 248, in getThreadStack()
[INFO]2021-05-26 12:07:44,301: name=agvThread.AGVwuliao, pid=1764, tid=6388
[01] File "C:/Users/comba/AppData/Local/Programs/Python/Python37/lib/threading.py", line 865, in run() 
[02] File "C:/Users/comba/Desktop/KLC/knowledgeCity/agvCtrl/agvList.py", line 566, in run() 
[03] File "../driver/seerAgv/agvCtrl.py", line 36, in checkLink() 
[04] File "../driver/seerAgv/agvApi.py", line 185, in checkLink() 
[05] File "C:/Users/comba/Desktop/KLC/knowledgeCity/common/lock.py", line 102, in release() 
[06] File "C:/Users/comba/Desktop/KLC/knowledgeCity/common/enhance.py", line 268, in getTrace() 
[07] File "C:/Users/comba/Desktop/KLC/knowledgeCity/common/enhance.py", line 248, in getThreadStack()
[DEBUG]2021-05-26 12:07:46,296: try connect AGVdiniu 172.16.217.121:19204
[DEBUG]2021-05-26 12:07:46,337: try connect AGVwuliao 172.16.217.211:19204
[WARN]2021-05-26 12:07:46,613: agvThread.AGVchache[tid:1484] <lock name:agv.AGVchache.lock_status,<locked _thread.RLock object owner=1484 count=1 at 0x00000239F9BB1440>> ,hold 10083 ms
[INFO]2021-05-26 12:07:46,714: name=agvThread.AGVchache, pid=1764, tid=1484
[01] File "C:/Users/comba/AppData/Local/Programs/Python/Python37/lib/threading.py", line 865, in run() 
[02] File "C:/Users/comba/Desktop/KLC/knowledgeCity/agvCtrl/agvList.py", line 574, in run() 
[03] File "C:/Users/comba/Desktop/KLC/knowledgeCity/agvCtrl/agvList.py", line 865, in readStatus1() 
[04] File "C:/Users/comba/Desktop/KLC/knowledgeCity/agvCtrl/agvList.py", line 845, in _readStatus1() 
[05] File "../driver/seerAgv/agvCtrl.py", line 846, in readStatus1() 
[06] File "../driver/seerAgv/agvApi.py", line 196, in status() 
[07] File "../driver/seerAgv/agvApi.py", line 255, in _handle() 
[08] File "C:/Users/comba/Desktop/KLC/knowledgeCity/common/lock.py", line 102, in release() 
[09] File "C:/Users/comba/Desktop/KLC/knowledgeCity/common/enhance.py", line 268, in getTrace() 
[10] File "C:/Users/comba/Desktop/KLC/knowledgeCity/common/enhance.py", line 248, in getThreadStack()
[WARN]2021-05-26 12:07:51,621: agvThread.AGVchache[tid:1484] <lock name:agv.AGVchache.lock_status,<locked _thread.RLock object owner=1484 count=1 at 0x00000239F9BB1440>> ,hold 4367 ms
[INFO]2021-05-26 12:07:51,687: name=agvThread.AGVchache, pid=1764, tid=1484
[01] File "C:/Users/comba/AppData/Local/Programs/Python/Python37/lib/threading.py", line 865, in run() 
[02] File "C:/Users/comba/Desktop/KLC/knowledgeCity/agvCtrl/agvList.py", line 574, in run() 
[03] File "C:/Users/comba/Desktop/KLC/knowledgeCity/agvCtrl/agvList.py", line 865, in readStatus1() 
[04] File "C:/Users/comba/Desktop/KLC/knowledgeCity/agvCtrl/agvList.py", line 845, in _readStatus1() 
[05] File "../driver/seerAgv/agvCtrl.py", line 846, in readStatus1() 
[06] File "../driver/seerAgv/agvApi.py", line 196, in status() 
[07] File "../driver/seerAgv/agvApi.py", line 255, in _handle() 
[08] File "C:/Users/comba/Desktop/KLC/knowledgeCity/common/lock.py", line 102, in release() 
[09] File "C:/Users/comba/Desktop/KLC/knowledgeCity/common/enhance.py", line 268, in getTrace() 
[10] File "C:/Users/comba/Desktop/KLC/knowledgeCity/common/enhance.py", line 248, in getThreadStack()
[WARN]2021-05-26 12:07:54,417: agvThread.AGV01[tid:864] <lock name:agv.AGV01.lock_status,<locked _thread.RLock object owner=864 count=1 at 0x00000239F9BB1A80>> ,hold 10008 ms
[INFO]2021-05-26 12:07:54,489: name=agvThread.AGV01, pid=1764, tid=864
[01] File "C:/Users/comba/AppData/Local/Programs/Python/Python37/lib/threading.py", line 865, in run() 
[02] File "C:/Users/comba/Desktop/KLC/knowledgeCity/agvCtrl/agvList.py", line 574, in run() 
[03] File "C:/Users/comba/Desktop/KLC/knowledgeCity/agvCtrl/agvList.py", line 865, in readStatus1() 
[04] File "C:/Users/comba/Desktop/KLC/knowledgeCity/agvCtrl/agvList.py", line 845, in _readStatus1() 
[05] File "../driver/seerAgv/agvCtrl.py", line 846, in readStatus1() 
[06] File "../driver/seerAgv/agvApi.py", line 196, in status() 
[07] File "../driver/seerAgv/agvApi.py", line 255, in _handle() 
[08] File "C:/Users/comba/Desktop/KLC/knowledgeCity/common/lock.py", line 102, in release() 
[09] File "C:/Users/comba/Desktop/KLC/knowledgeCity/common/enhance.py", line 268, in getTrace() 
[10] File "C:/Users/comba/Desktop/KLC/knowledgeCity/common/enhance.py", line 248, in getThreadStack()
[CRITICAL]2021-05-26 12:07:55,005: readDIList error cause a error: ('http get', 'http://127.0.0.1:8999/api/remoteio/readDOList', {'id': 'upStation01'}, 'error:', 'timed out')
pid=1764, ppid=10836, tid=1296
Traceback (most recent call last):
  File "C:\Users\comba\Desktop\KLC\knowledgeCity\common\webutility.py", line 103, in http_get
    f = urllib.request.urlopen(u,timeout=timeout)
  File "C:\Users\comba\AppData\Local\Programs\Python\Python37\lib\urllib\request.py", line 222, in urlopen
    return opener.open(url, data, timeout)
  File "C:\Users\comba\AppData\Local\Programs\Python\Python37\lib\urllib\request.py", line 525, in open
    response = self._open(req, data)
  File "C:\Users\comba\AppData\Local\Programs\Python\Python37\lib\urllib\request.py", line 543, in _open
    '_open', req)
  File "C:\Users\comba\AppData\Local\Programs\Python\Python37\lib\urllib\request.py", line 503, in _call_chain
    result = func(*args)
  File "C:\Users\comba\AppData\Local\Programs\Python\Python37\lib\urllib\request.py", line 1345, in http_open
    return self.do_open(http.client.HTTPConnection, req)
  File "C:\Users\comba\AppData\Local\Programs\Python\Python37\lib\urllib\request.py", line 1320, in do_open
    r = h.getresponse()
  File "C:\Users\comba\AppData\Local\Programs\Python\Python37\lib\http\client.py", line 1321, in getresponse
    response.begin()
  File "C:\Users\comba\AppData\Local\Programs\Python\Python37\lib\http\client.py", line 296, in begin
    version, status, reason = self._read_status()
  File "C:\Users\comba\AppData\Local\Programs\Python\Python37\lib\http\client.py", line 257, in _read_status
    line = str(self.fp.readline(_MAXLINE + 1), "iso-8859-1")
  File "C:\Users\comba\AppData\Local\Programs\Python\Python37\lib\socket.py", line 589, in readinto
    return self._sock.recv_into(b)
socket.timeout: timed out

During handling of the above exception, another exception occurred:

Traceback (most recent call last):
  File "C:\Users\comba\Desktop\KLC\knowledgeCity\autoCtrl\deviceCtrl.py", line 71, in _monitorDevices
    s1 = ioApi.readDOList(devices[d]["io1"])["status"] #上板机
  File "..\remoteio\remoteioApi.py", line 73, in readDOList
    return _remoteio('/api/remoteio/readDOList', id, param)
  File "..\remoteio\remoteioApi.py", line 100, in _remoteio
    return http_get(url + apiurl, param)
  File "..\remoteio\remoteioApi.py", line 16, in http_get
    r = webutility.http_get(url, param)
  File "C:\Users\comba\Desktop\KLC\knowledgeCity\common\webutility.py", line 105, in http_get
    raise Exception("http get",url,params,"error:",str(e))
Exception: ('http get', 'http://127.0.0.1:8999/api/remoteio/readDOList', {'id': 'upStation01'}, 'error:', 'timed out')

[ERROR]2021-05-26 12:07:56,347: connect AGVdiniu failed timed out
[INFO]2021-05-26 12:07:56,371: AGVdiniu checkLink failed 172.16.217.121 19204
[WARN]2021-05-26 12:07:56,401: agvThread.AGVdiniu[tid:11840] <lock name:agv.AGVdiniu.lock_status,<locked _thread.RLock object owner=11840 count=1 at 0x00000239F9BB1C88>> ,hold 10105 ms
[ERROR]2021-05-26 12:07:56,406: connect AGVwuliao failed timed out
[INFO]2021-05-26 12:07:56,484: AGVwuliao checkLink failed 172.16.217.211 19204
[INFO]2021-05-26 12:07:56,490: name=agvThread.AGVdiniu, pid=1764, tid=11840
[01] File "C:/Users/comba/AppData/Local/Programs/Python/Python37/lib/threading.py", line 865, in run() 
[02] File "C:/Users/comba/Desktop/KLC/knowledgeCity/agvCtrl/agvList.py", line 566, in run() 
[03] File "../driver/seerAgv/agvCtrl.py", line 36, in checkLink() 
[04] File "../driver/seerAgv/agvApi.py", line 185, in checkLink() 
[05] File "C:/Users/comba/Desktop/KLC/knowledgeCity/common/lock.py", line 102, in release() 
[06] File "C:/Users/comba/Desktop/KLC/knowledgeCity/common/enhance.py", line 268, in getTrace() 
[07] File "C:/Users/comba/Desktop/KLC/knowledgeCity/common/enhance.py", line 248, in getThreadStack()
[WARN]2021-05-26 12:07:56,508: agvThread.AGVwuliao[tid:6388] <lock name:agv.AGVwuliao.lock_status,<locked _thread.RLock object owner=6388 count=1 at 0x00000239F9BB1F30>> ,hold 10171 ms
[INFO]2021-05-26 12:07:56,658: name=agvThread.AGVwuliao, pid=1764, tid=6388
[01] File "C:/Users/comba/AppData/Local/Programs/Python/Python37/lib/threading.py", line 865, in run() 
[02] File "C:/Users/comba/Desktop/KLC/knowledgeCity/agvCtrl/agvList.py", line 566, in run() 
[03] File "../driver/seerAgv/agvCtrl.py", line 36, in checkLink() 
[04] File "../driver/seerAgv/agvApi.py", line 185, in checkLink() 
[05] File "C:/Users/comba/Desktop/KLC/knowledgeCity/common/lock.py", line 102, in release() 
[06] File "C:/Users/comba/Desktop/KLC/knowledgeCity/common/enhance.py", line 268, in getTrace() 
[07] File "C:/Users/comba/Desktop/KLC/knowledgeCity/common/enhance.py", line 248, in getThreadStack()
[DEBUG]2021-05-26 12:07:57,109: send http_get: http://127.0.0.1:8999/api/remoteio/readDOList?id=upStation01
[DEBUG]2021-05-26 12:07:58,559: try connect AGVdiniu 172.16.217.121:19204
[DEBUG]2021-05-26 12:07:58,708: try connect AGVwuliao 172.16.217.211:19204
[CRITICAL]2021-05-26 12:07:58,879: [modbusApi: 172.16.167.221] execute fcode=1, addr=8256 exception:  cause a error: [WinError 10054] 远程主机强迫关闭了一个现有的连接。
pid=1764, ppid=10836, tid=3996
Traceback (most recent call last):
  File "C:\Users\comba\Desktop\KLC\knowledgeCity\common\modbusapi.py", line 35, in __execute
    data = self.master.execute(self.__salveId, fcode, start, quantity_of_x=num, output_value=value)
  File "C:\Users\comba\AppData\Local\Programs\Python\Python37\lib\site-packages\modbus_tk\utils.py", line 39, in new
    raise excpt
  File "C:\Users\comba\AppData\Local\Programs\Python\Python37\lib\site-packages\modbus_tk\utils.py", line 37, in new
    ret = fcn(*args, **kwargs)
  File "C:\Users\comba\AppData\Local\Programs\Python\Python37\lib\site-packages\modbus_tk\modbus.py", line 298, in execute
    response = self._recv(expected_length)
  File "C:\Users\comba\AppData\Local\Programs\Python\Python37\lib\site-packages\modbus_tk\modbus_tcp.py", line 216, in _recv
    rcv_byte = self._sock.recv(1)
ConnectionResetError: [WinError 10054] 远程主机强迫关闭了一个现有的连接。

[WARN]2021-05-26 12:07:58,939: worker 8[tid:3996] <locked _thread.RLock object owner=3996 count=1 at 0x00000239F8601AA8> ,hold 19091 ms
[INFO]2021-05-26 12:07:59,279: name=worker 8, pid=1764, tid=3996
[01] File "C:/Users/comba/AppData/Local/Programs/Python/Python37/lib/threading.py", line 865, in run() 
[02] File "C:/Users/comba/AppData/Local/Programs/Python/Python37/lib/site-packages/paste/httpserver.py", line 895, in worker_thread_callback() 
[03] File "C:/Users/comba/AppData/Local/Programs/Python/Python37/lib/site-packages/paste/httpserver.py", line 1069, in <lambda>() 
[04] File "C:/Users/comba/AppData/Local/Programs/Python/Python37/lib/site-packages/paste/httpserver.py", line 1085, in process_request_in_thread() 
[05] File "C:/Users/comba/AppData/Local/Programs/Python/Python37/lib/socketserver.py", line 357, in finish_request() 
[06] File "C:/Users/comba/AppData/Local/Programs/Python/Python37/lib/socketserver.py", line 717, in __init__() 
[07] File "C:/Users/comba/AppData/Local/Programs/Python/Python37/lib/site-packages/paste/httpserver.py", line 459, in handle() 
[08] File "C:/Users/comba/AppData/Local/Programs/Python/Python37/lib/http/server.py", line 426, in handle() 
[09] File "C:/Users/comba/AppData/Local/Programs/Python/Python37/lib/site-packages/paste/httpserver.py", line 454, in handle_one_request() 
[10] File "C:/Users/comba/AppData/Local/Programs/Python/Python37/lib/site-packages/paste/httpserver.py", line 304, in wsgi_execute() 
[11] File "C:/Users/comba/AppData/Local/Programs/Python/Python37/lib/site-packages/paste/translogger.py", line 69, in __call__() 
[12] File "C:/Users/comba/AppData/Local/Programs/Python/Python37/lib/site-packages/bottle.py", line 979, in __call__() 
[13] File "C:/Users/comba/AppData/Local/Programs/Python/Python37/lib/site-packages/bottle.py", line 954, in wsgi() 
[14] File "C:/Users/comba/AppData/Local/Programs/Python/Python37/lib/site-packages/bottle.py", line 862, in _handle() 
[15] File "C:/Users/comba/AppData/Local/Programs/Python/Python37/lib/site-packages/bottle.py", line 1742, in wrapper() 
[16] File "C:/Users/comba/Desktop/KLC/knowledgeCity/common/webutility.py", line 465, in _enable_cors() 
[17] File "C:/Users/comba/Desktop/KLC/knowledgeCity/common/webutility.py", line 481, in _enable_cors() 
[18] File "C:/Users/comba/Desktop/KLC/knowledgeCity/common/scadaUtility.py", line 45, in __call() 
[19] File "C:/Users/comba/Desktop/KLC/knowledgeCity/remoteio/main_remoteio.py", line 87, in urlReadDOList() 
[20] File "../remoteio/remoteioMgr.py", line 158, in readDOList() 
[21] File "../remoteio/remoteioMgr.py", line 262, in readDOList() 
[22] File "C:/Users/comba/Desktop/KLC/knowledgeCity/common/lock.py", line 124, in _call() 
[23] File "C:/Users/comba/Desktop/KLC/knowledgeCity/common/lock.py", line 102, in release() 
[24] File "C:/Users/comba/Desktop/KLC/knowledgeCity/common/enhance.py", line 268, in getTrace() 
[25] File "C:/Users/comba/Desktop/KLC/knowledgeCity/common/enhance.py", line 248, in getThreadStack()
[CRITICAL]2021-05-26 12:07:59,367: upStation01 readDIList fail cause a error: [WinError 10054] 远程主机强迫关闭了一个现有的连接。
pid=1764, ppid=10836, tid=3996
Traceback (most recent call last):
  File "..\remoteio\remoteioMgr.py", line 262, in readDOList
    return self._read(M30, IO_LENTH)
  File "C:\Users\comba\Desktop\KLC\knowledgeCity\common\lock.py", line 122, in _call
    return func(*p,**pp)
  File "..\remoteio\remoteioMgr.py", line 314, in _read
    s = self.master.read(mdef.READ_COILS,addr, length)
  File "C:\Users\comba\Desktop\KLC\knowledgeCity\common\modbusapi.py", line 45, in read
    return self.__execute(fcode, start, num)
  File "C:\Users\comba\Desktop\KLC\knowledgeCity\common\modbusapi.py", line 35, in __execute
    data = self.master.execute(self.__salveId, fcode, start, quantity_of_x=num, output_value=value)
  File "C:\Users\comba\AppData\Local\Programs\Python\Python37\lib\site-packages\modbus_tk\utils.py", line 39, in new
    raise excpt
  File "C:\Users\comba\AppData\Local\Programs\Python\Python37\lib\site-packages\modbus_tk\utils.py", line 37, in new
    ret = fcn(*args, **kwargs)
  File "C:\Users\comba\AppData\Local\Programs\Python\Python37\lib\site-packages\modbus_tk\modbus.py", line 298, in execute
    response = self._recv(expected_length)
  File "C:\Users\comba\AppData\Local\Programs\Python\Python37\lib\site-packages\modbus_tk\modbus_tcp.py", line 216, in _recv
    rcv_byte = self._sock.recv(1)
ConnectionResetError: [WinError 10054] 远程主机强迫关闭了一个现有的连接。

[CRITICAL]2021-05-26 12:07:59,467: invoke <function urlReadDOList at 0x00000239F711EF28> cause a error: [WinError 10054] 远程主机强迫关闭了一个现有的连接。
pid=1764, ppid=10836, tid=3996
Traceback (most recent call last):
  File "C:\Users\comba\Desktop\KLC\knowledgeCity\common\scadaUtility.py", line 45, in __call
    ret = func(*p,**pp)
  File "C:\Users\comba\Desktop\KLC\knowledgeCity\remoteio\main_remoteio.py", line 87, in urlReadDOList
    return ioMgr.readDOList(id)
  File "..\remoteio\remoteioMgr.py", line 158, in readDOList
    result=remoteioInfo.readDOList()
  File "..\remoteio\remoteioMgr.py", line 262, in readDOList
    return self._read(M30, IO_LENTH)
  File "C:\Users\comba\Desktop\KLC\knowledgeCity\common\lock.py", line 122, in _call
    return func(*p,**pp)
  File "..\remoteio\remoteioMgr.py", line 314, in _read
    s = self.master.read(mdef.READ_COILS,addr, length)
  File "C:\Users\comba\Desktop\KLC\knowledgeCity\common\modbusapi.py", line 45, in read
    return self.__execute(fcode, start, num)
  File "C:\Users\comba\Desktop\KLC\knowledgeCity\common\modbusapi.py", line 35, in __execute
    data = self.master.execute(self.__salveId, fcode, start, quantity_of_x=num, output_value=value)
  File "C:\Users\comba\AppData\Local\Programs\Python\Python37\lib\site-packages\modbus_tk\utils.py", line 39, in new
    raise excpt
  File "C:\Users\comba\AppData\Local\Programs\Python\Python37\lib\site-packages\modbus_tk\utils.py", line 37, in new
    ret = fcn(*args, **kwargs)
  File "C:\Users\comba\AppData\Local\Programs\Python\Python37\lib\site-packages\modbus_tk\modbus.py", line 298, in execute
    response = self._recv(expected_length)
  File "C:\Users\comba\AppData\Local\Programs\Python\Python37\lib\site-packages\modbus_tk\modbus_tcp.py", line 216, in _recv
    rcv_byte = self._sock.recv(1)
ConnectionResetError: [WinError 10054] 远程主机强迫关闭了一个现有的连接。

[WARN]2021-05-26 12:08:00,826: disconnect AGV01 172.16.217.209 19204
[WARN]2021-05-26 12:08:00,868: agvThread.AGV01[tid:864] <lock name:agv.AGV01.lock_status,<locked _thread.RLock object owner=864 count=1 at 0x00000239F9BB1A80>> ,hold 5845 ms
[INFO]2021-05-26 12:08:00,968: name=agvThread.AGV01, pid=1764, tid=864
[01] File "C:/Users/comba/AppData/Local/Programs/Python/Python37/lib/threading.py", line 865, in run() 
[02] File "C:/Users/comba/Desktop/KLC/knowledgeCity/agvCtrl/agvList.py", line 574, in run() 
[03] File "C:/Users/comba/Desktop/KLC/knowledgeCity/agvCtrl/agvList.py", line 865, in readStatus1() 
[04] File "C:/Users/comba/Desktop/KLC/knowledgeCity/agvCtrl/agvList.py", line 845, in _readStatus1() 
[05] File "../driver/seerAgv/agvCtrl.py", line 846, in readStatus1() 
[06] File "../driver/seerAgv/agvApi.py", line 196, in status() 
[07] File "../driver/seerAgv/agvApi.py", line 255, in _handle() 
[08] File "C:/Users/comba/Desktop/KLC/knowledgeCity/common/lock.py", line 102, in release() 
[09] File "C:/Users/comba/Desktop/KLC/knowledgeCity/common/enhance.py", line 268, in getTrace() 
[10] File "C:/Users/comba/Desktop/KLC/knowledgeCity/common/enhance.py", line 248, in getThreadStack()
[DEBUG]2021-05-26 12:08:01,507: try connect AGV01 172.16.217.209:19204
[INFO]2021-05-26 12:08:01,656: AGV01 connected 172.16.217.209 19204
[WARN]2021-05-26 12:08:01,871: agvThread.AGVchache[tid:1484] <lock name:agv.AGVchache.lock_status,<locked _thread.RLock object owner=1484 count=1 at 0x00000239F9BB1440>> ,hold 4571 ms
[INFO]2021-05-26 12:08:01,961: name=agvThread.AGVchache, pid=1764, tid=1484
[01] File "C:/Users/comba/AppData/Local/Programs/Python/Python37/lib/threading.py", line 865, in run() 
[02] File "C:/Users/comba/Desktop/KLC/knowledgeCity/agvCtrl/agvList.py", line 574, in run() 
[03] File "C:/Users/comba/Desktop/KLC/knowledgeCity/agvCtrl/agvList.py", line 865, in readStatus1() 
[04] File "C:/Users/comba/Desktop/KLC/knowledgeCity/agvCtrl/agvList.py", line 845, in _readStatus1() 
[05] File "../driver/seerAgv/agvCtrl.py", line 846, in readStatus1() 
[06] File "../driver/seerAgv/agvApi.py", line 196, in status() 
[07] File "../driver/seerAgv/agvApi.py", line 255, in _handle() 
[08] File "C:/Users/comba/Desktop/KLC/knowledgeCity/common/lock.py", line 102, in release() 
[09] File "C:/Users/comba/Desktop/KLC/knowledgeCity/common/enhance.py", line 268, in getTrace() 
[10] File "C:/Users/comba/Desktop/KLC/knowledgeCity/common/enhance.py", line 248, in getThreadStack()
[ERROR]2021-05-26 12:08:08,640: connect AGVdiniu failed timed out
[INFO]2021-05-26 12:08:08,682: AGVdiniu checkLink failed 172.16.217.121 19204
[WARN]2021-05-26 12:08:08,717: agvThread.AGVdiniu[tid:11840] <lock name:agv.AGVdiniu.lock_status,<locked _thread.RLock object owner=11840 count=1 at 0x00000239F9BB1C88>> ,hold 10158 ms
[INFO]2021-05-26 12:08:08,784: name=agvThread.AGVdiniu, pid=1764, tid=11840
[01] File "C:/Users/comba/AppData/Local/Programs/Python/Python37/lib/threading.py", line 865, in run() 
[02] File "C:/Users/comba/Desktop/KLC/knowledgeCity/agvCtrl/agvList.py", line 566, in run() 
[03] File "../driver/seerAgv/agvCtrl.py", line 36, in checkLink() 
[04] File "../driver/seerAgv/agvApi.py", line 185, in checkLink() 
[05] File "C:/Users/comba/Desktop/KLC/knowledgeCity/common/lock.py", line 102, in release() 
[06] File "C:/Users/comba/Desktop/KLC/knowledgeCity/common/enhance.py", line 268, in getTrace() 
[07] File "C:/Users/comba/Desktop/KLC/knowledgeCity/common/enhance.py", line 248, in getThreadStack()
[ERROR]2021-05-26 12:08:08,826: connect AGVwuliao failed timed out
[INFO]2021-05-26 12:08:08,862: AGVwuliao checkLink failed 172.16.217.211 19204
[WARN]2021-05-26 12:08:08,886: agvThread.AGVwuliao[tid:6388] <lock name:agv.AGVwuliao.lock_status,<locked _thread.RLock object owner=6388 count=1 at 0x00000239F9BB1F30>> ,hold 10178 ms
[INFO]2021-05-26 12:08:08,972: name=agvThread.AGVwuliao, pid=1764, tid=6388
[01] File "C:/Users/comba/AppData/Local/Programs/Python/Python37/lib/threading.py", line 865, in run() 
[02] File "C:/Users/comba/Desktop/KLC/knowledgeCity/agvCtrl/agvList.py", line 566, in run() 
[03] File "../driver/seerAgv/agvCtrl.py", line 36, in checkLink() 
[04] File "../driver/seerAgv/agvApi.py", line 185, in checkLink() 
[05] File "C:/Users/comba/Desktop/KLC/knowledgeCity/common/lock.py", line 102, in release() 
[06] File "C:/Users/comba/Desktop/KLC/knowledgeCity/common/enhance.py", line 268, in getTrace() 
[07] File "C:/Users/comba/Desktop/KLC/knowledgeCity/common/enhance.py", line 248, in getThreadStack()
[DEBUG]2021-05-26 12:08:10,831: try connect AGVdiniu 172.16.217.121:19204
[DEBUG]2021-05-26 12:08:11,013: try connect AGVwuliao 172.16.217.211:19204
[CRITICAL]2021-05-26 12:08:12,205: readDIList error cause a error: ('http get', 'http://127.0.0.1:8999/api/remoteio/readDOList', {'id': 'upStation01'}, 'error:', 'timed out')
pid=1764, ppid=10836, tid=1296
Traceback (most recent call last):
  File "C:\Users\comba\Desktop\KLC\knowledgeCity\common\webutility.py", line 103, in http_get
    f = urllib.request.urlopen(u,timeout=timeout)
  File "C:\Users\comba\AppData\Local\Programs\Python\Python37\lib\urllib\request.py", line 222, in urlopen
    return opener.open(url, data, timeout)
  File "C:\Users\comba\AppData\Local\Programs\Python\Python37\lib\urllib\request.py", line 525, in open
    response = self._open(req, data)
  File "C:\Users\comba\AppData\Local\Programs\Python\Python37\lib\urllib\request.py", line 543, in _open
    '_open', req)
  File "C:\Users\comba\AppData\Local\Programs\Python\Python37\lib\urllib\request.py", line 503, in _call_chain
    result = func(*args)
  File "C:\Users\comba\AppData\Local\Programs\Python\Python37\lib\urllib\request.py", line 1345, in http_open
    return self.do_open(http.client.HTTPConnection, req)
  File "C:\Users\comba\AppData\Local\Programs\Python\Python37\lib\urllib\request.py", line 1320, in do_open
    r = h.getresponse()
  File "C:\Users\comba\AppData\Local\Programs\Python\Python37\lib\http\client.py", line 1321, in getresponse
    response.begin()
  File "C:\Users\comba\AppData\Local\Programs\Python\Python37\lib\http\client.py", line 296, in begin
    version, status, reason = self._read_status()
  File "C:\Users\comba\AppData\Local\Programs\Python\Python37\lib\http\client.py", line 257, in _read_status
    line = str(self.fp.readline(_MAXLINE + 1), "iso-8859-1")
  File "C:\Users\comba\AppData\Local\Programs\Python\Python37\lib\socket.py", line 589, in readinto
    return self._sock.recv_into(b)
socket.timeout: timed out

During handling of the above exception, another exception occurred:

Traceback (most recent call last):
  File "C:\Users\comba\Desktop\KLC\knowledgeCity\autoCtrl\deviceCtrl.py", line 71, in _monitorDevices
    s1 = ioApi.readDOList(devices[d]["io1"])["status"] #上板机
  File "..\remoteio\remoteioApi.py", line 73, in readDOList
    return _remoteio('/api/remoteio/readDOList', id, param)
  File "..\remoteio\remoteioApi.py", line 100, in _remoteio
    return http_get(url + apiurl, param)
  File "..\remoteio\remoteioApi.py", line 16, in http_get
    r = webutility.http_get(url, param)
  File "C:\Users\comba\Desktop\KLC\knowledgeCity\common\webutility.py", line 105, in http_get
    raise Exception("http get",url,params,"error:",str(e))
Exception: ('http get', 'http://127.0.0.1:8999/api/remoteio/readDOList', {'id': 'upStation01'}, 'error:', 'timed out')

[INFO]2021-05-26 12:08:13,277: remoteio is alarm: []
[DEBUG]2021-05-26 12:08:14,393: send http_get: http://127.0.0.1:8999/api/remoteio/readDOList?id=upStation01
[WARN]2021-05-26 12:08:14,696: agvThread.AGVchache[tid:1484] <lock name:agv.AGVchache.lock_status,<locked _thread.RLock object owner=1484 count=1 at 0x00000239F9BB1440>> ,hold 10007 ms
[INFO]2021-05-26 12:08:14,768: name=agvThread.AGVchache, pid=1764, tid=1484
[01] File "C:/Users/comba/AppData/Local/Programs/Python/Python37/lib/threading.py", line 865, in run() 
[02] File "C:/Users/comba/Desktop/KLC/knowledgeCity/agvCtrl/agvList.py", line 574, in run() 
[03] File "C:/Users/comba/Desktop/KLC/knowledgeCity/agvCtrl/agvList.py", line 865, in readStatus1() 
[04] File "C:/Users/comba/Desktop/KLC/knowledgeCity/agvCtrl/agvList.py", line 845, in _readStatus1() 
[05] File "../driver/seerAgv/agvCtrl.py", line 846, in readStatus1() 
[06] File "../driver/seerAgv/agvApi.py", line 196, in status() 
[07] File "../driver/seerAgv/agvApi.py", line 255, in _handle() 
[08] File "C:/Users/comba/Desktop/KLC/knowledgeCity/common/lock.py", line 102, in release() 
[09] File "C:/Users/comba/Desktop/KLC/knowledgeCity/common/enhance.py", line 268, in getTrace() 
[10] File "C:/Users/comba/Desktop/KLC/knowledgeCity/common/enhance.py", line 248, in getThreadStack()
[WARN]2021-05-26 12:08:15,023: agvThread.AGV01[tid:864] <lock name:agv.AGV01.lock_status,<locked _thread.RLock object owner=864 count=1 at 0x00000239F9BB1A80>> ,hold 6886 ms
[INFO]2021-05-26 12:08:15,098: name=agvThread.AGV01, pid=1764, tid=864
[01] File "C:/Users/comba/AppData/Local/Programs/Python/Python37/lib/threading.py", line 865, in run() 
[02] File "C:/Users/comba/Desktop/KLC/knowledgeCity/agvCtrl/agvList.py", line 574, in run() 
[03] File "C:/Users/comba/Desktop/KLC/knowledgeCity/agvCtrl/agvList.py", line 865, in readStatus1() 
[04] File "C:/Users/comba/Desktop/KLC/knowledgeCity/agvCtrl/agvList.py", line 845, in _readStatus1() 
[05] File "../driver/seerAgv/agvCtrl.py", line 846, in readStatus1() 
[06] File "../driver/seerAgv/agvApi.py", line 196, in status() 
[07] File "../driver/seerAgv/agvApi.py", line 255, in _handle() 
[08] File "C:/Users/comba/Desktop/KLC/knowledgeCity/common/lock.py", line 102, in release() 
[09] File "C:/Users/comba/Desktop/KLC/knowledgeCity/common/enhance.py", line 268, in getTrace() 
[10] File "C:/Users/comba/Desktop/KLC/knowledgeCity/common/enhance.py", line 248, in getThreadStack()
[CRITICAL]2021-05-26 12:08:16,905: [modbusApi: 172.16.167.221] execute fcode=1, addr=8256 exception:  cause a error: [WinError 10060] 由于连接方在一段时间后没有正确答复或连接的主机没有反应，连接尝试失败。
pid=1764, ppid=10836, tid=6108
Traceback (most recent call last):
  File "C:\Users\comba\AppData\Local\Programs\Python\Python37\lib\site-packages\modbus_tk\modbus_tcp.py", line 199, in _send
    flush_socket(self._sock, 3)
  File "C:\Users\comba\AppData\Local\Programs\Python\Python37\lib\site-packages\modbus_tk\utils.py", line 52, in flush_socket
    i_socks = select.select(input_socks, input_socks, input_socks, 0.0)[0]
ValueError: file descriptor cannot be a negative integer (-1)

During handling of the above exception, another exception occurred:

Traceback (most recent call last):
  File "C:\Users\comba\Desktop\KLC\knowledgeCity\common\modbusapi.py", line 35, in __execute
    data = self.master.execute(self.__salveId, fcode, start, quantity_of_x=num, output_value=value)
  File "C:\Users\comba\AppData\Local\Programs\Python\Python37\lib\site-packages\modbus_tk\utils.py", line 39, in new
    raise excpt
  File "C:\Users\comba\AppData\Local\Programs\Python\Python37\lib\site-packages\modbus_tk\utils.py", line 37, in new
    ret = fcn(*args, **kwargs)
  File "C:\Users\comba\AppData\Local\Programs\Python\Python37\lib\site-packages\modbus_tk\modbus.py", line 292, in execute
    self._send(request)
  File "C:\Users\comba\AppData\Local\Programs\Python\Python37\lib\site-packages\modbus_tk\modbus_tcp.py", line 204, in _send
    self._do_open()
  File "C:\Users\comba\AppData\Local\Programs\Python\Python37\lib\site-packages\modbus_tk\modbus_tcp.py", line 173, in _do_open
    self._sock.connect((self._host, self._port))
TimeoutError: [WinError 10060] 由于连接方在一段时间后没有正确答复或连接的主机没有反应，连接尝试失败。

[WARN]2021-05-26 12:08:16,950: worker 9[tid:6108] <locked _thread.RLock object owner=6108 count=1 at 0x00000239F8601AA8> ,hold 19767 ms
[INFO]2021-05-26 12:08:17,088: name=worker 9, pid=1764, tid=6108
[01] File "C:/Users/comba/AppData/Local/Programs/Python/Python37/lib/threading.py", line 865, in run() 
[02] File "C:/Users/comba/AppData/Local/Programs/Python/Python37/lib/site-packages/paste/httpserver.py", line 895, in worker_thread_callback() 
[03] File "C:/Users/comba/AppData/Local/Programs/Python/Python37/lib/site-packages/paste/httpserver.py", line 1069, in <lambda>() 
[04] File "C:/Users/comba/AppData/Local/Programs/Python/Python37/lib/site-packages/paste/httpserver.py", line 1085, in process_request_in_thread() 
[05] File "C:/Users/comba/AppData/Local/Programs/Python/Python37/lib/socketserver.py", line 357, in finish_request() 
[06] File "C:/Users/comba/AppData/Local/Programs/Python/Python37/lib/socketserver.py", line 717, in __init__() 
[07] File "C:/Users/comba/AppData/Local/Programs/Python/Python37/lib/site-packages/paste/httpserver.py", line 459, in handle() 
[08] File "C:/Users/comba/AppData/Local/Programs/Python/Python37/lib/http/server.py", line 426, in handle() 
[09] File "C:/Users/comba/AppData/Local/Programs/Python/Python37/lib/site-packages/paste/httpserver.py", line 454, in handle_one_request() 
[10] File "C:/Users/comba/AppData/Local/Programs/Python/Python37/lib/site-packages/paste/httpserver.py", line 304, in wsgi_execute() 
[11] File "C:/Users/comba/AppData/Local/Programs/Python/Python37/lib/site-packages/paste/translogger.py", line 69, in __call__() 
[12] File "C:/Users/comba/AppData/Local/Programs/Python/Python37/lib/site-packages/bottle.py", line 979, in __call__() 
[13] File "C:/Users/comba/AppData/Local/Programs/Python/Python37/lib/site-packages/bottle.py", line 954, in wsgi() 
[14] File "C:/Users/comba/AppData/Local/Programs/Python/Python37/lib/site-packages/bottle.py", line 862, in _handle() 
[15] File "C:/Users/comba/AppData/Local/Programs/Python/Python37/lib/site-packages/bottle.py", line 1742, in wrapper() 
[16] File "C:/Users/comba/Desktop/KLC/knowledgeCity/common/webutility.py", line 465, in _enable_cors() 
[17] File "C:/Users/comba/Desktop/KLC/knowledgeCity/common/webutility.py", line 481, in _enable_cors() 
[18] File "C:/Users/comba/Desktop/KLC/knowledgeCity/common/scadaUtility.py", line 45, in __call() 
[19] File "C:/Users/comba/Desktop/KLC/knowledgeCity/remoteio/main_remoteio.py", line 87, in urlReadDOList() 
[20] File "../remoteio/remoteioMgr.py", line 158, in readDOList() 
[21] File "../remoteio/remoteioMgr.py", line 262, in readDOList() 
[22] File "C:/Users/comba/Desktop/KLC/knowledgeCity/common/lock.py", line 124, in _call() 
[23] File "C:/Users/comba/Desktop/KLC/knowledgeCity/common/lock.py", line 102, in release() 
[24] File "C:/Users/comba/Desktop/KLC/knowledgeCity/common/enhance.py", line 268, in getTrace() 
[25] File "C:/Users/comba/Desktop/KLC/knowledgeCity/common/enhance.py", line 248, in getThreadStack()
[CRITICAL]2021-05-26 12:08:17,235: invoke <function urlReadDOList at 0x00000239F711EF28> cause a error: 'NoneType' object has no attribute 'close'
pid=1764, ppid=10836, tid=6108
Traceback (most recent call last):
  File "C:\Users\comba\AppData\Local\Programs\Python\Python37\lib\site-packages\modbus_tk\modbus_tcp.py", line 199, in _send
    flush_socket(self._sock, 3)
  File "C:\Users\comba\AppData\Local\Programs\Python\Python37\lib\site-packages\modbus_tk\utils.py", line 52, in flush_socket
    i_socks = select.select(input_socks, input_socks, input_socks, 0.0)[0]
ValueError: file descriptor cannot be a negative integer (-1)

During handling of the above exception, another exception occurred:

Traceback (most recent call last):
  File "..\remoteio\remoteioMgr.py", line 262, in readDOList
    return self._read(M30, IO_LENTH)
  File "C:\Users\comba\Desktop\KLC\knowledgeCity\common\lock.py", line 122, in _call
    return func(*p,**pp)
  File "..\remoteio\remoteioMgr.py", line 314, in _read
    s = self.master.read(mdef.READ_COILS,addr, length)
  File "C:\Users\comba\Desktop\KLC\knowledgeCity\common\modbusapi.py", line 45, in read
    return self.__execute(fcode, start, num)
  File "C:\Users\comba\Desktop\KLC\knowledgeCity\common\modbusapi.py", line 35, in __execute
    data = self.master.execute(self.__salveId, fcode, start, quantity_of_x=num, output_value=value)
  File "C:\Users\comba\AppData\Local\Programs\Python\Python37\lib\site-packages\modbus_tk\utils.py", line 39, in new
    raise excpt
  File "C:\Users\comba\AppData\Local\Programs\Python\Python37\lib\site-packages\modbus_tk\utils.py", line 37, in new
    ret = fcn(*args, **kwargs)
  File "C:\Users\comba\AppData\Local\Programs\Python\Python37\lib\site-packages\modbus_tk\modbus.py", line 292, in execute
    self._send(request)
  File "C:\Users\comba\AppData\Local\Programs\Python\Python37\lib\site-packages\modbus_tk\modbus_tcp.py", line 204, in _send
    self._do_open()
  File "C:\Users\comba\AppData\Local\Programs\Python\Python37\lib\site-packages\modbus_tk\modbus_tcp.py", line 173, in _do_open
    self._sock.connect((self._host, self._port))
TimeoutError: [WinError 10060] 由于连接方在一段时间后没有正确答复或连接的主机没有反应，连接尝试失败。

During handling of the above exception, another exception occurred:

Traceback (most recent call last):
  File "C:\Users\comba\Desktop\KLC\knowledgeCity\common\scadaUtility.py", line 45, in __call
    ret = func(*p,**pp)
  File "C:\Users\comba\Desktop\KLC\knowledgeCity\remoteio\main_remoteio.py", line 87, in urlReadDOList
    return ioMgr.readDOList(id)
  File "..\remoteio\remoteioMgr.py", line 158, in readDOList
    result=remoteioInfo.readDOList()
  File "..\remoteio\remoteioMgr.py", line 264, in readDOList
    self.master.close()
AttributeError: 'NoneType' object has no attribute 'close'

[WARN]2021-05-26 12:08:20,683: agvThread.AGV01[tid:864] <lock name:agv.AGV01.lock_status,<locked _thread.RLock object owner=864 count=1 at 0x00000239F9BB1A80>> ,hold 5008 ms
[WARN]2021-05-26 12:08:20,786: worker 0[tid:7892] <locked _thread.RLock object owner=7892 count=1 at 0x00000239F8601AA8> ,hold 6321 ms
[INFO]2021-05-26 12:08:20,816: name=agvThread.AGV01, pid=1764, tid=864
[01] File "C:/Users/comba/AppData/Local/Programs/Python/Python37/lib/threading.py", line 865, in run() 
[02] File "C:/Users/comba/Desktop/KLC/knowledgeCity/agvCtrl/agvList.py", line 574, in run() 
[03] File "C:/Users/comba/Desktop/KLC/knowledgeCity/agvCtrl/agvList.py", line 865, in readStatus1() 
[04] File "C:/Users/comba/Desktop/KLC/knowledgeCity/agvCtrl/agvList.py", line 845, in _readStatus1() 
[05] File "../driver/seerAgv/agvCtrl.py", line 846, in readStatus1() 
[06] File "../driver/seerAgv/agvApi.py", line 196, in status() 
[07] File "../driver/seerAgv/agvApi.py", line 255, in _handle() 
[08] File "C:/Users/comba/Desktop/KLC/knowledgeCity/common/lock.py", line 102, in release() 
[09] File "C:/Users/comba/Desktop/KLC/knowledgeCity/common/enhance.py", line 268, in getTrace() 
[10] File "C:/Users/comba/Desktop/KLC/knowledgeCity/common/enhance.py", line 248, in getThreadStack()
[ERROR]2021-05-26 12:08:20,899: connect AGVdiniu failed timed out
[INFO]2021-05-26 12:08:20,905: name=worker 0, pid=1764, tid=7892
[01] File "C:/Users/comba/AppData/Local/Programs/Python/Python37/lib/threading.py", line 865, in run() 
[02] File "C:/Users/comba/AppData/Local/Programs/Python/Python37/lib/site-packages/paste/httpserver.py", line 895, in worker_thread_callback() 
[03] File "C:/Users/comba/AppData/Local/Programs/Python/Python37/lib/site-packages/paste/httpserver.py", line 1069, in <lambda>() 
[04] File "C:/Users/comba/AppData/Local/Programs/Python/Python37/lib/site-packages/paste/httpserver.py", line 1085, in process_request_in_thread() 
[05] File "C:/Users/comba/AppData/Local/Programs/Python/Python37/lib/socketserver.py", line 357, in finish_request() 
[06] File "C:/Users/comba/AppData/Local/Programs/Python/Python37/lib/socketserver.py", line 717, in __init__() 
[07] File "C:/Users/comba/AppData/Local/Programs/Python/Python37/lib/site-packages/paste/httpserver.py", line 459, in handle() 
[08] File "C:/Users/comba/AppData/Local/Programs/Python/Python37/lib/http/server.py", line 426, in handle() 
[09] File "C:/Users/comba/AppData/Local/Programs/Python/Python37/lib/site-packages/paste/httpserver.py", line 454, in handle_one_request() 
[10] File "C:/Users/comba/AppData/Local/Programs/Python/Python37/lib/site-packages/paste/httpserver.py", line 304, in wsgi_execute() 
[11] File "C:/Users/comba/AppData/Local/Programs/Python/Python37/lib/site-packages/paste/translogger.py", line 69, in __call__() 
[12] File "C:/Users/comba/AppData/Local/Programs/Python/Python37/lib/site-packages/bottle.py", line 979, in __call__() 
[13] File "C:/Users/comba/AppData/Local/Programs/Python/Python37/lib/site-packages/bottle.py", line 954, in wsgi() 
[14] File "C:/Users/comba/AppData/Local/Programs/Python/Python37/lib/site-packages/bottle.py", line 862, in _handle() 
[15] File "C:/Users/comba/AppData/Local/Programs/Python/Python37/lib/site-packages/bottle.py", line 1742, in wrapper() 
[16] File "C:/Users/comba/Desktop/KLC/knowledgeCity/common/webutility.py", line 465, in _enable_cors() 
[17] File "C:/Users/comba/Desktop/KLC/knowledgeCity/common/webutility.py", line 481, in _enable_cors() 
[18] File "C:/Users/comba/Desktop/KLC/knowledgeCity/common/scadaUtility.py", line 45, in __call() 
[19] File "C:/Users/comba/Desktop/KLC/knowledgeCity/remoteio/main_remoteio.py", line 87, in urlReadDOList() 
[20] File "../remoteio/remoteioMgr.py", line 158, in readDOList() 
[21] File "../remoteio/remoteioMgr.py", line 262, in readDOList() 
[22] File "C:/Users/comba/Desktop/KLC/knowledgeCity/common/lock.py", line 124, in _call() 
[23] File "C:/Users/comba/Desktop/KLC/knowledgeCity/common/lock.py", line 102, in release() 
[24] File "C:/Users/comba/Desktop/KLC/knowledgeCity/common/enhance.py", line 268, in getTrace() 
[25] File "C:/Users/comba/Desktop/KLC/knowledgeCity/common/enhance.py", line 248, in getThreadStack()
[INFO]2021-05-26 12:08:20,941: AGVdiniu checkLink failed 172.16.217.121 19204
[DEBUG]2021-05-26 12:08:21,010: [return] use 6617 ms,http_get: http://127.0.0.1:8999/api/remoteio/readDOList?id=upStation01
[WARN]2021-05-26 12:08:21,034: agvThread.AGVdiniu[tid:11840] <lock name:agv.AGVdiniu.lock_status,<locked _thread.RLock object owner=11840 count=1 at 0x00000239F9BB1C88>> ,hold 10203 ms
[DEBUG]2021-05-26 12:08:21,064: send http_get: http://127.0.0.1:8999/api/remoteio/readDOList?id=downStation01
[ERROR]2021-05-26 12:08:21,086: connect AGVwuliao failed timed out
[INFO]2021-05-26 12:08:21,137: name=agvThread.AGVdiniu, pid=1764, tid=11840
[01] File "C:/Users/comba/AppData/Local/Programs/Python/Python37/lib/threading.py", line 865, in run() 
[02] File "C:/Users/comba/Desktop/KLC/knowledgeCity/agvCtrl/agvList.py", line 566, in run() 
[03] File "../driver/seerAgv/agvCtrl.py", line 36, in checkLink() 
[04] File "../driver/seerAgv/agvApi.py", line 185, in checkLink() 
[05] File "C:/Users/comba/Desktop/KLC/knowledgeCity/common/lock.py", line 102, in release() 
[06] File "C:/Users/comba/Desktop/KLC/knowledgeCity/common/enhance.py", line 268, in getTrace() 
[07] File "C:/Users/comba/Desktop/KLC/knowledgeCity/common/enhance.py", line 248, in getThreadStack()
[INFO]2021-05-26 12:08:21,213: AGVwuliao checkLink failed 172.16.217.211 19204
[WARN]2021-05-26 12:08:21,329: agvThread.AGVwuliao[tid:6388] <lock name:agv.AGVwuliao.lock_status,<locked _thread.RLock object owner=6388 count=1 at 0x00000239F9BB1F30>> ,hold 10316 ms
[INFO]2021-05-26 12:08:21,414: name=agvThread.AGVwuliao, pid=1764, tid=6388
[01] File "C:/Users/comba/AppData/Local/Programs/Python/Python37/lib/threading.py", line 865, in run() 
[02] File "C:/Users/comba/Desktop/KLC/knowledgeCity/agvCtrl/agvList.py", line 566, in run() 
[03] File "../driver/seerAgv/agvCtrl.py", line 36, in checkLink() 
[04] File "../driver/seerAgv/agvApi.py", line 185, in checkLink() 
[05] File "C:/Users/comba/Desktop/KLC/knowledgeCity/common/lock.py", line 102, in release() 
[06] File "C:/Users/comba/Desktop/KLC/knowledgeCity/common/enhance.py", line 268, in getTrace() 
[07] File "C:/Users/comba/Desktop/KLC/knowledgeCity/common/enhance.py", line 248, in getThreadStack()
[DEBUG]2021-05-26 12:08:22,505: [return] use 1441 ms,http_get: http://127.0.0.1:8999/api/remoteio/readDOList?id=downStation01
[INFO]2021-05-26 12:08:22,534: AAS产线 upStation01 [0, 0, 0, 0, 0, 0, 0, 0] downStation01 [1, 0, 0, 0, 1, 0, 0, 0]
[DEBUG]2021-05-26 12:08:23,269: try connect AGVdiniu 172.16.217.121:19204
[DEBUG]2021-05-26 12:08:23,444: try connect AGVwuliao 172.16.217.211:19204
[INFO]2021-05-26 12:08:23,599: remoteio is alarm: []
[DEBUG]2021-05-26 12:08:24,719: send http_get: http://127.0.0.1:8999/api/remoteio/readDOList?id=upStation01
[DEBUG]2021-05-26 12:08:24,917: [return] use 198 ms,http_get: http://127.0.0.1:8999/api/remoteio/readDOList?id=upStation01
[DEBUG]2021-05-26 12:08:24,931: send http_get: http://127.0.0.1:8999/api/remoteio/readDOList?id=downStation01
[DEBUG]2021-05-26 12:08:25,043: [return] use 112 ms,http_get: http://127.0.0.1:8999/api/remoteio/readDOList?id=downStation01
[INFO]2021-05-26 12:08:25,066: AAS产线 upStation01 [0, 0, 0, 0, 0, 0, 0, 0] downStation01 [1, 0, 0, 0, 1, 0, 0, 0]
[INFO]2021-05-26 12:08:26,142: remoteio is alarm: []
