[INFO]2021-01-25 15:50:29,490: log files at E:\python_work\knowledgeCity\common\log
[INFO]2021-01-25 15:50:29,490: find module agvCtrl.main_agv
[INFO]2021-01-25 15:50:29,490: find module agvDevice.main_agvDevice
[INFO]2021-01-25 15:50:29,491: find module alarm.main_alarm
[INFO]2021-01-25 15:50:29,491: find module auth.main_auth
[INFO]2021-01-25 15:50:29,491: find module autoCtrl.main_akmCtrl
[INFO]2021-01-25 15:50:29,492: find module door.main_door
[INFO]2021-01-25 15:50:29,492: find module elevator.main_elevator
[INFO]2021-01-25 15:50:29,492: find module remoteio.main_remoteio
[INFO]2021-01-25 15:50:29,492: import agvCtrl.main_agv
[INFO]2021-01-25 15:50:29,963: create lock <lock name:doorMgr.lock,<unlocked _thread.RLock object owner=0 count=0 at 0x00000266E1FAAAE0>>
[INFO]2021-01-25 15:50:29,966: create lock <lock name:door.lock,<unlocked _thread.RLock object owner=0 count=0 at 0x00000266E1FBC390>>
[INFO]2021-01-25 15:50:30,063: create lock <lock name:timer.lock_2640903896416,<unlocked _thread.RLock object owner=0 count=0 at 0x00000266E2237EA0>>
[ERROR]2021-01-25 15:50:30,079: mqtt is disabled
[INFO]2021-01-25 15:50:30,079: mqtt: subscribe [alarm/raise/+]
[INFO]2021-01-25 15:50:30,079: mqtt: subscribe [alarm/clear/+]
[INFO]2021-01-25 15:50:33,111: Mongodb connect to 127.0.0.1 port 27017
[INFO]2021-01-25 15:50:33,144: create lock <lock name:elevatorApi.tcp_lock,<unlocked _thread.RLock object owner=0 count=0 at 0x00000266E242C090>>
[INFO]2021-01-25 15:50:33,144: create lock <lock name:elevatorApi.g_lock,<unlocked _thread.RLock object owner=0 count=0 at 0x00000266E2425990>>
[INFO]2021-01-25 15:50:33,144: create lock <lock name:elevatorMgr.lock,<unlocked _thread.RLock object owner=0 count=0 at 0x00000266E2414DB0>>
[INFO]2021-01-25 15:50:33,158: create lock <lock name:agvserver,<unlocked _thread.RLock object owner=0 count=0 at 0x00000266E250D450>>
[INFO]2021-01-25 15:50:33,678: create lock <lock name:mapMgr.lock,<unlocked _thread.RLock object owner=0 count=0 at 0x00000266E24D8180>>
[INFO]2021-01-25 15:50:34,092: create lock <lock name:agvList.g_agvLock,<unlocked _thread.RLock object owner=0 count=0 at 0x00000266E2624ED0>>
[INFO]2021-01-25 15:50:34,096: create lock <lock name:taskList.lock,<unlocked _thread.RLock object owner=0 count=0 at 0x00000266E26E58D0>>
[INFO]2021-01-25 15:50:34,199: charge policy 0 , fix time
[INFO]2021-01-25 15:50:34,246: create lock <lock name:agvApi.g_lock,<unlocked _thread.RLock object owner=0 count=0 at 0x00000266E26EE4E0>>
[INFO]2021-01-25 15:50:34,334: start load map E:\python_work\knowledgeCity\agvCtrl\projects\knowledgeCity\comba-ZXC-F3.smap
[DEBUG]2021-01-25 15:50:34,426: elevator thread start
[INFO]2021-01-25 15:50:34,453: load map E:\python_work\knowledgeCity\agvCtrl\projects\knowledgeCity\comba-ZXC-F3.smap ,used 133 ms
[INFO]2021-01-25 15:50:34,466: start load map E:\python_work\knowledgeCity\agvCtrl\projects\knowledgeCity\office.smap
[INFO]2021-01-25 15:50:34,520: load map E:\python_work\knowledgeCity\agvCtrl\projects\knowledgeCity\office.smap ,used 67 ms
[INFO]2021-01-25 15:50:34,523: import agvDevice.main_agvDevice
[INFO]2021-01-25 15:50:34,524: import alarm.main_alarm
[INFO]2021-01-25 15:50:34,524: import auth.main_auth
[INFO]2021-01-25 15:50:34,537: import autoCtrl.main_akmCtrl
[INFO]2021-01-25 15:50:34,550: create lock <lock name:agvApi.g_lock,<unlocked _thread.RLock object owner=0 count=0 at 0x00000266E37621B0>>
[INFO]2021-01-25 15:50:34,557: create lock <lock name:IOAlarm.s_lock,<unlocked _thread.RLock object owner=0 count=0 at 0x00000266E37449C0>>
[INFO]2021-01-25 15:50:34,559: create lock <lock name:mapMgr.lock,<unlocked _thread.RLock object owner=0 count=0 at 0x00000266E378E4B0>>
[INFO]2021-01-25 15:50:35,661: import door.main_door
[INFO]2021-01-25 15:50:35,664: import elevator.main_elevator
[INFO]2021-01-25 15:50:35,664: import remoteio.main_remoteio
[SUCC]2021-01-25 15:50:35,709: utility start, pid=19072, ppid=18348
[DEBUG]2021-01-25 15:50:35,709: start timer
[DEBUG]2021-01-25 15:50:35,710: create aliveObj upStation01 远程控制IO离线异常 timeout 120
[DEBUG]2021-01-25 15:50:35,711: create aliveObj downStation01 远程控制IO离线异常 timeout 120
[INFO]2021-01-25 15:50:35,725: load agv file: E:\python_work\knowledgeCity\agvCtrl/projects/knowledgeCity/agv.cfg
[INFO]2021-01-25 15:50:35,725: create lock <lock name:agvList.AGV01.lock,<unlocked _thread.RLock object owner=0 count=0 at 0x00000266E9B1FE40>>
[DEBUG]2021-01-25 15:50:35,728: create aliveObj AGV01 AGV离线异常 timeout 300
[INFO]2021-01-25 15:50:35,728: AGV01 start agvList run thread
[INFO]2021-01-25 15:50:35,729: create lock <lock name:agv.AGV01.lock_status,<unlocked _thread.RLock object owner=0 count=0 at 0x00000266E9B23E10>>
[INFO]2021-01-25 15:50:35,729: AGV01 start agvList run2 thread
[DEBUG]2021-01-25 15:50:35,729: try connect AGV01 172.16.207.209:19204
[WARN]2021-01-25 15:50:35,733: Local server start! version 3.8.0, path E:\python_work\knowledgeCity\common, pid 19072
[INFO]2021-01-25 15:50:35,733: add_ignore: taskStatus
[DEBUG]2021-01-25 15:50:40,732: GET: http://127.0.0.1:8999/api/agv/init?appName=akmTask addr: 127.0.0.1
[INFO]2021-01-25 15:50:40,733: akmTask init client agvApi
[DEBUG]2021-01-25 15:50:40,734: used 2ms 200 OK application/json;charset=utf-8, GET: http://127.0.0.1:8999/api/agv/init?appName=akmTask
[WARN]2021-01-25 15:50:40,736: timer_thread[tid:18856] <locked _thread.RLock object owner=18856 count=1 at 0x00000266E374C330> ,hold 5016 ms
[INFO]2021-01-25 15:50:40,737: name=timer_thread, pid=19072, tid=18856
[01] File "D:/Python/Python38/lib/threading.py", line 870, in run() 
[02] File "E:/python_work/knowledgeCity/common/mytimer.py", line 113, in _loop() 
[03] File "E:/python_work/knowledgeCity/common/lock.py", line 124, in _call() 
[04] File "E:/python_work/knowledgeCity/common/lock.py", line 102, in release() 
[05] File "E:/python_work/knowledgeCity/common/enhance.py", line 268, in getTrace() 
[06] File "E:/python_work/knowledgeCity/common/enhance.py", line 248, in getThreadStack()
[DEBUG]2021-01-25 15:50:40,920: send http_get: http://127.0.0.1:8999/api/remoteio/readDOList?id=upStation01
[DEBUG]2021-01-25 15:50:41,142: [return] use 222 ms,http_get: http://127.0.0.1:8999/api/remoteio/readDOList?id=upStation01
[DEBUG]2021-01-25 15:50:41,142: send http_get: http://127.0.0.1:8999/api/remoteio/readDOList?id=downStation01
[ERROR]2021-01-25 15:50:45,731: connect AGV01 failed timed out
[DEBUG]2021-01-25 15:50:45,731: try connect AGV01 172.16.207.209:19204
[CRITICAL]2021-01-25 15:50:46,239: [modbusApi: 172.16.167.220] execute fcode=1, addr=8256 exception:  cause a error: timed out
pid=19072, ppid=18348, tid=17272
Traceback (most recent call last):
  File "E:\python_work\knowledgeCity\common\modbusapi.py", line 35, in __execute
    data = self.master.execute(self.__salveId, fcode, start, quantity_of_x=num, output_value=value)
  File "D:\Python\Python38\lib\site-packages\modbus_tk\utils.py", line 39, in new
    raise excpt
  File "D:\Python\Python38\lib\site-packages\modbus_tk\utils.py", line 37, in new
    ret = fcn(*args, **kwargs)
  File "D:\Python\Python38\lib\site-packages\modbus_tk\modbus.py", line 152, in execute
    self.open()
  File "D:\Python\Python38\lib\site-packages\modbus_tk\modbus.py", line 99, in open
    self._do_open()
  File "D:\Python\Python38\lib\site-packages\modbus_tk\modbus_tcp.py", line 173, in _do_open
    self._sock.connect((self._host, self._port))
socket.timeout: timed out

[WARN]2021-01-25 15:50:46,241: worker 2[tid:17272] <locked _thread.RLock object owner=17272 count=1 at 0x00000266E9B1FB10> ,hold 5047 ms
[INFO]2021-01-25 15:50:46,255: name=worker 2, pid=19072, tid=17272
[01] File "D:/Python/Python38/lib/threading.py", line 870, in run() 
[02] File "D:/Python/Python38/lib/site-packages/paste/httpserver.py", line 903, in worker_thread_callback() 
[03] File "D:/Python/Python38/lib/site-packages/paste/httpserver.py", line 1077, in <lambda>() 
[04] File "D:/Python/Python38/lib/site-packages/paste/httpserver.py", line 1092, in process_request_in_thread() 
[05] File "D:/Python/Python38/lib/socketserver.py", line 360, in finish_request() 
[06] File "D:/Python/Python38/lib/socketserver.py", line 720, in __init__() 
[07] File "D:/Python/Python38/lib/site-packages/paste/httpserver.py", line 460, in handle() 
[08] File "D:/Python/Python38/lib/http/server.py", line 426, in handle() 
[09] File "D:/Python/Python38/lib/site-packages/paste/httpserver.py", line 455, in handle_one_request() 
[10] File "D:/Python/Python38/lib/site-packages/paste/httpserver.py", line 304, in wsgi_execute() 
[11] File "D:/Python/Python38/lib/site-packages/paste/translogger.py", line 69, in __call__() 
[12] File "D:/Python/Python38/lib/site-packages/bottle.py", line 979, in __call__() 
[13] File "D:/Python/Python38/lib/site-packages/bottle.py", line 954, in wsgi() 
[14] File "D:/Python/Python38/lib/site-packages/bottle.py", line 862, in _handle() 
[15] File "D:/Python/Python38/lib/site-packages/bottle.py", line 1742, in wrapper() 
[16] File "E:/python_work/knowledgeCity/common/webutility.py", line 465, in _enable_cors() 
[17] File "E:/python_work/knowledgeCity/common/webutility.py", line 481, in _enable_cors() 
[18] File "E:/python_work/knowledgeCity/common/scadaUtility.py", line 45, in __call() 
[19] File "E:/python_work/knowledgeCity/remoteio/main_remoteio.py", line 87, in urlReadDOList() 
[20] File "E:/python_work/knowledgeCity/remoteio/remoteioMgr.py", line 158, in readDOList() 
[21] File "E:/python_work/knowledgeCity/remoteio/remoteioMgr.py", line 262, in readDOList() 
[22] File "E:/python_work/knowledgeCity/common/lock.py", line 124, in _call() 
[23] File "E:/python_work/knowledgeCity/common/lock.py", line 102, in release() 
[24] File "E:/python_work/knowledgeCity/common/enhance.py", line 268, in getTrace() 
[25] File "E:/python_work/knowledgeCity/common/enhance.py", line 248, in getThreadStack()
[CRITICAL]2021-01-25 15:50:46,276: downStation01 readDIList fail cause a error: timed out
pid=19072, ppid=18348, tid=17272
Traceback (most recent call last):
  File "E:\python_work\knowledgeCity\remoteio\remoteioMgr.py", line 262, in readDOList
    return self._read(M30, IO_LENTH)
  File "E:\python_work\knowledgeCity\common\lock.py", line 122, in _call
    return func(*p,**pp)
  File "E:\python_work\knowledgeCity\remoteio\remoteioMgr.py", line 314, in _read
    s = self.master.read(mdef.READ_COILS,addr, length)
  File "E:\python_work\knowledgeCity\common\modbusapi.py", line 45, in read
    return self.__execute(fcode, start, num)
  File "E:\python_work\knowledgeCity\common\modbusapi.py", line 35, in __execute
    data = self.master.execute(self.__salveId, fcode, start, quantity_of_x=num, output_value=value)
  File "D:\Python\Python38\lib\site-packages\modbus_tk\utils.py", line 39, in new
    raise excpt
  File "D:\Python\Python38\lib\site-packages\modbus_tk\utils.py", line 37, in new
    ret = fcn(*args, **kwargs)
  File "D:\Python\Python38\lib\site-packages\modbus_tk\modbus.py", line 152, in execute
    self.open()
  File "D:\Python\Python38\lib\site-packages\modbus_tk\modbus.py", line 99, in open
    self._do_open()
  File "D:\Python\Python38\lib\site-packages\modbus_tk\modbus_tcp.py", line 173, in _do_open
    self._sock.connect((self._host, self._port))
socket.timeout: timed out

[CRITICAL]2021-01-25 15:50:46,299: invoke <function urlReadDOList at 0x00000266E9B1E1F0> cause a error: timed out
pid=19072, ppid=18348, tid=17272
Traceback (most recent call last):
  File "E:\python_work\knowledgeCity\common\scadaUtility.py", line 45, in __call
    ret = func(*p,**pp)
  File "E:\python_work\knowledgeCity\remoteio\main_remoteio.py", line 87, in urlReadDOList
    return ioMgr.readDOList(id)
  File "E:\python_work\knowledgeCity\remoteio\remoteioMgr.py", line 158, in readDOList
    result=remoteioInfo.readDOList()
  File "E:\python_work\knowledgeCity\remoteio\remoteioMgr.py", line 262, in readDOList
    return self._read(M30, IO_LENTH)
  File "E:\python_work\knowledgeCity\common\lock.py", line 122, in _call
    return func(*p,**pp)
  File "E:\python_work\knowledgeCity\remoteio\remoteioMgr.py", line 314, in _read
    s = self.master.read(mdef.READ_COILS,addr, length)
  File "E:\python_work\knowledgeCity\common\modbusapi.py", line 45, in read
    return self.__execute(fcode, start, num)
  File "E:\python_work\knowledgeCity\common\modbusapi.py", line 35, in __execute
    data = self.master.execute(self.__salveId, fcode, start, quantity_of_x=num, output_value=value)
  File "D:\Python\Python38\lib\site-packages\modbus_tk\utils.py", line 39, in new
    raise excpt
  File "D:\Python\Python38\lib\site-packages\modbus_tk\utils.py", line 37, in new
    ret = fcn(*args, **kwargs)
  File "D:\Python\Python38\lib\site-packages\modbus_tk\modbus.py", line 152, in execute
    self.open()
  File "D:\Python\Python38\lib\site-packages\modbus_tk\modbus.py", line 99, in open
    self._do_open()
  File "D:\Python\Python38\lib\site-packages\modbus_tk\modbus_tcp.py", line 173, in _do_open
    self._sock.connect((self._host, self._port))
socket.timeout: timed out

[DEBUG]2021-01-25 15:50:46,302: [return] use 5160 ms,http_get: http://127.0.0.1:8999/api/remoteio/readDOList?id=downStation01
[CRITICAL]2021-01-25 15:50:46,323: downStation01 init failed cause a error: timeout: timed out
pid=19072, ppid=18348, tid=18856
Traceback (most recent call last):
  File "E:\python_work\knowledgeCity\autoCtrl\deviceCtrl.py", line 175, in _checkInit
    s = ioApi.readDOList(devices[d][ioId])["status"]
  File "E:\python_work\knowledgeCity\remoteio\remoteioApi.py", line 73, in readDOList
    return _remoteio('/api/remoteio/readDOList', id, param)
  File "E:\python_work\knowledgeCity\remoteio\remoteioApi.py", line 100, in _remoteio
    return http_get(url + apiurl, param)
  File "E:\python_work\knowledgeCity\remoteio\remoteioApi.py", line 19, in http_get
    raise Exception(result["errormsg"])
Exception: timeout: timed out

[INFO]2021-01-25 15:50:47,325: init IO success
[DEBUG]2021-01-25 15:50:47,325: send http_get: http://127.0.0.1:8999/api/remoteio/readDOList?id=upStation01
[DEBUG]2021-01-25 15:50:47,332: [return] use 7 ms,http_get: http://127.0.0.1:8999/api/remoteio/readDOList?id=upStation01
[DEBUG]2021-01-25 15:50:47,332: send http_get: http://127.0.0.1:8999/api/remoteio/readDOList?id=downStation01
[WARN]2021-01-25 15:50:52,344: worker 4[tid:16828] <locked _thread.RLock object owner=16828 count=1 at 0x00000266E9B1FB10> ,hold 5001 ms
[INFO]2021-01-25 15:50:52,345: name=worker 4, pid=19072, tid=16828
[01] File "D:/Python/Python38/lib/threading.py", line 870, in run() 
[02] File "D:/Python/Python38/lib/site-packages/paste/httpserver.py", line 903, in worker_thread_callback() 
[03] File "D:/Python/Python38/lib/site-packages/paste/httpserver.py", line 1077, in <lambda>() 
[04] File "D:/Python/Python38/lib/site-packages/paste/httpserver.py", line 1092, in process_request_in_thread() 
[05] File "D:/Python/Python38/lib/socketserver.py", line 360, in finish_request() 
[06] File "D:/Python/Python38/lib/socketserver.py", line 720, in __init__() 
[07] File "D:/Python/Python38/lib/site-packages/paste/httpserver.py", line 460, in handle() 
[08] File "D:/Python/Python38/lib/http/server.py", line 426, in handle() 
[09] File "D:/Python/Python38/lib/site-packages/paste/httpserver.py", line 455, in handle_one_request() 
[10] File "D:/Python/Python38/lib/site-packages/paste/httpserver.py", line 304, in wsgi_execute() 
[11] File "D:/Python/Python38/lib/site-packages/paste/translogger.py", line 69, in __call__() 
[12] File "D:/Python/Python38/lib/site-packages/bottle.py", line 979, in __call__() 
[13] File "D:/Python/Python38/lib/site-packages/bottle.py", line 954, in wsgi() 
[14] File "D:/Python/Python38/lib/site-packages/bottle.py", line 862, in _handle() 
[15] File "D:/Python/Python38/lib/site-packages/bottle.py", line 1742, in wrapper() 
[16] File "E:/python_work/knowledgeCity/common/webutility.py", line 465, in _enable_cors() 
[17] File "E:/python_work/knowledgeCity/common/webutility.py", line 481, in _enable_cors() 
[18] File "E:/python_work/knowledgeCity/common/scadaUtility.py", line 45, in __call() 
[19] File "E:/python_work/knowledgeCity/remoteio/main_remoteio.py", line 87, in urlReadDOList() 
[20] File "E:/python_work/knowledgeCity/remoteio/remoteioMgr.py", line 158, in readDOList() 
[21] File "E:/python_work/knowledgeCity/remoteio/remoteioMgr.py", line 262, in readDOList() 
[22] File "E:/python_work/knowledgeCity/common/lock.py", line 124, in _call() 
[23] File "E:/python_work/knowledgeCity/common/lock.py", line 102, in release() 
[24] File "E:/python_work/knowledgeCity/common/enhance.py", line 268, in getTrace() 
[25] File "E:/python_work/knowledgeCity/common/enhance.py", line 248, in getThreadStack()
[CRITICAL]2021-01-25 15:50:52,353: downStation01 readDIList fail cause a error: timed out
pid=19072, ppid=18348, tid=16828
Traceback (most recent call last):
  File "E:\python_work\knowledgeCity\remoteio\remoteioMgr.py", line 262, in readDOList
    return self._read(M30, IO_LENTH)
  File "E:\python_work\knowledgeCity\common\lock.py", line 122, in _call
    return func(*p,**pp)
  File "E:\python_work\knowledgeCity\remoteio\remoteioMgr.py", line 311, in _read
    self.master.open()
  File "E:\python_work\knowledgeCity\common\modbusapi.py", line 60, in open
    self.master.open()
  File "D:\Python\Python38\lib\site-packages\modbus_tk\modbus.py", line 99, in open
    self._do_open()
  File "D:\Python\Python38\lib\site-packages\modbus_tk\modbus_tcp.py", line 173, in _do_open
    self._sock.connect((self._host, self._port))
socket.timeout: timed out

[CRITICAL]2021-01-25 15:50:52,361: invoke <function urlReadDOList at 0x00000266E9B1E1F0> cause a error: timed out
pid=19072, ppid=18348, tid=16828
Traceback (most recent call last):
  File "E:\python_work\knowledgeCity\common\scadaUtility.py", line 45, in __call
    ret = func(*p,**pp)
  File "E:\python_work\knowledgeCity\remoteio\main_remoteio.py", line 87, in urlReadDOList
    return ioMgr.readDOList(id)
  File "E:\python_work\knowledgeCity\remoteio\remoteioMgr.py", line 158, in readDOList
    result=remoteioInfo.readDOList()
  File "E:\python_work\knowledgeCity\remoteio\remoteioMgr.py", line 262, in readDOList
    return self._read(M30, IO_LENTH)
  File "E:\python_work\knowledgeCity\common\lock.py", line 122, in _call
    return func(*p,**pp)
  File "E:\python_work\knowledgeCity\remoteio\remoteioMgr.py", line 311, in _read
    self.master.open()
  File "E:\python_work\knowledgeCity\common\modbusapi.py", line 60, in open
    self.master.open()
  File "D:\Python\Python38\lib\site-packages\modbus_tk\modbus.py", line 99, in open
    self._do_open()
  File "D:\Python\Python38\lib\site-packages\modbus_tk\modbus_tcp.py", line 173, in _do_open
    self._sock.connect((self._host, self._port))
socket.timeout: timed out

[DEBUG]2021-01-25 15:50:52,363: [return] use 5030 ms,http_get: http://127.0.0.1:8999/api/remoteio/readDOList?id=downStation01
[CRITICAL]2021-01-25 15:50:52,370: readDIList error cause a error: timeout: timed out
pid=19072, ppid=18348, tid=18856
Traceback (most recent call last):
  File "E:\python_work\knowledgeCity\autoCtrl\deviceCtrl.py", line 79, in _monitorDevices
    s2 = ioApi.readDOList(devices[d]["io2"])["status"] #上板机
  File "E:\python_work\knowledgeCity\remoteio\remoteioApi.py", line 73, in readDOList
    return _remoteio('/api/remoteio/readDOList', id, param)
  File "E:\python_work\knowledgeCity\remoteio\remoteioApi.py", line 100, in _remoteio
    return http_get(url + apiurl, param)
  File "E:\python_work\knowledgeCity\remoteio\remoteioApi.py", line 19, in http_get
    raise Exception(result["errormsg"])
Exception: timeout: timed out

[ERROR]2021-01-25 15:50:54,372: process exited, living 0:00:24.927020 seconds
[ERROR]2021-01-25 15:50:55,732: connect AGV01 failed timed out
[INFO]2021-01-25 15:50:55,732: AGV01 checkLink failed 172.16.207.209 19204
[WARN]2021-01-25 15:50:55,732: agvThread.AGV01[tid:11304] <lock name:agv.AGV01.lock_status,<locked _thread.RLock object owner=11304 count=1 at 0x00000266E9B23E10>> ,hold 20003 ms
[INFO]2021-01-25 15:50:55,733: name=agvThread.AGV01, pid=19072, tid=11304
[01] File "D:/Python/Python38/lib/threading.py", line 870, in run() 
[02] File "E:/python_work/knowledgeCity/agvCtrl/agvList.py", line 565, in run() 
[03] File "E:/python_work/knowledgeCity/driver/seerAgv/agvCtrl.py", line 36, in checkLink() 
[04] File "E:/python_work/knowledgeCity/driver/seerAgv/agvApi.py", line 184, in checkLink() 
[05] File "E:/python_work/knowledgeCity/common/lock.py", line 102, in release() 
[06] File "E:/python_work/knowledgeCity/common/enhance.py", line 268, in getTrace() 
[07] File "E:/python_work/knowledgeCity/common/enhance.py", line 248, in getThreadStack()
