[INFO]2021-05-08 16:42:39,199: log files at C:\Users\comba\Desktop\知识城地牛\knowledgeCity\common\log
[INFO]2021-05-08 16:42:39,200: find module agvCtrl.main_agv
[INFO]2021-05-08 16:42:39,200: find module agvDevice.main_agvDevice
[INFO]2021-05-08 16:42:39,200: find module alarm.main_alarm
[INFO]2021-05-08 16:42:39,201: find module auth.main_auth
[INFO]2021-05-08 16:42:39,201: find module autoCtrl.main_akmCtrl
[INFO]2021-05-08 16:42:39,201: find module door.main_door
[INFO]2021-05-08 16:42:39,202: find module elevator.main_elevator
[INFO]2021-05-08 16:42:39,202: find module feed.main_feed
[INFO]2021-05-08 16:42:39,207: find module remoteio.main_remoteio
[INFO]2021-05-08 16:42:39,208: import agvCtrl.main_agv
[INFO]2021-05-08 16:42:39,443: create lock <lock name:doorMgr.lock,<unlocked _thread.RLock object owner=0 count=0 at 0x000002029CE557B0>>
[INFO]2021-05-08 16:42:39,445: create lock <lock name:door.lock,<unlocked _thread.RLock object owner=0 count=0 at 0x000002029CE55918>>
[INFO]2021-05-08 16:42:39,494: create lock <lock name:timer.lock_2210247911352,<unlocked _thread.RLock object owner=0 count=0 at 0x000002029D09F440>>
[ERROR]2021-05-08 16:42:39,503: mqtt is disabled
[INFO]2021-05-08 16:42:39,503: mqtt: subscribe [alarm/raise/+]
[INFO]2021-05-08 16:42:39,505: mqtt: subscribe [alarm/clear/+]
[INFO]2021-05-08 16:42:42,524: Mongodb connect to 127.0.0.1 port 27017
[INFO]2021-05-08 16:42:42,556: create lock <lock name:elevatorApi.tcp_lock,<unlocked _thread.RLock object owner=0 count=0 at 0x000002029D268B48>>
[INFO]2021-05-08 16:42:42,558: create lock <lock name:elevatorApi.g_lock,<unlocked _thread.RLock object owner=0 count=0 at 0x000002029D268788>>
[INFO]2021-05-08 16:42:42,559: create lock <lock name:elevatorMgr.lock,<unlocked _thread.RLock object owner=0 count=0 at 0x000002029D268300>>
[INFO]2021-05-08 16:42:42,569: create lock <lock name:agvserver,<unlocked _thread.RLock object owner=0 count=0 at 0x000002029D3A2760>>
[INFO]2021-05-08 16:42:42,717: create lock <lock name:mapMgr.lock,<unlocked _thread.RLock object owner=0 count=0 at 0x000002029B62C198>>
[INFO]2021-05-08 16:42:42,924: create lock <lock name:agvList.g_agvLock,<unlocked _thread.RLock object owner=0 count=0 at 0x000002029D45DE40>>
[INFO]2021-05-08 16:42:42,927: create lock <lock name:taskList.lock,<unlocked _thread.RLock object owner=0 count=0 at 0x000002029D4A5F30>>
[INFO]2021-05-08 16:42:42,973: charge policy 0 , fix time
[INFO]2021-05-08 16:42:43,005: create lock <lock name:agvApi.g_lock,<unlocked _thread.RLock object owner=0 count=0 at 0x000002029D51B1C0>>
[INFO]2021-05-08 16:42:43,433: start load map C:\Users\comba\Desktop\知识城地牛\knowledgeCity\agvCtrl\projects\knowledgeCity\comba-ZSC-3F_0419.smap
[DEBUG]2021-05-08 16:42:43,512: elevator thread start
[INFO]2021-05-08 16:42:43,527: load map C:\Users\comba\Desktop\知识城地牛\knowledgeCity\agvCtrl\projects\knowledgeCity\comba-ZSC-3F_0419.smap ,used 101 ms
[INFO]2021-05-08 16:42:43,535: start load map C:\Users\comba\Desktop\知识城地牛\knowledgeCity\agvCtrl\projects\knowledgeCity\comba-ZSC-F1-F3.smap
[INFO]2021-05-08 16:42:43,678: load map C:\Users\comba\Desktop\知识城地牛\knowledgeCity\agvCtrl\projects\knowledgeCity\comba-ZSC-F1-F3.smap ,used 151 ms
[INFO]2021-05-08 16:42:43,687: start load map C:\Users\comba\Desktop\知识城地牛\knowledgeCity\agvCtrl\projects\knowledgeCity\comba-ZXC-3F.smap
[INFO]2021-05-08 16:42:43,766: load map C:\Users\comba\Desktop\知识城地牛\knowledgeCity\agvCtrl\projects\knowledgeCity\comba-ZXC-3F.smap ,used 86 ms
[INFO]2021-05-08 16:42:43,774: start load map C:\Users\comba\Desktop\知识城地牛\knowledgeCity\agvCtrl\projects\knowledgeCity\comba-ZXC-F3.smap
[INFO]2021-05-08 16:42:43,825: load map C:\Users\comba\Desktop\知识城地牛\knowledgeCity\agvCtrl\projects\knowledgeCity\comba-ZXC-F3.smap ,used 58 ms
[INFO]2021-05-08 16:42:43,834: start load map C:\Users\comba\Desktop\知识城地牛\knowledgeCity\agvCtrl\projects\knowledgeCity\office.smap
[INFO]2021-05-08 16:42:43,868: load map C:\Users\comba\Desktop\知识城地牛\knowledgeCity\agvCtrl\projects\knowledgeCity\office.smap ,used 41 ms
[INFO]2021-05-08 16:42:43,871: import agvDevice.main_agvDevice
[INFO]2021-05-08 16:42:43,872: import alarm.main_alarm
[INFO]2021-05-08 16:42:43,873: import auth.main_auth
[INFO]2021-05-08 16:42:43,880: import autoCtrl.main_akmCtrl
[INFO]2021-05-08 16:42:43,890: create lock <lock name:agvApi.g_lock,<unlocked _thread.RLock object owner=0 count=0 at 0x000002029D933418>>
[INFO]2021-05-08 16:42:43,896: create lock <lock name:runTasks.pre_lock,<unlocked _thread.RLock object owner=0 count=0 at 0x000002029D909648>>
[INFO]2021-05-08 16:42:43,916: create lock <lock name:IOAlarm.s_lock,<unlocked _thread.RLock object owner=0 count=0 at 0x000002029D909210>>
[INFO]2021-05-08 16:42:43,921: create lock <lock name:mapMgr.lock,<unlocked _thread.RLock object owner=0 count=0 at 0x000002029E0CE148>>
[INFO]2021-05-08 16:42:44,464: import door.main_door
[INFO]2021-05-08 16:42:44,466: import elevator.main_elevator
[INFO]2021-05-08 16:42:44,466: import feed.main_feed
[INFO]2021-05-08 16:42:44,472: create lock <lock name:feedTask.g_lock,<unlocked _thread.RLock object owner=0 count=0 at 0x000002029F8CF508>>
[INFO]2021-05-08 16:42:44,507: import remoteio.main_remoteio
[SUCC]2021-05-08 16:42:44,524: utility start, pid=7600, ppid=4848
[DEBUG]2021-05-08 16:42:44,524: start timer
[DEBUG]2021-05-08 16:42:44,524: create aliveObj upStation01 远程控制IO离线异常 timeout 120
[DEBUG]2021-05-08 16:42:44,527: create aliveObj downStation01 远程控制IO离线异常 timeout 120
[INFO]2021-05-08 16:42:44,533: load agv file: C:\Users\comba\Desktop\知识城地牛\knowledgeCity\agvCtrl/projects/knowledgeCity/agv.cfg
[INFO]2021-05-08 16:42:44,534: create lock <lock name:agvList.AGV01.lock,<unlocked _thread.RLock object owner=0 count=0 at 0x000002029F97B4B8>>
[DEBUG]2021-05-08 16:42:44,536: create aliveObj AGV01 AGV离线异常 timeout 300
[INFO]2021-05-08 16:42:44,537: AGV01 start agvList run thread
[INFO]2021-05-08 16:42:44,538: AGV01 start agvList run2 thread
[INFO]2021-05-08 16:42:44,538: create lock <lock name:agv.AGV01.lock_status,<unlocked _thread.RLock object owner=0 count=0 at 0x000002029F97BA08>>
[DEBUG]2021-05-08 16:42:44,540: try connect AGV01 172.16.217.209:19204
[INFO]2021-05-08 16:42:44,542: create lock <lock name:agvList.AGV03.lock,<unlocked _thread.RLock object owner=0 count=0 at 0x000002029F97B940>>
[DEBUG]2021-05-08 16:42:44,544: create aliveObj AGV03 AGV离线异常 timeout 300
[INFO]2021-05-08 16:42:44,545: AGV03 start agvList run thread
[INFO]2021-05-08 16:42:44,546: AGV03 start agvList run2 thread
[INFO]2021-05-08 16:42:44,546: create lock <lock name:agvList.AGV04.lock,<unlocked _thread.RLock object owner=0 count=0 at 0x000002029F97BBC0>>
[INFO]2021-05-08 16:42:44,546: create lock <lock name:agv.AGV03.lock_status,<unlocked _thread.RLock object owner=0 count=0 at 0x000002029F97BC10>>
[DEBUG]2021-05-08 16:42:44,549: try connect AGV03 172.16.217.121:19204
[DEBUG]2021-05-08 16:42:44,550: create aliveObj AGV04 AGV离线异常 timeout 300
[INFO]2021-05-08 16:42:44,551: AGV04 start agvList run thread
[INFO]2021-05-08 16:42:44,551: AGV04 start agvList run2 thread
[INFO]2021-05-08 16:42:44,551: create lock <lock name:agvList.AGV02.lock,<unlocked _thread.RLock object owner=0 count=0 at 0x000002029F97BE40>>
[INFO]2021-05-08 16:42:44,552: create lock <lock name:agv.AGV04.lock_status,<unlocked _thread.RLock object owner=0 count=0 at 0x000002029F97BE90>>
[DEBUG]2021-05-08 16:42:44,553: try connect AGV04 172.16.217.211:19204
[DEBUG]2021-05-08 16:42:44,554: create aliveObj AGV02 AGV离线异常 timeout 300
[INFO]2021-05-08 16:42:44,555: AGV02 start agvList run thread
[INFO]2021-05-08 16:42:44,555: AGV02 start agvList run2 thread
[WARN]2021-05-08 16:42:44,556: Local server start! version 3.7.0, path C:\Users\comba\Desktop\知识城地牛\knowledgeCity\common, pid 7600
[INFO]2021-05-08 16:42:44,556: create lock <lock name:agv.AGV02.lock_status,<unlocked _thread.RLock object owner=0 count=0 at 0x000002029F8CF5F8>>
[INFO]2021-05-08 16:42:44,557: add_ignore: taskStatus
[DEBUG]2021-05-08 16:42:44,557: try connect AGV02 172.16.217.213:19204
[INFO]2021-05-08 16:42:44,581: AGV04 connected 172.16.217.211 19204
[INFO]2021-05-08 16:42:44,582: create lock <lock name:agv.AGV04.lock_ctrl,<unlocked _thread.RLock object owner=0 count=0 at 0x000002029F97BFD0>>
[DEBUG]2021-05-08 16:42:44,583: try connect AGV04 172.16.217.211:19205
[INFO]2021-05-08 16:42:44,602: AGV04 connected 172.16.217.211 19205
[INFO]2021-05-08 16:42:44,603: create lock <lock name:agv.AGV04.lock_task,<unlocked _thread.RLock object owner=0 count=0 at 0x000002029C44EAD0>>
[DEBUG]2021-05-08 16:42:44,604: try connect AGV04 172.16.217.211:19206
[INFO]2021-05-08 16:42:44,612: AGV04 connected 172.16.217.211 19206
[INFO]2021-05-08 16:42:44,612: create lock <lock name:agv.AGV04.lock_conf,<unlocked _thread.RLock object owner=0 count=0 at 0x000002029C44EAA8>>
[DEBUG]2021-05-08 16:42:44,613: try connect AGV04 172.16.217.211:19207
[INFO]2021-05-08 16:42:44,632: AGV04 connected 172.16.217.211 19207
[INFO]2021-05-08 16:42:44,634: create lock <lock name:agv.AGV04.lock_core,<unlocked _thread.RLock object owner=0 count=0 at 0x000002029C44EA80>>
[DEBUG]2021-05-08 16:42:44,634: try connect AGV04 172.16.217.211:19208
[INFO]2021-05-08 16:42:44,645: AGV04 connected 172.16.217.211 19208
[INFO]2021-05-08 16:42:44,646: create lock <lock name:agv.AGV04.lock_other,<unlocked _thread.RLock object owner=0 count=0 at 0x000002029C44EBE8>>
[DEBUG]2021-05-08 16:42:44,646: try connect AGV04 172.16.217.211:19210
[INFO]2021-05-08 16:42:44,651: AGV04 connected 172.16.217.211 19210
[INFO]2021-05-08 16:42:44,670: AGV04 current map comba-ZXC-F3
[INFO]2021-05-08 16:42:44,718: AGV04 is online
[DEBUG]2021-05-08 16:42:49,540: GET: http://127.0.0.1:8999/api/agv/init?appName=akmTask addr: 127.0.0.1
[INFO]2021-05-08 16:42:49,542: akmTask init client agvApi
[DEBUG]2021-05-08 16:42:49,543: used 3ms 200 OK application/json;charset=utf-8, GET: http://127.0.0.1:8999/api/agv/init?appName=akmTask
[DEBUG]2021-05-08 16:42:52,648: GET: http://127.0.0.1:8999/api/agv/startCharge?appName=akmTask addr: 127.0.0.1
[DEBUG]2021-05-08 16:42:52,665: used 17ms 200 OK application/json;charset=utf-8, GET: http://127.0.0.1:8999/api/agv/startCharge?appName=akmTask
[WARN]2021-05-08 16:42:52,718: timer_thread[tid:10368] <locked _thread.RLock object owner=10368 count=1 at 0x000002029D909620> ,hold 8191 ms
[INFO]2021-05-08 16:42:52,835: name=timer_thread, pid=7600, tid=10368
[01] File "C:/Users/comba/AppData/Local/Programs/Python/Python37/lib/threading.py", line 865, in run() 
[02] File "C:/Users/comba/Desktop/知识城地牛/knowledgeCity/common/mytimer.py", line 113, in _loop() 
[03] File "C:/Users/comba/Desktop/知识城地牛/knowledgeCity/common/lock.py", line 124, in _call() 
[04] File "C:/Users/comba/Desktop/知识城地牛/knowledgeCity/common/lock.py", line 102, in release() 
[05] File "C:/Users/comba/Desktop/知识城地牛/knowledgeCity/common/enhance.py", line 268, in getTrace() 
[06] File "C:/Users/comba/Desktop/知识城地牛/knowledgeCity/common/enhance.py", line 248, in getThreadStack()
[WARN]2021-05-08 16:42:53,994: AGV04 low battery charge,batteryLevel= 0.252 start charge level= 0.400
[WARN]2021-05-08 16:42:54,009: AGV04 battery 0.252 check failed: no_idle_9.457
[DEBUG]2021-05-08 16:42:54,467: send http_get: http://127.0.0.1:8999/api/remoteio/readDOList?id=upStation01
[ERROR]2021-05-08 16:42:54,543: connect AGV01 failed timed out
[ERROR]2021-05-08 16:42:54,561: connect AGV02 failed timed out
[ERROR]2021-05-08 16:42:54,561: connect AGV03 failed timed out
[DEBUG]2021-05-08 16:42:54,624: try connect AGV01 172.16.217.209:19204
[DEBUG]2021-05-08 16:42:54,664: try connect AGV02 172.16.217.213:19204
[DEBUG]2021-05-08 16:42:54,699: try connect AGV03 172.16.217.121:19204
[ERROR]2021-05-08 16:43:04,764: connect AGV01 failed timed out
[ERROR]2021-05-08 16:43:04,794: connect AGV02 failed timed out
[INFO]2021-05-08 16:43:04,834: AGV01 checkLink failed 172.16.217.209 19204
[ERROR]2021-05-08 16:43:04,881: connect AGV03 failed timed out
[INFO]2021-05-08 16:43:04,887: AGV02 checkLink failed 172.16.217.213 19204
[WARN]2021-05-08 16:43:04,917: agvThread.AGV01[tid:13976] <lock name:agv.AGV01.lock_status,<locked _thread.RLock object owner=13976 count=1 at 0x000002029F97BA08>> ,hold 20377 ms
[INFO]2021-05-08 16:43:04,947: AGV03 checkLink failed 172.16.217.121 19204
[WARN]2021-05-08 16:43:04,964: agvThread.AGV02[tid:13684] <lock name:agv.AGV02.lock_status,<locked _thread.RLock object owner=13684 count=1 at 0x000002029F8CF5F8>> ,hold 20407 ms
[WARN]2021-05-08 16:43:05,039: agvThread.AGV03[tid:13128] <lock name:agv.AGV03.lock_status,<locked _thread.RLock object owner=13128 count=1 at 0x000002029F97BC10>> ,hold 20490 ms
[INFO]2021-05-08 16:43:05,050: name=agvThread.AGV01, pid=7600, tid=13976
[01] File "C:/Users/comba/AppData/Local/Programs/Python/Python37/lib/threading.py", line 865, in run() 
[02] File "C:/Users/comba/Desktop/知识城地牛/knowledgeCity/agvCtrl/agvList.py", line 565, in run() 
[03] File "../driver/seerAgv/agvCtrl.py", line 36, in checkLink() 
[04] File "../driver/seerAgv/agvApi.py", line 184, in checkLink() 
[05] File "C:/Users/comba/Desktop/知识城地牛/knowledgeCity/common/lock.py", line 102, in release() 
[06] File "C:/Users/comba/Desktop/知识城地牛/knowledgeCity/common/enhance.py", line 268, in getTrace() 
[07] File "C:/Users/comba/Desktop/知识城地牛/knowledgeCity/common/enhance.py", line 248, in getThreadStack()
[INFO]2021-05-08 16:43:05,165: name=agvThread.AGV02, pid=7600, tid=13684
[01] File "C:/Users/comba/AppData/Local/Programs/Python/Python37/lib/threading.py", line 865, in run() 
[02] File "C:/Users/comba/Desktop/知识城地牛/knowledgeCity/agvCtrl/agvList.py", line 565, in run() 
[03] File "../driver/seerAgv/agvCtrl.py", line 36, in checkLink() 
[04] File "../driver/seerAgv/agvApi.py", line 184, in checkLink() 
[05] File "C:/Users/comba/Desktop/知识城地牛/knowledgeCity/common/lock.py", line 102, in release() 
[06] File "C:/Users/comba/Desktop/知识城地牛/knowledgeCity/common/enhance.py", line 268, in getTrace() 
[07] File "C:/Users/comba/Desktop/知识城地牛/knowledgeCity/common/enhance.py", line 248, in getThreadStack()
[INFO]2021-05-08 16:43:05,188: name=agvThread.AGV03, pid=7600, tid=13128
[01] File "C:/Users/comba/AppData/Local/Programs/Python/Python37/lib/threading.py", line 865, in run() 
[02] File "C:/Users/comba/Desktop/知识城地牛/knowledgeCity/agvCtrl/agvList.py", line 565, in run() 
[03] File "../driver/seerAgv/agvCtrl.py", line 36, in checkLink() 
[04] File "../driver/seerAgv/agvApi.py", line 184, in checkLink() 
[05] File "C:/Users/comba/Desktop/知识城地牛/knowledgeCity/common/lock.py", line 102, in release() 
[06] File "C:/Users/comba/Desktop/知识城地牛/knowledgeCity/common/enhance.py", line 268, in getTrace() 
[07] File "C:/Users/comba/Desktop/知识城地牛/knowledgeCity/common/enhance.py", line 248, in getThreadStack()
[DEBUG]2021-05-08 16:43:07,213: try connect AGV01 172.16.217.209:19204
[DEBUG]2021-05-08 16:43:07,248: try connect AGV02 172.16.217.213:19204
[DEBUG]2021-05-08 16:43:07,290: try connect AGV03 172.16.217.121:19204
[CRITICAL]2021-05-08 16:43:09,947: upStation01 init failed cause a error: ('http get', 'http://127.0.0.1:8999/api/remoteio/readDOList', {'id': 'upStation01'}, 'error:', 'timed out')
pid=7600, ppid=4848, tid=10368
Traceback (most recent call last):
  File "C:\Users\comba\Desktop\知识城地牛\knowledgeCity\common\webutility.py", line 103, in http_get
    f = urllib.request.urlopen(u,timeout=timeout)
  File "C:\Users\comba\AppData\Local\Programs\Python\Python37\lib\urllib\request.py", line 222, in urlopen
    return opener.open(url, data, timeout)
  File "C:\Users\comba\AppData\Local\Programs\Python\Python37\lib\urllib\request.py", line 525, in open
    response = self._open(req, data)
  File "C:\Users\comba\AppData\Local\Programs\Python\Python37\lib\urllib\request.py", line 543, in _open
    '_open', req)
  File "C:\Users\comba\AppData\Local\Programs\Python\Python37\lib\urllib\request.py", line 503, in _call_chain
    result = func(*args)
  File "C:\Users\comba\AppData\Local\Programs\Python\Python37\lib\urllib\request.py", line 1345, in http_open
    return self.do_open(http.client.HTTPConnection, req)
  File "C:\Users\comba\AppData\Local\Programs\Python\Python37\lib\urllib\request.py", line 1320, in do_open
    r = h.getresponse()
  File "C:\Users\comba\AppData\Local\Programs\Python\Python37\lib\http\client.py", line 1321, in getresponse
    response.begin()
  File "C:\Users\comba\AppData\Local\Programs\Python\Python37\lib\http\client.py", line 296, in begin
    version, status, reason = self._read_status()
  File "C:\Users\comba\AppData\Local\Programs\Python\Python37\lib\http\client.py", line 257, in _read_status
    line = str(self.fp.readline(_MAXLINE + 1), "iso-8859-1")
  File "C:\Users\comba\AppData\Local\Programs\Python\Python37\lib\socket.py", line 589, in readinto
    return self._sock.recv_into(b)
socket.timeout: timed out

During handling of the above exception, another exception occurred:

Traceback (most recent call last):
  File "C:\Users\comba\Desktop\知识城地牛\knowledgeCity\autoCtrl\deviceCtrl.py", line 175, in _checkInit
    s = ioApi.readDOList(devices[d][ioId])["status"]
  File "..\remoteio\remoteioApi.py", line 73, in readDOList
    return _remoteio('/api/remoteio/readDOList', id, param)
  File "..\remoteio\remoteioApi.py", line 100, in _remoteio
    return http_get(url + apiurl, param)
  File "..\remoteio\remoteioApi.py", line 16, in http_get
    r = webutility.http_get(url, param)
  File "C:\Users\comba\Desktop\知识城地牛\knowledgeCity\common\webutility.py", line 105, in http_get
    raise Exception("http get",url,params,"error:",str(e))
Exception: ('http get', 'http://127.0.0.1:8999/api/remoteio/readDOList', {'id': 'upStation01'}, 'error:', 'timed out')

[DEBUG]2021-05-08 16:43:10,999: send http_get: http://127.0.0.1:8999/api/remoteio/readDOList?id=downStation01
[CRITICAL]2021-05-08 16:43:15,875: [modbusApi: 172.16.167.221] execute fcode=1, addr=8256 exception:  cause a error: [WinError 10060] 由于连接方在一段时间后没有正确答复或连接的主机没有反应，连接尝试失败。
pid=7600, ppid=4848, tid=13448
Traceback (most recent call last):
  File "C:\Users\comba\Desktop\知识城地牛\knowledgeCity\common\modbusapi.py", line 35, in __execute
    data = self.master.execute(self.__salveId, fcode, start, quantity_of_x=num, output_value=value)
  File "C:\Users\comba\AppData\Local\Programs\Python\Python37\lib\site-packages\modbus_tk\utils.py", line 39, in new
    raise excpt
  File "C:\Users\comba\AppData\Local\Programs\Python\Python37\lib\site-packages\modbus_tk\utils.py", line 37, in new
    ret = fcn(*args, **kwargs)
  File "C:\Users\comba\AppData\Local\Programs\Python\Python37\lib\site-packages\modbus_tk\modbus.py", line 152, in execute
    self.open()
  File "C:\Users\comba\AppData\Local\Programs\Python\Python37\lib\site-packages\modbus_tk\modbus.py", line 99, in open
    self._do_open()
  File "C:\Users\comba\AppData\Local\Programs\Python\Python37\lib\site-packages\modbus_tk\modbus_tcp.py", line 173, in _do_open
    self._sock.connect((self._host, self._port))
TimeoutError: [WinError 10060] 由于连接方在一段时间后没有正确答复或连接的主机没有反应，连接尝试失败。

[WARN]2021-05-08 16:43:15,929: worker 2[tid:13448] <locked _thread.RLock object owner=13448 count=1 at 0x000002029D8E0670> ,hold 21380 ms
[INFO]2021-05-08 16:43:16,619: name=worker 2, pid=7600, tid=13448
[01] File "C:/Users/comba/AppData/Local/Programs/Python/Python37/lib/threading.py", line 865, in run() 
[02] File "C:/Users/comba/AppData/Local/Programs/Python/Python37/lib/site-packages/paste/httpserver.py", line 895, in worker_thread_callback() 
[03] File "C:/Users/comba/AppData/Local/Programs/Python/Python37/lib/site-packages/paste/httpserver.py", line 1069, in <lambda>() 
[04] File "C:/Users/comba/AppData/Local/Programs/Python/Python37/lib/site-packages/paste/httpserver.py", line 1085, in process_request_in_thread() 
[05] File "C:/Users/comba/AppData/Local/Programs/Python/Python37/lib/socketserver.py", line 357, in finish_request() 
[06] File "C:/Users/comba/AppData/Local/Programs/Python/Python37/lib/socketserver.py", line 717, in __init__() 
[07] File "C:/Users/comba/AppData/Local/Programs/Python/Python37/lib/site-packages/paste/httpserver.py", line 459, in handle() 
[08] File "C:/Users/comba/AppData/Local/Programs/Python/Python37/lib/http/server.py", line 426, in handle() 
[09] File "C:/Users/comba/AppData/Local/Programs/Python/Python37/lib/site-packages/paste/httpserver.py", line 454, in handle_one_request() 
[10] File "C:/Users/comba/AppData/Local/Programs/Python/Python37/lib/site-packages/paste/httpserver.py", line 304, in wsgi_execute() 
[11] File "C:/Users/comba/AppData/Local/Programs/Python/Python37/lib/site-packages/paste/translogger.py", line 69, in __call__() 
[12] File "C:/Users/comba/AppData/Local/Programs/Python/Python37/lib/site-packages/bottle.py", line 979, in __call__() 
[13] File "C:/Users/comba/AppData/Local/Programs/Python/Python37/lib/site-packages/bottle.py", line 954, in wsgi() 
[14] File "C:/Users/comba/AppData/Local/Programs/Python/Python37/lib/site-packages/bottle.py", line 862, in _handle() 
[15] File "C:/Users/comba/AppData/Local/Programs/Python/Python37/lib/site-packages/bottle.py", line 1742, in wrapper() 
[16] File "C:/Users/comba/Desktop/知识城地牛/knowledgeCity/common/webutility.py", line 465, in _enable_cors() 
[17] File "C:/Users/comba/Desktop/知识城地牛/knowledgeCity/common/webutility.py", line 481, in _enable_cors() 
[18] File "C:/Users/comba/Desktop/知识城地牛/knowledgeCity/common/scadaUtility.py", line 45, in __call() 
[19] File "C:/Users/comba/Desktop/知识城地牛/knowledgeCity/remoteio/main_remoteio.py", line 87, in urlReadDOList() 
[20] File "../remoteio/remoteioMgr.py", line 158, in readDOList() 
[21] File "../remoteio/remoteioMgr.py", line 262, in readDOList() 
[22] File "C:/Users/comba/Desktop/知识城地牛/knowledgeCity/common/lock.py", line 124, in _call() 
[23] File "C:/Users/comba/Desktop/知识城地牛/knowledgeCity/common/lock.py", line 102, in release() 
[24] File "C:/Users/comba/Desktop/知识城地牛/knowledgeCity/common/enhance.py", line 268, in getTrace() 
[25] File "C:/Users/comba/Desktop/知识城地牛/knowledgeCity/common/enhance.py", line 248, in getThreadStack()
[DEBUG]2021-05-08 16:43:16,809: GET: http://127.0.0.1:8999/api/scada/addTask?source=%E4%B8%89%E6%A5%BC%E5%A4%B9%E5%85%B7%E7%82%B9A&target=%E4%B8%89%E6%A5%BC%E5%A4%B9%E5%85%B7%E7%82%B9B addr: 127.0.0.1
[CRITICAL]2021-05-08 16:43:16,809: upStation01 readDIList fail cause a error: [WinError 10060] 由于连接方在一段时间后没有正确答复或连接的主机没有反应，连接尝试失败。
pid=7600, ppid=4848, tid=13448
Traceback (most recent call last):
  File "..\remoteio\remoteioMgr.py", line 262, in readDOList
    return self._read(M30, IO_LENTH)
  File "C:\Users\comba\Desktop\知识城地牛\knowledgeCity\common\lock.py", line 122, in _call
    return func(*p,**pp)
  File "..\remoteio\remoteioMgr.py", line 314, in _read
    s = self.master.read(mdef.READ_COILS,addr, length)
  File "C:\Users\comba\Desktop\知识城地牛\knowledgeCity\common\modbusapi.py", line 45, in read
    return self.__execute(fcode, start, num)
  File "C:\Users\comba\Desktop\知识城地牛\knowledgeCity\common\modbusapi.py", line 35, in __execute
    data = self.master.execute(self.__salveId, fcode, start, quantity_of_x=num, output_value=value)
  File "C:\Users\comba\AppData\Local\Programs\Python\Python37\lib\site-packages\modbus_tk\utils.py", line 39, in new
    raise excpt
  File "C:\Users\comba\AppData\Local\Programs\Python\Python37\lib\site-packages\modbus_tk\utils.py", line 37, in new
    ret = fcn(*args, **kwargs)
  File "C:\Users\comba\AppData\Local\Programs\Python\Python37\lib\site-packages\modbus_tk\modbus.py", line 152, in execute
    self.open()
  File "C:\Users\comba\AppData\Local\Programs\Python\Python37\lib\site-packages\modbus_tk\modbus.py", line 99, in open
    self._do_open()
  File "C:\Users\comba\AppData\Local\Programs\Python\Python37\lib\site-packages\modbus_tk\modbus_tcp.py", line 173, in _do_open
    self._sock.connect((self._host, self._port))
TimeoutError: [WinError 10060] 由于连接方在一段时间后没有正确答复或连接的主机没有反应，连接尝试失败。

[INFO]2021-05-08 16:43:16,843: Scada send a task to the server from 三楼夹具点A to 三楼夹具点B payloadId: None
[INFO]2021-05-08 16:43:16,921: create task[60964f2473dabd1db0d9decc]: type= scadaTask , 从三楼夹具点A运送货架到三楼夹具点B {'source': '三楼夹具点A', 'target': '三楼夹具点B', 'payloadId': None, 'priority': 1, 'type': 'scadaTask', 'taskName': '从三楼夹具点A运送货架到三楼夹具点B', 'createTime': datetime.datetime(2021, 5, 8, 16, 43, 16, 909738), 'updateTime': datetime.datetime(2021, 5, 8, 16, 43, 16, 909738), 'startTime': None, 'endTime': None, 'status': 'waiting', 'step': 'waiting', 'msg': None, 'history': [], '_id': ObjectId('60964f2473dabd1db0d9decc')}
[CRITICAL]2021-05-08 16:43:16,938: invoke <function urlReadDOList at 0x000002029C40ED08> cause a error: [WinError 10060] 由于连接方在一段时间后没有正确答复或连接的主机没有反应，连接尝试失败。
pid=7600, ppid=4848, tid=13448
Traceback (most recent call last):
  File "C:\Users\comba\Desktop\知识城地牛\knowledgeCity\common\scadaUtility.py", line 45, in __call
    ret = func(*p,**pp)
  File "C:\Users\comba\Desktop\知识城地牛\knowledgeCity\remoteio\main_remoteio.py", line 87, in urlReadDOList
    return ioMgr.readDOList(id)
  File "..\remoteio\remoteioMgr.py", line 158, in readDOList
    result=remoteioInfo.readDOList()
  File "..\remoteio\remoteioMgr.py", line 262, in readDOList
    return self._read(M30, IO_LENTH)
  File "C:\Users\comba\Desktop\知识城地牛\knowledgeCity\common\lock.py", line 122, in _call
    return func(*p,**pp)
  File "..\remoteio\remoteioMgr.py", line 314, in _read
    s = self.master.read(mdef.READ_COILS,addr, length)
  File "C:\Users\comba\Desktop\知识城地牛\knowledgeCity\common\modbusapi.py", line 45, in read
    return self.__execute(fcode, start, num)
  File "C:\Users\comba\Desktop\知识城地牛\knowledgeCity\common\modbusapi.py", line 35, in __execute
    data = self.master.execute(self.__salveId, fcode, start, quantity_of_x=num, output_value=value)
  File "C:\Users\comba\AppData\Local\Programs\Python\Python37\lib\site-packages\modbus_tk\utils.py", line 39, in new
    raise excpt
  File "C:\Users\comba\AppData\Local\Programs\Python\Python37\lib\site-packages\modbus_tk\utils.py", line 37, in new
    ret = fcn(*args, **kwargs)
  File "C:\Users\comba\AppData\Local\Programs\Python\Python37\lib\site-packages\modbus_tk\modbus.py", line 152, in execute
    self.open()
  File "C:\Users\comba\AppData\Local\Programs\Python\Python37\lib\site-packages\modbus_tk\modbus.py", line 99, in open
    self._do_open()
  File "C:\Users\comba\AppData\Local\Programs\Python\Python37\lib\site-packages\modbus_tk\modbus_tcp.py", line 173, in _do_open
    self._sock.connect((self._host, self._port))
TimeoutError: [WinError 10060] 由于连接方在一段时间后没有正确答复或连接的主机没有反应，连接尝试失败。

[INFO]2021-05-08 16:43:16,949: 三楼夹具点B 三楼夹具点A
[INFO]2021-05-08 16:43:17,041: task[60964f2473dabd1db0d9decc][-] AP22(LM17) -> AP18(LM17) [waiting] is inside False
[INFO]2021-05-08 16:43:17,059: task cmd: got a task from scada task[60964f2473dabd1db0d9decc][-] AP22(LM17) -> AP18(LM17) [waiting]
[ERROR]2021-05-08 16:43:17,275: connect AGV01 failed timed out
[INFO]2021-05-08 16:43:17,298: AGV01 checkLink failed 172.16.217.209 19204
[WARN]2021-05-08 16:43:17,337: agvThread.AGV01[tid:13976] <lock name:agv.AGV01.lock_status,<locked _thread.RLock object owner=13976 count=1 at 0x000002029F97BA08>> ,hold 10124 ms
[ERROR]2021-05-08 16:43:17,361: connect AGV02 failed timed out
[ERROR]2021-05-08 16:43:17,387: connect AGV03 failed timed out
[INFO]2021-05-08 16:43:17,446: AGV02 checkLink failed 172.16.217.213 19204
[INFO]2021-05-08 16:43:17,451: name=agvThread.AGV01, pid=7600, tid=13976
[01] File "C:/Users/comba/AppData/Local/Programs/Python/Python37/lib/threading.py", line 865, in run() 
[02] File "C:/Users/comba/Desktop/知识城地牛/knowledgeCity/agvCtrl/agvList.py", line 565, in run() 
[03] File "../driver/seerAgv/agvCtrl.py", line 36, in checkLink() 
[04] File "../driver/seerAgv/agvApi.py", line 184, in checkLink() 
[05] File "C:/Users/comba/Desktop/知识城地牛/knowledgeCity/common/lock.py", line 102, in release() 
[06] File "C:/Users/comba/Desktop/知识城地牛/knowledgeCity/common/enhance.py", line 268, in getTrace() 
[07] File "C:/Users/comba/Desktop/知识城地牛/knowledgeCity/common/enhance.py", line 248, in getThreadStack()
[INFO]2021-05-08 16:43:17,481: AGV03 checkLink failed 172.16.217.121 19204
[WARN]2021-05-08 16:43:17,515: agvThread.AGV02[tid:13684] <lock name:agv.AGV02.lock_status,<locked _thread.RLock object owner=13684 count=1 at 0x000002029F8CF5F8>> ,hold 10267 ms
[WARN]2021-05-08 16:43:17,590: agvThread.AGV03[tid:13128] <lock name:agv.AGV03.lock_status,<locked _thread.RLock object owner=13128 count=1 at 0x000002029F97BC10>> ,hold 10300 ms
[INFO]2021-05-08 16:43:17,700: name=agvThread.AGV02, pid=7600, tid=13684
[01] File "C:/Users/comba/AppData/Local/Programs/Python/Python37/lib/threading.py", line 865, in run() 
[02] File "C:/Users/comba/Desktop/知识城地牛/knowledgeCity/agvCtrl/agvList.py", line 565, in run() 
[03] File "../driver/seerAgv/agvCtrl.py", line 36, in checkLink() 
[04] File "../driver/seerAgv/agvApi.py", line 184, in checkLink() 
[05] File "C:/Users/comba/Desktop/知识城地牛/knowledgeCity/common/lock.py", line 102, in release() 
[06] File "C:/Users/comba/Desktop/知识城地牛/knowledgeCity/common/enhance.py", line 268, in getTrace() 
[07] File "C:/Users/comba/Desktop/知识城地牛/knowledgeCity/common/enhance.py", line 248, in getThreadStack()
[INFO]2021-05-08 16:43:17,711: name=agvThread.AGV03, pid=7600, tid=13128
[01] File "C:/Users/comba/AppData/Local/Programs/Python/Python37/lib/threading.py", line 865, in run() 
[02] File "C:/Users/comba/Desktop/知识城地牛/knowledgeCity/agvCtrl/agvList.py", line 565, in run() 
[03] File "../driver/seerAgv/agvCtrl.py", line 36, in checkLink() 
[04] File "../driver/seerAgv/agvApi.py", line 184, in checkLink() 
[05] File "C:/Users/comba/Desktop/知识城地牛/knowledgeCity/common/lock.py", line 102, in release() 
[06] File "C:/Users/comba/Desktop/知识城地牛/knowledgeCity/common/enhance.py", line 268, in getTrace() 
[07] File "C:/Users/comba/Desktop/知识城地牛/knowledgeCity/common/enhance.py", line 248, in getThreadStack()
[DEBUG]2021-05-08 16:43:19,559: try connect AGV01 172.16.217.209:19204
[DEBUG]2021-05-08 16:43:19,752: try connect AGV02 172.16.217.213:19204
[DEBUG]2021-05-08 16:43:19,812: try connect AGV03 172.16.217.121:19204
[CRITICAL]2021-05-08 16:43:26,133: downStation01 init failed cause a error: ('http get', 'http://127.0.0.1:8999/api/remoteio/readDOList', {'id': 'downStation01'}, 'error:', 'timed out')
pid=7600, ppid=4848, tid=10368
Traceback (most recent call last):
  File "C:\Users\comba\Desktop\知识城地牛\knowledgeCity\common\webutility.py", line 103, in http_get
    f = urllib.request.urlopen(u,timeout=timeout)
  File "C:\Users\comba\AppData\Local\Programs\Python\Python37\lib\urllib\request.py", line 222, in urlopen
    return opener.open(url, data, timeout)
  File "C:\Users\comba\AppData\Local\Programs\Python\Python37\lib\urllib\request.py", line 525, in open
    response = self._open(req, data)
  File "C:\Users\comba\AppData\Local\Programs\Python\Python37\lib\urllib\request.py", line 543, in _open
    '_open', req)
  File "C:\Users\comba\AppData\Local\Programs\Python\Python37\lib\urllib\request.py", line 503, in _call_chain
    result = func(*args)
  File "C:\Users\comba\AppData\Local\Programs\Python\Python37\lib\urllib\request.py", line 1345, in http_open
    return self.do_open(http.client.HTTPConnection, req)
  File "C:\Users\comba\AppData\Local\Programs\Python\Python37\lib\urllib\request.py", line 1320, in do_open
    r = h.getresponse()
  File "C:\Users\comba\AppData\Local\Programs\Python\Python37\lib\http\client.py", line 1321, in getresponse
    response.begin()
  File "C:\Users\comba\AppData\Local\Programs\Python\Python37\lib\http\client.py", line 296, in begin
    version, status, reason = self._read_status()
  File "C:\Users\comba\AppData\Local\Programs\Python\Python37\lib\http\client.py", line 257, in _read_status
    line = str(self.fp.readline(_MAXLINE + 1), "iso-8859-1")
  File "C:\Users\comba\AppData\Local\Programs\Python\Python37\lib\socket.py", line 589, in readinto
    return self._sock.recv_into(b)
socket.timeout: timed out

During handling of the above exception, another exception occurred:

Traceback (most recent call last):
  File "C:\Users\comba\Desktop\知识城地牛\knowledgeCity\autoCtrl\deviceCtrl.py", line 175, in _checkInit
    s = ioApi.readDOList(devices[d][ioId])["status"]
  File "..\remoteio\remoteioApi.py", line 73, in readDOList
    return _remoteio('/api/remoteio/readDOList', id, param)
  File "..\remoteio\remoteioApi.py", line 100, in _remoteio
    return http_get(url + apiurl, param)
  File "..\remoteio\remoteioApi.py", line 16, in http_get
    r = webutility.http_get(url, param)
  File "C:\Users\comba\Desktop\知识城地牛\knowledgeCity\common\webutility.py", line 105, in http_get
    raise Exception("http get",url,params,"error:",str(e))
Exception: ('http get', 'http://127.0.0.1:8999/api/remoteio/readDOList', {'id': 'downStation01'}, 'error:', 'timed out')

[INFO]2021-05-08 16:43:27,183: init IO success
[DEBUG]2021-05-08 16:43:27,213: send http_get: http://127.0.0.1:8999/api/remoteio/readDOList?id=upStation01
[ERROR]2021-05-08 16:43:29,632: connect AGV01 failed timed out
[INFO]2021-05-08 16:43:29,677: AGV01 checkLink failed 172.16.217.209 19204
[WARN]2021-05-08 16:43:29,741: agvThread.AGV01[tid:13976] <lock name:agv.AGV01.lock_status,<locked _thread.RLock object owner=13976 count=1 at 0x000002029F97BA08>> ,hold 10182 ms
[INFO]2021-05-08 16:43:29,828: name=agvThread.AGV01, pid=7600, tid=13976
[01] File "C:/Users/comba/AppData/Local/Programs/Python/Python37/lib/threading.py", line 865, in run() 
[02] File "C:/Users/comba/Desktop/知识城地牛/knowledgeCity/agvCtrl/agvList.py", line 565, in run() 
[03] File "../driver/seerAgv/agvCtrl.py", line 36, in checkLink() 
[04] File "../driver/seerAgv/agvApi.py", line 184, in checkLink() 
[05] File "C:/Users/comba/Desktop/知识城地牛/knowledgeCity/common/lock.py", line 102, in release() 
[06] File "C:/Users/comba/Desktop/知识城地牛/knowledgeCity/common/enhance.py", line 268, in getTrace() 
[07] File "C:/Users/comba/Desktop/知识城地牛/knowledgeCity/common/enhance.py", line 248, in getThreadStack()
[ERROR]2021-05-08 16:43:29,834: connect AGV02 failed timed out
[ERROR]2021-05-08 16:43:29,897: connect AGV03 failed timed out
[INFO]2021-05-08 16:43:29,921: AGV02 checkLink failed 172.16.217.213 19204
[INFO]2021-05-08 16:43:29,969: AGV03 checkLink failed 172.16.217.121 19204
[WARN]2021-05-08 16:43:29,997: agvThread.AGV02[tid:13684] <lock name:agv.AGV02.lock_status,<locked _thread.RLock object owner=13684 count=1 at 0x000002029F8CF5F8>> ,hold 10245 ms
[WARN]2021-05-08 16:43:30,023: agvThread.AGV03[tid:13128] <lock name:agv.AGV03.lock_status,<locked _thread.RLock object owner=13128 count=1 at 0x000002029F97BC10>> ,hold 10211 ms
[INFO]2021-05-08 16:43:30,162: name=agvThread.AGV02, pid=7600, tid=13684
[01] File "C:/Users/comba/AppData/Local/Programs/Python/Python37/lib/threading.py", line 865, in run() 
[02] File "C:/Users/comba/Desktop/知识城地牛/knowledgeCity/agvCtrl/agvList.py", line 565, in run() 
[03] File "../driver/seerAgv/agvCtrl.py", line 36, in checkLink() 
[04] File "../driver/seerAgv/agvApi.py", line 184, in checkLink() 
[05] File "C:/Users/comba/Desktop/知识城地牛/knowledgeCity/common/lock.py", line 102, in release() 
[06] File "C:/Users/comba/Desktop/知识城地牛/knowledgeCity/common/enhance.py", line 268, in getTrace() 
[07] File "C:/Users/comba/Desktop/知识城地牛/knowledgeCity/common/enhance.py", line 248, in getThreadStack()
[INFO]2021-05-08 16:43:30,208: name=agvThread.AGV03, pid=7600, tid=13128
[01] File "C:/Users/comba/AppData/Local/Programs/Python/Python37/lib/threading.py", line 865, in run() 
[02] File "C:/Users/comba/Desktop/知识城地牛/knowledgeCity/agvCtrl/agvList.py", line 565, in run() 
[03] File "../driver/seerAgv/agvCtrl.py", line 36, in checkLink() 
[04] File "../driver/seerAgv/agvApi.py", line 184, in checkLink() 
[05] File "C:/Users/comba/Desktop/知识城地牛/knowledgeCity/common/lock.py", line 102, in release() 
[06] File "C:/Users/comba/Desktop/知识城地牛/knowledgeCity/common/enhance.py", line 268, in getTrace() 
[07] File "C:/Users/comba/Desktop/知识城地牛/knowledgeCity/common/enhance.py", line 248, in getThreadStack()
[DEBUG]2021-05-08 16:43:31,885: try connect AGV01 172.16.217.209:19204
[DEBUG]2021-05-08 16:43:32,214: try connect AGV02 172.16.217.213:19204
[DEBUG]2021-05-08 16:43:32,267: try connect AGV03 172.16.217.121:19204
[CRITICAL]2021-05-08 16:43:36,735: [modbusApi: 172.16.167.220] execute fcode=1, addr=8256 exception:  cause a error: [WinError 10060] 由于连接方在一段时间后没有正确答复或连接的主机没有反应，连接尝试失败。
pid=7600, ppid=4848, tid=13532
Traceback (most recent call last):
  File "C:\Users\comba\Desktop\知识城地牛\knowledgeCity\common\modbusapi.py", line 35, in __execute
    data = self.master.execute(self.__salveId, fcode, start, quantity_of_x=num, output_value=value)
  File "C:\Users\comba\AppData\Local\Programs\Python\Python37\lib\site-packages\modbus_tk\utils.py", line 39, in new
    raise excpt
  File "C:\Users\comba\AppData\Local\Programs\Python\Python37\lib\site-packages\modbus_tk\utils.py", line 37, in new
    ret = fcn(*args, **kwargs)
  File "C:\Users\comba\AppData\Local\Programs\Python\Python37\lib\site-packages\modbus_tk\modbus.py", line 152, in execute
    self.open()
  File "C:\Users\comba\AppData\Local\Programs\Python\Python37\lib\site-packages\modbus_tk\modbus.py", line 99, in open
    self._do_open()
  File "C:\Users\comba\AppData\Local\Programs\Python\Python37\lib\site-packages\modbus_tk\modbus_tcp.py", line 173, in _do_open
    self._sock.connect((self._host, self._port))
TimeoutError: [WinError 10060] 由于连接方在一段时间后没有正确答复或连接的主机没有反应，连接尝试失败。

[WARN]2021-05-08 16:43:36,771: worker 3[tid:13532] <locked _thread.RLock object owner=13532 count=1 at 0x000002029D8E07B0> ,hold 25645 ms
[INFO]2021-05-08 16:43:36,883: name=worker 3, pid=7600, tid=13532
[01] File "C:/Users/comba/AppData/Local/Programs/Python/Python37/lib/threading.py", line 865, in run() 
[02] File "C:/Users/comba/AppData/Local/Programs/Python/Python37/lib/site-packages/paste/httpserver.py", line 895, in worker_thread_callback() 
[03] File "C:/Users/comba/AppData/Local/Programs/Python/Python37/lib/site-packages/paste/httpserver.py", line 1069, in <lambda>() 
[04] File "C:/Users/comba/AppData/Local/Programs/Python/Python37/lib/site-packages/paste/httpserver.py", line 1085, in process_request_in_thread() 
[05] File "C:/Users/comba/AppData/Local/Programs/Python/Python37/lib/socketserver.py", line 357, in finish_request() 
[06] File "C:/Users/comba/AppData/Local/Programs/Python/Python37/lib/socketserver.py", line 717, in __init__() 
[07] File "C:/Users/comba/AppData/Local/Programs/Python/Python37/lib/site-packages/paste/httpserver.py", line 459, in handle() 
[08] File "C:/Users/comba/AppData/Local/Programs/Python/Python37/lib/http/server.py", line 426, in handle() 
[09] File "C:/Users/comba/AppData/Local/Programs/Python/Python37/lib/site-packages/paste/httpserver.py", line 454, in handle_one_request() 
[10] File "C:/Users/comba/AppData/Local/Programs/Python/Python37/lib/site-packages/paste/httpserver.py", line 304, in wsgi_execute() 
[11] File "C:/Users/comba/AppData/Local/Programs/Python/Python37/lib/site-packages/paste/translogger.py", line 69, in __call__() 
[12] File "C:/Users/comba/AppData/Local/Programs/Python/Python37/lib/site-packages/bottle.py", line 979, in __call__() 
[13] File "C:/Users/comba/AppData/Local/Programs/Python/Python37/lib/site-packages/bottle.py", line 954, in wsgi() 
[14] File "C:/Users/comba/AppData/Local/Programs/Python/Python37/lib/site-packages/bottle.py", line 862, in _handle() 
[15] File "C:/Users/comba/AppData/Local/Programs/Python/Python37/lib/site-packages/bottle.py", line 1742, in wrapper() 
[16] File "C:/Users/comba/Desktop/知识城地牛/knowledgeCity/common/webutility.py", line 465, in _enable_cors() 
[17] File "C:/Users/comba/Desktop/知识城地牛/knowledgeCity/common/webutility.py", line 481, in _enable_cors() 
[18] File "C:/Users/comba/Desktop/知识城地牛/knowledgeCity/common/scadaUtility.py", line 45, in __call() 
[19] File "C:/Users/comba/Desktop/知识城地牛/knowledgeCity/remoteio/main_remoteio.py", line 87, in urlReadDOList() 
[20] File "../remoteio/remoteioMgr.py", line 158, in readDOList() 
[21] File "../remoteio/remoteioMgr.py", line 262, in readDOList() 
[22] File "C:/Users/comba/Desktop/知识城地牛/knowledgeCity/common/lock.py", line 124, in _call() 
[23] File "C:/Users/comba/Desktop/知识城地牛/knowledgeCity/common/lock.py", line 102, in release() 
[24] File "C:/Users/comba/Desktop/知识城地牛/knowledgeCity/common/enhance.py", line 268, in getTrace() 
[25] File "C:/Users/comba/Desktop/知识城地牛/knowledgeCity/common/enhance.py", line 248, in getThreadStack()
[CRITICAL]2021-05-08 16:43:36,989: downStation01 readDIList fail cause a error: [WinError 10060] 由于连接方在一段时间后没有正确答复或连接的主机没有反应，连接尝试失败。
pid=7600, ppid=4848, tid=13532
Traceback (most recent call last):
  File "..\remoteio\remoteioMgr.py", line 262, in readDOList
    return self._read(M30, IO_LENTH)
  File "C:\Users\comba\Desktop\知识城地牛\knowledgeCity\common\lock.py", line 122, in _call
    return func(*p,**pp)
  File "..\remoteio\remoteioMgr.py", line 314, in _read
    s = self.master.read(mdef.READ_COILS,addr, length)
  File "C:\Users\comba\Desktop\知识城地牛\knowledgeCity\common\modbusapi.py", line 45, in read
    return self.__execute(fcode, start, num)
  File "C:\Users\comba\Desktop\知识城地牛\knowledgeCity\common\modbusapi.py", line 35, in __execute
    data = self.master.execute(self.__salveId, fcode, start, quantity_of_x=num, output_value=value)
  File "C:\Users\comba\AppData\Local\Programs\Python\Python37\lib\site-packages\modbus_tk\utils.py", line 39, in new
    raise excpt
  File "C:\Users\comba\AppData\Local\Programs\Python\Python37\lib\site-packages\modbus_tk\utils.py", line 37, in new
    ret = fcn(*args, **kwargs)
  File "C:\Users\comba\AppData\Local\Programs\Python\Python37\lib\site-packages\modbus_tk\modbus.py", line 152, in execute
    self.open()
  File "C:\Users\comba\AppData\Local\Programs\Python\Python37\lib\site-packages\modbus_tk\modbus.py", line 99, in open
    self._do_open()
  File "C:\Users\comba\AppData\Local\Programs\Python\Python37\lib\site-packages\modbus_tk\modbus_tcp.py", line 173, in _do_open
    self._sock.connect((self._host, self._port))
TimeoutError: [WinError 10060] 由于连接方在一段时间后没有正确答复或连接的主机没有反应，连接尝试失败。

[CRITICAL]2021-05-08 16:43:37,084: invoke <function urlReadDOList at 0x000002029C40ED08> cause a error: [WinError 10060] 由于连接方在一段时间后没有正确答复或连接的主机没有反应，连接尝试失败。
pid=7600, ppid=4848, tid=13532
Traceback (most recent call last):
  File "C:\Users\comba\Desktop\知识城地牛\knowledgeCity\common\scadaUtility.py", line 45, in __call
    ret = func(*p,**pp)
  File "C:\Users\comba\Desktop\知识城地牛\knowledgeCity\remoteio\main_remoteio.py", line 87, in urlReadDOList
    return ioMgr.readDOList(id)
  File "..\remoteio\remoteioMgr.py", line 158, in readDOList
    result=remoteioInfo.readDOList()
  File "..\remoteio\remoteioMgr.py", line 262, in readDOList
    return self._read(M30, IO_LENTH)
  File "C:\Users\comba\Desktop\知识城地牛\knowledgeCity\common\lock.py", line 122, in _call
    return func(*p,**pp)
  File "..\remoteio\remoteioMgr.py", line 314, in _read
    s = self.master.read(mdef.READ_COILS,addr, length)
  File "C:\Users\comba\Desktop\知识城地牛\knowledgeCity\common\modbusapi.py", line 45, in read
    return self.__execute(fcode, start, num)
  File "C:\Users\comba\Desktop\知识城地牛\knowledgeCity\common\modbusapi.py", line 35, in __execute
    data = self.master.execute(self.__salveId, fcode, start, quantity_of_x=num, output_value=value)
  File "C:\Users\comba\AppData\Local\Programs\Python\Python37\lib\site-packages\modbus_tk\utils.py", line 39, in new
    raise excpt
  File "C:\Users\comba\AppData\Local\Programs\Python\Python37\lib\site-packages\modbus_tk\utils.py", line 37, in new
    ret = fcn(*args, **kwargs)
  File "C:\Users\comba\AppData\Local\Programs\Python\Python37\lib\site-packages\modbus_tk\modbus.py", line 152, in execute
    self.open()
  File "C:\Users\comba\AppData\Local\Programs\Python\Python37\lib\site-packages\modbus_tk\modbus.py", line 99, in open
    self._do_open()
  File "C:\Users\comba\AppData\Local\Programs\Python\Python37\lib\site-packages\modbus_tk\modbus_tcp.py", line 173, in _do_open
    self._sock.connect((self._host, self._port))
TimeoutError: [WinError 10060] 由于连接方在一段时间后没有正确答复或连接的主机没有反应，连接尝试失败。

[ERROR]2021-05-08 16:43:41,965: connect AGV01 failed timed out
[INFO]2021-05-08 16:43:41,986: AGV01 checkLink failed 172.16.217.209 19204
[WARN]2021-05-08 16:43:42,006: agvThread.AGV01[tid:13976] <lock name:agv.AGV01.lock_status,<locked _thread.RLock object owner=13976 count=1 at 0x000002029F97BA08>> ,hold 10121 ms
[INFO]2021-05-08 16:43:42,090: name=agvThread.AGV01, pid=7600, tid=13976
[01] File "C:/Users/comba/AppData/Local/Programs/Python/Python37/lib/threading.py", line 865, in run() 
[02] File "C:/Users/comba/Desktop/知识城地牛/knowledgeCity/agvCtrl/agvList.py", line 565, in run() 
[03] File "../driver/seerAgv/agvCtrl.py", line 36, in checkLink() 
[04] File "../driver/seerAgv/agvApi.py", line 184, in checkLink() 
[05] File "C:/Users/comba/Desktop/知识城地牛/knowledgeCity/common/lock.py", line 102, in release() 
[06] File "C:/Users/comba/Desktop/知识城地牛/knowledgeCity/common/enhance.py", line 268, in getTrace() 
[07] File "C:/Users/comba/Desktop/知识城地牛/knowledgeCity/common/enhance.py", line 248, in getThreadStack()
[ERROR]2021-05-08 16:43:42,302: connect AGV02 failed timed out
[CRITICAL]2021-05-08 16:43:42,355: readDIList error cause a error: ('http get', 'http://127.0.0.1:8999/api/remoteio/readDOList', {'id': 'upStation01'}, 'error:', 'timed out')
pid=7600, ppid=4848, tid=10368
Traceback (most recent call last):
  File "C:\Users\comba\Desktop\知识城地牛\knowledgeCity\common\webutility.py", line 103, in http_get
    f = urllib.request.urlopen(u,timeout=timeout)
  File "C:\Users\comba\AppData\Local\Programs\Python\Python37\lib\urllib\request.py", line 222, in urlopen
    return opener.open(url, data, timeout)
  File "C:\Users\comba\AppData\Local\Programs\Python\Python37\lib\urllib\request.py", line 525, in open
    response = self._open(req, data)
  File "C:\Users\comba\AppData\Local\Programs\Python\Python37\lib\urllib\request.py", line 543, in _open
    '_open', req)
  File "C:\Users\comba\AppData\Local\Programs\Python\Python37\lib\urllib\request.py", line 503, in _call_chain
    result = func(*args)
  File "C:\Users\comba\AppData\Local\Programs\Python\Python37\lib\urllib\request.py", line 1345, in http_open
    return self.do_open(http.client.HTTPConnection, req)
  File "C:\Users\comba\AppData\Local\Programs\Python\Python37\lib\urllib\request.py", line 1320, in do_open
    r = h.getresponse()
  File "C:\Users\comba\AppData\Local\Programs\Python\Python37\lib\http\client.py", line 1321, in getresponse
    response.begin()
  File "C:\Users\comba\AppData\Local\Programs\Python\Python37\lib\http\client.py", line 296, in begin
    version, status, reason = self._read_status()
  File "C:\Users\comba\AppData\Local\Programs\Python\Python37\lib\http\client.py", line 257, in _read_status
    line = str(self.fp.readline(_MAXLINE + 1), "iso-8859-1")
  File "C:\Users\comba\AppData\Local\Programs\Python\Python37\lib\socket.py", line 589, in readinto
    return self._sock.recv_into(b)
socket.timeout: timed out

During handling of the above exception, another exception occurred:

Traceback (most recent call last):
  File "C:\Users\comba\Desktop\知识城地牛\knowledgeCity\autoCtrl\deviceCtrl.py", line 71, in _monitorDevices
    s1 = ioApi.readDOList(devices[d]["io1"])["status"] #上板机
  File "..\remoteio\remoteioApi.py", line 73, in readDOList
    return _remoteio('/api/remoteio/readDOList', id, param)
  File "..\remoteio\remoteioApi.py", line 100, in _remoteio
    return http_get(url + apiurl, param)
  File "..\remoteio\remoteioApi.py", line 16, in http_get
    r = webutility.http_get(url, param)
  File "C:\Users\comba\Desktop\知识城地牛\knowledgeCity\common\webutility.py", line 105, in http_get
    raise Exception("http get",url,params,"error:",str(e))
Exception: ('http get', 'http://127.0.0.1:8999/api/remoteio/readDOList', {'id': 'upStation01'}, 'error:', 'timed out')

[ERROR]2021-05-08 16:43:42,361: connect AGV03 failed timed out
[INFO]2021-05-08 16:43:42,366: AGV02 checkLink failed 172.16.217.213 19204
[INFO]2021-05-08 16:43:42,447: AGV03 checkLink failed 172.16.217.121 19204
[WARN]2021-05-08 16:43:42,469: agvThread.AGV02[tid:13684] <lock name:agv.AGV02.lock_status,<locked _thread.RLock object owner=13684 count=1 at 0x000002029F8CF5F8>> ,hold 10255 ms
[WARN]2021-05-08 16:43:42,511: agvThread.AGV03[tid:13128] <lock name:agv.AGV03.lock_status,<locked _thread.RLock object owner=13128 count=1 at 0x000002029F97BC10>> ,hold 10244 ms
[INFO]2021-05-08 16:43:42,592: name=agvThread.AGV02, pid=7600, tid=13684
[01] File "C:/Users/comba/AppData/Local/Programs/Python/Python37/lib/threading.py", line 865, in run() 
[02] File "C:/Users/comba/Desktop/知识城地牛/knowledgeCity/agvCtrl/agvList.py", line 565, in run() 
[03] File "../driver/seerAgv/agvCtrl.py", line 36, in checkLink() 
[04] File "../driver/seerAgv/agvApi.py", line 184, in checkLink() 
[05] File "C:/Users/comba/Desktop/知识城地牛/knowledgeCity/common/lock.py", line 102, in release() 
[06] File "C:/Users/comba/Desktop/知识城地牛/knowledgeCity/common/enhance.py", line 268, in getTrace() 
[07] File "C:/Users/comba/Desktop/知识城地牛/knowledgeCity/common/enhance.py", line 248, in getThreadStack()
[INFO]2021-05-08 16:43:42,640: name=agvThread.AGV03, pid=7600, tid=13128
[01] File "C:/Users/comba/AppData/Local/Programs/Python/Python37/lib/threading.py", line 865, in run() 
[02] File "C:/Users/comba/Desktop/知识城地牛/knowledgeCity/agvCtrl/agvList.py", line 565, in run() 
[03] File "../driver/seerAgv/agvCtrl.py", line 36, in checkLink() 
[04] File "../driver/seerAgv/agvApi.py", line 184, in checkLink() 
[05] File "C:/Users/comba/Desktop/知识城地牛/knowledgeCity/common/lock.py", line 102, in release() 
[06] File "C:/Users/comba/Desktop/知识城地牛/knowledgeCity/common/enhance.py", line 268, in getTrace() 
[07] File "C:/Users/comba/Desktop/知识城地牛/knowledgeCity/common/enhance.py", line 248, in getThreadStack()
[WARN]2021-05-08 16:43:43,536: clear alarm obj=upStation01, typeId=39998, id=60964b93697d98928ef14b78
[WARN]2021-05-08 16:43:43,761: clear alarm obj=downStation01, typeId=39998, id=60964b93697d98928ef14b7a
[WARN]2021-05-08 16:43:43,895: clear alarm obj=AGV01, typeId=49999, id=60964c44697d98928ef14f4f
[WARN]2021-05-08 16:43:43,995: clear alarm obj=AGV03, typeId=49999, id=60964c44697d98928ef14f51
[DEBUG]2021-05-08 16:43:44,119: try connect AGV01 172.16.217.209:19204
[WARN]2021-05-08 16:43:44,131: clear alarm obj=AGV02, typeId=49999, id=60964c44697d98928ef14f53
[DEBUG]2021-05-08 16:43:44,654: try connect AGV02 172.16.217.213:19204
[DEBUG]2021-05-08 16:43:44,707: try connect AGV03 172.16.217.121:19204
[WARN]2021-05-08 16:43:45,329: AGV04 low battery charge,batteryLevel= 0.252 start charge level= 0.400
[INFO]2021-05-08 16:43:45,363: AGV04 battery 0.252 check success
[WARN]2021-05-08 16:43:45,540: AGV04 Can't find charge point at comba-ZXC-F3 battery: 0.252
[INFO]2021-05-08 16:43:45,645: task[60964f2473dabd1db0d9decc]:  start {'failMsg': '任务等待执行', 'startTime': datetime.datetime(2021, 5, 8, 16, 43, 45, 604859), 'updateTime': datetime.datetime(2021, 5, 8, 16, 43, 45, 604859), 'status': 'running'}
[INFO]2021-05-08 16:43:45,699: task: start task[60964f2473dabd1db0d9decc][-] AP22(LM17) -> AP18(LM17) [waiting]
[INFO]2021-05-08 16:43:45,734: this is handle taskStep=============>waiting
[INFO]2021-05-08 16:43:45,781: task[60964f2473dabd1db0d9decc] update info: {'failMsg': '等待分配小车', 'updateTime': datetime.datetime(2021, 5, 8, 16, 43, 45, 769422)}
[DEBUG]2021-05-08 16:43:45,805: task[60964f2473dabd1db0d9decc][-] AP22(LM17) -> AP18(LM17) [waitForAgv] waiting -> waitForAgv
[DEBUG]2021-05-08 16:43:46,701: send http_get: http://127.0.0.1:8999/api/remoteio/readDOList?id=upStation01
[INFO]2021-05-08 16:43:47,042: this is handle taskStep=============>waitForAgv
[DEBUG]2021-05-08 16:43:47,124: GET: http://127.0.0.1:8999/api/agv/apply?appName=akmTask&autoLock=False&exclude&loc=AP22&mapId=comba-ZXC-F3&taskId=60964f2473dabd1db0d9decc&timeout=10 addr: 127.0.0.1
[INFO]2021-05-08 16:43:47,164: agvControl中的_apply进去
[INFO]2021-05-08 16:43:47,199: [('comba-ZXC-F3.AP22', 'AGV04')]
[INFO]2021-05-08 16:43:48,046: apply AGV04 ,taskId: 60964f2473dabd1db0d9decc ,loc comba-ZXC-F3.AP22 ,autoLock False , used 847 ms
[INFO]2021-05-08 16:43:48,080: AGV04
[INFO]2021-05-08 16:43:48,115: 5555555555555555555555555
[INFO]2021-05-08 16:43:48,196: 6666666666666666666666666
[INFO]2021-05-08 16:43:48,243: AGV04
[DEBUG]2021-05-08 16:43:48,272: used 1148ms 200 OK application/json;charset=utf-8, GET: http://127.0.0.1:8999/api/agv/apply?appName=akmTask&autoLock=False&exclude&loc=AP22&mapId=comba-ZXC-F3&taskId=60964f2473dabd1db0d9decc&timeout=10
[INFO]2021-05-08 16:43:48,305: comba-ZXC-F3.AP22 comba-ZXC-F3.AP18
[WARN]2021-05-08 16:43:48,319: worker 6[tid:14284] <locked _thread.RLock object owner=14284 count=1 at 0x000002029D8E0670> ,hold 21026 ms
[INFO]2021-05-08 16:43:48,344: AGV04
[INFO]2021-05-08 16:43:48,474: 判断类型
[INFO]2021-05-08 16:43:48,515: 1111111111111111111111
[INFO]2021-05-08 16:43:48,562: name=worker 6, pid=7600, tid=14284
[01] File "C:/Users/comba/AppData/Local/Programs/Python/Python37/lib/threading.py", line 865, in run() 
[02] File "C:/Users/comba/AppData/Local/Programs/Python/Python37/lib/site-packages/paste/httpserver.py", line 895, in worker_thread_callback() 
[03] File "C:/Users/comba/AppData/Local/Programs/Python/Python37/lib/site-packages/paste/httpserver.py", line 1069, in <lambda>() 
[04] File "C:/Users/comba/AppData/Local/Programs/Python/Python37/lib/site-packages/paste/httpserver.py", line 1085, in process_request_in_thread() 
[05] File "C:/Users/comba/AppData/Local/Programs/Python/Python37/lib/socketserver.py", line 357, in finish_request() 
[06] File "C:/Users/comba/AppData/Local/Programs/Python/Python37/lib/socketserver.py", line 717, in __init__() 
[07] File "C:/Users/comba/AppData/Local/Programs/Python/Python37/lib/site-packages/paste/httpserver.py", line 459, in handle() 
[08] File "C:/Users/comba/AppData/Local/Programs/Python/Python37/lib/http/server.py", line 426, in handle() 
[09] File "C:/Users/comba/AppData/Local/Programs/Python/Python37/lib/site-packages/paste/httpserver.py", line 454, in handle_one_request() 
[10] File "C:/Users/comba/AppData/Local/Programs/Python/Python37/lib/site-packages/paste/httpserver.py", line 304, in wsgi_execute() 
[11] File "C:/Users/comba/AppData/Local/Programs/Python/Python37/lib/site-packages/paste/translogger.py", line 69, in __call__() 
[12] File "C:/Users/comba/AppData/Local/Programs/Python/Python37/lib/site-packages/bottle.py", line 979, in __call__() 
[13] File "C:/Users/comba/AppData/Local/Programs/Python/Python37/lib/site-packages/bottle.py", line 954, in wsgi() 
[14] File "C:/Users/comba/AppData/Local/Programs/Python/Python37/lib/site-packages/bottle.py", line 862, in _handle() 
[15] File "C:/Users/comba/AppData/Local/Programs/Python/Python37/lib/site-packages/bottle.py", line 1742, in wrapper() 
[16] File "C:/Users/comba/Desktop/知识城地牛/knowledgeCity/common/webutility.py", line 465, in _enable_cors() 
[17] File "C:/Users/comba/Desktop/知识城地牛/knowledgeCity/common/webutility.py", line 481, in _enable_cors() 
[18] File "C:/Users/comba/Desktop/知识城地牛/knowledgeCity/common/scadaUtility.py", line 45, in __call() 
[19] File "C:/Users/comba/Desktop/知识城地牛/knowledgeCity/remoteio/main_remoteio.py", line 87, in urlReadDOList() 
[20] File "../remoteio/remoteioMgr.py", line 158, in readDOList() 
[21] File "../remoteio/remoteioMgr.py", line 262, in readDOList() 
[22] File "C:/Users/comba/Desktop/知识城地牛/knowledgeCity/common/lock.py", line 124, in _call() 
[23] File "C:/Users/comba/Desktop/知识城地牛/knowledgeCity/common/lock.py", line 102, in release() 
[24] File "C:/Users/comba/Desktop/知识城地牛/knowledgeCity/common/enhance.py", line 268, in getTrace() 
[25] File "C:/Users/comba/Desktop/知识城地牛/knowledgeCity/common/enhance.py", line 248, in getThreadStack()
[DEBUG]2021-05-08 16:43:48,645: GET: http://127.0.0.1:8999/api/agv/lock?agv=AGV04&appName=akmTask&taskId=60964f2473dabd1db0d9decc addr: 127.0.0.1
[CRITICAL]2021-05-08 16:43:48,707: upStation01 readDIList fail cause a error: [WinError 10060] 由于连接方在一段时间后没有正确答复或连接的主机没有反应，连接尝试失败。
pid=7600, ppid=4848, tid=14284
Traceback (most recent call last):
  File "..\remoteio\remoteioMgr.py", line 262, in readDOList
    return self._read(M30, IO_LENTH)
  File "C:\Users\comba\Desktop\知识城地牛\knowledgeCity\common\lock.py", line 122, in _call
    return func(*p,**pp)
  File "..\remoteio\remoteioMgr.py", line 311, in _read
    self.master.open()
  File "C:\Users\comba\Desktop\知识城地牛\knowledgeCity\common\modbusapi.py", line 60, in open
    self.master.open()
  File "C:\Users\comba\AppData\Local\Programs\Python\Python37\lib\site-packages\modbus_tk\modbus.py", line 99, in open
    self._do_open()
  File "C:\Users\comba\AppData\Local\Programs\Python\Python37\lib\site-packages\modbus_tk\modbus_tcp.py", line 173, in _do_open
    self._sock.connect((self._host, self._port))
TimeoutError: [WinError 10060] 由于连接方在一段时间后没有正确答复或连接的主机没有反应，连接尝试失败。

[DEBUG]2021-05-08 16:43:48,742: lock:  AGV04 taskId 60964f2473dabd1db0d9decc app akmTask
[CRITICAL]2021-05-08 16:43:48,851: invoke <function urlReadDOList at 0x000002029C40ED08> cause a error: [WinError 10060] 由于连接方在一段时间后没有正确答复或连接的主机没有反应，连接尝试失败。
pid=7600, ppid=4848, tid=14284
Traceback (most recent call last):
  File "C:\Users\comba\Desktop\知识城地牛\knowledgeCity\common\scadaUtility.py", line 45, in __call
    ret = func(*p,**pp)
  File "C:\Users\comba\Desktop\知识城地牛\knowledgeCity\remoteio\main_remoteio.py", line 87, in urlReadDOList
    return ioMgr.readDOList(id)
  File "..\remoteio\remoteioMgr.py", line 158, in readDOList
    result=remoteioInfo.readDOList()
  File "..\remoteio\remoteioMgr.py", line 262, in readDOList
    return self._read(M30, IO_LENTH)
  File "C:\Users\comba\Desktop\知识城地牛\knowledgeCity\common\lock.py", line 122, in _call
    return func(*p,**pp)
  File "..\remoteio\remoteioMgr.py", line 311, in _read
    self.master.open()
  File "C:\Users\comba\Desktop\知识城地牛\knowledgeCity\common\modbusapi.py", line 60, in open
    self.master.open()
  File "C:\Users\comba\AppData\Local\Programs\Python\Python37\lib\site-packages\modbus_tk\modbus.py", line 99, in open
    self._do_open()
  File "C:\Users\comba\AppData\Local\Programs\Python\Python37\lib\site-packages\modbus_tk\modbus_tcp.py", line 173, in _do_open
    self._sock.connect((self._host, self._port))
TimeoutError: [WinError 10060] 由于连接方在一段时间后没有正确答复或连接的主机没有反应，连接尝试失败。

[WARN]2021-05-08 16:43:49,828: AGV04 clear task finish, cur= comba-ZXC-F3.AP22 task_status= 4
[INFO]2021-05-08 16:43:49,876: 22222222222222222222222
[INFO]2021-05-08 16:43:49,918: AGV04
[INFO]2021-05-08 16:43:49,942: task[60964f2473dabd1db0d9decc][-] AP22(LM17) -> AP18(LM17) [waitForAgv] apply AGV04
[INFO]2021-05-08 16:43:49,995: task[60964f2473dabd1db0d9decc] update info: {'agvId': 'AGV04', 'failMsg': '成功分配小车AGV04', 'updateTime': datetime.datetime(2021, 5, 8, 16, 43, 49, 971163)}
[DEBUG]2021-05-08 16:43:50,023: task[60964f2473dabd1db0d9decc][AGV04] AP22(LM17) -> AP18(LM17) [initAGV] waitForAgv -> initAGV
[INFO]2021-05-08 16:43:50,396: this is handle taskStep=============>initAGV
[INFO]2021-05-08 16:43:50,466: task[60964f2473dabd1db0d9decc] update info: {'failMsg': '前往三楼夹具点A工位点', 'updateTime': datetime.datetime(2021, 5, 8, 16, 43, 50, 443866)}
[DEBUG]2021-05-08 16:43:50,513: task[60964f2473dabd1db0d9decc][AGV04] AP22(LM17) -> AP18(LM17) [startMoveAGV] initAGV -> startMoveAGV
[INFO]2021-05-08 16:43:50,880: this is handle taskStep=============>startMoveAGV
[DEBUG]2021-05-08 16:43:50,920: GET: http://127.0.0.1:8999/api/agv/move?WorkPlace=true&agv=AGV04&agvId=AGV04&appName=akmTask&direction=None&floorId=comba-ZXC-F3&isRotate&loc=comba-ZXC-F3.AP22&location=AP22&p_direction=0.0&pgv_type=1&recognize=False&seer_jackup=JackLoad&taskId=60964f2473dabd1db0d9decc_2&taskType=scadaTask&timeoutSec=86400&use_pgv=False addr: 127.0.0.1
[DEBUG]2021-05-08 16:43:50,921: agvInfo: AGV04 comba-ZXC-F3.AP22 move jackup to comba-ZXC-F3.AP22 ,taskId 60964f2473dabd1db0d9decc_2
[INFO]2021-05-08 16:43:50,921: --------------------跳转到driver下的seerAgv下的agcCtrl.py中的goTargetAndDoWork函数中-----------------10---------
[INFO]2021-05-08 16:43:50,922: 1
[INFO]2021-05-08 16:43:50,922: {'id': 'AP22', 'operation': 'JackLoad', 'recognize': False, 'use_pgv': False}
[INFO]2021-05-08 16:43:50,923: --------------------------准备进去driver中的seerAgv.py下的task函数-----------------（11）--------------
[DEBUG]2021-05-08 16:43:51,174: used 254ms 200 OK application/json;charset=utf-8, GET: http://127.0.0.1:8999/api/agv/move?WorkPlace=true&agv=AGV04&agvId=AGV04&appName=akmTask&direction=None&floorId=comba-ZXC-F3&isRotate&loc=comba-ZXC-F3.AP22&location=AP22&p_direction=0.0&pgv_type=1&recognize=False&seer_jackup=JackLoad&taskId=60964f2473dabd1db0d9decc_2&taskType=scadaTask&timeoutSec=86400&use_pgv=False
[DEBUG]2021-05-08 16:43:51,177: task[60964f2473dabd1db0d9decc][AGV04] AP22(LM17) -> AP18(LM17) [loadPlayload] startMoveAGV -> loadPlayload
[INFO]2021-05-08 16:43:51,425: task: move finish callback task[60964f2473dabd1db0d9decc][AGV04] AP22(LM17) -> AP18(LM17) [loadPlayload]
[INFO]2021-05-08 16:43:51,427: task[60964f2473dabd1db0d9decc] update info: {'failMsg': 'AGV二层出料', 'updateTime': datetime.datetime(2021, 5, 8, 16, 43, 51, 426236)}
[INFO]2021-05-08 16:43:51,481: this is handle taskStep=============>loadPlayload_readqr
[DEBUG]2021-05-08 16:43:51,483: send http_get: http://127.0.0.1:8999/api/agv/rollerRobotUnLoad?agv=AGV04&timeoutSec=30&unitId=2
[DEBUG]2021-05-08 16:43:51,495: GET: http://127.0.0.1:8999/api/agv/rollerRobotUnLoad?agv=AGV04&timeoutSec=30&unitId=2 addr: 127.0.0.1
[INFO]2021-05-08 16:43:51,497: AGV04 rollerRobotUnLoad unitId: 2
[DEBUG]2021-05-08 16:43:51,568: used 73ms 200 OK application/json;charset=utf-8, GET: http://127.0.0.1:8999/api/agv/rollerRobotUnLoad?agv=AGV04&timeoutSec=30&unitId=2
[DEBUG]2021-05-08 16:43:51,572: [return] use 90 ms,http_get: http://127.0.0.1:8999/api/agv/rollerRobotUnLoad?agv=AGV04&timeoutSec=30&unitId=2
[INFO]2021-05-08 16:43:51,575: task[60964f2473dabd1db0d9decc] update info: {'failMsg': '二层滚筒出料三楼夹具点B', 'updateTime': datetime.datetime(2021, 5, 8, 16, 43, 51, 575834)}
[DEBUG]2021-05-08 16:43:51,576: task[60964f2473dabd1db0d9decc][AGV04] AP22(LM17) -> AP18(LM17) [checkTwoLayerGoing] loadPlayload_readqr -> checkTwoLayerGoing
[INFO]2021-05-08 16:43:51,879: this is handle taskStep=============>checkTwoLayerGoing
[DEBUG]2021-05-08 16:43:51,881: send http_get: http://127.0.0.1:8999/api/agv/checkUnitUnloadStatus?agv=AGV04&timeoutSec=30&unitId=2
[DEBUG]2021-05-08 16:43:51,893: GET: http://127.0.0.1:8999/api/agv/checkUnitUnloadStatus?agv=AGV04&timeoutSec=30&unitId=2 addr: 127.0.0.1
[INFO]2021-05-08 16:43:51,899: AGV04 checkUnitUnloadStatus unitId: 2
[DEBUG]2021-05-08 16:43:51,900: used 7ms 200 OK application/json;charset=utf-8, GET: http://127.0.0.1:8999/api/agv/checkUnitUnloadStatus?agv=AGV04&timeoutSec=30&unitId=2
[DEBUG]2021-05-08 16:43:51,901: [return] use 20 ms,http_get: http://127.0.0.1:8999/api/agv/checkUnitUnloadStatus?agv=AGV04&timeoutSec=30&unitId=2
[DEBUG]2021-05-08 16:43:53,907: send http_get: http://127.0.0.1:8999/api/agv/checkUnitUnloadStatus?agv=AGV04&timeoutSec=30&unitId=2
[DEBUG]2021-05-08 16:43:54,017: GET: http://127.0.0.1:8999/api/agv/checkUnitUnloadStatus?agv=AGV04&timeoutSec=30&unitId=2 addr: 127.0.0.1
[INFO]2021-05-08 16:43:54,170: AGV04 checkUnitUnloadStatus unitId: 2
[ERROR]2021-05-08 16:43:54,242: connect AGV01 failed timed out
[DEBUG]2021-05-08 16:43:54,254: used 237ms 200 OK application/json;charset=utf-8, GET: http://127.0.0.1:8999/api/agv/checkUnitUnloadStatus?agv=AGV04&timeoutSec=30&unitId=2
[INFO]2021-05-08 16:43:54,325: AGV01 checkLink failed 172.16.217.209 19204
[WARN]2021-05-08 16:43:54,343: agvThread.AGV01[tid:13976] <lock name:agv.AGV01.lock_status,<locked _thread.RLock object owner=13976 count=1 at 0x000002029F97BA08>> ,hold 10224 ms
[DEBUG]2021-05-08 16:43:54,372: [return] use 465 ms,http_get: http://127.0.0.1:8999/api/agv/checkUnitUnloadStatus?agv=AGV04&timeoutSec=30&unitId=2
[INFO]2021-05-08 16:43:54,462: name=agvThread.AGV01, pid=7600, tid=13976
[01] File "C:/Users/comba/AppData/Local/Programs/Python/Python37/lib/threading.py", line 865, in run() 
[02] File "C:/Users/comba/Desktop/知识城地牛/knowledgeCity/agvCtrl/agvList.py", line 565, in run() 
[03] File "../driver/seerAgv/agvCtrl.py", line 36, in checkLink() 
[04] File "../driver/seerAgv/agvApi.py", line 184, in checkLink() 
[05] File "C:/Users/comba/Desktop/知识城地牛/knowledgeCity/common/lock.py", line 102, in release() 
[06] File "C:/Users/comba/Desktop/知识城地牛/knowledgeCity/common/enhance.py", line 268, in getTrace() 
[07] File "C:/Users/comba/Desktop/知识城地牛/knowledgeCity/common/enhance.py", line 248, in getThreadStack()
[ERROR]2021-05-08 16:43:54,724: connect AGV02 failed timed out
[INFO]2021-05-08 16:43:54,759: AGV02 checkLink failed 172.16.217.213 19204
[WARN]2021-05-08 16:43:54,789: agvThread.AGV02[tid:13684] <lock name:agv.AGV02.lock_status,<locked _thread.RLock object owner=13684 count=1 at 0x000002029F8CF5F8>> ,hold 10135 ms
[ERROR]2021-05-08 16:43:54,847: connect AGV03 failed timed out
[INFO]2021-05-08 16:43:54,853: name=agvThread.AGV02, pid=7600, tid=13684
[01] File "C:/Users/comba/AppData/Local/Programs/Python/Python37/lib/threading.py", line 865, in run() 
[02] File "C:/Users/comba/Desktop/知识城地牛/knowledgeCity/agvCtrl/agvList.py", line 565, in run() 
[03] File "../driver/seerAgv/agvCtrl.py", line 36, in checkLink() 
[04] File "../driver/seerAgv/agvApi.py", line 184, in checkLink() 
[05] File "C:/Users/comba/Desktop/知识城地牛/knowledgeCity/common/lock.py", line 102, in release() 
[06] File "C:/Users/comba/Desktop/知识城地牛/knowledgeCity/common/enhance.py", line 268, in getTrace() 
[07] File "C:/Users/comba/Desktop/知识城地牛/knowledgeCity/common/enhance.py", line 248, in getThreadStack()
[INFO]2021-05-08 16:43:54,882: AGV03 checkLink failed 172.16.217.121 19204
[WARN]2021-05-08 16:43:54,979: agvThread.AGV03[tid:13128] <lock name:agv.AGV03.lock_status,<locked _thread.RLock object owner=13128 count=1 at 0x000002029F97BC10>> ,hold 10272 ms
[INFO]2021-05-08 16:43:55,103: name=agvThread.AGV03, pid=7600, tid=13128
[01] File "C:/Users/comba/AppData/Local/Programs/Python/Python37/lib/threading.py", line 865, in run() 
[02] File "C:/Users/comba/Desktop/知识城地牛/knowledgeCity/agvCtrl/agvList.py", line 565, in run() 
[03] File "../driver/seerAgv/agvCtrl.py", line 36, in checkLink() 
[04] File "../driver/seerAgv/agvApi.py", line 184, in checkLink() 
[05] File "C:/Users/comba/Desktop/知识城地牛/knowledgeCity/common/lock.py", line 102, in release() 
[06] File "C:/Users/comba/Desktop/知识城地牛/knowledgeCity/common/enhance.py", line 268, in getTrace() 
[07] File "C:/Users/comba/Desktop/知识城地牛/knowledgeCity/common/enhance.py", line 248, in getThreadStack()
[INFO]2021-05-08 16:43:56,451: task[60964f2473dabd1db0d9decc] update info: {'step': 'checkTwoLayerFinish', 'msg': '检测2层设置出料完成信号', 'updateTime': datetime.datetime(2021, 5, 8, 16, 43, 56, 434847)}
[WARN]2021-05-08 16:43:56,515: scada.60964f2473dabd1db0d9decc[tid:2564] <locked _thread.RLock object owner=2564 count=1 at 0x00000202A15BD4E0> ,hold 4636 ms
[DEBUG]2021-05-08 16:43:56,527: try connect AGV01 172.16.217.209:19204
[INFO]2021-05-08 16:43:56,690: name=scada.60964f2473dabd1db0d9decc, pid=7600, tid=2564
[01] File "C:/Users/comba/AppData/Local/Programs/Python/Python37/lib/threading.py", line 865, in run() 
[02] File "C:/Users/comba/Desktop/知识城地牛/knowledgeCity/common/utility.py", line 167, in __call() 
[03] File "C:/Users/comba/Desktop/知识城地牛/knowledgeCity/autoCtrl/runTasks.py", line 917, in _taskFunc() 
[04] File "C:/Users/comba/Desktop/知识城地牛/knowledgeCity/common/lock.py", line 124, in _call() 
[05] File "C:/Users/comba/Desktop/知识城地牛/knowledgeCity/common/lock.py", line 102, in release() 
[06] File "C:/Users/comba/Desktop/知识城地牛/knowledgeCity/common/enhance.py", line 268, in getTrace() 
[07] File "C:/Users/comba/Desktop/知识城地牛/knowledgeCity/common/enhance.py", line 248, in getThreadStack()
[DEBUG]2021-05-08 16:43:56,714: task[60964f2473dabd1db0d9decc][AGV04] AP22(LM17) -> AP18(LM17) [checkTwoLayerFinish] checkTwoLayerGoing -> checkTwoLayerFinish
[DEBUG]2021-05-08 16:43:56,941: try connect AGV02 172.16.217.213:19204
[INFO]2021-05-08 16:43:57,076: this is handle taskStep=============>checkTwoLayerFinish
[DEBUG]2021-05-08 16:43:57,111: send http_get: http://127.0.0.1:8999/api/agv/rollerRobotLoad?agv=AGV04&timeoutSec=30&unitId=1
[DEBUG]2021-05-08 16:43:57,169: try connect AGV03 172.16.217.121:19204
[DEBUG]2021-05-08 16:43:57,224: GET: http://127.0.0.1:8999/api/agv/rollerRobotLoad?agv=AGV04&timeoutSec=30&unitId=1 addr: 127.0.0.1
[INFO]2021-05-08 16:43:57,248: AGV04 rollerRobotLoad unitId: 1
[DEBUG]2021-05-08 16:43:57,361: used 137ms 200 OK application/json;charset=utf-8, GET: http://127.0.0.1:8999/api/agv/rollerRobotLoad?agv=AGV04&timeoutSec=30&unitId=1
[DEBUG]2021-05-08 16:43:57,427: [return] use 316 ms,http_get: http://127.0.0.1:8999/api/agv/rollerRobotLoad?agv=AGV04&timeoutSec=30&unitId=1
[INFO]2021-05-08 16:43:57,457: task[60964f2473dabd1db0d9decc] update info: {'failMsg': '一层滚筒进料三楼夹具点B', 'updateTime': datetime.datetime(2021, 5, 8, 16, 43, 57, 451124)}
[DEBUG]2021-05-08 16:43:57,481: task[60964f2473dabd1db0d9decc][AGV04] AP22(LM17) -> AP18(LM17) [waitPushrodPush] checkTwoLayerFinish -> waitPushrodPush
[INFO]2021-05-08 16:43:57,823: this is handle taskStep=============>waitPushrodPush
[DEBUG]2021-05-08 16:43:57,851: send http_get: http://127.0.0.1:8999/api/agv/rollerRobotPush?agv=AGV04&timeoutSec=30
[DEBUG]2021-05-08 16:43:57,935: GET: http://127.0.0.1:8999/api/agv/rollerRobotPush?agv=AGV04&timeoutSec=30 addr: 127.0.0.1
[DEBUG]2021-05-08 16:43:58,061: used 126ms 200 OK application/json;charset=utf-8, GET: http://127.0.0.1:8999/api/agv/rollerRobotPush?agv=AGV04&timeoutSec=30
[DEBUG]2021-05-08 16:43:58,103: [return] use 252 ms,http_get: http://127.0.0.1:8999/api/agv/rollerRobotPush?agv=AGV04&timeoutSec=30
[INFO]2021-05-08 16:43:58,128: task[60964f2473dabd1db0d9decc] update info: {'failMsg': '推杆推出三楼夹具点B', 'updateTime': datetime.datetime(2021, 5, 8, 16, 43, 58, 122325)}
[DEBUG]2021-05-08 16:43:58,170: task[60964f2473dabd1db0d9decc][AGV04] AP22(LM17) -> AP18(LM17) [RollerPushFinish] waitPushrodPush -> RollerPushFinish
[INFO]2021-05-08 16:43:58,532: this is handle taskStep=============>RollerPushFinish
[DEBUG]2021-05-08 16:43:58,549: send http_get: http://127.0.0.1:8999/api/agv/checkUnitloadStatus?agv=AGV04&timeoutSec=30&unitId=1
[DEBUG]2021-05-08 16:43:58,695: GET: http://127.0.0.1:8999/api/agv/checkUnitloadStatus?agv=AGV04&timeoutSec=30&unitId=1 addr: 127.0.0.1
[INFO]2021-05-08 16:43:58,771: AGV04 checkUnitloadStatus unitId: 1
[DEBUG]2021-05-08 16:43:58,800: used 105ms 200 OK application/json;charset=utf-8, GET: http://127.0.0.1:8999/api/agv/checkUnitloadStatus?agv=AGV04&timeoutSec=30&unitId=1
[DEBUG]2021-05-08 16:43:58,871: [return] use 322 ms,http_get: http://127.0.0.1:8999/api/agv/checkUnitloadStatus?agv=AGV04&timeoutSec=30&unitId=1
[CRITICAL]2021-05-08 16:44:01,874: readDIList error cause a error: ('http get', 'http://127.0.0.1:8999/api/remoteio/readDOList', {'id': 'upStation01'}, 'error:', 'timed out')
pid=7600, ppid=4848, tid=10368
Traceback (most recent call last):
  File "C:\Users\comba\Desktop\知识城地牛\knowledgeCity\common\webutility.py", line 103, in http_get
    f = urllib.request.urlopen(u,timeout=timeout)
  File "C:\Users\comba\AppData\Local\Programs\Python\Python37\lib\urllib\request.py", line 222, in urlopen
    return opener.open(url, data, timeout)
  File "C:\Users\comba\AppData\Local\Programs\Python\Python37\lib\urllib\request.py", line 525, in open
    response = self._open(req, data)
  File "C:\Users\comba\AppData\Local\Programs\Python\Python37\lib\urllib\request.py", line 543, in _open
    '_open', req)
  File "C:\Users\comba\AppData\Local\Programs\Python\Python37\lib\urllib\request.py", line 503, in _call_chain
    result = func(*args)
  File "C:\Users\comba\AppData\Local\Programs\Python\Python37\lib\urllib\request.py", line 1345, in http_open
    return self.do_open(http.client.HTTPConnection, req)
  File "C:\Users\comba\AppData\Local\Programs\Python\Python37\lib\urllib\request.py", line 1320, in do_open
    r = h.getresponse()
  File "C:\Users\comba\AppData\Local\Programs\Python\Python37\lib\http\client.py", line 1321, in getresponse
    response.begin()
  File "C:\Users\comba\AppData\Local\Programs\Python\Python37\lib\http\client.py", line 296, in begin
    version, status, reason = self._read_status()
  File "C:\Users\comba\AppData\Local\Programs\Python\Python37\lib\http\client.py", line 257, in _read_status
    line = str(self.fp.readline(_MAXLINE + 1), "iso-8859-1")
  File "C:\Users\comba\AppData\Local\Programs\Python\Python37\lib\socket.py", line 589, in readinto
    return self._sock.recv_into(b)
socket.timeout: timed out

During handling of the above exception, another exception occurred:

Traceback (most recent call last):
  File "C:\Users\comba\Desktop\知识城地牛\knowledgeCity\autoCtrl\deviceCtrl.py", line 71, in _monitorDevices
    s1 = ioApi.readDOList(devices[d]["io1"])["status"] #上板机
  File "..\remoteio\remoteioApi.py", line 73, in readDOList
    return _remoteio('/api/remoteio/readDOList', id, param)
  File "..\remoteio\remoteioApi.py", line 100, in _remoteio
    return http_get(url + apiurl, param)
  File "..\remoteio\remoteioApi.py", line 16, in http_get
    r = webutility.http_get(url, param)
  File "C:\Users\comba\Desktop\知识城地牛\knowledgeCity\common\webutility.py", line 105, in http_get
    raise Exception("http get",url,params,"error:",str(e))
Exception: ('http get', 'http://127.0.0.1:8999/api/remoteio/readDOList', {'id': 'upStation01'}, 'error:', 'timed out')

[DEBUG]2021-05-08 16:44:02,923: send http_get: http://127.0.0.1:8999/api/agv/checkUnitloadStatus?agv=AGV04&timeoutSec=30&unitId=1
[INFO]2021-05-08 16:44:02,988: remoteio is alarm: []
[DEBUG]2021-05-08 16:44:03,065: GET: http://127.0.0.1:8999/api/agv/checkUnitloadStatus?agv=AGV04&timeoutSec=30&unitId=1 addr: 127.0.0.1
[INFO]2021-05-08 16:44:03,209: AGV04 checkUnitloadStatus unitId: 1
[DEBUG]2021-05-08 16:44:03,244: used 179ms 200 OK application/json;charset=utf-8, GET: http://127.0.0.1:8999/api/agv/checkUnitloadStatus?agv=AGV04&timeoutSec=30&unitId=1
[DEBUG]2021-05-08 16:44:03,367: [return] use 444 ms,http_get: http://127.0.0.1:8999/api/agv/checkUnitloadStatus?agv=AGV04&timeoutSec=30&unitId=1
[WARN]2021-05-08 16:44:04,142: AGV04 low battery charge,batteryLevel= 0.252 start charge level= 0.400
[WARN]2021-05-08 16:44:04,174: AGV04 battery 0.252 check failed: isLocked
[DEBUG]2021-05-08 16:44:04,220: send http_get: http://127.0.0.1:8999/api/remoteio/readDOList?id=upStation01
[ERROR]2021-05-08 16:44:06,638: connect AGV01 failed timed out
[INFO]2021-05-08 16:44:06,662: AGV01 checkLink failed 172.16.217.209 19204
[WARN]2021-05-08 16:44:06,692: agvThread.AGV01[tid:13976] <lock name:agv.AGV01.lock_status,<locked _thread.RLock object owner=13976 count=1 at 0x000002029F97BA08>> ,hold 10165 ms
[INFO]2021-05-08 16:44:06,774: name=agvThread.AGV01, pid=7600, tid=13976
[01] File "C:/Users/comba/AppData/Local/Programs/Python/Python37/lib/threading.py", line 865, in run() 
[02] File "C:/Users/comba/Desktop/知识城地牛/knowledgeCity/agvCtrl/agvList.py", line 565, in run() 
[03] File "../driver/seerAgv/agvCtrl.py", line 36, in checkLink() 
[04] File "../driver/seerAgv/agvApi.py", line 184, in checkLink() 
[05] File "C:/Users/comba/Desktop/知识城地牛/knowledgeCity/common/lock.py", line 102, in release() 
[06] File "C:/Users/comba/Desktop/知识城地牛/knowledgeCity/common/enhance.py", line 268, in getTrace() 
[07] File "C:/Users/comba/Desktop/知识城地牛/knowledgeCity/common/enhance.py", line 248, in getThreadStack()
[ERROR]2021-05-08 16:44:07,130: connect AGV02 failed timed out
[INFO]2021-05-08 16:44:07,166: AGV02 checkLink failed 172.16.217.213 19204
[WARN]2021-05-08 16:44:07,193: agvThread.AGV02[tid:13684] <lock name:agv.AGV02.lock_status,<locked _thread.RLock object owner=13684 count=1 at 0x000002029F8CF5F8>> ,hold 10252 ms
[INFO]2021-05-08 16:44:07,262: name=agvThread.AGV02, pid=7600, tid=13684
[01] File "C:/Users/comba/AppData/Local/Programs/Python/Python37/lib/threading.py", line 865, in run() 
[02] File "C:/Users/comba/Desktop/知识城地牛/knowledgeCity/agvCtrl/agvList.py", line 565, in run() 
[03] File "../driver/seerAgv/agvCtrl.py", line 36, in checkLink() 
[04] File "../driver/seerAgv/agvApi.py", line 184, in checkLink() 
[05] File "C:/Users/comba/Desktop/知识城地牛/knowledgeCity/common/lock.py", line 102, in release() 
[06] File "C:/Users/comba/Desktop/知识城地牛/knowledgeCity/common/enhance.py", line 268, in getTrace() 
[07] File "C:/Users/comba/Desktop/知识城地牛/knowledgeCity/common/enhance.py", line 248, in getThreadStack()
[ERROR]2021-05-08 16:44:07,273: connect AGV03 failed timed out
[INFO]2021-05-08 16:44:07,343: AGV03 checkLink failed 172.16.217.121 19204
[WARN]2021-05-08 16:44:07,370: agvThread.AGV03[tid:13128] <lock name:agv.AGV03.lock_status,<locked _thread.RLock object owner=13128 count=1 at 0x000002029F97BC10>> ,hold 10201 ms
[INFO]2021-05-08 16:44:07,423: task[60964f2473dabd1db0d9decc] update info: {'step': 'waitPushrodUnpush', 'msg': '检测一层设置出料完成信号', 'updateTime': datetime.datetime(2021, 5, 8, 16, 44, 7, 393486)}
[WARN]2021-05-08 16:44:07,446: scada.60964f2473dabd1db0d9decc[tid:2564] <locked _thread.RLock object owner=2564 count=1 at 0x00000202A15BD4E0> ,hold 8914 ms
[INFO]2021-05-08 16:44:07,487: name=agvThread.AGV03, pid=7600, tid=13128
[01] File "C:/Users/comba/AppData/Local/Programs/Python/Python37/lib/threading.py", line 865, in run() 
[02] File "C:/Users/comba/Desktop/知识城地牛/knowledgeCity/agvCtrl/agvList.py", line 565, in run() 
[03] File "../driver/seerAgv/agvCtrl.py", line 36, in checkLink() 
[04] File "../driver/seerAgv/agvApi.py", line 184, in checkLink() 
[05] File "C:/Users/comba/Desktop/知识城地牛/knowledgeCity/common/lock.py", line 102, in release() 
[06] File "C:/Users/comba/Desktop/知识城地牛/knowledgeCity/common/enhance.py", line 268, in getTrace() 
[07] File "C:/Users/comba/Desktop/知识城地牛/knowledgeCity/common/enhance.py", line 248, in getThreadStack()
[INFO]2021-05-08 16:44:07,516: name=scada.60964f2473dabd1db0d9decc, pid=7600, tid=2564
[01] File "C:/Users/comba/AppData/Local/Programs/Python/Python37/lib/threading.py", line 865, in run() 
[02] File "C:/Users/comba/Desktop/知识城地牛/knowledgeCity/common/utility.py", line 167, in __call() 
[03] File "C:/Users/comba/Desktop/知识城地牛/knowledgeCity/autoCtrl/runTasks.py", line 917, in _taskFunc() 
[04] File "C:/Users/comba/Desktop/知识城地牛/knowledgeCity/common/lock.py", line 124, in _call() 
[05] File "C:/Users/comba/Desktop/知识城地牛/knowledgeCity/common/lock.py", line 102, in release() 
[06] File "C:/Users/comba/Desktop/知识城地牛/knowledgeCity/common/enhance.py", line 268, in getTrace() 
[07] File "C:/Users/comba/Desktop/知识城地牛/knowledgeCity/common/enhance.py", line 248, in getThreadStack()
[DEBUG]2021-05-08 16:44:07,587: task[60964f2473dabd1db0d9decc][AGV04] AP22(LM17) -> AP18(LM17) [waitPushrodUnpush] RollerPushFinish -> waitPushrodUnpush
[INFO]2021-05-08 16:44:07,965: this is handle taskStep=============>waitPushrodUnpush
[DEBUG]2021-05-08 16:44:07,983: send http_get: http://127.0.0.1:8999/api/agv/rollerRobotUnPush?agv=AGV04&timeoutSec=30
[DEBUG]2021-05-08 16:44:08,093: GET: http://127.0.0.1:8999/api/agv/rollerRobotUnPush?agv=AGV04&timeoutSec=30 addr: 127.0.0.1
[DEBUG]2021-05-08 16:44:08,187: used 94ms 200 OK application/json;charset=utf-8, GET: http://127.0.0.1:8999/api/agv/rollerRobotUnPush?agv=AGV04&timeoutSec=30
[DEBUG]2021-05-08 16:44:08,245: [return] use 262 ms,http_get: http://127.0.0.1:8999/api/agv/rollerRobotUnPush?agv=AGV04&timeoutSec=30
[DEBUG]2021-05-08 16:44:08,833: try connect AGV01 172.16.217.209:19204
[DEBUG]2021-05-08 16:44:09,307: try connect AGV02 172.16.217.213:19204
[DEBUG]2021-05-08 16:44:09,583: try connect AGV03 172.16.217.121:19204
[WARN]2021-05-08 16:44:09,687: worker 7[tid:12764] <locked _thread.RLock object owner=12764 count=1 at 0x000002029D8E0670> ,hold 22837 ms
[INFO]2021-05-08 16:44:09,834: name=worker 7, pid=7600, tid=12764
[01] File "C:/Users/comba/AppData/Local/Programs/Python/Python37/lib/threading.py", line 865, in run() 
[02] File "C:/Users/comba/AppData/Local/Programs/Python/Python37/lib/site-packages/paste/httpserver.py", line 895, in worker_thread_callback() 
[03] File "C:/Users/comba/AppData/Local/Programs/Python/Python37/lib/site-packages/paste/httpserver.py", line 1069, in <lambda>() 
[04] File "C:/Users/comba/AppData/Local/Programs/Python/Python37/lib/site-packages/paste/httpserver.py", line 1085, in process_request_in_thread() 
[05] File "C:/Users/comba/AppData/Local/Programs/Python/Python37/lib/socketserver.py", line 357, in finish_request() 
[06] File "C:/Users/comba/AppData/Local/Programs/Python/Python37/lib/socketserver.py", line 717, in __init__() 
[07] File "C:/Users/comba/AppData/Local/Programs/Python/Python37/lib/site-packages/paste/httpserver.py", line 459, in handle() 
[08] File "C:/Users/comba/AppData/Local/Programs/Python/Python37/lib/http/server.py", line 426, in handle() 
[09] File "C:/Users/comba/AppData/Local/Programs/Python/Python37/lib/site-packages/paste/httpserver.py", line 454, in handle_one_request() 
[10] File "C:/Users/comba/AppData/Local/Programs/Python/Python37/lib/site-packages/paste/httpserver.py", line 304, in wsgi_execute() 
[11] File "C:/Users/comba/AppData/Local/Programs/Python/Python37/lib/site-packages/paste/translogger.py", line 69, in __call__() 
[12] File "C:/Users/comba/AppData/Local/Programs/Python/Python37/lib/site-packages/bottle.py", line 979, in __call__() 
[13] File "C:/Users/comba/AppData/Local/Programs/Python/Python37/lib/site-packages/bottle.py", line 954, in wsgi() 
[14] File "C:/Users/comba/AppData/Local/Programs/Python/Python37/lib/site-packages/bottle.py", line 862, in _handle() 
[15] File "C:/Users/comba/AppData/Local/Programs/Python/Python37/lib/site-packages/bottle.py", line 1742, in wrapper() 
[16] File "C:/Users/comba/Desktop/知识城地牛/knowledgeCity/common/webutility.py", line 465, in _enable_cors() 
[17] File "C:/Users/comba/Desktop/知识城地牛/knowledgeCity/common/webutility.py", line 481, in _enable_cors() 
[18] File "C:/Users/comba/Desktop/知识城地牛/knowledgeCity/common/scadaUtility.py", line 45, in __call() 
[19] File "C:/Users/comba/Desktop/知识城地牛/knowledgeCity/remoteio/main_remoteio.py", line 87, in urlReadDOList() 
[20] File "../remoteio/remoteioMgr.py", line 158, in readDOList() 
[21] File "../remoteio/remoteioMgr.py", line 262, in readDOList() 
[22] File "C:/Users/comba/Desktop/知识城地牛/knowledgeCity/common/lock.py", line 124, in _call() 
[23] File "C:/Users/comba/Desktop/知识城地牛/knowledgeCity/common/lock.py", line 102, in release() 
[24] File "C:/Users/comba/Desktop/知识城地牛/knowledgeCity/common/enhance.py", line 268, in getTrace() 
[25] File "C:/Users/comba/Desktop/知识城地牛/knowledgeCity/common/enhance.py", line 248, in getThreadStack()
[CRITICAL]2021-05-08 16:44:09,971: upStation01 readDIList fail cause a error: [WinError 10060] 由于连接方在一段时间后没有正确答复或连接的主机没有反应，连接尝试失败。
pid=7600, ppid=4848, tid=12764
Traceback (most recent call last):
  File "..\remoteio\remoteioMgr.py", line 262, in readDOList
    return self._read(M30, IO_LENTH)
  File "C:\Users\comba\Desktop\知识城地牛\knowledgeCity\common\lock.py", line 122, in _call
    return func(*p,**pp)
  File "..\remoteio\remoteioMgr.py", line 311, in _read
    self.master.open()
  File "C:\Users\comba\Desktop\知识城地牛\knowledgeCity\common\modbusapi.py", line 60, in open
    self.master.open()
  File "C:\Users\comba\AppData\Local\Programs\Python\Python37\lib\site-packages\modbus_tk\modbus.py", line 99, in open
    self._do_open()
  File "C:\Users\comba\AppData\Local\Programs\Python\Python37\lib\site-packages\modbus_tk\modbus_tcp.py", line 173, in _do_open
    self._sock.connect((self._host, self._port))
TimeoutError: [WinError 10060] 由于连接方在一段时间后没有正确答复或连接的主机没有反应，连接尝试失败。

[CRITICAL]2021-05-08 16:44:10,095: invoke <function urlReadDOList at 0x000002029C40ED08> cause a error: [WinError 10060] 由于连接方在一段时间后没有正确答复或连接的主机没有反应，连接尝试失败。
pid=7600, ppid=4848, tid=12764
Traceback (most recent call last):
  File "C:\Users\comba\Desktop\知识城地牛\knowledgeCity\common\scadaUtility.py", line 45, in __call
    ret = func(*p,**pp)
  File "C:\Users\comba\Desktop\知识城地牛\knowledgeCity\remoteio\main_remoteio.py", line 87, in urlReadDOList
    return ioMgr.readDOList(id)
  File "..\remoteio\remoteioMgr.py", line 158, in readDOList
    result=remoteioInfo.readDOList()
  File "..\remoteio\remoteioMgr.py", line 262, in readDOList
    return self._read(M30, IO_LENTH)
  File "C:\Users\comba\Desktop\知识城地牛\knowledgeCity\common\lock.py", line 122, in _call
    return func(*p,**pp)
  File "..\remoteio\remoteioMgr.py", line 311, in _read
    self.master.open()
  File "C:\Users\comba\Desktop\知识城地牛\knowledgeCity\common\modbusapi.py", line 60, in open
    self.master.open()
  File "C:\Users\comba\AppData\Local\Programs\Python\Python37\lib\site-packages\modbus_tk\modbus.py", line 99, in open
    self._do_open()
  File "C:\Users\comba\AppData\Local\Programs\Python\Python37\lib\site-packages\modbus_tk\modbus_tcp.py", line 173, in _do_open
    self._sock.connect((self._host, self._port))
TimeoutError: [WinError 10060] 由于连接方在一段时间后没有正确答复或连接的主机没有反应，连接尝试失败。

[INFO]2021-05-08 16:44:12,295: task[60964f2473dabd1db0d9decc] update info: {'failMsg': '推杆收回三楼夹具点B', 'updateTime': datetime.datetime(2021, 5, 8, 16, 44, 12, 283386)}
[WARN]2021-05-08 16:44:12,319: scada.60964f2473dabd1db0d9decc[tid:2564] <locked _thread.RLock object owner=2564 count=1 at 0x00000202A15BD4E0> ,hold 4354 ms
[INFO]2021-05-08 16:44:12,381: name=scada.60964f2473dabd1db0d9decc, pid=7600, tid=2564
[01] File "C:/Users/comba/AppData/Local/Programs/Python/Python37/lib/threading.py", line 865, in run() 
[02] File "C:/Users/comba/Desktop/知识城地牛/knowledgeCity/common/utility.py", line 167, in __call() 
[03] File "C:/Users/comba/Desktop/知识城地牛/knowledgeCity/autoCtrl/runTasks.py", line 917, in _taskFunc() 
[04] File "C:/Users/comba/Desktop/知识城地牛/knowledgeCity/common/lock.py", line 124, in _call() 
[05] File "C:/Users/comba/Desktop/知识城地牛/knowledgeCity/common/lock.py", line 102, in release() 
[06] File "C:/Users/comba/Desktop/知识城地牛/knowledgeCity/common/enhance.py", line 268, in getTrace() 
[07] File "C:/Users/comba/Desktop/知识城地牛/knowledgeCity/common/enhance.py", line 248, in getThreadStack()
[DEBUG]2021-05-08 16:44:12,427: task[60964f2473dabd1db0d9decc][AGV04] AP22(LM17) -> AP18(LM17) [waitDestPreLoc] waitPushrodUnpush -> waitDestPreLoc
[INFO]2021-05-08 16:44:12,791: this is handle taskStep=============>waitDestPreLoc
[INFO]2021-05-08 16:44:12,813: task: prepoint locked  60964f2473dabd1db0d9decc comba-ZXC-F3.AP18
[INFO]2021-05-08 16:44:12,836: task[60964f2473dabd1db0d9decc] update info: {'failMsg': '前往AP18工位点放下货架', 'updateTime': datetime.datetime(2021, 5, 8, 16, 44, 12, 825931)}
[DEBUG]2021-05-08 16:44:12,866: task[60964f2473dabd1db0d9decc][AGV04] AP22(LM17) -> AP18(LM17) [dropPayloadMove] waitDestPreLoc -> dropPayloadMove
[INFO]2021-05-08 16:44:13,228: this is handle taskStep=============>dropPayloadMove
[DEBUG]2021-05-08 16:44:13,254: GET: http://127.0.0.1:8999/api/agv/move?WorkPlace=true&agv=AGV04&agvId=AGV04&appName=akmTask&direction=None&floorId=comba-ZXC-F3&isRotate&loc=comba-ZXC-F3.AP18&location=AP18&p_direction=0.0&pgv_type=1&recognize=False&result=True&resultDesc=None&seer_jackup=JackUnload&taskId=60964f2473dabd1db0d9decc_4&taskType=scadaTask&timeoutSec=86400&use_pgv=False addr: 127.0.0.1
[INFO]2021-05-08 16:44:13,260: Begin: AGV04 move from comba-ZXC-F3.AP22 to comba-ZXC-F3.AP18 by paths: [('comba-ZXC-F3', ['AP22', 'LM19', 'LM20', 'LM21', 'LM17', 'AP18'], 6.5686328999305434)] task: 60964f2473dabd1db0d9decc_4 timeout 86400 used 5 ms
[DEBUG]2021-05-08 16:44:13,261: used 7ms 200 OK application/json;charset=utf-8, GET: http://127.0.0.1:8999/api/agv/move?WorkPlace=true&agv=AGV04&agvId=AGV04&appName=akmTask&direction=None&floorId=comba-ZXC-F3&isRotate&loc=comba-ZXC-F3.AP18&location=AP18&p_direction=0.0&pgv_type=1&recognize=False&result=True&resultDesc=None&seer_jackup=JackUnload&taskId=60964f2473dabd1db0d9decc_4&taskType=scadaTask&timeoutSec=86400&use_pgv=False
[INFO]2021-05-08 16:44:13,263: task[60964f2473dabd1db0d9decc] update info: {'step': 'dropPayload', 'updateTime': datetime.datetime(2021, 5, 8, 16, 44, 13, 263750)}
[DEBUG]2021-05-08 16:44:13,264: task[60964f2473dabd1db0d9decc][AGV04] AP22(LM17) -> AP18(LM17) [dropPayload] dropPayloadMove -> dropPayload
[INFO]2021-05-08 16:44:13,567: this is handle taskStep=============>dropPayload
[INFO]2021-05-08 16:44:13,875: this is handle taskStep=============>dropPayload
[DEBUG]2021-05-08 16:44:13,894: agvInfo: AGV04 comba-ZXC-F3.AP22 move to comba-ZXC-F3.LM19 ,taskId 60964f2473dabd1db0d9decc_4
[INFO]2021-05-08 16:44:14,180: this is handle taskStep=============>dropPayload
[INFO]2021-05-08 16:44:14,484: this is handle taskStep=============>dropPayload
[INFO]2021-05-08 16:44:14,787: this is handle taskStep=============>dropPayload
[INFO]2021-05-08 16:44:15,092: this is handle taskStep=============>dropPayload
[INFO]2021-05-08 16:44:15,396: this is handle taskStep=============>dropPayload
[DEBUG]2021-05-08 16:44:15,608: AGV04 turn to wait check cur AP22 next LM20 0.912 False
[INFO]2021-05-08 16:44:15,699: this is handle taskStep=============>dropPayload
[INFO]2021-05-08 16:44:16,002: this is handle taskStep=============>dropPayload
[DEBUG]2021-05-08 16:44:16,123: agvInfo: AGV04 comba-ZXC-F3.AP22 move to comba-ZXC-F3.LM20 ,taskId 60964f2473dabd1db0d9decc_4
[INFO]2021-05-08 16:44:16,305: this is handle taskStep=============>dropPayload
[INFO]2021-05-08 16:44:16,607: this is handle taskStep=============>dropPayload
[INFO]2021-05-08 16:44:16,910: this is handle taskStep=============>dropPayload
[INFO]2021-05-08 16:44:17,216: this is handle taskStep=============>dropPayload
[DEBUG]2021-05-08 16:44:17,331: AGV04 turn to wait check cur AP22 next LM21 0.759 False
[INFO]2021-05-08 16:44:17,521: this is handle taskStep=============>dropPayload
[INFO]2021-05-08 16:44:17,823: this is handle taskStep=============>dropPayload
[DEBUG]2021-05-08 16:44:17,838: agvInfo: AGV04 comba-ZXC-F3.AP22 move to comba-ZXC-F3.LM21 ,taskId 60964f2473dabd1db0d9decc_4
[INFO]2021-05-08 16:44:18,126: this is handle taskStep=============>dropPayload
[INFO]2021-05-08 16:44:18,429: this is handle taskStep=============>dropPayload
[DEBUG]2021-05-08 16:44:18,530: AGV04 set loc comba-ZXC-F3.LM19 ,old AP22 (6.14,5.80)
[INFO]2021-05-08 16:44:18,734: this is handle taskStep=============>dropPayload
[ERROR]2021-05-08 16:44:18,885: connect AGV01 failed timed out
[INFO]2021-05-08 16:44:18,886: AGV01 checkLink failed 172.16.217.209 19204
[WARN]2021-05-08 16:44:18,887: agvThread.AGV01[tid:13976] <lock name:agv.AGV01.lock_status,<locked _thread.RLock object owner=13976 count=1 at 0x000002029F97BA08>> ,hold 10054 ms
[INFO]2021-05-08 16:44:18,888: name=agvThread.AGV01, pid=7600, tid=13976
[01] File "C:/Users/comba/AppData/Local/Programs/Python/Python37/lib/threading.py", line 865, in run() 
[02] File "C:/Users/comba/Desktop/知识城地牛/knowledgeCity/agvCtrl/agvList.py", line 565, in run() 
[03] File "../driver/seerAgv/agvCtrl.py", line 36, in checkLink() 
[04] File "../driver/seerAgv/agvApi.py", line 184, in checkLink() 
[05] File "C:/Users/comba/Desktop/知识城地牛/knowledgeCity/common/lock.py", line 102, in release() 
[06] File "C:/Users/comba/Desktop/知识城地牛/knowledgeCity/common/enhance.py", line 268, in getTrace() 
[07] File "C:/Users/comba/Desktop/知识城地牛/knowledgeCity/common/enhance.py", line 248, in getThreadStack()
[INFO]2021-05-08 16:44:19,038: this is handle taskStep=============>dropPayload
[CRITICAL]2021-05-08 16:44:19,319: readDIList error cause a error: ('http get', 'http://127.0.0.1:8999/api/remoteio/readDOList', {'id': 'upStation01'}, 'error:', 'timed out')
pid=7600, ppid=4848, tid=10368
Traceback (most recent call last):
  File "C:\Users\comba\Desktop\知识城地牛\knowledgeCity\common\webutility.py", line 103, in http_get
    f = urllib.request.urlopen(u,timeout=timeout)
  File "C:\Users\comba\AppData\Local\Programs\Python\Python37\lib\urllib\request.py", line 222, in urlopen
    return opener.open(url, data, timeout)
  File "C:\Users\comba\AppData\Local\Programs\Python\Python37\lib\urllib\request.py", line 525, in open
    response = self._open(req, data)
  File "C:\Users\comba\AppData\Local\Programs\Python\Python37\lib\urllib\request.py", line 543, in _open
    '_open', req)
  File "C:\Users\comba\AppData\Local\Programs\Python\Python37\lib\urllib\request.py", line 503, in _call_chain
    result = func(*args)
  File "C:\Users\comba\AppData\Local\Programs\Python\Python37\lib\urllib\request.py", line 1345, in http_open
    return self.do_open(http.client.HTTPConnection, req)
  File "C:\Users\comba\AppData\Local\Programs\Python\Python37\lib\urllib\request.py", line 1320, in do_open
    r = h.getresponse()
  File "C:\Users\comba\AppData\Local\Programs\Python\Python37\lib\http\client.py", line 1321, in getresponse
    response.begin()
  File "C:\Users\comba\AppData\Local\Programs\Python\Python37\lib\http\client.py", line 296, in begin
    version, status, reason = self._read_status()
  File "C:\Users\comba\AppData\Local\Programs\Python\Python37\lib\http\client.py", line 257, in _read_status
    line = str(self.fp.readline(_MAXLINE + 1), "iso-8859-1")
  File "C:\Users\comba\AppData\Local\Programs\Python\Python37\lib\socket.py", line 589, in readinto
    return self._sock.recv_into(b)
socket.timeout: timed out

During handling of the above exception, another exception occurred:

Traceback (most recent call last):
  File "C:\Users\comba\Desktop\知识城地牛\knowledgeCity\autoCtrl\deviceCtrl.py", line 71, in _monitorDevices
    s1 = ioApi.readDOList(devices[d]["io1"])["status"] #上板机
  File "..\remoteio\remoteioApi.py", line 73, in readDOList
    return _remoteio('/api/remoteio/readDOList', id, param)
  File "..\remoteio\remoteioApi.py", line 100, in _remoteio
    return http_get(url + apiurl, param)
  File "..\remoteio\remoteioApi.py", line 16, in http_get
    r = webutility.http_get(url, param)
  File "C:\Users\comba\Desktop\知识城地牛\knowledgeCity\common\webutility.py", line 105, in http_get
    raise Exception("http get",url,params,"error:",str(e))
Exception: ('http get', 'http://127.0.0.1:8999/api/remoteio/readDOList', {'id': 'upStation01'}, 'error:', 'timed out')

[INFO]2021-05-08 16:44:19,340: this is handle taskStep=============>dropPayload
[ERROR]2021-05-08 16:44:19,389: connect AGV02 failed timed out
[INFO]2021-05-08 16:44:19,390: AGV02 checkLink failed 172.16.217.213 19204
[WARN]2021-05-08 16:44:19,391: agvThread.AGV02[tid:13684] <lock name:agv.AGV02.lock_status,<locked _thread.RLock object owner=13684 count=1 at 0x000002029F8CF5F8>> ,hold 10084 ms
[INFO]2021-05-08 16:44:19,392: name=agvThread.AGV02, pid=7600, tid=13684
[01] File "C:/Users/comba/AppData/Local/Programs/Python/Python37/lib/threading.py", line 865, in run() 
[02] File "C:/Users/comba/Desktop/知识城地牛/knowledgeCity/agvCtrl/agvList.py", line 565, in run() 
[03] File "../driver/seerAgv/agvCtrl.py", line 36, in checkLink() 
[04] File "../driver/seerAgv/agvApi.py", line 184, in checkLink() 
[05] File "C:/Users/comba/Desktop/知识城地牛/knowledgeCity/common/lock.py", line 102, in release() 
[06] File "C:/Users/comba/Desktop/知识城地牛/knowledgeCity/common/enhance.py", line 268, in getTrace() 
[07] File "C:/Users/comba/Desktop/知识城地牛/knowledgeCity/common/enhance.py", line 248, in getThreadStack()
[ERROR]2021-05-08 16:44:19,629: connect AGV03 failed timed out
[INFO]2021-05-08 16:44:19,630: AGV03 checkLink failed 172.16.217.121 19204
[WARN]2021-05-08 16:44:19,633: agvThread.AGV03[tid:13128] <lock name:agv.AGV03.lock_status,<locked _thread.RLock object owner=13128 count=1 at 0x000002029F97BC10>> ,hold 10050 ms
[INFO]2021-05-08 16:44:19,635: name=agvThread.AGV03, pid=7600, tid=13128
[01] File "C:/Users/comba/AppData/Local/Programs/Python/Python37/lib/threading.py", line 865, in run() 
[02] File "C:/Users/comba/Desktop/知识城地牛/knowledgeCity/agvCtrl/agvList.py", line 565, in run() 
[03] File "../driver/seerAgv/agvCtrl.py", line 36, in checkLink() 
[04] File "../driver/seerAgv/agvApi.py", line 184, in checkLink() 
[05] File "C:/Users/comba/Desktop/知识城地牛/knowledgeCity/common/lock.py", line 102, in release() 
[06] File "C:/Users/comba/Desktop/知识城地牛/knowledgeCity/common/enhance.py", line 268, in getTrace() 
[07] File "C:/Users/comba/Desktop/知识城地牛/knowledgeCity/common/enhance.py", line 248, in getThreadStack()
[INFO]2021-05-08 16:44:19,643: this is handle taskStep=============>dropPayload
[INFO]2021-05-08 16:44:19,945: this is handle taskStep=============>dropPayload
[INFO]2021-05-08 16:44:20,249: this is handle taskStep=============>dropPayload
[INFO]2021-05-08 16:44:20,325: remoteio is alarm: []
[INFO]2021-05-08 16:44:20,551: this is handle taskStep=============>dropPayload
[INFO]2021-05-08 16:44:20,854: this is handle taskStep=============>dropPayload
[DEBUG]2021-05-08 16:44:20,891: try connect AGV01 172.16.217.209:19204
[INFO]2021-05-08 16:44:21,157: this is handle taskStep=============>dropPayload
[WARN]2021-05-08 16:44:21,330: AGV04 low battery charge,batteryLevel= 0.252 start charge level= 0.400
[WARN]2021-05-08 16:44:21,331: AGV04 battery 0.252 check failed: isLocked
[DEBUG]2021-05-08 16:44:21,332: send http_get: http://127.0.0.1:8999/api/remoteio/readDOList?id=upStation01
[DEBUG]2021-05-08 16:44:21,394: try connect AGV02 172.16.217.213:19204
[INFO]2021-05-08 16:44:21,460: this is handle taskStep=============>dropPayload
[DEBUG]2021-05-08 16:44:21,638: try connect AGV03 172.16.217.121:19204
[INFO]2021-05-08 16:44:21,763: this is handle taskStep=============>dropPayload
[INFO]2021-05-08 16:44:22,066: this is handle taskStep=============>dropPayload
[INFO]2021-05-08 16:44:22,368: this is handle taskStep=============>dropPayload
[INFO]2021-05-08 16:44:22,671: this is handle taskStep=============>dropPayload
[INFO]2021-05-08 16:44:22,974: this is handle taskStep=============>dropPayload
[INFO]2021-05-08 16:44:23,280: this is handle taskStep=============>dropPayload
[INFO]2021-05-08 16:44:23,582: this is handle taskStep=============>dropPayload
[INFO]2021-05-08 16:44:23,885: this is handle taskStep=============>dropPayload
[INFO]2021-05-08 16:44:24,188: this is handle taskStep=============>dropPayload
[INFO]2021-05-08 16:44:24,492: this is handle taskStep=============>dropPayload
[INFO]2021-05-08 16:44:24,795: this is handle taskStep=============>dropPayload
[DEBUG]2021-05-08 16:44:24,898: AGV04 set loc comba-ZXC-F3.LM20 ,old LM19 (6.05,6.18)
[INFO]2021-05-08 16:44:25,098: this is handle taskStep=============>dropPayload
[INFO]2021-05-08 16:44:25,400: this is handle taskStep=============>dropPayload
[INFO]2021-05-08 16:44:25,702: this is handle taskStep=============>dropPayload
[INFO]2021-05-08 16:44:26,006: this is handle taskStep=============>dropPayload
[INFO]2021-05-08 16:44:26,310: this is handle taskStep=============>dropPayload
[INFO]2021-05-08 16:44:26,616: this is handle taskStep=============>dropPayload
[INFO]2021-05-08 16:44:26,919: this is handle taskStep=============>dropPayload
[INFO]2021-05-08 16:44:27,222: this is handle taskStep=============>dropPayload
[INFO]2021-05-08 16:44:27,525: this is handle taskStep=============>dropPayload
[INFO]2021-05-08 16:44:27,827: this is handle taskStep=============>dropPayload
[INFO]2021-05-08 16:44:28,130: this is handle taskStep=============>dropPayload
[INFO]2021-05-08 16:44:28,433: this is handle taskStep=============>dropPayload
[INFO]2021-05-08 16:44:28,738: this is handle taskStep=============>dropPayload
[INFO]2021-05-08 16:44:29,040: this is handle taskStep=============>dropPayload
[INFO]2021-05-08 16:44:29,343: this is handle taskStep=============>dropPayload
[INFO]2021-05-08 16:44:29,651: this is handle taskStep=============>dropPayload
[INFO]2021-05-08 16:44:29,953: this is handle taskStep=============>dropPayload
[INFO]2021-05-08 16:44:30,256: this is handle taskStep=============>dropPayload
[INFO]2021-05-08 16:44:30,560: this is handle taskStep=============>dropPayload
[INFO]2021-05-08 16:44:30,868: this is handle taskStep=============>dropPayload
[WARN]2021-05-08 16:44:30,883: worker 2[tid:13448] <locked _thread.RLock object owner=13448 count=1 at 0x000002029D8E0670> ,hold 26569 ms
[INFO]2021-05-08 16:44:30,886: name=worker 2, pid=7600, tid=13448
[01] File "C:/Users/comba/AppData/Local/Programs/Python/Python37/lib/threading.py", line 865, in run() 
[02] File "C:/Users/comba/AppData/Local/Programs/Python/Python37/lib/site-packages/paste/httpserver.py", line 895, in worker_thread_callback() 
[03] File "C:/Users/comba/AppData/Local/Programs/Python/Python37/lib/site-packages/paste/httpserver.py", line 1069, in <lambda>() 
[04] File "C:/Users/comba/AppData/Local/Programs/Python/Python37/lib/site-packages/paste/httpserver.py", line 1085, in process_request_in_thread() 
[05] File "C:/Users/comba/AppData/Local/Programs/Python/Python37/lib/socketserver.py", line 357, in finish_request() 
[06] File "C:/Users/comba/AppData/Local/Programs/Python/Python37/lib/socketserver.py", line 717, in __init__() 
[07] File "C:/Users/comba/AppData/Local/Programs/Python/Python37/lib/site-packages/paste/httpserver.py", line 459, in handle() 
[08] File "C:/Users/comba/AppData/Local/Programs/Python/Python37/lib/http/server.py", line 426, in handle() 
[09] File "C:/Users/comba/AppData/Local/Programs/Python/Python37/lib/site-packages/paste/httpserver.py", line 454, in handle_one_request() 
[10] File "C:/Users/comba/AppData/Local/Programs/Python/Python37/lib/site-packages/paste/httpserver.py", line 304, in wsgi_execute() 
[11] File "C:/Users/comba/AppData/Local/Programs/Python/Python37/lib/site-packages/paste/translogger.py", line 69, in __call__() 
[12] File "C:/Users/comba/AppData/Local/Programs/Python/Python37/lib/site-packages/bottle.py", line 979, in __call__() 
[13] File "C:/Users/comba/AppData/Local/Programs/Python/Python37/lib/site-packages/bottle.py", line 954, in wsgi() 
[14] File "C:/Users/comba/AppData/Local/Programs/Python/Python37/lib/site-packages/bottle.py", line 862, in _handle() 
[15] File "C:/Users/comba/AppData/Local/Programs/Python/Python37/lib/site-packages/bottle.py", line 1742, in wrapper() 
[16] File "C:/Users/comba/Desktop/知识城地牛/knowledgeCity/common/webutility.py", line 465, in _enable_cors() 
[17] File "C:/Users/comba/Desktop/知识城地牛/knowledgeCity/common/webutility.py", line 481, in _enable_cors() 
[18] File "C:/Users/comba/Desktop/知识城地牛/knowledgeCity/common/scadaUtility.py", line 45, in __call() 
[19] File "C:/Users/comba/Desktop/知识城地牛/knowledgeCity/remoteio/main_remoteio.py", line 87, in urlReadDOList() 
[20] File "../remoteio/remoteioMgr.py", line 158, in readDOList() 
[21] File "../remoteio/remoteioMgr.py", line 262, in readDOList() 
[22] File "C:/Users/comba/Desktop/知识城地牛/knowledgeCity/common/lock.py", line 124, in _call() 
[23] File "C:/Users/comba/Desktop/知识城地牛/knowledgeCity/common/lock.py", line 102, in release() 
[24] File "C:/Users/comba/Desktop/知识城地牛/knowledgeCity/common/enhance.py", line 268, in getTrace() 
[25] File "C:/Users/comba/Desktop/知识城地牛/knowledgeCity/common/enhance.py", line 248, in getThreadStack()
[ERROR]2021-05-08 16:44:30,893: connect AGV01 failed timed out
[CRITICAL]2021-05-08 16:44:30,902: upStation01 readDIList fail cause a error: [WinError 10060] 由于连接方在一段时间后没有正确答复或连接的主机没有反应，连接尝试失败。
pid=7600, ppid=4848, tid=13448
Traceback (most recent call last):
  File "..\remoteio\remoteioMgr.py", line 262, in readDOList
    return self._read(M30, IO_LENTH)
  File "C:\Users\comba\Desktop\知识城地牛\knowledgeCity\common\lock.py", line 122, in _call
    return func(*p,**pp)
  File "..\remoteio\remoteioMgr.py", line 311, in _read
    self.master.open()
  File "C:\Users\comba\Desktop\知识城地牛\knowledgeCity\common\modbusapi.py", line 60, in open
    self.master.open()
  File "C:\Users\comba\AppData\Local\Programs\Python\Python37\lib\site-packages\modbus_tk\modbus.py", line 99, in open
    self._do_open()
  File "C:\Users\comba\AppData\Local\Programs\Python\Python37\lib\site-packages\modbus_tk\modbus_tcp.py", line 173, in _do_open
    self._sock.connect((self._host, self._port))
TimeoutError: [WinError 10060] 由于连接方在一段时间后没有正确答复或连接的主机没有反应，连接尝试失败。

[INFO]2021-05-08 16:44:30,902: AGV01 checkLink failed 172.16.217.209 19204
[CRITICAL]2021-05-08 16:44:30,909: invoke <function urlReadDOList at 0x000002029C40ED08> cause a error: [WinError 10060] 由于连接方在一段时间后没有正确答复或连接的主机没有反应，连接尝试失败。
pid=7600, ppid=4848, tid=13448
Traceback (most recent call last):
  File "C:\Users\comba\Desktop\知识城地牛\knowledgeCity\common\scadaUtility.py", line 45, in __call
    ret = func(*p,**pp)
  File "C:\Users\comba\Desktop\知识城地牛\knowledgeCity\remoteio\main_remoteio.py", line 87, in urlReadDOList
    return ioMgr.readDOList(id)
  File "..\remoteio\remoteioMgr.py", line 158, in readDOList
    result=remoteioInfo.readDOList()
  File "..\remoteio\remoteioMgr.py", line 262, in readDOList
    return self._read(M30, IO_LENTH)
  File "C:\Users\comba\Desktop\知识城地牛\knowledgeCity\common\lock.py", line 122, in _call
    return func(*p,**pp)
  File "..\remoteio\remoteioMgr.py", line 311, in _read
    self.master.open()
  File "C:\Users\comba\Desktop\知识城地牛\knowledgeCity\common\modbusapi.py", line 60, in open
    self.master.open()
  File "C:\Users\comba\AppData\Local\Programs\Python\Python37\lib\site-packages\modbus_tk\modbus.py", line 99, in open
    self._do_open()
  File "C:\Users\comba\AppData\Local\Programs\Python\Python37\lib\site-packages\modbus_tk\modbus_tcp.py", line 173, in _do_open
    self._sock.connect((self._host, self._port))
TimeoutError: [WinError 10060] 由于连接方在一段时间后没有正确答复或连接的主机没有反应，连接尝试失败。

[WARN]2021-05-08 16:44:30,909: agvThread.AGV01[tid:13976] <lock name:agv.AGV01.lock_status,<locked _thread.RLock object owner=13976 count=1 at 0x000002029F97BA08>> ,hold 10018 ms
[INFO]2021-05-08 16:44:30,913: name=agvThread.AGV01, pid=7600, tid=13976
[01] File "C:/Users/comba/AppData/Local/Programs/Python/Python37/lib/threading.py", line 865, in run() 
[02] File "C:/Users/comba/Desktop/知识城地牛/knowledgeCity/agvCtrl/agvList.py", line 565, in run() 
[03] File "../driver/seerAgv/agvCtrl.py", line 36, in checkLink() 
[04] File "../driver/seerAgv/agvApi.py", line 184, in checkLink() 
[05] File "C:/Users/comba/Desktop/知识城地牛/knowledgeCity/common/lock.py", line 102, in release() 
[06] File "C:/Users/comba/Desktop/知识城地牛/knowledgeCity/common/enhance.py", line 268, in getTrace() 
[07] File "C:/Users/comba/Desktop/知识城地牛/knowledgeCity/common/enhance.py", line 248, in getThreadStack()
[INFO]2021-05-08 16:44:31,172: this is handle taskStep=============>dropPayload
[ERROR]2021-05-08 16:44:31,397: connect AGV02 failed timed out
[INFO]2021-05-08 16:44:31,399: AGV02 checkLink failed 172.16.217.213 19204
[WARN]2021-05-08 16:44:31,400: agvThread.AGV02[tid:13684] <lock name:agv.AGV02.lock_status,<locked _thread.RLock object owner=13684 count=1 at 0x000002029F8CF5F8>> ,hold 10006 ms
[INFO]2021-05-08 16:44:31,402: name=agvThread.AGV02, pid=7600, tid=13684
[01] File "C:/Users/comba/AppData/Local/Programs/Python/Python37/lib/threading.py", line 865, in run() 
[02] File "C:/Users/comba/Desktop/知识城地牛/knowledgeCity/agvCtrl/agvList.py", line 565, in run() 
[03] File "../driver/seerAgv/agvCtrl.py", line 36, in checkLink() 
[04] File "../driver/seerAgv/agvApi.py", line 184, in checkLink() 
[05] File "C:/Users/comba/Desktop/知识城地牛/knowledgeCity/common/lock.py", line 102, in release() 
[06] File "C:/Users/comba/Desktop/知识城地牛/knowledgeCity/common/enhance.py", line 268, in getTrace() 
[07] File "C:/Users/comba/Desktop/知识城地牛/knowledgeCity/common/enhance.py", line 248, in getThreadStack()
[INFO]2021-05-08 16:44:31,475: this is handle taskStep=============>dropPayload
[ERROR]2021-05-08 16:44:31,639: connect AGV03 failed timed out
[INFO]2021-05-08 16:44:31,640: AGV03 checkLink failed 172.16.217.121 19204
[WARN]2021-05-08 16:44:31,641: agvThread.AGV03[tid:13128] <lock name:agv.AGV03.lock_status,<locked _thread.RLock object owner=13128 count=1 at 0x000002029F97BC10>> ,hold 10003 ms
[INFO]2021-05-08 16:44:31,642: name=agvThread.AGV03, pid=7600, tid=13128
[01] File "C:/Users/comba/AppData/Local/Programs/Python/Python37/lib/threading.py", line 865, in run() 
[02] File "C:/Users/comba/Desktop/知识城地牛/knowledgeCity/agvCtrl/agvList.py", line 565, in run() 
[03] File "../driver/seerAgv/agvCtrl.py", line 36, in checkLink() 
[04] File "../driver/seerAgv/agvApi.py", line 184, in checkLink() 
[05] File "C:/Users/comba/Desktop/知识城地牛/knowledgeCity/common/lock.py", line 102, in release() 
[06] File "C:/Users/comba/Desktop/知识城地牛/knowledgeCity/common/enhance.py", line 268, in getTrace() 
[07] File "C:/Users/comba/Desktop/知识城地牛/knowledgeCity/common/enhance.py", line 248, in getThreadStack()
[INFO]2021-05-08 16:44:31,778: this is handle taskStep=============>dropPayload
[INFO]2021-05-08 16:44:32,082: this is handle taskStep=============>dropPayload
[INFO]2021-05-08 16:44:32,385: this is handle taskStep=============>dropPayload
[INFO]2021-05-08 16:44:32,688: this is handle taskStep=============>dropPayload
[DEBUG]2021-05-08 16:44:32,916: try connect AGV01 172.16.217.209:19204
[INFO]2021-05-08 16:44:32,992: this is handle taskStep=============>dropPayload
[INFO]2021-05-08 16:44:33,295: this is handle taskStep=============>dropPayload
[DEBUG]2021-05-08 16:44:33,404: try connect AGV02 172.16.217.213:19204
[INFO]2021-05-08 16:44:33,597: this is handle taskStep=============>dropPayload
[DEBUG]2021-05-08 16:44:33,644: try connect AGV03 172.16.217.121:19204
[INFO]2021-05-08 16:44:33,900: this is handle taskStep=============>dropPayload
[INFO]2021-05-08 16:44:34,207: this is handle taskStep=============>dropPayload
[INFO]2021-05-08 16:44:34,509: this is handle taskStep=============>dropPayload
[INFO]2021-05-08 16:44:34,813: this is handle taskStep=============>dropPayload
[INFO]2021-05-08 16:44:35,116: this is handle taskStep=============>dropPayload
[DEBUG]2021-05-08 16:44:35,388: AGV04 turn to wait check cur LM20 next LM17 0.962 False
[INFO]2021-05-08 16:44:35,419: this is handle taskStep=============>dropPayload
[INFO]2021-05-08 16:44:35,721: this is handle taskStep=============>dropPayload
[DEBUG]2021-05-08 16:44:35,901: agvInfo: AGV04 comba-ZXC-F3.LM20 move to comba-ZXC-F3.LM17 ,taskId 60964f2473dabd1db0d9decc_4
[INFO]2021-05-08 16:44:36,025: this is handle taskStep=============>dropPayload
[INFO]2021-05-08 16:44:36,327: this is handle taskStep=============>dropPayload
[CRITICAL]2021-05-08 16:44:36,351: readDIList error cause a error: ('http get', 'http://127.0.0.1:8999/api/remoteio/readDOList', {'id': 'upStation01'}, 'error:', 'timed out')
pid=7600, ppid=4848, tid=10368
Traceback (most recent call last):
  File "C:\Users\comba\Desktop\知识城地牛\knowledgeCity\common\webutility.py", line 103, in http_get
    f = urllib.request.urlopen(u,timeout=timeout)
  File "C:\Users\comba\AppData\Local\Programs\Python\Python37\lib\urllib\request.py", line 222, in urlopen
    return opener.open(url, data, timeout)
  File "C:\Users\comba\AppData\Local\Programs\Python\Python37\lib\urllib\request.py", line 525, in open
    response = self._open(req, data)
  File "C:\Users\comba\AppData\Local\Programs\Python\Python37\lib\urllib\request.py", line 543, in _open
    '_open', req)
  File "C:\Users\comba\AppData\Local\Programs\Python\Python37\lib\urllib\request.py", line 503, in _call_chain
    result = func(*args)
  File "C:\Users\comba\AppData\Local\Programs\Python\Python37\lib\urllib\request.py", line 1345, in http_open
    return self.do_open(http.client.HTTPConnection, req)
  File "C:\Users\comba\AppData\Local\Programs\Python\Python37\lib\urllib\request.py", line 1320, in do_open
    r = h.getresponse()
  File "C:\Users\comba\AppData\Local\Programs\Python\Python37\lib\http\client.py", line 1321, in getresponse
    response.begin()
  File "C:\Users\comba\AppData\Local\Programs\Python\Python37\lib\http\client.py", line 296, in begin
    version, status, reason = self._read_status()
  File "C:\Users\comba\AppData\Local\Programs\Python\Python37\lib\http\client.py", line 257, in _read_status
    line = str(self.fp.readline(_MAXLINE + 1), "iso-8859-1")
  File "C:\Users\comba\AppData\Local\Programs\Python\Python37\lib\socket.py", line 589, in readinto
    return self._sock.recv_into(b)
socket.timeout: timed out

During handling of the above exception, another exception occurred:

Traceback (most recent call last):
  File "C:\Users\comba\Desktop\知识城地牛\knowledgeCity\autoCtrl\deviceCtrl.py", line 71, in _monitorDevices
    s1 = ioApi.readDOList(devices[d]["io1"])["status"] #上板机
  File "..\remoteio\remoteioApi.py", line 73, in readDOList
    return _remoteio('/api/remoteio/readDOList', id, param)
  File "..\remoteio\remoteioApi.py", line 100, in _remoteio
    return http_get(url + apiurl, param)
  File "..\remoteio\remoteioApi.py", line 16, in http_get
    r = webutility.http_get(url, param)
  File "C:\Users\comba\Desktop\知识城地牛\knowledgeCity\common\webutility.py", line 105, in http_get
    raise Exception("http get",url,params,"error:",str(e))
Exception: ('http get', 'http://127.0.0.1:8999/api/remoteio/readDOList', {'id': 'upStation01'}, 'error:', 'timed out')

[DEBUG]2021-05-08 16:44:36,607: AGV04 turn to wait check cur LM20 next AP18 0.756 False
[INFO]2021-05-08 16:44:36,631: this is handle taskStep=============>dropPayload
[INFO]2021-05-08 16:44:36,934: this is handle taskStep=============>dropPayload
[DEBUG]2021-05-08 16:44:37,010: AGV04 set loc comba-ZXC-F3.LM21 ,old LM20 (9.06,6.18)
[DEBUG]2021-05-08 16:44:37,115: agvInfo: AGV04 comba-ZXC-F3.LM21 move jackdown to comba-ZXC-F3.AP18 ,taskId 60964f2473dabd1db0d9decc_4
[INFO]2021-05-08 16:44:37,117: --------------------跳转到driver下的seerAgv下的agcCtrl.py中的goTargetAndDoWork函数中-----------------10---------
[INFO]2021-05-08 16:44:37,117: 1
[INFO]2021-05-08 16:44:37,118: {'id': 'AP18', 'operation': 'JackUnload', 'recognize': False, 'use_pgv': False}
[INFO]2021-05-08 16:44:37,118: --------------------------准备进去driver中的seerAgv.py下的task函数-----------------（11）--------------
[INFO]2021-05-08 16:44:37,237: this is handle taskStep=============>dropPayload
[INFO]2021-05-08 16:44:37,365: remoteio is alarm: []
[INFO]2021-05-08 16:44:37,541: this is handle taskStep=============>dropPayload
[INFO]2021-05-08 16:44:37,861: this is handle taskStep=============>dropPayload
[INFO]2021-05-08 16:44:38,165: this is handle taskStep=============>dropPayload
[WARN]2021-05-08 16:44:38,374: AGV04 low battery charge,batteryLevel= 0.252 start charge level= 0.400
[WARN]2021-05-08 16:44:38,375: AGV04 battery 0.252 check failed: isLocked
[DEBUG]2021-05-08 16:44:38,376: send http_get: http://127.0.0.1:8999/api/remoteio/readDOList?id=upStation01
[INFO]2021-05-08 16:44:38,467: this is handle taskStep=============>dropPayload
[INFO]2021-05-08 16:44:38,771: this is handle taskStep=============>dropPayload
[INFO]2021-05-08 16:44:39,073: this is handle taskStep=============>dropPayload
[INFO]2021-05-08 16:44:39,379: this is handle taskStep=============>dropPayload
[INFO]2021-05-08 16:44:39,683: this is handle taskStep=============>dropPayload
[INFO]2021-05-08 16:44:39,985: this is handle taskStep=============>dropPayload
[INFO]2021-05-08 16:44:40,288: this is handle taskStep=============>dropPayload
[INFO]2021-05-08 16:44:40,591: this is handle taskStep=============>dropPayload
[INFO]2021-05-08 16:44:40,893: this is handle taskStep=============>dropPayload
[INFO]2021-05-08 16:44:41,197: this is handle taskStep=============>dropPayload
[INFO]2021-05-08 16:44:41,503: this is handle taskStep=============>dropPayload
[INFO]2021-05-08 16:44:41,806: this is handle taskStep=============>dropPayload
[INFO]2021-05-08 16:44:42,109: this is handle taskStep=============>dropPayload
[INFO]2021-05-08 16:44:42,412: this is handle taskStep=============>dropPayload
[INFO]2021-05-08 16:44:42,716: this is handle taskStep=============>dropPayload
[ERROR]2021-05-08 16:44:42,918: connect AGV01 failed timed out
[INFO]2021-05-08 16:44:42,920: AGV01 checkLink failed 172.16.217.209 19204
[WARN]2021-05-08 16:44:42,921: agvThread.AGV01[tid:13976] <lock name:agv.AGV01.lock_status,<locked _thread.RLock object owner=13976 count=1 at 0x000002029F97BA08>> ,hold 10005 ms
[INFO]2021-05-08 16:44:42,922: name=agvThread.AGV01, pid=7600, tid=13976
[01] File "C:/Users/comba/AppData/Local/Programs/Python/Python37/lib/threading.py", line 865, in run() 
[02] File "C:/Users/comba/Desktop/知识城地牛/knowledgeCity/agvCtrl/agvList.py", line 565, in run() 
[03] File "../driver/seerAgv/agvCtrl.py", line 36, in checkLink() 
[04] File "../driver/seerAgv/agvApi.py", line 184, in checkLink() 
[05] File "C:/Users/comba/Desktop/知识城地牛/knowledgeCity/common/lock.py", line 102, in release() 
[06] File "C:/Users/comba/Desktop/知识城地牛/knowledgeCity/common/enhance.py", line 268, in getTrace() 
[07] File "C:/Users/comba/Desktop/知识城地牛/knowledgeCity/common/enhance.py", line 248, in getThreadStack()
[INFO]2021-05-08 16:44:43,019: this is handle taskStep=============>dropPayload
[INFO]2021-05-08 16:44:43,322: this is handle taskStep=============>dropPayload
[ERROR]2021-05-08 16:44:43,407: connect AGV02 failed timed out
[INFO]2021-05-08 16:44:43,408: AGV02 checkLink failed 172.16.217.213 19204
[WARN]2021-05-08 16:44:43,408: agvThread.AGV02[tid:13684] <lock name:agv.AGV02.lock_status,<locked _thread.RLock object owner=13684 count=1 at 0x000002029F8CF5F8>> ,hold 10004 ms
[INFO]2021-05-08 16:44:43,409: name=agvThread.AGV02, pid=7600, tid=13684
[01] File "C:/Users/comba/AppData/Local/Programs/Python/Python37/lib/threading.py", line 865, in run() 
[02] File "C:/Users/comba/Desktop/知识城地牛/knowledgeCity/agvCtrl/agvList.py", line 565, in run() 
[03] File "../driver/seerAgv/agvCtrl.py", line 36, in checkLink() 
[04] File "../driver/seerAgv/agvApi.py", line 184, in checkLink() 
[05] File "C:/Users/comba/Desktop/知识城地牛/knowledgeCity/common/lock.py", line 102, in release() 
[06] File "C:/Users/comba/Desktop/知识城地牛/knowledgeCity/common/enhance.py", line 268, in getTrace() 
[07] File "C:/Users/comba/Desktop/知识城地牛/knowledgeCity/common/enhance.py", line 248, in getThreadStack()
[INFO]2021-05-08 16:44:43,624: this is handle taskStep=============>dropPayload
[ERROR]2021-05-08 16:44:43,645: connect AGV03 failed timed out
[INFO]2021-05-08 16:44:43,646: AGV03 checkLink failed 172.16.217.121 19204
[WARN]2021-05-08 16:44:43,647: agvThread.AGV03[tid:13128] <lock name:agv.AGV03.lock_status,<locked _thread.RLock object owner=13128 count=1 at 0x000002029F97BC10>> ,hold 10003 ms
[INFO]2021-05-08 16:44:43,648: name=agvThread.AGV03, pid=7600, tid=13128
[01] File "C:/Users/comba/AppData/Local/Programs/Python/Python37/lib/threading.py", line 865, in run() 
[02] File "C:/Users/comba/Desktop/知识城地牛/knowledgeCity/agvCtrl/agvList.py", line 565, in run() 
[03] File "../driver/seerAgv/agvCtrl.py", line 36, in checkLink() 
[04] File "../driver/seerAgv/agvApi.py", line 184, in checkLink() 
[05] File "C:/Users/comba/Desktop/知识城地牛/knowledgeCity/common/lock.py", line 102, in release() 
[06] File "C:/Users/comba/Desktop/知识城地牛/knowledgeCity/common/enhance.py", line 268, in getTrace() 
[07] File "C:/Users/comba/Desktop/知识城地牛/knowledgeCity/common/enhance.py", line 248, in getThreadStack()
[INFO]2021-05-08 16:44:43,927: this is handle taskStep=============>dropPayload
[INFO]2021-05-08 16:44:44,230: this is handle taskStep=============>dropPayload
[INFO]2021-05-08 16:44:44,532: this is handle taskStep=============>dropPayload
[INFO]2021-05-08 16:44:44,837: this is handle taskStep=============>dropPayload
[DEBUG]2021-05-08 16:44:44,923: try connect AGV01 172.16.217.209:19204
[INFO]2021-05-08 16:44:45,140: this is handle taskStep=============>dropPayload
[DEBUG]2021-05-08 16:44:45,142: AGV04 set loc comba-ZXC-F3.LM17 ,old LM21 (9.19,5.74)
[DEBUG]2021-05-08 16:44:45,411: try connect AGV02 172.16.217.213:19204
[INFO]2021-05-08 16:44:45,443: this is handle taskStep=============>dropPayload
[DEBUG]2021-05-08 16:44:45,650: try connect AGV03 172.16.217.121:19204
[INFO]2021-05-08 16:44:45,746: this is handle taskStep=============>dropPayload
[INFO]2021-05-08 16:44:46,054: this is handle taskStep=============>dropPayload
[INFO]2021-05-08 16:44:46,357: this is handle taskStep=============>dropPayload
[INFO]2021-05-08 16:44:46,660: this is handle taskStep=============>dropPayload
[INFO]2021-05-08 16:44:46,964: this is handle taskStep=============>dropPayload
[INFO]2021-05-08 16:44:47,268: this is handle taskStep=============>dropPayload
[INFO]2021-05-08 16:44:47,573: this is handle taskStep=============>dropPayload
[INFO]2021-05-08 16:44:47,877: this is handle taskStep=============>dropPayload
[INFO]2021-05-08 16:44:48,183: this is handle taskStep=============>dropPayload
[INFO]2021-05-08 16:44:48,486: this is handle taskStep=============>dropPayload
[INFO]2021-05-08 16:44:48,790: this is handle taskStep=============>dropPayload
[INFO]2021-05-08 16:44:49,094: this is handle taskStep=============>dropPayload
[INFO]2021-05-08 16:44:49,396: this is handle taskStep=============>dropPayload
[INFO]2021-05-08 16:44:49,703: this is handle taskStep=============>dropPayload
[INFO]2021-05-08 16:44:50,005: this is handle taskStep=============>dropPayload
[ERROR]2021-05-08 16:44:50,172: raise alarm obj=AGV04, typeId=54231, desc=AGV异常, id=60964f82697d98928ef153d2
[INFO]2021-05-08 16:44:50,310: this is handle taskStep=============>dropPayload
[INFO]2021-05-08 16:44:50,613: this is handle taskStep=============>dropPayload
[INFO]2021-05-08 16:44:50,916: this is handle taskStep=============>dropPayload
[INFO]2021-05-08 16:44:51,220: this is handle taskStep=============>dropPayload
[INFO]2021-05-08 16:44:51,523: this is handle taskStep=============>dropPayload
[INFO]2021-05-08 16:44:51,826: this is handle taskStep=============>dropPayload
[ERROR]2021-05-08 16:44:51,878: raise alarm obj=AGV04, typeId=52200, desc=AGV异常, id=60964f83697d98928ef153d5
[WARN]2021-05-08 16:44:51,907: worker 3[tid:13532] <locked _thread.RLock object owner=13532 count=1 at 0x000002029D8E0670> ,hold 30563 ms
[INFO]2021-05-08 16:44:51,909: name=worker 3, pid=7600, tid=13532
[01] File "C:/Users/comba/AppData/Local/Programs/Python/Python37/lib/threading.py", line 865, in run() 
[02] File "C:/Users/comba/AppData/Local/Programs/Python/Python37/lib/site-packages/paste/httpserver.py", line 895, in worker_thread_callback() 
[03] File "C:/Users/comba/AppData/Local/Programs/Python/Python37/lib/site-packages/paste/httpserver.py", line 1069, in <lambda>() 
[04] File "C:/Users/comba/AppData/Local/Programs/Python/Python37/lib/site-packages/paste/httpserver.py", line 1085, in process_request_in_thread() 
[05] File "C:/Users/comba/AppData/Local/Programs/Python/Python37/lib/socketserver.py", line 357, in finish_request() 
[06] File "C:/Users/comba/AppData/Local/Programs/Python/Python37/lib/socketserver.py", line 717, in __init__() 
[07] File "C:/Users/comba/AppData/Local/Programs/Python/Python37/lib/site-packages/paste/httpserver.py", line 459, in handle() 
[08] File "C:/Users/comba/AppData/Local/Programs/Python/Python37/lib/http/server.py", line 426, in handle() 
[09] File "C:/Users/comba/AppData/Local/Programs/Python/Python37/lib/site-packages/paste/httpserver.py", line 454, in handle_one_request() 
[10] File "C:/Users/comba/AppData/Local/Programs/Python/Python37/lib/site-packages/paste/httpserver.py", line 304, in wsgi_execute() 
[11] File "C:/Users/comba/AppData/Local/Programs/Python/Python37/lib/site-packages/paste/translogger.py", line 69, in __call__() 
[12] File "C:/Users/comba/AppData/Local/Programs/Python/Python37/lib/site-packages/bottle.py", line 979, in __call__() 
[13] File "C:/Users/comba/AppData/Local/Programs/Python/Python37/lib/site-packages/bottle.py", line 954, in wsgi() 
[14] File "C:/Users/comba/AppData/Local/Programs/Python/Python37/lib/site-packages/bottle.py", line 862, in _handle() 
[15] File "C:/Users/comba/AppData/Local/Programs/Python/Python37/lib/site-packages/bottle.py", line 1742, in wrapper() 
[16] File "C:/Users/comba/Desktop/知识城地牛/knowledgeCity/common/webutility.py", line 465, in _enable_cors() 
[17] File "C:/Users/comba/Desktop/知识城地牛/knowledgeCity/common/webutility.py", line 481, in _enable_cors() 
[18] File "C:/Users/comba/Desktop/知识城地牛/knowledgeCity/common/scadaUtility.py", line 45, in __call() 
[19] File "C:/Users/comba/Desktop/知识城地牛/knowledgeCity/remoteio/main_remoteio.py", line 87, in urlReadDOList() 
[20] File "../remoteio/remoteioMgr.py", line 158, in readDOList() 
[21] File "../remoteio/remoteioMgr.py", line 262, in readDOList() 
[22] File "C:/Users/comba/Desktop/知识城地牛/knowledgeCity/common/lock.py", line 124, in _call() 
[23] File "C:/Users/comba/Desktop/知识城地牛/knowledgeCity/common/lock.py", line 102, in release() 
[24] File "C:/Users/comba/Desktop/知识城地牛/knowledgeCity/common/enhance.py", line 268, in getTrace() 
[25] File "C:/Users/comba/Desktop/知识城地牛/knowledgeCity/common/enhance.py", line 248, in getThreadStack()
[CRITICAL]2021-05-08 16:44:51,916: upStation01 readDIList fail cause a error: [WinError 10060] 由于连接方在一段时间后没有正确答复或连接的主机没有反应，连接尝试失败。
pid=7600, ppid=4848, tid=13532
Traceback (most recent call last):
  File "..\remoteio\remoteioMgr.py", line 262, in readDOList
    return self._read(M30, IO_LENTH)
  File "C:\Users\comba\Desktop\知识城地牛\knowledgeCity\common\lock.py", line 122, in _call
    return func(*p,**pp)
  File "..\remoteio\remoteioMgr.py", line 311, in _read
    self.master.open()
  File "C:\Users\comba\Desktop\知识城地牛\knowledgeCity\common\modbusapi.py", line 60, in open
    self.master.open()
  File "C:\Users\comba\AppData\Local\Programs\Python\Python37\lib\site-packages\modbus_tk\modbus.py", line 99, in open
    self._do_open()
  File "C:\Users\comba\AppData\Local\Programs\Python\Python37\lib\site-packages\modbus_tk\modbus_tcp.py", line 173, in _do_open
    self._sock.connect((self._host, self._port))
TimeoutError: [WinError 10060] 由于连接方在一段时间后没有正确答复或连接的主机没有反应，连接尝试失败。

[CRITICAL]2021-05-08 16:44:51,923: invoke <function urlReadDOList at 0x000002029C40ED08> cause a error: [WinError 10060] 由于连接方在一段时间后没有正确答复或连接的主机没有反应，连接尝试失败。
pid=7600, ppid=4848, tid=13532
Traceback (most recent call last):
  File "C:\Users\comba\Desktop\知识城地牛\knowledgeCity\common\scadaUtility.py", line 45, in __call
    ret = func(*p,**pp)
  File "C:\Users\comba\Desktop\知识城地牛\knowledgeCity\remoteio\main_remoteio.py", line 87, in urlReadDOList
    return ioMgr.readDOList(id)
  File "..\remoteio\remoteioMgr.py", line 158, in readDOList
    result=remoteioInfo.readDOList()
  File "..\remoteio\remoteioMgr.py", line 262, in readDOList
    return self._read(M30, IO_LENTH)
  File "C:\Users\comba\Desktop\知识城地牛\knowledgeCity\common\lock.py", line 122, in _call
    return func(*p,**pp)
  File "..\remoteio\remoteioMgr.py", line 311, in _read
    self.master.open()
  File "C:\Users\comba\Desktop\知识城地牛\knowledgeCity\common\modbusapi.py", line 60, in open
    self.master.open()
  File "C:\Users\comba\AppData\Local\Programs\Python\Python37\lib\site-packages\modbus_tk\modbus.py", line 99, in open
    self._do_open()
  File "C:\Users\comba\AppData\Local\Programs\Python\Python37\lib\site-packages\modbus_tk\modbus_tcp.py", line 173, in _do_open
    self._sock.connect((self._host, self._port))
TimeoutError: [WinError 10060] 由于连接方在一段时间后没有正确答复或连接的主机没有反应，连接尝试失败。

[INFO]2021-05-08 16:44:52,130: this is handle taskStep=============>dropPayload
[INFO]2021-05-08 16:44:52,433: this is handle taskStep=============>dropPayload
[INFO]2021-05-08 16:44:52,736: this is handle taskStep=============>dropPayload
[INFO]2021-05-08 16:44:53,039: this is handle taskStep=============>dropPayload
[INFO]2021-05-08 16:44:53,342: this is handle taskStep=============>dropPayload
[CRITICAL]2021-05-08 16:44:53,389: readDIList error cause a error: ('http get', 'http://127.0.0.1:8999/api/remoteio/readDOList', {'id': 'upStation01'}, 'error:', 'timed out')
pid=7600, ppid=4848, tid=10368
Traceback (most recent call last):
  File "C:\Users\comba\Desktop\知识城地牛\knowledgeCity\common\webutility.py", line 103, in http_get
    f = urllib.request.urlopen(u,timeout=timeout)
  File "C:\Users\comba\AppData\Local\Programs\Python\Python37\lib\urllib\request.py", line 222, in urlopen
    return opener.open(url, data, timeout)
  File "C:\Users\comba\AppData\Local\Programs\Python\Python37\lib\urllib\request.py", line 525, in open
    response = self._open(req, data)
  File "C:\Users\comba\AppData\Local\Programs\Python\Python37\lib\urllib\request.py", line 543, in _open
    '_open', req)
  File "C:\Users\comba\AppData\Local\Programs\Python\Python37\lib\urllib\request.py", line 503, in _call_chain
    result = func(*args)
  File "C:\Users\comba\AppData\Local\Programs\Python\Python37\lib\urllib\request.py", line 1345, in http_open
    return self.do_open(http.client.HTTPConnection, req)
  File "C:\Users\comba\AppData\Local\Programs\Python\Python37\lib\urllib\request.py", line 1320, in do_open
    r = h.getresponse()
  File "C:\Users\comba\AppData\Local\Programs\Python\Python37\lib\http\client.py", line 1321, in getresponse
    response.begin()
  File "C:\Users\comba\AppData\Local\Programs\Python\Python37\lib\http\client.py", line 296, in begin
    version, status, reason = self._read_status()
  File "C:\Users\comba\AppData\Local\Programs\Python\Python37\lib\http\client.py", line 257, in _read_status
    line = str(self.fp.readline(_MAXLINE + 1), "iso-8859-1")
  File "C:\Users\comba\AppData\Local\Programs\Python\Python37\lib\socket.py", line 589, in readinto
    return self._sock.recv_into(b)
socket.timeout: timed out

During handling of the above exception, another exception occurred:

Traceback (most recent call last):
  File "C:\Users\comba\Desktop\知识城地牛\knowledgeCity\autoCtrl\deviceCtrl.py", line 71, in _monitorDevices
    s1 = ioApi.readDOList(devices[d]["io1"])["status"] #上板机
  File "..\remoteio\remoteioApi.py", line 73, in readDOList
    return _remoteio('/api/remoteio/readDOList', id, param)
  File "..\remoteio\remoteioApi.py", line 100, in _remoteio
    return http_get(url + apiurl, param)
  File "..\remoteio\remoteioApi.py", line 16, in http_get
    r = webutility.http_get(url, param)
  File "C:\Users\comba\Desktop\知识城地牛\knowledgeCity\common\webutility.py", line 105, in http_get
    raise Exception("http get",url,params,"error:",str(e))
Exception: ('http get', 'http://127.0.0.1:8999/api/remoteio/readDOList', {'id': 'upStation01'}, 'error:', 'timed out')

[INFO]2021-05-08 16:44:53,646: this is handle taskStep=============>dropPayload
[INFO]2021-05-08 16:44:53,949: this is handle taskStep=============>dropPayload
[INFO]2021-05-08 16:44:54,252: this is handle taskStep=============>dropPayload
[INFO]2021-05-08 16:44:54,397: remoteio is alarm: []
[ERROR]2021-05-08 16:44:54,402: raise alarm obj=upStation01, typeId=39998, desc=远程控制IO离线异常, id=60964f86697d98928ef153da
[ERROR]2021-05-08 16:44:54,406: raise alarm obj=downStation01, typeId=39998, desc=远程控制IO离线异常, id=60964f86697d98928ef153dc
[INFO]2021-05-08 16:44:54,555: this is handle taskStep=============>dropPayload
[INFO]2021-05-08 16:44:54,858: this is handle taskStep=============>dropPayload
[ERROR]2021-05-08 16:44:54,925: connect AGV01 failed timed out
[INFO]2021-05-08 16:44:54,926: AGV01 checkLink failed 172.16.217.209 19204
[WARN]2021-05-08 16:44:54,927: agvThread.AGV01[tid:13976] <lock name:agv.AGV01.lock_status,<locked _thread.RLock object owner=13976 count=1 at 0x000002029F97BA08>> ,hold 10004 ms
[INFO]2021-05-08 16:44:54,928: name=agvThread.AGV01, pid=7600, tid=13976
[01] File "C:/Users/comba/AppData/Local/Programs/Python/Python37/lib/threading.py", line 865, in run() 
[02] File "C:/Users/comba/Desktop/知识城地牛/knowledgeCity/agvCtrl/agvList.py", line 565, in run() 
[03] File "../driver/seerAgv/agvCtrl.py", line 36, in checkLink() 
[04] File "../driver/seerAgv/agvApi.py", line 184, in checkLink() 
[05] File "C:/Users/comba/Desktop/知识城地牛/knowledgeCity/common/lock.py", line 102, in release() 
[06] File "C:/Users/comba/Desktop/知识城地牛/knowledgeCity/common/enhance.py", line 268, in getTrace() 
[07] File "C:/Users/comba/Desktop/知识城地牛/knowledgeCity/common/enhance.py", line 248, in getThreadStack()
[INFO]2021-05-08 16:44:55,161: this is handle taskStep=============>dropPayload
[WARN]2021-05-08 16:44:55,411: AGV04 low battery charge,batteryLevel= 0.252 start charge level= 0.400
[ERROR]2021-05-08 16:44:55,415: connect AGV02 failed timed out
[WARN]2021-05-08 16:44:55,418: AGV04 battery 0.252 check failed: isLocked
[INFO]2021-05-08 16:44:55,419: AGV02 checkLink failed 172.16.217.213 19204
[DEBUG]2021-05-08 16:44:55,419: send http_get: http://127.0.0.1:8999/api/remoteio/readDOList?id=upStation01
[WARN]2021-05-08 16:44:55,420: agvThread.AGV02[tid:13684] <lock name:agv.AGV02.lock_status,<locked _thread.RLock object owner=13684 count=1 at 0x000002029F8CF5F8>> ,hold 10009 ms
[INFO]2021-05-08 16:44:55,423: name=agvThread.AGV02, pid=7600, tid=13684
[01] File "C:/Users/comba/AppData/Local/Programs/Python/Python37/lib/threading.py", line 865, in run() 
[02] File "C:/Users/comba/Desktop/知识城地牛/knowledgeCity/agvCtrl/agvList.py", line 565, in run() 
[03] File "../driver/seerAgv/agvCtrl.py", line 36, in checkLink() 
[04] File "../driver/seerAgv/agvApi.py", line 184, in checkLink() 
[05] File "C:/Users/comba/Desktop/知识城地牛/knowledgeCity/common/lock.py", line 102, in release() 
[06] File "C:/Users/comba/Desktop/知识城地牛/knowledgeCity/common/enhance.py", line 268, in getTrace() 
[07] File "C:/Users/comba/Desktop/知识城地牛/knowledgeCity/common/enhance.py", line 248, in getThreadStack()
[INFO]2021-05-08 16:44:55,467: this is handle taskStep=============>dropPayload
[ERROR]2021-05-08 16:44:55,651: connect AGV03 failed timed out
[INFO]2021-05-08 16:44:55,652: AGV03 checkLink failed 172.16.217.121 19204
[WARN]2021-05-08 16:44:55,653: agvThread.AGV03[tid:13128] <lock name:agv.AGV03.lock_status,<locked _thread.RLock object owner=13128 count=1 at 0x000002029F97BC10>> ,hold 10003 ms
[INFO]2021-05-08 16:44:55,662: name=agvThread.AGV03, pid=7600, tid=13128
[01] File "C:/Users/comba/AppData/Local/Programs/Python/Python37/lib/threading.py", line 865, in run() 
[02] File "C:/Users/comba/Desktop/知识城地牛/knowledgeCity/agvCtrl/agvList.py", line 565, in run() 
[03] File "../driver/seerAgv/agvCtrl.py", line 36, in checkLink() 
[04] File "../driver/seerAgv/agvApi.py", line 184, in checkLink() 
[05] File "C:/Users/comba/Desktop/知识城地牛/knowledgeCity/common/lock.py", line 102, in release() 
[06] File "C:/Users/comba/Desktop/知识城地牛/knowledgeCity/common/enhance.py", line 268, in getTrace() 
[07] File "C:/Users/comba/Desktop/知识城地牛/knowledgeCity/common/enhance.py", line 248, in getThreadStack()
[INFO]2021-05-08 16:44:55,770: this is handle taskStep=============>dropPayload
[INFO]2021-05-08 16:44:56,076: this is handle taskStep=============>dropPayload
[INFO]2021-05-08 16:44:56,379: this is handle taskStep=============>dropPayload
[INFO]2021-05-08 16:44:56,682: this is handle taskStep=============>dropPayload
[DEBUG]2021-05-08 16:44:56,930: try connect AGV01 172.16.217.209:19204
[INFO]2021-05-08 16:44:56,986: this is handle taskStep=============>dropPayload
[INFO]2021-05-08 16:44:57,289: this is handle taskStep=============>dropPayload
[DEBUG]2021-05-08 16:44:57,426: try connect AGV02 172.16.217.213:19204
[INFO]2021-05-08 16:44:57,592: this is handle taskStep=============>dropPayload
[DEBUG]2021-05-08 16:44:57,668: try connect AGV03 172.16.217.121:19204
[INFO]2021-05-08 16:44:57,895: this is handle taskStep=============>dropPayload
[INFO]2021-05-08 16:44:58,198: this is handle taskStep=============>dropPayload
[INFO]2021-05-08 16:44:58,501: this is handle taskStep=============>dropPayload
[INFO]2021-05-08 16:44:58,808: this is handle taskStep=============>dropPayload
[INFO]2021-05-08 16:44:59,111: this is handle taskStep=============>dropPayload
[INFO]2021-05-08 16:44:59,414: this is handle taskStep=============>dropPayload
[INFO]2021-05-08 16:44:59,716: this is handle taskStep=============>dropPayload
[INFO]2021-05-08 16:45:00,018: this is handle taskStep=============>dropPayload
[INFO]2021-05-08 16:45:00,321: this is handle taskStep=============>dropPayload
[INFO]2021-05-08 16:45:00,624: this is handle taskStep=============>dropPayload
[INFO]2021-05-08 16:45:00,927: this is handle taskStep=============>dropPayload
[INFO]2021-05-08 16:45:01,235: this is handle taskStep=============>dropPayload
[INFO]2021-05-08 16:45:01,537: this is handle taskStep=============>dropPayload
[INFO]2021-05-08 16:45:01,839: this is handle taskStep=============>dropPayload
[INFO]2021-05-08 16:45:02,142: this is handle taskStep=============>dropPayload
[INFO]2021-05-08 16:45:02,445: this is handle taskStep=============>dropPayload
[INFO]2021-05-08 16:45:02,748: this is handle taskStep=============>dropPayload
