[CRITICAL]2021-05-08 14:58:05,706: upStation01 init failed cause a error: ('http get', 'http://127.0.0.1:8999/api/remoteio/readDOList', {'id': 'upStation01'}, 'error:', 'timed out')
pid=11196, ppid=2040, tid=11544
Traceback (most recent call last):
  File "C:\Users\comba\Desktop\知识城地牛\knowledgeCity\common\webutility.py", line 103, in http_get
    f = urllib.request.urlopen(u,timeout=timeout)
  File "C:\Users\comba\AppData\Local\Programs\Python\Python37\lib\urllib\request.py", line 222, in urlopen
    return opener.open(url, data, timeout)
  File "C:\Users\comba\AppData\Local\Programs\Python\Python37\lib\urllib\request.py", line 525, in open
    response = self._open(req, data)
  File "C:\Users\comba\AppData\Local\Programs\Python\Python37\lib\urllib\request.py", line 543, in _open
    '_open', req)
  File "C:\Users\comba\AppData\Local\Programs\Python\Python37\lib\urllib\request.py", line 503, in _call_chain
    result = func(*args)
  File "C:\Users\comba\AppData\Local\Programs\Python\Python37\lib\urllib\request.py", line 1345, in http_open
    return self.do_open(http.client.HTTPConnection, req)
  File "C:\Users\comba\AppData\Local\Programs\Python\Python37\lib\urllib\request.py", line 1320, in do_open
    r = h.getresponse()
  File "C:\Users\comba\AppData\Local\Programs\Python\Python37\lib\http\client.py", line 1321, in getresponse
    response.begin()
  File "C:\Users\comba\AppData\Local\Programs\Python\Python37\lib\http\client.py", line 296, in begin
    version, status, reason = self._read_status()
  File "C:\Users\comba\AppData\Local\Programs\Python\Python37\lib\http\client.py", line 257, in _read_status
    line = str(self.fp.readline(_MAXLINE + 1), "iso-8859-1")
  File "C:\Users\comba\AppData\Local\Programs\Python\Python37\lib\socket.py", line 589, in readinto
    return self._sock.recv_into(b)
socket.timeout: timed out

During handling of the above exception, another exception occurred:

Traceback (most recent call last):
  File "C:\Users\comba\Desktop\知识城地牛\knowledgeCity\autoCtrl\deviceCtrl.py", line 175, in _checkInit
    s = ioApi.readDOList(devices[d][ioId])["status"]
  File "..\remoteio\remoteioApi.py", line 73, in readDOList
    return _remoteio('/api/remoteio/readDOList', id, param)
  File "..\remoteio\remoteioApi.py", line 100, in _remoteio
    return http_get(url + apiurl, param)
  File "..\remoteio\remoteioApi.py", line 16, in http_get
    r = webutility.http_get(url, param)
  File "C:\Users\comba\Desktop\知识城地牛\knowledgeCity\common\webutility.py", line 105, in http_get
    raise Exception("http get",url,params,"error:",str(e))
Exception: ('http get', 'http://127.0.0.1:8999/api/remoteio/readDOList', {'id': 'upStation01'}, 'error:', 'timed out')

[CRITICAL]2021-05-08 14:58:11,618: [modbusApi: 172.16.167.221] execute fcode=1, addr=8256 exception:  cause a error: [WinError 10060] 由于连接方在一段时间后没有正确答复或连接的主机没有反应，连接尝试失败。
pid=11196, ppid=2040, tid=536
Traceback (most recent call last):
  File "C:\Users\comba\Desktop\知识城地牛\knowledgeCity\common\modbusapi.py", line 35, in __execute
    data = self.master.execute(self.__salveId, fcode, start, quantity_of_x=num, output_value=value)
  File "C:\Users\comba\AppData\Local\Programs\Python\Python37\lib\site-packages\modbus_tk\utils.py", line 39, in new
    raise excpt
  File "C:\Users\comba\AppData\Local\Programs\Python\Python37\lib\site-packages\modbus_tk\utils.py", line 37, in new
    ret = fcn(*args, **kwargs)
  File "C:\Users\comba\AppData\Local\Programs\Python\Python37\lib\site-packages\modbus_tk\modbus.py", line 152, in execute
    self.open()
  File "C:\Users\comba\AppData\Local\Programs\Python\Python37\lib\site-packages\modbus_tk\modbus.py", line 99, in open
    self._do_open()
  File "C:\Users\comba\AppData\Local\Programs\Python\Python37\lib\site-packages\modbus_tk\modbus_tcp.py", line 173, in _do_open
    self._sock.connect((self._host, self._port))
TimeoutError: [WinError 10060] 由于连接方在一段时间后没有正确答复或连接的主机没有反应，连接尝试失败。

[CRITICAL]2021-05-08 14:58:12,146: upStation01 readDIList fail cause a error: [WinError 10060] 由于连接方在一段时间后没有正确答复或连接的主机没有反应，连接尝试失败。
pid=11196, ppid=2040, tid=536
Traceback (most recent call last):
  File "..\remoteio\remoteioMgr.py", line 262, in readDOList
    return self._read(M30, IO_LENTH)
  File "C:\Users\comba\Desktop\知识城地牛\knowledgeCity\common\lock.py", line 122, in _call
    return func(*p,**pp)
  File "..\remoteio\remoteioMgr.py", line 314, in _read
    s = self.master.read(mdef.READ_COILS,addr, length)
  File "C:\Users\comba\Desktop\知识城地牛\knowledgeCity\common\modbusapi.py", line 45, in read
    return self.__execute(fcode, start, num)
  File "C:\Users\comba\Desktop\知识城地牛\knowledgeCity\common\modbusapi.py", line 35, in __execute
    data = self.master.execute(self.__salveId, fcode, start, quantity_of_x=num, output_value=value)
  File "C:\Users\comba\AppData\Local\Programs\Python\Python37\lib\site-packages\modbus_tk\utils.py", line 39, in new
    raise excpt
  File "C:\Users\comba\AppData\Local\Programs\Python\Python37\lib\site-packages\modbus_tk\utils.py", line 37, in new
    ret = fcn(*args, **kwargs)
  File "C:\Users\comba\AppData\Local\Programs\Python\Python37\lib\site-packages\modbus_tk\modbus.py", line 152, in execute
    self.open()
  File "C:\Users\comba\AppData\Local\Programs\Python\Python37\lib\site-packages\modbus_tk\modbus.py", line 99, in open
    self._do_open()
  File "C:\Users\comba\AppData\Local\Programs\Python\Python37\lib\site-packages\modbus_tk\modbus_tcp.py", line 173, in _do_open
    self._sock.connect((self._host, self._port))
TimeoutError: [WinError 10060] 由于连接方在一段时间后没有正确答复或连接的主机没有反应，连接尝试失败。

[CRITICAL]2021-05-08 14:58:12,244: invoke <function urlReadDOList at 0x000002748F28FD08> cause a error: [WinError 10060] 由于连接方在一段时间后没有正确答复或连接的主机没有反应，连接尝试失败。
pid=11196, ppid=2040, tid=536
Traceback (most recent call last):
  File "C:\Users\comba\Desktop\知识城地牛\knowledgeCity\common\scadaUtility.py", line 45, in __call
    ret = func(*p,**pp)
  File "C:\Users\comba\Desktop\知识城地牛\knowledgeCity\remoteio\main_remoteio.py", line 87, in urlReadDOList
    return ioMgr.readDOList(id)
  File "..\remoteio\remoteioMgr.py", line 158, in readDOList
    result=remoteioInfo.readDOList()
  File "..\remoteio\remoteioMgr.py", line 262, in readDOList
    return self._read(M30, IO_LENTH)
  File "C:\Users\comba\Desktop\知识城地牛\knowledgeCity\common\lock.py", line 122, in _call
    return func(*p,**pp)
  File "..\remoteio\remoteioMgr.py", line 314, in _read
    s = self.master.read(mdef.READ_COILS,addr, length)
  File "C:\Users\comba\Desktop\知识城地牛\knowledgeCity\common\modbusapi.py", line 45, in read
    return self.__execute(fcode, start, num)
  File "C:\Users\comba\Desktop\知识城地牛\knowledgeCity\common\modbusapi.py", line 35, in __execute
    data = self.master.execute(self.__salveId, fcode, start, quantity_of_x=num, output_value=value)
  File "C:\Users\comba\AppData\Local\Programs\Python\Python37\lib\site-packages\modbus_tk\utils.py", line 39, in new
    raise excpt
  File "C:\Users\comba\AppData\Local\Programs\Python\Python37\lib\site-packages\modbus_tk\utils.py", line 37, in new
    ret = fcn(*args, **kwargs)
  File "C:\Users\comba\AppData\Local\Programs\Python\Python37\lib\site-packages\modbus_tk\modbus.py", line 152, in execute
    self.open()
  File "C:\Users\comba\AppData\Local\Programs\Python\Python37\lib\site-packages\modbus_tk\modbus.py", line 99, in open
    self._do_open()
  File "C:\Users\comba\AppData\Local\Programs\Python\Python37\lib\site-packages\modbus_tk\modbus_tcp.py", line 173, in _do_open
    self._sock.connect((self._host, self._port))
TimeoutError: [WinError 10060] 由于连接方在一段时间后没有正确答复或连接的主机没有反应，连接尝试失败。

[CRITICAL]2021-05-08 14:58:21,836: downStation01 init failed cause a error: ('http get', 'http://127.0.0.1:8999/api/remoteio/readDOList', {'id': 'downStation01'}, 'error:', 'timed out')
pid=11196, ppid=2040, tid=11544
Traceback (most recent call last):
  File "C:\Users\comba\Desktop\知识城地牛\knowledgeCity\common\webutility.py", line 103, in http_get
    f = urllib.request.urlopen(u,timeout=timeout)
  File "C:\Users\comba\AppData\Local\Programs\Python\Python37\lib\urllib\request.py", line 222, in urlopen
    return opener.open(url, data, timeout)
  File "C:\Users\comba\AppData\Local\Programs\Python\Python37\lib\urllib\request.py", line 525, in open
    response = self._open(req, data)
  File "C:\Users\comba\AppData\Local\Programs\Python\Python37\lib\urllib\request.py", line 543, in _open
    '_open', req)
  File "C:\Users\comba\AppData\Local\Programs\Python\Python37\lib\urllib\request.py", line 503, in _call_chain
    result = func(*args)
  File "C:\Users\comba\AppData\Local\Programs\Python\Python37\lib\urllib\request.py", line 1345, in http_open
    return self.do_open(http.client.HTTPConnection, req)
  File "C:\Users\comba\AppData\Local\Programs\Python\Python37\lib\urllib\request.py", line 1320, in do_open
    r = h.getresponse()
  File "C:\Users\comba\AppData\Local\Programs\Python\Python37\lib\http\client.py", line 1321, in getresponse
    response.begin()
  File "C:\Users\comba\AppData\Local\Programs\Python\Python37\lib\http\client.py", line 296, in begin
    version, status, reason = self._read_status()
  File "C:\Users\comba\AppData\Local\Programs\Python\Python37\lib\http\client.py", line 257, in _read_status
    line = str(self.fp.readline(_MAXLINE + 1), "iso-8859-1")
  File "C:\Users\comba\AppData\Local\Programs\Python\Python37\lib\socket.py", line 589, in readinto
    return self._sock.recv_into(b)
socket.timeout: timed out

During handling of the above exception, another exception occurred:

Traceback (most recent call last):
  File "C:\Users\comba\Desktop\知识城地牛\knowledgeCity\autoCtrl\deviceCtrl.py", line 175, in _checkInit
    s = ioApi.readDOList(devices[d][ioId])["status"]
  File "..\remoteio\remoteioApi.py", line 73, in readDOList
    return _remoteio('/api/remoteio/readDOList', id, param)
  File "..\remoteio\remoteioApi.py", line 100, in _remoteio
    return http_get(url + apiurl, param)
  File "..\remoteio\remoteioApi.py", line 16, in http_get
    r = webutility.http_get(url, param)
  File "C:\Users\comba\Desktop\知识城地牛\knowledgeCity\common\webutility.py", line 105, in http_get
    raise Exception("http get",url,params,"error:",str(e))
Exception: ('http get', 'http://127.0.0.1:8999/api/remoteio/readDOList', {'id': 'downStation01'}, 'error:', 'timed out')

[CRITICAL]2021-05-08 14:58:32,563: [modbusApi: 172.16.167.220] execute fcode=1, addr=8256 exception:  cause a error: [WinError 10060] 由于连接方在一段时间后没有正确答复或连接的主机没有反应，连接尝试失败。
pid=11196, ppid=2040, tid=10140
Traceback (most recent call last):
  File "C:\Users\comba\Desktop\知识城地牛\knowledgeCity\common\modbusapi.py", line 35, in __execute
    data = self.master.execute(self.__salveId, fcode, start, quantity_of_x=num, output_value=value)
  File "C:\Users\comba\AppData\Local\Programs\Python\Python37\lib\site-packages\modbus_tk\utils.py", line 39, in new
    raise excpt
  File "C:\Users\comba\AppData\Local\Programs\Python\Python37\lib\site-packages\modbus_tk\utils.py", line 37, in new
    ret = fcn(*args, **kwargs)
  File "C:\Users\comba\AppData\Local\Programs\Python\Python37\lib\site-packages\modbus_tk\modbus.py", line 152, in execute
    self.open()
  File "C:\Users\comba\AppData\Local\Programs\Python\Python37\lib\site-packages\modbus_tk\modbus.py", line 99, in open
    self._do_open()
  File "C:\Users\comba\AppData\Local\Programs\Python\Python37\lib\site-packages\modbus_tk\modbus_tcp.py", line 173, in _do_open
    self._sock.connect((self._host, self._port))
TimeoutError: [WinError 10060] 由于连接方在一段时间后没有正确答复或连接的主机没有反应，连接尝试失败。

[CRITICAL]2021-05-08 14:58:32,782: downStation01 readDIList fail cause a error: [WinError 10060] 由于连接方在一段时间后没有正确答复或连接的主机没有反应，连接尝试失败。
pid=11196, ppid=2040, tid=10140
Traceback (most recent call last):
  File "..\remoteio\remoteioMgr.py", line 262, in readDOList
    return self._read(M30, IO_LENTH)
  File "C:\Users\comba\Desktop\知识城地牛\knowledgeCity\common\lock.py", line 122, in _call
    return func(*p,**pp)
  File "..\remoteio\remoteioMgr.py", line 314, in _read
    s = self.master.read(mdef.READ_COILS,addr, length)
  File "C:\Users\comba\Desktop\知识城地牛\knowledgeCity\common\modbusapi.py", line 45, in read
    return self.__execute(fcode, start, num)
  File "C:\Users\comba\Desktop\知识城地牛\knowledgeCity\common\modbusapi.py", line 35, in __execute
    data = self.master.execute(self.__salveId, fcode, start, quantity_of_x=num, output_value=value)
  File "C:\Users\comba\AppData\Local\Programs\Python\Python37\lib\site-packages\modbus_tk\utils.py", line 39, in new
    raise excpt
  File "C:\Users\comba\AppData\Local\Programs\Python\Python37\lib\site-packages\modbus_tk\utils.py", line 37, in new
    ret = fcn(*args, **kwargs)
  File "C:\Users\comba\AppData\Local\Programs\Python\Python37\lib\site-packages\modbus_tk\modbus.py", line 152, in execute
    self.open()
  File "C:\Users\comba\AppData\Local\Programs\Python\Python37\lib\site-packages\modbus_tk\modbus.py", line 99, in open
    self._do_open()
  File "C:\Users\comba\AppData\Local\Programs\Python\Python37\lib\site-packages\modbus_tk\modbus_tcp.py", line 173, in _do_open
    self._sock.connect((self._host, self._port))
TimeoutError: [WinError 10060] 由于连接方在一段时间后没有正确答复或连接的主机没有反应，连接尝试失败。

[CRITICAL]2021-05-08 14:58:32,916: invoke <function urlReadDOList at 0x000002748F28FD08> cause a error: [WinError 10060] 由于连接方在一段时间后没有正确答复或连接的主机没有反应，连接尝试失败。
pid=11196, ppid=2040, tid=10140
Traceback (most recent call last):
  File "C:\Users\comba\Desktop\知识城地牛\knowledgeCity\common\scadaUtility.py", line 45, in __call
    ret = func(*p,**pp)
  File "C:\Users\comba\Desktop\知识城地牛\knowledgeCity\remoteio\main_remoteio.py", line 87, in urlReadDOList
    return ioMgr.readDOList(id)
  File "..\remoteio\remoteioMgr.py", line 158, in readDOList
    result=remoteioInfo.readDOList()
  File "..\remoteio\remoteioMgr.py", line 262, in readDOList
    return self._read(M30, IO_LENTH)
  File "C:\Users\comba\Desktop\知识城地牛\knowledgeCity\common\lock.py", line 122, in _call
    return func(*p,**pp)
  File "..\remoteio\remoteioMgr.py", line 314, in _read
    s = self.master.read(mdef.READ_COILS,addr, length)
  File "C:\Users\comba\Desktop\知识城地牛\knowledgeCity\common\modbusapi.py", line 45, in read
    return self.__execute(fcode, start, num)
  File "C:\Users\comba\Desktop\知识城地牛\knowledgeCity\common\modbusapi.py", line 35, in __execute
    data = self.master.execute(self.__salveId, fcode, start, quantity_of_x=num, output_value=value)
  File "C:\Users\comba\AppData\Local\Programs\Python\Python37\lib\site-packages\modbus_tk\utils.py", line 39, in new
    raise excpt
  File "C:\Users\comba\AppData\Local\Programs\Python\Python37\lib\site-packages\modbus_tk\utils.py", line 37, in new
    ret = fcn(*args, **kwargs)
  File "C:\Users\comba\AppData\Local\Programs\Python\Python37\lib\site-packages\modbus_tk\modbus.py", line 152, in execute
    self.open()
  File "C:\Users\comba\AppData\Local\Programs\Python\Python37\lib\site-packages\modbus_tk\modbus.py", line 99, in open
    self._do_open()
  File "C:\Users\comba\AppData\Local\Programs\Python\Python37\lib\site-packages\modbus_tk\modbus_tcp.py", line 173, in _do_open
    self._sock.connect((self._host, self._port))
TimeoutError: [WinError 10060] 由于连接方在一段时间后没有正确答复或连接的主机没有反应，连接尝试失败。

[CRITICAL]2021-05-08 14:58:38,092: readDIList error cause a error: ('http get', 'http://127.0.0.1:8999/api/remoteio/readDOList', {'id': 'upStation01'}, 'error:', 'timed out')
pid=11196, ppid=2040, tid=11544
Traceback (most recent call last):
  File "C:\Users\comba\Desktop\知识城地牛\knowledgeCity\common\webutility.py", line 103, in http_get
    f = urllib.request.urlopen(u,timeout=timeout)
  File "C:\Users\comba\AppData\Local\Programs\Python\Python37\lib\urllib\request.py", line 222, in urlopen
    return opener.open(url, data, timeout)
  File "C:\Users\comba\AppData\Local\Programs\Python\Python37\lib\urllib\request.py", line 525, in open
    response = self._open(req, data)
  File "C:\Users\comba\AppData\Local\Programs\Python\Python37\lib\urllib\request.py", line 543, in _open
    '_open', req)
  File "C:\Users\comba\AppData\Local\Programs\Python\Python37\lib\urllib\request.py", line 503, in _call_chain
    result = func(*args)
  File "C:\Users\comba\AppData\Local\Programs\Python\Python37\lib\urllib\request.py", line 1345, in http_open
    return self.do_open(http.client.HTTPConnection, req)
  File "C:\Users\comba\AppData\Local\Programs\Python\Python37\lib\urllib\request.py", line 1320, in do_open
    r = h.getresponse()
  File "C:\Users\comba\AppData\Local\Programs\Python\Python37\lib\http\client.py", line 1321, in getresponse
    response.begin()
  File "C:\Users\comba\AppData\Local\Programs\Python\Python37\lib\http\client.py", line 296, in begin
    version, status, reason = self._read_status()
  File "C:\Users\comba\AppData\Local\Programs\Python\Python37\lib\http\client.py", line 257, in _read_status
    line = str(self.fp.readline(_MAXLINE + 1), "iso-8859-1")
  File "C:\Users\comba\AppData\Local\Programs\Python\Python37\lib\socket.py", line 589, in readinto
    return self._sock.recv_into(b)
socket.timeout: timed out

During handling of the above exception, another exception occurred:

Traceback (most recent call last):
  File "C:\Users\comba\Desktop\知识城地牛\knowledgeCity\autoCtrl\deviceCtrl.py", line 71, in _monitorDevices
    s1 = ioApi.readDOList(devices[d]["io1"])["status"] #上板机
  File "..\remoteio\remoteioApi.py", line 73, in readDOList
    return _remoteio('/api/remoteio/readDOList', id, param)
  File "..\remoteio\remoteioApi.py", line 100, in _remoteio
    return http_get(url + apiurl, param)
  File "..\remoteio\remoteioApi.py", line 16, in http_get
    r = webutility.http_get(url, param)
  File "C:\Users\comba\Desktop\知识城地牛\knowledgeCity\common\webutility.py", line 105, in http_get
    raise Exception("http get",url,params,"error:",str(e))
Exception: ('http get', 'http://127.0.0.1:8999/api/remoteio/readDOList', {'id': 'upStation01'}, 'error:', 'timed out')

[CRITICAL]2021-05-08 14:58:44,277: upStation01 readDIList fail cause a error: [WinError 10060] 由于连接方在一段时间后没有正确答复或连接的主机没有反应，连接尝试失败。
pid=11196, ppid=2040, tid=12660
Traceback (most recent call last):
  File "..\remoteio\remoteioMgr.py", line 262, in readDOList
    return self._read(M30, IO_LENTH)
  File "C:\Users\comba\Desktop\知识城地牛\knowledgeCity\common\lock.py", line 122, in _call
    return func(*p,**pp)
  File "..\remoteio\remoteioMgr.py", line 311, in _read
    self.master.open()
  File "C:\Users\comba\Desktop\知识城地牛\knowledgeCity\common\modbusapi.py", line 60, in open
    self.master.open()
  File "C:\Users\comba\AppData\Local\Programs\Python\Python37\lib\site-packages\modbus_tk\modbus.py", line 99, in open
    self._do_open()
  File "C:\Users\comba\AppData\Local\Programs\Python\Python37\lib\site-packages\modbus_tk\modbus_tcp.py", line 173, in _do_open
    self._sock.connect((self._host, self._port))
TimeoutError: [WinError 10060] 由于连接方在一段时间后没有正确答复或连接的主机没有反应，连接尝试失败。

[CRITICAL]2021-05-08 14:58:44,388: invoke <function urlReadDOList at 0x000002748F28FD08> cause a error: [WinError 10060] 由于连接方在一段时间后没有正确答复或连接的主机没有反应，连接尝试失败。
pid=11196, ppid=2040, tid=12660
Traceback (most recent call last):
  File "C:\Users\comba\Desktop\知识城地牛\knowledgeCity\common\scadaUtility.py", line 45, in __call
    ret = func(*p,**pp)
  File "C:\Users\comba\Desktop\知识城地牛\knowledgeCity\remoteio\main_remoteio.py", line 87, in urlReadDOList
    return ioMgr.readDOList(id)
  File "..\remoteio\remoteioMgr.py", line 158, in readDOList
    result=remoteioInfo.readDOList()
  File "..\remoteio\remoteioMgr.py", line 262, in readDOList
    return self._read(M30, IO_LENTH)
  File "C:\Users\comba\Desktop\知识城地牛\knowledgeCity\common\lock.py", line 122, in _call
    return func(*p,**pp)
  File "..\remoteio\remoteioMgr.py", line 311, in _read
    self.master.open()
  File "C:\Users\comba\Desktop\知识城地牛\knowledgeCity\common\modbusapi.py", line 60, in open
    self.master.open()
  File "C:\Users\comba\AppData\Local\Programs\Python\Python37\lib\site-packages\modbus_tk\modbus.py", line 99, in open
    self._do_open()
  File "C:\Users\comba\AppData\Local\Programs\Python\Python37\lib\site-packages\modbus_tk\modbus_tcp.py", line 173, in _do_open
    self._sock.connect((self._host, self._port))
TimeoutError: [WinError 10060] 由于连接方在一段时间后没有正确答复或连接的主机没有反应，连接尝试失败。

[CRITICAL]2021-05-08 14:58:57,027: readDIList error cause a error: ('http get', 'http://127.0.0.1:8999/api/remoteio/readDOList', {'id': 'upStation01'}, 'error:', 'timed out')
pid=11196, ppid=2040, tid=11544
Traceback (most recent call last):
  File "C:\Users\comba\Desktop\知识城地牛\knowledgeCity\common\webutility.py", line 103, in http_get
    f = urllib.request.urlopen(u,timeout=timeout)
  File "C:\Users\comba\AppData\Local\Programs\Python\Python37\lib\urllib\request.py", line 222, in urlopen
    return opener.open(url, data, timeout)
  File "C:\Users\comba\AppData\Local\Programs\Python\Python37\lib\urllib\request.py", line 525, in open
    response = self._open(req, data)
  File "C:\Users\comba\AppData\Local\Programs\Python\Python37\lib\urllib\request.py", line 543, in _open
    '_open', req)
  File "C:\Users\comba\AppData\Local\Programs\Python\Python37\lib\urllib\request.py", line 503, in _call_chain
    result = func(*args)
  File "C:\Users\comba\AppData\Local\Programs\Python\Python37\lib\urllib\request.py", line 1345, in http_open
    return self.do_open(http.client.HTTPConnection, req)
  File "C:\Users\comba\AppData\Local\Programs\Python\Python37\lib\urllib\request.py", line 1320, in do_open
    r = h.getresponse()
  File "C:\Users\comba\AppData\Local\Programs\Python\Python37\lib\http\client.py", line 1321, in getresponse
    response.begin()
  File "C:\Users\comba\AppData\Local\Programs\Python\Python37\lib\http\client.py", line 296, in begin
    version, status, reason = self._read_status()
  File "C:\Users\comba\AppData\Local\Programs\Python\Python37\lib\http\client.py", line 257, in _read_status
    line = str(self.fp.readline(_MAXLINE + 1), "iso-8859-1")
  File "C:\Users\comba\AppData\Local\Programs\Python\Python37\lib\socket.py", line 589, in readinto
    return self._sock.recv_into(b)
socket.timeout: timed out

During handling of the above exception, another exception occurred:

Traceback (most recent call last):
  File "C:\Users\comba\Desktop\知识城地牛\knowledgeCity\autoCtrl\deviceCtrl.py", line 71, in _monitorDevices
    s1 = ioApi.readDOList(devices[d]["io1"])["status"] #上板机
  File "..\remoteio\remoteioApi.py", line 73, in readDOList
    return _remoteio('/api/remoteio/readDOList', id, param)
  File "..\remoteio\remoteioApi.py", line 100, in _remoteio
    return http_get(url + apiurl, param)
  File "..\remoteio\remoteioApi.py", line 16, in http_get
    r = webutility.http_get(url, param)
  File "C:\Users\comba\Desktop\知识城地牛\knowledgeCity\common\webutility.py", line 105, in http_get
    raise Exception("http get",url,params,"error:",str(e))
Exception: ('http get', 'http://127.0.0.1:8999/api/remoteio/readDOList', {'id': 'upStation01'}, 'error:', 'timed out')

[CRITICAL]2021-05-08 14:59:05,271: upStation01 readDIList fail cause a error: [WinError 10060] 由于连接方在一段时间后没有正确答复或连接的主机没有反应，连接尝试失败。
pid=11196, ppid=2040, tid=884
Traceback (most recent call last):
  File "..\remoteio\remoteioMgr.py", line 262, in readDOList
    return self._read(M30, IO_LENTH)
  File "C:\Users\comba\Desktop\知识城地牛\knowledgeCity\common\lock.py", line 122, in _call
    return func(*p,**pp)
  File "..\remoteio\remoteioMgr.py", line 311, in _read
    self.master.open()
  File "C:\Users\comba\Desktop\知识城地牛\knowledgeCity\common\modbusapi.py", line 60, in open
    self.master.open()
  File "C:\Users\comba\AppData\Local\Programs\Python\Python37\lib\site-packages\modbus_tk\modbus.py", line 99, in open
    self._do_open()
  File "C:\Users\comba\AppData\Local\Programs\Python\Python37\lib\site-packages\modbus_tk\modbus_tcp.py", line 173, in _do_open
    self._sock.connect((self._host, self._port))
TimeoutError: [WinError 10060] 由于连接方在一段时间后没有正确答复或连接的主机没有反应，连接尝试失败。

[CRITICAL]2021-05-08 14:59:05,277: invoke <function urlReadDOList at 0x000002748F28FD08> cause a error: [WinError 10060] 由于连接方在一段时间后没有正确答复或连接的主机没有反应，连接尝试失败。
pid=11196, ppid=2040, tid=884
Traceback (most recent call last):
  File "C:\Users\comba\Desktop\知识城地牛\knowledgeCity\common\scadaUtility.py", line 45, in __call
    ret = func(*p,**pp)
  File "C:\Users\comba\Desktop\知识城地牛\knowledgeCity\remoteio\main_remoteio.py", line 87, in urlReadDOList
    return ioMgr.readDOList(id)
  File "..\remoteio\remoteioMgr.py", line 158, in readDOList
    result=remoteioInfo.readDOList()
  File "..\remoteio\remoteioMgr.py", line 262, in readDOList
    return self._read(M30, IO_LENTH)
  File "C:\Users\comba\Desktop\知识城地牛\knowledgeCity\common\lock.py", line 122, in _call
    return func(*p,**pp)
  File "..\remoteio\remoteioMgr.py", line 311, in _read
    self.master.open()
  File "C:\Users\comba\Desktop\知识城地牛\knowledgeCity\common\modbusapi.py", line 60, in open
    self.master.open()
  File "C:\Users\comba\AppData\Local\Programs\Python\Python37\lib\site-packages\modbus_tk\modbus.py", line 99, in open
    self._do_open()
  File "C:\Users\comba\AppData\Local\Programs\Python\Python37\lib\site-packages\modbus_tk\modbus_tcp.py", line 173, in _do_open
    self._sock.connect((self._host, self._port))
TimeoutError: [WinError 10060] 由于连接方在一段时间后没有正确答复或连接的主机没有反应，连接尝试失败。

[CRITICAL]2021-05-08 14:59:14,073: readDIList error cause a error: ('http get', 'http://127.0.0.1:8999/api/remoteio/readDOList', {'id': 'upStation01'}, 'error:', 'timed out')
pid=11196, ppid=2040, tid=11544
Traceback (most recent call last):
  File "C:\Users\comba\Desktop\知识城地牛\knowledgeCity\common\webutility.py", line 103, in http_get
    f = urllib.request.urlopen(u,timeout=timeout)
  File "C:\Users\comba\AppData\Local\Programs\Python\Python37\lib\urllib\request.py", line 222, in urlopen
    return opener.open(url, data, timeout)
  File "C:\Users\comba\AppData\Local\Programs\Python\Python37\lib\urllib\request.py", line 525, in open
    response = self._open(req, data)
  File "C:\Users\comba\AppData\Local\Programs\Python\Python37\lib\urllib\request.py", line 543, in _open
    '_open', req)
  File "C:\Users\comba\AppData\Local\Programs\Python\Python37\lib\urllib\request.py", line 503, in _call_chain
    result = func(*args)
  File "C:\Users\comba\AppData\Local\Programs\Python\Python37\lib\urllib\request.py", line 1345, in http_open
    return self.do_open(http.client.HTTPConnection, req)
  File "C:\Users\comba\AppData\Local\Programs\Python\Python37\lib\urllib\request.py", line 1320, in do_open
    r = h.getresponse()
  File "C:\Users\comba\AppData\Local\Programs\Python\Python37\lib\http\client.py", line 1321, in getresponse
    response.begin()
  File "C:\Users\comba\AppData\Local\Programs\Python\Python37\lib\http\client.py", line 296, in begin
    version, status, reason = self._read_status()
  File "C:\Users\comba\AppData\Local\Programs\Python\Python37\lib\http\client.py", line 257, in _read_status
    line = str(self.fp.readline(_MAXLINE + 1), "iso-8859-1")
  File "C:\Users\comba\AppData\Local\Programs\Python\Python37\lib\socket.py", line 589, in readinto
    return self._sock.recv_into(b)
socket.timeout: timed out

During handling of the above exception, another exception occurred:

Traceback (most recent call last):
  File "C:\Users\comba\Desktop\知识城地牛\knowledgeCity\autoCtrl\deviceCtrl.py", line 71, in _monitorDevices
    s1 = ioApi.readDOList(devices[d]["io1"])["status"] #上板机
  File "..\remoteio\remoteioApi.py", line 73, in readDOList
    return _remoteio('/api/remoteio/readDOList', id, param)
  File "..\remoteio\remoteioApi.py", line 100, in _remoteio
    return http_get(url + apiurl, param)
  File "..\remoteio\remoteioApi.py", line 16, in http_get
    r = webutility.http_get(url, param)
  File "C:\Users\comba\Desktop\知识城地牛\knowledgeCity\common\webutility.py", line 105, in http_get
    raise Exception("http get",url,params,"error:",str(e))
Exception: ('http get', 'http://127.0.0.1:8999/api/remoteio/readDOList', {'id': 'upStation01'}, 'error:', 'timed out')

[CRITICAL]2021-05-08 14:59:18,508: taskFunc2:task[6096367d73dabd2bbc9b67af][AGV04] AP22(LM17) -> AP25(LM24) [checkTwoLayerGoing] cause a error: not all arguments converted during string formatting
pid=11196, ppid=2040, tid=11916
Traceback (most recent call last):
  File "C:\Users\comba\Desktop\知识城地牛\knowledgeCity\autoCtrl\runTasks.py", line 916, in _taskFunc
    elif not self.handle():
  File "C:\Users\comba\Desktop\知识城地牛\knowledgeCity\common\lock.py", line 122, in _call
    return func(*p,**pp)
  File "C:\Users\comba\Desktop\知识城地牛\knowledgeCity\autoCtrl\runTasks.py", line 673, in handle
    taskMgr.update(self.taskId, failMsg="二层滚筒出料" % self.target)
TypeError: not all arguments converted during string formatting

[CRITICAL]2021-05-08 14:59:26,542: upStation01 readDIList fail cause a error: [WinError 10060] 由于连接方在一段时间后没有正确答复或连接的主机没有反应，连接尝试失败。
pid=11196, ppid=2040, tid=10140
Traceback (most recent call last):
  File "..\remoteio\remoteioMgr.py", line 262, in readDOList
    return self._read(M30, IO_LENTH)
  File "C:\Users\comba\Desktop\知识城地牛\knowledgeCity\common\lock.py", line 122, in _call
    return func(*p,**pp)
  File "..\remoteio\remoteioMgr.py", line 311, in _read
    self.master.open()
  File "C:\Users\comba\Desktop\知识城地牛\knowledgeCity\common\modbusapi.py", line 60, in open
    self.master.open()
  File "C:\Users\comba\AppData\Local\Programs\Python\Python37\lib\site-packages\modbus_tk\modbus.py", line 99, in open
    self._do_open()
  File "C:\Users\comba\AppData\Local\Programs\Python\Python37\lib\site-packages\modbus_tk\modbus_tcp.py", line 173, in _do_open
    self._sock.connect((self._host, self._port))
TimeoutError: [WinError 10060] 由于连接方在一段时间后没有正确答复或连接的主机没有反应，连接尝试失败。

[CRITICAL]2021-05-08 14:59:26,647: invoke <function urlReadDOList at 0x000002748F28FD08> cause a error: [WinError 10060] 由于连接方在一段时间后没有正确答复或连接的主机没有反应，连接尝试失败。
pid=11196, ppid=2040, tid=10140
Traceback (most recent call last):
  File "C:\Users\comba\Desktop\知识城地牛\knowledgeCity\common\scadaUtility.py", line 45, in __call
    ret = func(*p,**pp)
  File "C:\Users\comba\Desktop\知识城地牛\knowledgeCity\remoteio\main_remoteio.py", line 87, in urlReadDOList
    return ioMgr.readDOList(id)
  File "..\remoteio\remoteioMgr.py", line 158, in readDOList
    result=remoteioInfo.readDOList()
  File "..\remoteio\remoteioMgr.py", line 262, in readDOList
    return self._read(M30, IO_LENTH)
  File "C:\Users\comba\Desktop\知识城地牛\knowledgeCity\common\lock.py", line 122, in _call
    return func(*p,**pp)
  File "..\remoteio\remoteioMgr.py", line 311, in _read
    self.master.open()
  File "C:\Users\comba\Desktop\知识城地牛\knowledgeCity\common\modbusapi.py", line 60, in open
    self.master.open()
  File "C:\Users\comba\AppData\Local\Programs\Python\Python37\lib\site-packages\modbus_tk\modbus.py", line 99, in open
    self._do_open()
  File "C:\Users\comba\AppData\Local\Programs\Python\Python37\lib\site-packages\modbus_tk\modbus_tcp.py", line 173, in _do_open
    self._sock.connect((self._host, self._port))
TimeoutError: [WinError 10060] 由于连接方在一段时间后没有正确答复或连接的主机没有反应，连接尝试失败。

[CRITICAL]2021-05-08 14:59:31,164: readDIList error cause a error: ('http get', 'http://127.0.0.1:8999/api/remoteio/readDOList', {'id': 'upStation01'}, 'error:', 'timed out')
pid=11196, ppid=2040, tid=11544
Traceback (most recent call last):
  File "C:\Users\comba\Desktop\知识城地牛\knowledgeCity\common\webutility.py", line 103, in http_get
    f = urllib.request.urlopen(u,timeout=timeout)
  File "C:\Users\comba\AppData\Local\Programs\Python\Python37\lib\urllib\request.py", line 222, in urlopen
    return opener.open(url, data, timeout)
  File "C:\Users\comba\AppData\Local\Programs\Python\Python37\lib\urllib\request.py", line 525, in open
    response = self._open(req, data)
  File "C:\Users\comba\AppData\Local\Programs\Python\Python37\lib\urllib\request.py", line 543, in _open
    '_open', req)
  File "C:\Users\comba\AppData\Local\Programs\Python\Python37\lib\urllib\request.py", line 503, in _call_chain
    result = func(*args)
  File "C:\Users\comba\AppData\Local\Programs\Python\Python37\lib\urllib\request.py", line 1345, in http_open
    return self.do_open(http.client.HTTPConnection, req)
  File "C:\Users\comba\AppData\Local\Programs\Python\Python37\lib\urllib\request.py", line 1320, in do_open
    r = h.getresponse()
  File "C:\Users\comba\AppData\Local\Programs\Python\Python37\lib\http\client.py", line 1321, in getresponse
    response.begin()
  File "C:\Users\comba\AppData\Local\Programs\Python\Python37\lib\http\client.py", line 296, in begin
    version, status, reason = self._read_status()
  File "C:\Users\comba\AppData\Local\Programs\Python\Python37\lib\http\client.py", line 257, in _read_status
    line = str(self.fp.readline(_MAXLINE + 1), "iso-8859-1")
  File "C:\Users\comba\AppData\Local\Programs\Python\Python37\lib\socket.py", line 589, in readinto
    return self._sock.recv_into(b)
socket.timeout: timed out

During handling of the above exception, another exception occurred:

Traceback (most recent call last):
  File "C:\Users\comba\Desktop\知识城地牛\knowledgeCity\autoCtrl\deviceCtrl.py", line 71, in _monitorDevices
    s1 = ioApi.readDOList(devices[d]["io1"])["status"] #上板机
  File "..\remoteio\remoteioApi.py", line 73, in readDOList
    return _remoteio('/api/remoteio/readDOList', id, param)
  File "..\remoteio\remoteioApi.py", line 100, in _remoteio
    return http_get(url + apiurl, param)
  File "..\remoteio\remoteioApi.py", line 16, in http_get
    r = webutility.http_get(url, param)
  File "C:\Users\comba\Desktop\知识城地牛\knowledgeCity\common\webutility.py", line 105, in http_get
    raise Exception("http get",url,params,"error:",str(e))
Exception: ('http get', 'http://127.0.0.1:8999/api/remoteio/readDOList', {'id': 'upStation01'}, 'error:', 'timed out')

[CRITICAL]2021-05-08 14:59:47,746: upStation01 readDIList fail cause a error: [WinError 10060] 由于连接方在一段时间后没有正确答复或连接的主机没有反应，连接尝试失败。
pid=11196, ppid=2040, tid=4300
Traceback (most recent call last):
  File "..\remoteio\remoteioMgr.py", line 262, in readDOList
    return self._read(M30, IO_LENTH)
  File "C:\Users\comba\Desktop\知识城地牛\knowledgeCity\common\lock.py", line 122, in _call
    return func(*p,**pp)
  File "..\remoteio\remoteioMgr.py", line 311, in _read
    self.master.open()
  File "C:\Users\comba\Desktop\知识城地牛\knowledgeCity\common\modbusapi.py", line 60, in open
    self.master.open()
  File "C:\Users\comba\AppData\Local\Programs\Python\Python37\lib\site-packages\modbus_tk\modbus.py", line 99, in open
    self._do_open()
  File "C:\Users\comba\AppData\Local\Programs\Python\Python37\lib\site-packages\modbus_tk\modbus_tcp.py", line 173, in _do_open
    self._sock.connect((self._host, self._port))
TimeoutError: [WinError 10060] 由于连接方在一段时间后没有正确答复或连接的主机没有反应，连接尝试失败。

[CRITICAL]2021-05-08 14:59:47,898: invoke <function urlReadDOList at 0x000002748F28FD08> cause a error: [WinError 10060] 由于连接方在一段时间后没有正确答复或连接的主机没有反应，连接尝试失败。
pid=11196, ppid=2040, tid=4300
Traceback (most recent call last):
  File "C:\Users\comba\Desktop\知识城地牛\knowledgeCity\common\scadaUtility.py", line 45, in __call
    ret = func(*p,**pp)
  File "C:\Users\comba\Desktop\知识城地牛\knowledgeCity\remoteio\main_remoteio.py", line 87, in urlReadDOList
    return ioMgr.readDOList(id)
  File "..\remoteio\remoteioMgr.py", line 158, in readDOList
    result=remoteioInfo.readDOList()
  File "..\remoteio\remoteioMgr.py", line 262, in readDOList
    return self._read(M30, IO_LENTH)
  File "C:\Users\comba\Desktop\知识城地牛\knowledgeCity\common\lock.py", line 122, in _call
    return func(*p,**pp)
  File "..\remoteio\remoteioMgr.py", line 311, in _read
    self.master.open()
  File "C:\Users\comba\Desktop\知识城地牛\knowledgeCity\common\modbusapi.py", line 60, in open
    self.master.open()
  File "C:\Users\comba\AppData\Local\Programs\Python\Python37\lib\site-packages\modbus_tk\modbus.py", line 99, in open
    self._do_open()
  File "C:\Users\comba\AppData\Local\Programs\Python\Python37\lib\site-packages\modbus_tk\modbus_tcp.py", line 173, in _do_open
    self._sock.connect((self._host, self._port))
TimeoutError: [WinError 10060] 由于连接方在一段时间后没有正确答复或连接的主机没有反应，连接尝试失败。

[CRITICAL]2021-05-08 14:59:48,521: readDIList error cause a error: ('http get', 'http://127.0.0.1:8999/api/remoteio/readDOList', {'id': 'upStation01'}, 'error:', 'timed out')
pid=11196, ppid=2040, tid=11544
Traceback (most recent call last):
  File "C:\Users\comba\Desktop\知识城地牛\knowledgeCity\common\webutility.py", line 103, in http_get
    f = urllib.request.urlopen(u,timeout=timeout)
  File "C:\Users\comba\AppData\Local\Programs\Python\Python37\lib\urllib\request.py", line 222, in urlopen
    return opener.open(url, data, timeout)
  File "C:\Users\comba\AppData\Local\Programs\Python\Python37\lib\urllib\request.py", line 525, in open
    response = self._open(req, data)
  File "C:\Users\comba\AppData\Local\Programs\Python\Python37\lib\urllib\request.py", line 543, in _open
    '_open', req)
  File "C:\Users\comba\AppData\Local\Programs\Python\Python37\lib\urllib\request.py", line 503, in _call_chain
    result = func(*args)
  File "C:\Users\comba\AppData\Local\Programs\Python\Python37\lib\urllib\request.py", line 1345, in http_open
    return self.do_open(http.client.HTTPConnection, req)
  File "C:\Users\comba\AppData\Local\Programs\Python\Python37\lib\urllib\request.py", line 1320, in do_open
    r = h.getresponse()
  File "C:\Users\comba\AppData\Local\Programs\Python\Python37\lib\http\client.py", line 1321, in getresponse
    response.begin()
  File "C:\Users\comba\AppData\Local\Programs\Python\Python37\lib\http\client.py", line 296, in begin
    version, status, reason = self._read_status()
  File "C:\Users\comba\AppData\Local\Programs\Python\Python37\lib\http\client.py", line 257, in _read_status
    line = str(self.fp.readline(_MAXLINE + 1), "iso-8859-1")
  File "C:\Users\comba\AppData\Local\Programs\Python\Python37\lib\socket.py", line 589, in readinto
    return self._sock.recv_into(b)
socket.timeout: timed out

During handling of the above exception, another exception occurred:

Traceback (most recent call last):
  File "C:\Users\comba\Desktop\知识城地牛\knowledgeCity\autoCtrl\deviceCtrl.py", line 71, in _monitorDevices
    s1 = ioApi.readDOList(devices[d]["io1"])["status"] #上板机
  File "..\remoteio\remoteioApi.py", line 73, in readDOList
    return _remoteio('/api/remoteio/readDOList', id, param)
  File "..\remoteio\remoteioApi.py", line 100, in _remoteio
    return http_get(url + apiurl, param)
  File "..\remoteio\remoteioApi.py", line 16, in http_get
    r = webutility.http_get(url, param)
  File "C:\Users\comba\Desktop\知识城地牛\knowledgeCity\common\webutility.py", line 105, in http_get
    raise Exception("http get",url,params,"error:",str(e))
Exception: ('http get', 'http://127.0.0.1:8999/api/remoteio/readDOList', {'id': 'upStation01'}, 'error:', 'timed out')

