[CRITICAL]2021-06-03 13:25:30,020: [modbusApi: 172.16.166.182] execute fcode=5, addr=16 exception:  cause a error: [WinError 10060] 由于连接方在一段时间后没有正确答复或连接的主机没有反应，连接尝试失败。
pid=9176, ppid=8016, tid=9120
Traceback (most recent call last):
  File "C:\Users\comba\Desktop\KLC\knowledgeCity\common\modbusapi.py", line 35, in __execute
    data = self.master.execute(self.__salveId, fcode, start, quantity_of_x=num, output_value=value)
  File "C:\Users\comba\AppData\Local\Programs\Python\Python37\lib\site-packages\modbus_tk\utils.py", line 39, in new
    raise excpt
  File "C:\Users\comba\AppData\Local\Programs\Python\Python37\lib\site-packages\modbus_tk\utils.py", line 37, in new
    ret = fcn(*args, **kwargs)
  File "C:\Users\comba\AppData\Local\Programs\Python\Python37\lib\site-packages\modbus_tk\modbus.py", line 152, in execute
    self.open()
  File "C:\Users\comba\AppData\Local\Programs\Python\Python37\lib\site-packages\modbus_tk\modbus.py", line 99, in open
    self._do_open()
  File "C:\Users\comba\AppData\Local\Programs\Python\Python37\lib\site-packages\modbus_tk\modbus_tcp.py", line 173, in _do_open
    self._sock.connect((self._host, self._port))
TimeoutError: [WinError 10060] 由于连接方在一段时间后没有正确答复或连接的主机没有反应，连接尝试失败。

[CRITICAL]2021-06-03 13:25:30,379: 3FLamp writeDO fail cause a error: [WinError 10060] 由于连接方在一段时间后没有正确答复或连接的主机没有反应，连接尝试失败。
pid=9176, ppid=8016, tid=9120
Traceback (most recent call last):
  File "..\remoteio\remoteioMgr_old.py", line 109, in writeDO
    self._write(ioAddr, value)
  File "C:\Users\comba\Desktop\KLC\knowledgeCity\common\lock.py", line 122, in _call
    return func(*p,**pp)
  File "..\remoteio\remoteioMgr_old.py", line 186, in _write
    s = self.master.write(mdef.WRITE_SINGLE_COIL,addr,value)
  File "C:\Users\comba\Desktop\KLC\knowledgeCity\common\modbusapi.py", line 51, in write
    return self.__execute(fcode, start, num, value)
  File "C:\Users\comba\Desktop\KLC\knowledgeCity\common\modbusapi.py", line 35, in __execute
    data = self.master.execute(self.__salveId, fcode, start, quantity_of_x=num, output_value=value)
  File "C:\Users\comba\AppData\Local\Programs\Python\Python37\lib\site-packages\modbus_tk\utils.py", line 39, in new
    raise excpt
  File "C:\Users\comba\AppData\Local\Programs\Python\Python37\lib\site-packages\modbus_tk\utils.py", line 37, in new
    ret = fcn(*args, **kwargs)
  File "C:\Users\comba\AppData\Local\Programs\Python\Python37\lib\site-packages\modbus_tk\modbus.py", line 152, in execute
    self.open()
  File "C:\Users\comba\AppData\Local\Programs\Python\Python37\lib\site-packages\modbus_tk\modbus.py", line 99, in open
    self._do_open()
  File "C:\Users\comba\AppData\Local\Programs\Python\Python37\lib\site-packages\modbus_tk\modbus_tcp.py", line 173, in _do_open
    self._sock.connect((self._host, self._port))
TimeoutError: [WinError 10060] 由于连接方在一段时间后没有正确答复或连接的主机没有反应，连接尝试失败。

[CRITICAL]2021-06-03 13:25:30,662: invoke timer func<function lock.<locals>.call.<locals>._call at 0x000002C6BCADB048> cause a error: [WinError 10060] 由于连接方在一段时间后没有正确答复或连接的主机没有反应，连接尝试失败。
pid=9176, ppid=8016, tid=9120
Traceback (most recent call last):
  File "C:\Users\comba\Desktop\KLC\knowledgeCity\common\mytimer.py", line 113, in _loop
    v.func(*v.args)
  File "C:\Users\comba\Desktop\KLC\knowledgeCity\common\lock.py", line 122, in _call
    return func(*p,**pp)
  File "C:\Users\comba\Desktop\KLC\knowledgeCity\autoCtrl\runTasks.py", line 257, in run
    checkLampStatus()
  File "C:\Users\comba\Desktop\KLC\knowledgeCity\autoCtrl\runTasks.py", line 188, in checkLampStatus
    ioMgr.writeDO('3FLamp', 1, 0)
  File "..\remoteio\remoteioMgr_old.py", line 65, in writeDO
    remoteioInfo.writeDO(index,value)
  File "..\remoteio\remoteioMgr_old.py", line 109, in writeDO
    self._write(ioAddr, value)
  File "C:\Users\comba\Desktop\KLC\knowledgeCity\common\lock.py", line 122, in _call
    return func(*p,**pp)
  File "..\remoteio\remoteioMgr_old.py", line 186, in _write
    s = self.master.write(mdef.WRITE_SINGLE_COIL,addr,value)
  File "C:\Users\comba\Desktop\KLC\knowledgeCity\common\modbusapi.py", line 51, in write
    return self.__execute(fcode, start, num, value)
  File "C:\Users\comba\Desktop\KLC\knowledgeCity\common\modbusapi.py", line 35, in __execute
    data = self.master.execute(self.__salveId, fcode, start, quantity_of_x=num, output_value=value)
  File "C:\Users\comba\AppData\Local\Programs\Python\Python37\lib\site-packages\modbus_tk\utils.py", line 39, in new
    raise excpt
  File "C:\Users\comba\AppData\Local\Programs\Python\Python37\lib\site-packages\modbus_tk\utils.py", line 37, in new
    ret = fcn(*args, **kwargs)
  File "C:\Users\comba\AppData\Local\Programs\Python\Python37\lib\site-packages\modbus_tk\modbus.py", line 152, in execute
    self.open()
  File "C:\Users\comba\AppData\Local\Programs\Python\Python37\lib\site-packages\modbus_tk\modbus.py", line 99, in open
    self._do_open()
  File "C:\Users\comba\AppData\Local\Programs\Python\Python37\lib\site-packages\modbus_tk\modbus_tcp.py", line 173, in _do_open
    self._sock.connect((self._host, self._port))
TimeoutError: [WinError 10060] 由于连接方在一段时间后没有正确答复或连接的主机没有反应，连接尝试失败。

[CRITICAL]2021-06-03 13:25:54,953: 3FLamp writeDO fail cause a error: [WinError 10060] 由于连接方在一段时间后没有正确答复或连接的主机没有反应，连接尝试失败。
pid=9176, ppid=8016, tid=9120
Traceback (most recent call last):
  File "..\remoteio\remoteioMgr_old.py", line 109, in writeDO
    self._write(ioAddr, value)
  File "C:\Users\comba\Desktop\KLC\knowledgeCity\common\lock.py", line 122, in _call
    return func(*p,**pp)
  File "..\remoteio\remoteioMgr_old.py", line 181, in _write
    self.master.open()
  File "C:\Users\comba\Desktop\KLC\knowledgeCity\common\modbusapi.py", line 60, in open
    self.master.open()
  File "C:\Users\comba\AppData\Local\Programs\Python\Python37\lib\site-packages\modbus_tk\modbus.py", line 99, in open
    self._do_open()
  File "C:\Users\comba\AppData\Local\Programs\Python\Python37\lib\site-packages\modbus_tk\modbus_tcp.py", line 173, in _do_open
    self._sock.connect((self._host, self._port))
TimeoutError: [WinError 10060] 由于连接方在一段时间后没有正确答复或连接的主机没有反应，连接尝试失败。

[CRITICAL]2021-06-03 13:25:55,171: invoke timer func<function lock.<locals>.call.<locals>._call at 0x000002C6BCADB048> cause a error: [WinError 10060] 由于连接方在一段时间后没有正确答复或连接的主机没有反应，连接尝试失败。
pid=9176, ppid=8016, tid=9120
Traceback (most recent call last):
  File "C:\Users\comba\Desktop\KLC\knowledgeCity\common\mytimer.py", line 113, in _loop
    v.func(*v.args)
  File "C:\Users\comba\Desktop\KLC\knowledgeCity\common\lock.py", line 122, in _call
    return func(*p,**pp)
  File "C:\Users\comba\Desktop\KLC\knowledgeCity\autoCtrl\runTasks.py", line 257, in run
    checkLampStatus()
  File "C:\Users\comba\Desktop\KLC\knowledgeCity\autoCtrl\runTasks.py", line 188, in checkLampStatus
    ioMgr.writeDO('3FLamp', 1, 0)
  File "..\remoteio\remoteioMgr_old.py", line 65, in writeDO
    remoteioInfo.writeDO(index,value)
  File "..\remoteio\remoteioMgr_old.py", line 109, in writeDO
    self._write(ioAddr, value)
  File "C:\Users\comba\Desktop\KLC\knowledgeCity\common\lock.py", line 122, in _call
    return func(*p,**pp)
  File "..\remoteio\remoteioMgr_old.py", line 181, in _write
    self.master.open()
  File "C:\Users\comba\Desktop\KLC\knowledgeCity\common\modbusapi.py", line 60, in open
    self.master.open()
  File "C:\Users\comba\AppData\Local\Programs\Python\Python37\lib\site-packages\modbus_tk\modbus.py", line 99, in open
    self._do_open()
  File "C:\Users\comba\AppData\Local\Programs\Python\Python37\lib\site-packages\modbus_tk\modbus_tcp.py", line 173, in _do_open
    self._sock.connect((self._host, self._port))
TimeoutError: [WinError 10060] 由于连接方在一段时间后没有正确答复或连接的主机没有反应，连接尝试失败。

[CRITICAL]2021-06-03 13:26:05,440: taskFunc2:task[60b867ca73dabd23d8631883][AGVwuliao] AP18(LM17) -> AP22(LM17) [checkOneLayerFinish] cause a error: name 'info' is not defined
pid=9176, ppid=8016, tid=7900
Traceback (most recent call last):
  File "C:\Users\comba\Desktop\KLC\knowledgeCity\autoCtrl\runTasks.py", line 1098, in _taskFunc
    elif not self.handle():
  File "C:\Users\comba\Desktop\KLC\knowledgeCity\common\lock.py", line 122, in _call
    return func(*p,**pp)
  File "C:\Users\comba\Desktop\KLC\knowledgeCity\autoCtrl\runTasks.py", line 748, in handle
    log,info('this')
NameError: name 'info' is not defined

[CRITICAL]2021-06-03 13:26:11,319: upStation01 init failed cause a error: ('http get', 'http://127.0.0.1:8999/api/remoteio/readDOList', {'id': 'upStation01'}, 'error:', 'timed out')
pid=9176, ppid=8016, tid=9120
Traceback (most recent call last):
  File "C:\Users\comba\Desktop\KLC\knowledgeCity\common\webutility.py", line 103, in http_get
    f = urllib.request.urlopen(u,timeout=timeout)
  File "C:\Users\comba\AppData\Local\Programs\Python\Python37\lib\urllib\request.py", line 222, in urlopen
    return opener.open(url, data, timeout)
  File "C:\Users\comba\AppData\Local\Programs\Python\Python37\lib\urllib\request.py", line 525, in open
    response = self._open(req, data)
  File "C:\Users\comba\AppData\Local\Programs\Python\Python37\lib\urllib\request.py", line 543, in _open
    '_open', req)
  File "C:\Users\comba\AppData\Local\Programs\Python\Python37\lib\urllib\request.py", line 503, in _call_chain
    result = func(*args)
  File "C:\Users\comba\AppData\Local\Programs\Python\Python37\lib\urllib\request.py", line 1345, in http_open
    return self.do_open(http.client.HTTPConnection, req)
  File "C:\Users\comba\AppData\Local\Programs\Python\Python37\lib\urllib\request.py", line 1320, in do_open
    r = h.getresponse()
  File "C:\Users\comba\AppData\Local\Programs\Python\Python37\lib\http\client.py", line 1321, in getresponse
    response.begin()
  File "C:\Users\comba\AppData\Local\Programs\Python\Python37\lib\http\client.py", line 296, in begin
    version, status, reason = self._read_status()
  File "C:\Users\comba\AppData\Local\Programs\Python\Python37\lib\http\client.py", line 257, in _read_status
    line = str(self.fp.readline(_MAXLINE + 1), "iso-8859-1")
  File "C:\Users\comba\AppData\Local\Programs\Python\Python37\lib\socket.py", line 589, in readinto
    return self._sock.recv_into(b)
socket.timeout: timed out

During handling of the above exception, another exception occurred:

Traceback (most recent call last):
  File "C:\Users\comba\Desktop\KLC\knowledgeCity\autoCtrl\deviceCtrl.py", line 175, in _checkInit
    s = ioApi.readDOList(devices[d][ioId])["status"]
  File "..\remoteio\remoteioApi.py", line 73, in readDOList
    return _remoteio('/api/remoteio/readDOList', id, param)
  File "..\remoteio\remoteioApi.py", line 100, in _remoteio
    return http_get(url + apiurl, param)
  File "..\remoteio\remoteioApi.py", line 16, in http_get
    r = webutility.http_get(url, param)
  File "C:\Users\comba\Desktop\KLC\knowledgeCity\common\webutility.py", line 105, in http_get
    raise Exception("http get",url,params,"error:",str(e))
Exception: ('http get', 'http://127.0.0.1:8999/api/remoteio/readDOList', {'id': 'upStation01'}, 'error:', 'timed out')

[CRITICAL]2021-06-03 13:26:17,159: [modbusApi: 172.16.167.221] execute fcode=1, addr=8256 exception:  cause a error: [WinError 10060] 由于连接方在一段时间后没有正确答复或连接的主机没有反应，连接尝试失败。
pid=9176, ppid=8016, tid=7196
Traceback (most recent call last):
  File "C:\Users\comba\Desktop\KLC\knowledgeCity\common\modbusapi.py", line 35, in __execute
    data = self.master.execute(self.__salveId, fcode, start, quantity_of_x=num, output_value=value)
  File "C:\Users\comba\AppData\Local\Programs\Python\Python37\lib\site-packages\modbus_tk\utils.py", line 39, in new
    raise excpt
  File "C:\Users\comba\AppData\Local\Programs\Python\Python37\lib\site-packages\modbus_tk\utils.py", line 37, in new
    ret = fcn(*args, **kwargs)
  File "C:\Users\comba\AppData\Local\Programs\Python\Python37\lib\site-packages\modbus_tk\modbus.py", line 152, in execute
    self.open()
  File "C:\Users\comba\AppData\Local\Programs\Python\Python37\lib\site-packages\modbus_tk\modbus.py", line 99, in open
    self._do_open()
  File "C:\Users\comba\AppData\Local\Programs\Python\Python37\lib\site-packages\modbus_tk\modbus_tcp.py", line 173, in _do_open
    self._sock.connect((self._host, self._port))
TimeoutError: [WinError 10060] 由于连接方在一段时间后没有正确答复或连接的主机没有反应，连接尝试失败。

[CRITICAL]2021-06-03 13:26:17,451: upStation01 readDIList fail cause a error: [WinError 10060] 由于连接方在一段时间后没有正确答复或连接的主机没有反应，连接尝试失败。
pid=9176, ppid=8016, tid=7196
Traceback (most recent call last):
  File "..\remoteio\remoteioMgr.py", line 266, in readDOList
    return self._read(M30, IO_LENTH)
  File "C:\Users\comba\Desktop\KLC\knowledgeCity\common\lock.py", line 122, in _call
    return func(*p,**pp)
  File "..\remoteio\remoteioMgr.py", line 318, in _read
    s = self.master.read(mdef.READ_COILS,addr, length)
  File "C:\Users\comba\Desktop\KLC\knowledgeCity\common\modbusapi.py", line 45, in read
    return self.__execute(fcode, start, num)
  File "C:\Users\comba\Desktop\KLC\knowledgeCity\common\modbusapi.py", line 35, in __execute
    data = self.master.execute(self.__salveId, fcode, start, quantity_of_x=num, output_value=value)
  File "C:\Users\comba\AppData\Local\Programs\Python\Python37\lib\site-packages\modbus_tk\utils.py", line 39, in new
    raise excpt
  File "C:\Users\comba\AppData\Local\Programs\Python\Python37\lib\site-packages\modbus_tk\utils.py", line 37, in new
    ret = fcn(*args, **kwargs)
  File "C:\Users\comba\AppData\Local\Programs\Python\Python37\lib\site-packages\modbus_tk\modbus.py", line 152, in execute
    self.open()
  File "C:\Users\comba\AppData\Local\Programs\Python\Python37\lib\site-packages\modbus_tk\modbus.py", line 99, in open
    self._do_open()
  File "C:\Users\comba\AppData\Local\Programs\Python\Python37\lib\site-packages\modbus_tk\modbus_tcp.py", line 173, in _do_open
    self._sock.connect((self._host, self._port))
TimeoutError: [WinError 10060] 由于连接方在一段时间后没有正确答复或连接的主机没有反应，连接尝试失败。

[CRITICAL]2021-06-03 13:26:17,560: invoke <function urlReadDOList at 0x000002C6BB57DBF8> cause a error: [WinError 10060] 由于连接方在一段时间后没有正确答复或连接的主机没有反应，连接尝试失败。
pid=9176, ppid=8016, tid=7196
Traceback (most recent call last):
  File "C:\Users\comba\Desktop\KLC\knowledgeCity\common\scadaUtility.py", line 45, in __call
    ret = func(*p,**pp)
  File "C:\Users\comba\Desktop\KLC\knowledgeCity\remoteio\main_remoteio.py", line 109, in urlReadDOList
    return ioMgr.readDOList(id)
  File "..\remoteio\remoteioMgr.py", line 162, in readDOList
    result=remoteioInfo.readDOList()
  File "..\remoteio\remoteioMgr.py", line 266, in readDOList
    return self._read(M30, IO_LENTH)
  File "C:\Users\comba\Desktop\KLC\knowledgeCity\common\lock.py", line 122, in _call
    return func(*p,**pp)
  File "..\remoteio\remoteioMgr.py", line 318, in _read
    s = self.master.read(mdef.READ_COILS,addr, length)
  File "C:\Users\comba\Desktop\KLC\knowledgeCity\common\modbusapi.py", line 45, in read
    return self.__execute(fcode, start, num)
  File "C:\Users\comba\Desktop\KLC\knowledgeCity\common\modbusapi.py", line 35, in __execute
    data = self.master.execute(self.__salveId, fcode, start, quantity_of_x=num, output_value=value)
  File "C:\Users\comba\AppData\Local\Programs\Python\Python37\lib\site-packages\modbus_tk\utils.py", line 39, in new
    raise excpt
  File "C:\Users\comba\AppData\Local\Programs\Python\Python37\lib\site-packages\modbus_tk\utils.py", line 37, in new
    ret = fcn(*args, **kwargs)
  File "C:\Users\comba\AppData\Local\Programs\Python\Python37\lib\site-packages\modbus_tk\modbus.py", line 152, in execute
    self.open()
  File "C:\Users\comba\AppData\Local\Programs\Python\Python37\lib\site-packages\modbus_tk\modbus.py", line 99, in open
    self._do_open()
  File "C:\Users\comba\AppData\Local\Programs\Python\Python37\lib\site-packages\modbus_tk\modbus_tcp.py", line 173, in _do_open
    self._sock.connect((self._host, self._port))
TimeoutError: [WinError 10060] 由于连接方在一段时间后没有正确答复或连接的主机没有反应，连接尝试失败。

[CRITICAL]2021-06-03 13:26:27,547: downStation01 init failed cause a error: ('http get', 'http://127.0.0.1:8999/api/remoteio/readDOList', {'id': 'downStation01'}, 'error:', 'timed out')
pid=9176, ppid=8016, tid=9120
Traceback (most recent call last):
  File "C:\Users\comba\Desktop\KLC\knowledgeCity\common\webutility.py", line 103, in http_get
    f = urllib.request.urlopen(u,timeout=timeout)
  File "C:\Users\comba\AppData\Local\Programs\Python\Python37\lib\urllib\request.py", line 222, in urlopen
    return opener.open(url, data, timeout)
  File "C:\Users\comba\AppData\Local\Programs\Python\Python37\lib\urllib\request.py", line 525, in open
    response = self._open(req, data)
  File "C:\Users\comba\AppData\Local\Programs\Python\Python37\lib\urllib\request.py", line 543, in _open
    '_open', req)
  File "C:\Users\comba\AppData\Local\Programs\Python\Python37\lib\urllib\request.py", line 503, in _call_chain
    result = func(*args)
  File "C:\Users\comba\AppData\Local\Programs\Python\Python37\lib\urllib\request.py", line 1345, in http_open
    return self.do_open(http.client.HTTPConnection, req)
  File "C:\Users\comba\AppData\Local\Programs\Python\Python37\lib\urllib\request.py", line 1320, in do_open
    r = h.getresponse()
  File "C:\Users\comba\AppData\Local\Programs\Python\Python37\lib\http\client.py", line 1321, in getresponse
    response.begin()
  File "C:\Users\comba\AppData\Local\Programs\Python\Python37\lib\http\client.py", line 296, in begin
    version, status, reason = self._read_status()
  File "C:\Users\comba\AppData\Local\Programs\Python\Python37\lib\http\client.py", line 257, in _read_status
    line = str(self.fp.readline(_MAXLINE + 1), "iso-8859-1")
  File "C:\Users\comba\AppData\Local\Programs\Python\Python37\lib\socket.py", line 589, in readinto
    return self._sock.recv_into(b)
socket.timeout: timed out

During handling of the above exception, another exception occurred:

Traceback (most recent call last):
  File "C:\Users\comba\Desktop\KLC\knowledgeCity\autoCtrl\deviceCtrl.py", line 175, in _checkInit
    s = ioApi.readDOList(devices[d][ioId])["status"]
  File "..\remoteio\remoteioApi.py", line 73, in readDOList
    return _remoteio('/api/remoteio/readDOList', id, param)
  File "..\remoteio\remoteioApi.py", line 100, in _remoteio
    return http_get(url + apiurl, param)
  File "..\remoteio\remoteioApi.py", line 16, in http_get
    r = webutility.http_get(url, param)
  File "C:\Users\comba\Desktop\KLC\knowledgeCity\common\webutility.py", line 105, in http_get
    raise Exception("http get",url,params,"error:",str(e))
Exception: ('http get', 'http://127.0.0.1:8999/api/remoteio/readDOList', {'id': 'downStation01'}, 'error:', 'timed out')

[CRITICAL]2021-06-03 13:26:38,170: [modbusApi: 172.16.167.220] execute fcode=1, addr=8256 exception:  cause a error: [WinError 10060] 由于连接方在一段时间后没有正确答复或连接的主机没有反应，连接尝试失败。
pid=9176, ppid=8016, tid=3744
Traceback (most recent call last):
  File "C:\Users\comba\Desktop\KLC\knowledgeCity\common\modbusapi.py", line 35, in __execute
    data = self.master.execute(self.__salveId, fcode, start, quantity_of_x=num, output_value=value)
  File "C:\Users\comba\AppData\Local\Programs\Python\Python37\lib\site-packages\modbus_tk\utils.py", line 39, in new
    raise excpt
  File "C:\Users\comba\AppData\Local\Programs\Python\Python37\lib\site-packages\modbus_tk\utils.py", line 37, in new
    ret = fcn(*args, **kwargs)
  File "C:\Users\comba\AppData\Local\Programs\Python\Python37\lib\site-packages\modbus_tk\modbus.py", line 152, in execute
    self.open()
  File "C:\Users\comba\AppData\Local\Programs\Python\Python37\lib\site-packages\modbus_tk\modbus.py", line 99, in open
    self._do_open()
  File "C:\Users\comba\AppData\Local\Programs\Python\Python37\lib\site-packages\modbus_tk\modbus_tcp.py", line 173, in _do_open
    self._sock.connect((self._host, self._port))
TimeoutError: [WinError 10060] 由于连接方在一段时间后没有正确答复或连接的主机没有反应，连接尝试失败。

[CRITICAL]2021-06-03 13:26:38,392: downStation01 readDIList fail cause a error: [WinError 10060] 由于连接方在一段时间后没有正确答复或连接的主机没有反应，连接尝试失败。
pid=9176, ppid=8016, tid=3744
Traceback (most recent call last):
  File "..\remoteio\remoteioMgr.py", line 266, in readDOList
    return self._read(M30, IO_LENTH)
  File "C:\Users\comba\Desktop\KLC\knowledgeCity\common\lock.py", line 122, in _call
    return func(*p,**pp)
  File "..\remoteio\remoteioMgr.py", line 318, in _read
    s = self.master.read(mdef.READ_COILS,addr, length)
  File "C:\Users\comba\Desktop\KLC\knowledgeCity\common\modbusapi.py", line 45, in read
    return self.__execute(fcode, start, num)
  File "C:\Users\comba\Desktop\KLC\knowledgeCity\common\modbusapi.py", line 35, in __execute
    data = self.master.execute(self.__salveId, fcode, start, quantity_of_x=num, output_value=value)
  File "C:\Users\comba\AppData\Local\Programs\Python\Python37\lib\site-packages\modbus_tk\utils.py", line 39, in new
    raise excpt
  File "C:\Users\comba\AppData\Local\Programs\Python\Python37\lib\site-packages\modbus_tk\utils.py", line 37, in new
    ret = fcn(*args, **kwargs)
  File "C:\Users\comba\AppData\Local\Programs\Python\Python37\lib\site-packages\modbus_tk\modbus.py", line 152, in execute
    self.open()
  File "C:\Users\comba\AppData\Local\Programs\Python\Python37\lib\site-packages\modbus_tk\modbus.py", line 99, in open
    self._do_open()
  File "C:\Users\comba\AppData\Local\Programs\Python\Python37\lib\site-packages\modbus_tk\modbus_tcp.py", line 173, in _do_open
    self._sock.connect((self._host, self._port))
TimeoutError: [WinError 10060] 由于连接方在一段时间后没有正确答复或连接的主机没有反应，连接尝试失败。

[CRITICAL]2021-06-03 13:26:38,467: invoke <function urlReadDOList at 0x000002C6BB57DBF8> cause a error: [WinError 10060] 由于连接方在一段时间后没有正确答复或连接的主机没有反应，连接尝试失败。
pid=9176, ppid=8016, tid=3744
Traceback (most recent call last):
  File "C:\Users\comba\Desktop\KLC\knowledgeCity\common\scadaUtility.py", line 45, in __call
    ret = func(*p,**pp)
  File "C:\Users\comba\Desktop\KLC\knowledgeCity\remoteio\main_remoteio.py", line 109, in urlReadDOList
    return ioMgr.readDOList(id)
  File "..\remoteio\remoteioMgr.py", line 162, in readDOList
    result=remoteioInfo.readDOList()
  File "..\remoteio\remoteioMgr.py", line 266, in readDOList
    return self._read(M30, IO_LENTH)
  File "C:\Users\comba\Desktop\KLC\knowledgeCity\common\lock.py", line 122, in _call
    return func(*p,**pp)
  File "..\remoteio\remoteioMgr.py", line 318, in _read
    s = self.master.read(mdef.READ_COILS,addr, length)
  File "C:\Users\comba\Desktop\KLC\knowledgeCity\common\modbusapi.py", line 45, in read
    return self.__execute(fcode, start, num)
  File "C:\Users\comba\Desktop\KLC\knowledgeCity\common\modbusapi.py", line 35, in __execute
    data = self.master.execute(self.__salveId, fcode, start, quantity_of_x=num, output_value=value)
  File "C:\Users\comba\AppData\Local\Programs\Python\Python37\lib\site-packages\modbus_tk\utils.py", line 39, in new
    raise excpt
  File "C:\Users\comba\AppData\Local\Programs\Python\Python37\lib\site-packages\modbus_tk\utils.py", line 37, in new
    ret = fcn(*args, **kwargs)
  File "C:\Users\comba\AppData\Local\Programs\Python\Python37\lib\site-packages\modbus_tk\modbus.py", line 152, in execute
    self.open()
  File "C:\Users\comba\AppData\Local\Programs\Python\Python37\lib\site-packages\modbus_tk\modbus.py", line 99, in open
    self._do_open()
  File "C:\Users\comba\AppData\Local\Programs\Python\Python37\lib\site-packages\modbus_tk\modbus_tcp.py", line 173, in _do_open
    self._sock.connect((self._host, self._port))
TimeoutError: [WinError 10060] 由于连接方在一段时间后没有正确答复或连接的主机没有反应，连接尝试失败。

[CRITICAL]2021-06-03 13:26:43,767: readDIList error cause a error: ('http get', 'http://127.0.0.1:8999/api/remoteio/readDOList', {'id': 'upStation01'}, 'error:', 'timed out')
pid=9176, ppid=8016, tid=9120
Traceback (most recent call last):
  File "C:\Users\comba\Desktop\KLC\knowledgeCity\common\webutility.py", line 103, in http_get
    f = urllib.request.urlopen(u,timeout=timeout)
  File "C:\Users\comba\AppData\Local\Programs\Python\Python37\lib\urllib\request.py", line 222, in urlopen
    return opener.open(url, data, timeout)
  File "C:\Users\comba\AppData\Local\Programs\Python\Python37\lib\urllib\request.py", line 525, in open
    response = self._open(req, data)
  File "C:\Users\comba\AppData\Local\Programs\Python\Python37\lib\urllib\request.py", line 543, in _open
    '_open', req)
  File "C:\Users\comba\AppData\Local\Programs\Python\Python37\lib\urllib\request.py", line 503, in _call_chain
    result = func(*args)
  File "C:\Users\comba\AppData\Local\Programs\Python\Python37\lib\urllib\request.py", line 1345, in http_open
    return self.do_open(http.client.HTTPConnection, req)
  File "C:\Users\comba\AppData\Local\Programs\Python\Python37\lib\urllib\request.py", line 1320, in do_open
    r = h.getresponse()
  File "C:\Users\comba\AppData\Local\Programs\Python\Python37\lib\http\client.py", line 1321, in getresponse
    response.begin()
  File "C:\Users\comba\AppData\Local\Programs\Python\Python37\lib\http\client.py", line 296, in begin
    version, status, reason = self._read_status()
  File "C:\Users\comba\AppData\Local\Programs\Python\Python37\lib\http\client.py", line 257, in _read_status
    line = str(self.fp.readline(_MAXLINE + 1), "iso-8859-1")
  File "C:\Users\comba\AppData\Local\Programs\Python\Python37\lib\socket.py", line 589, in readinto
    return self._sock.recv_into(b)
socket.timeout: timed out

During handling of the above exception, another exception occurred:

Traceback (most recent call last):
  File "C:\Users\comba\Desktop\KLC\knowledgeCity\autoCtrl\deviceCtrl.py", line 71, in _monitorDevices
    s1 = ioApi.readDOList(devices[d]["io1"])["status"] #上板机
  File "..\remoteio\remoteioApi.py", line 73, in readDOList
    return _remoteio('/api/remoteio/readDOList', id, param)
  File "..\remoteio\remoteioApi.py", line 100, in _remoteio
    return http_get(url + apiurl, param)
  File "..\remoteio\remoteioApi.py", line 16, in http_get
    r = webutility.http_get(url, param)
  File "C:\Users\comba\Desktop\KLC\knowledgeCity\common\webutility.py", line 105, in http_get
    raise Exception("http get",url,params,"error:",str(e))
Exception: ('http get', 'http://127.0.0.1:8999/api/remoteio/readDOList', {'id': 'upStation01'}, 'error:', 'timed out')

[CRITICAL]2021-06-03 13:26:49,932: upStation01 readDIList fail cause a error: [WinError 10060] 由于连接方在一段时间后没有正确答复或连接的主机没有反应，连接尝试失败。
pid=9176, ppid=8016, tid=8988
Traceback (most recent call last):
  File "..\remoteio\remoteioMgr.py", line 266, in readDOList
    return self._read(M30, IO_LENTH)
  File "C:\Users\comba\Desktop\KLC\knowledgeCity\common\lock.py", line 122, in _call
    return func(*p,**pp)
  File "..\remoteio\remoteioMgr.py", line 315, in _read
    self.master.open()
  File "C:\Users\comba\Desktop\KLC\knowledgeCity\common\modbusapi.py", line 60, in open
    self.master.open()
  File "C:\Users\comba\AppData\Local\Programs\Python\Python37\lib\site-packages\modbus_tk\modbus.py", line 99, in open
    self._do_open()
  File "C:\Users\comba\AppData\Local\Programs\Python\Python37\lib\site-packages\modbus_tk\modbus_tcp.py", line 173, in _do_open
    self._sock.connect((self._host, self._port))
TimeoutError: [WinError 10060] 由于连接方在一段时间后没有正确答复或连接的主机没有反应，连接尝试失败。

[CRITICAL]2021-06-03 13:26:50,030: invoke <function urlReadDOList at 0x000002C6BB57DBF8> cause a error: [WinError 10060] 由于连接方在一段时间后没有正确答复或连接的主机没有反应，连接尝试失败。
pid=9176, ppid=8016, tid=8988
Traceback (most recent call last):
  File "C:\Users\comba\Desktop\KLC\knowledgeCity\common\scadaUtility.py", line 45, in __call
    ret = func(*p,**pp)
  File "C:\Users\comba\Desktop\KLC\knowledgeCity\remoteio\main_remoteio.py", line 109, in urlReadDOList
    return ioMgr.readDOList(id)
  File "..\remoteio\remoteioMgr.py", line 162, in readDOList
    result=remoteioInfo.readDOList()
  File "..\remoteio\remoteioMgr.py", line 266, in readDOList
    return self._read(M30, IO_LENTH)
  File "C:\Users\comba\Desktop\KLC\knowledgeCity\common\lock.py", line 122, in _call
    return func(*p,**pp)
  File "..\remoteio\remoteioMgr.py", line 315, in _read
    self.master.open()
  File "C:\Users\comba\Desktop\KLC\knowledgeCity\common\modbusapi.py", line 60, in open
    self.master.open()
  File "C:\Users\comba\AppData\Local\Programs\Python\Python37\lib\site-packages\modbus_tk\modbus.py", line 99, in open
    self._do_open()
  File "C:\Users\comba\AppData\Local\Programs\Python\Python37\lib\site-packages\modbus_tk\modbus_tcp.py", line 173, in _do_open
    self._sock.connect((self._host, self._port))
TimeoutError: [WinError 10060] 由于连接方在一段时间后没有正确答复或连接的主机没有反应，连接尝试失败。

[CRITICAL]2021-06-03 13:27:54,474: 3FLamp writeDO fail cause a error: [WinError 10060] 由于连接方在一段时间后没有正确答复或连接的主机没有反应，连接尝试失败。
pid=9176, ppid=8016, tid=9120
Traceback (most recent call last):
  File "..\remoteio\remoteioMgr_old.py", line 109, in writeDO
    self._write(ioAddr, value)
  File "C:\Users\comba\Desktop\KLC\knowledgeCity\common\lock.py", line 122, in _call
    return func(*p,**pp)
  File "..\remoteio\remoteioMgr_old.py", line 181, in _write
    self.master.open()
  File "C:\Users\comba\Desktop\KLC\knowledgeCity\common\modbusapi.py", line 60, in open
    self.master.open()
  File "C:\Users\comba\AppData\Local\Programs\Python\Python37\lib\site-packages\modbus_tk\modbus.py", line 99, in open
    self._do_open()
  File "C:\Users\comba\AppData\Local\Programs\Python\Python37\lib\site-packages\modbus_tk\modbus_tcp.py", line 173, in _do_open
    self._sock.connect((self._host, self._port))
TimeoutError: [WinError 10060] 由于连接方在一段时间后没有正确答复或连接的主机没有反应，连接尝试失败。

[CRITICAL]2021-06-03 13:27:54,873: invoke timer func<function lock.<locals>.call.<locals>._call at 0x000002C6BCADB048> cause a error: [WinError 10060] 由于连接方在一段时间后没有正确答复或连接的主机没有反应，连接尝试失败。
pid=9176, ppid=8016, tid=9120
Traceback (most recent call last):
  File "C:\Users\comba\Desktop\KLC\knowledgeCity\common\mytimer.py", line 113, in _loop
    v.func(*v.args)
  File "C:\Users\comba\Desktop\KLC\knowledgeCity\common\lock.py", line 122, in _call
    return func(*p,**pp)
  File "C:\Users\comba\Desktop\KLC\knowledgeCity\autoCtrl\runTasks.py", line 257, in run
    checkLampStatus()
  File "C:\Users\comba\Desktop\KLC\knowledgeCity\autoCtrl\runTasks.py", line 188, in checkLampStatus
    ioMgr.writeDO('3FLamp', 1, 0)
  File "..\remoteio\remoteioMgr_old.py", line 65, in writeDO
    remoteioInfo.writeDO(index,value)
  File "..\remoteio\remoteioMgr_old.py", line 109, in writeDO
    self._write(ioAddr, value)
  File "C:\Users\comba\Desktop\KLC\knowledgeCity\common\lock.py", line 122, in _call
    return func(*p,**pp)
  File "..\remoteio\remoteioMgr_old.py", line 181, in _write
    self.master.open()
  File "C:\Users\comba\Desktop\KLC\knowledgeCity\common\modbusapi.py", line 60, in open
    self.master.open()
  File "C:\Users\comba\AppData\Local\Programs\Python\Python37\lib\site-packages\modbus_tk\modbus.py", line 99, in open
    self._do_open()
  File "C:\Users\comba\AppData\Local\Programs\Python\Python37\lib\site-packages\modbus_tk\modbus_tcp.py", line 173, in _do_open
    self._sock.connect((self._host, self._port))
TimeoutError: [WinError 10060] 由于连接方在一段时间后没有正确答复或连接的主机没有反应，连接尝试失败。

