[CRITICAL]2021-04-06 13:01:42,479: agvApi step callback cause a error: 'dict' object is not callable
pid=16068, ppid=15228, tid=3564
Traceback (most recent call last):
  File "E:\安捷利电梯项目\AKMfloor\agvCtrl\agvApi.py", line 261, in _checkFinish
    t.stepCallback(t.params,t.status)
TypeError: 'dict' object is not callable

[CRITICAL]2021-04-06 13:01:45,079: agvApi step callback cause a error: 'dict' object is not callable
pid=16068, ppid=15228, tid=3564
Traceback (most recent call last):
  File "E:\安捷利电梯项目\AKMfloor\agvCtrl\agvApi.py", line 261, in _checkFinish
    t.stepCallback(t.params,t.status)
TypeError: 'dict' object is not callable

[CRITICAL]2021-04-06 13:01:55,494: agvApi step callback cause a error: 'dict' object is not callable
pid=16068, ppid=15228, tid=3564
Traceback (most recent call last):
  File "E:\安捷利电梯项目\AKMfloor\agvCtrl\agvApi.py", line 261, in _checkFinish
    t.stepCallback(t.params,t.status)
TypeError: 'dict' object is not callable

[CRITICAL]2021-04-06 13:02:07,908: agvApi step callback cause a error: 'dict' object is not callable
pid=16068, ppid=15228, tid=3564
Traceback (most recent call last):
  File "E:\安捷利电梯项目\AKMfloor\agvCtrl\agvApi.py", line 261, in _checkFinish
    t.stepCallback(t.params,t.status)
TypeError: 'dict' object is not callable

