[CRITICAL]2021-03-31 15:42:40,031: agvApi step callback cause a error: 'dict' object is not callable
pid=17948, ppid=10228, tid=16424
Traceback (most recent call last):
  File "E:\安捷利电梯项目\AKMfloor\agvCtrl\agvApi.py", line 261, in _checkFinish
    t.stepCallback(t.params,t.status)
TypeError: 'dict' object is not callable

[CRITICAL]2021-03-31 15:42:41,081: agvApi step callback cause a error: 'dict' object is not callable
pid=17948, ppid=10228, tid=16424
Traceback (most recent call last):
  File "E:\安捷利电梯项目\AKMfloor\agvCtrl\agvApi.py", line 261, in _checkFinish
    t.stepCallback(t.params,t.status)
TypeError: 'dict' object is not callable

[CRITICAL]2021-03-31 15:42:53,515: agvApi step callback cause a error: 'dict' object is not callable
pid=17948, ppid=10228, tid=16424
Traceback (most recent call last):
  File "E:\安捷利电梯项目\AKMfloor\agvCtrl\agvApi.py", line 261, in _checkFinish
    t.stepCallback(t.params,t.status)
TypeError: 'dict' object is not callable

[CRITICAL]2021-03-31 15:42:56,114: agvApi step callback cause a error: 'dict' object is not callable
pid=17948, ppid=10228, tid=16424
Traceback (most recent call last):
  File "E:\安捷利电梯项目\AKMfloor\agvCtrl\agvApi.py", line 261, in _checkFinish
    t.stepCallback(t.params,t.status)
TypeError: 'dict' object is not callable

[CRITICAL]2021-03-31 15:42:57,164: agvApi step callback cause a error: 'dict' object is not callable
pid=17948, ppid=10228, tid=16424
Traceback (most recent call last):
  File "E:\安捷利电梯项目\AKMfloor\agvCtrl\agvApi.py", line 261, in _checkFinish
    t.stepCallback(t.params,t.status)
TypeError: 'dict' object is not callable

[CRITICAL]2021-03-31 15:43:08,612: agvApi step callback cause a error: 'dict' object is not callable
pid=17948, ppid=10228, tid=16424
Traceback (most recent call last):
  File "E:\安捷利电梯项目\AKMfloor\agvCtrl\agvApi.py", line 261, in _checkFinish
    t.stepCallback(t.params,t.status)
TypeError: 'dict' object is not callable

[CRITICAL]2021-03-31 15:43:24,159: agvApi step callback cause a error: 'dict' object is not callable
pid=17948, ppid=10228, tid=16424
Traceback (most recent call last):
  File "E:\安捷利电梯项目\AKMfloor\agvCtrl\agvApi.py", line 261, in _checkFinish
    t.stepCallback(t.params,t.status)
TypeError: 'dict' object is not callable

[CRITICAL]2021-03-31 15:43:35,076: agvApi step callback cause a error: 'dict' object is not callable
pid=17948, ppid=10228, tid=16424
Traceback (most recent call last):
  File "E:\安捷利电梯项目\AKMfloor\agvCtrl\agvApi.py", line 261, in _checkFinish
    t.stepCallback(t.params,t.status)
TypeError: 'dict' object is not callable

[CRITICAL]2021-03-31 15:43:36,138: agvApi step callback cause a error: 'dict' object is not callable
pid=17948, ppid=10228, tid=16424
Traceback (most recent call last):
  File "E:\安捷利电梯项目\AKMfloor\agvCtrl\agvApi.py", line 261, in _checkFinish
    t.stepCallback(t.params,t.status)
TypeError: 'dict' object is not callable

[CRITICAL]2021-03-31 15:43:49,623: agvApi step callback cause a error: 'dict' object is not callable
pid=17948, ppid=10228, tid=16424
Traceback (most recent call last):
  File "E:\安捷利电梯项目\AKMfloor\agvCtrl\agvApi.py", line 261, in _checkFinish
    t.stepCallback(t.params,t.status)
TypeError: 'dict' object is not callable

[CRITICAL]2021-03-31 15:43:50,692: agvApi step callback cause a error: 'dict' object is not callable
pid=17948, ppid=10228, tid=16424
Traceback (most recent call last):
  File "E:\安捷利电梯项目\AKMfloor\agvCtrl\agvApi.py", line 261, in _checkFinish
    t.stepCallback(t.params,t.status)
TypeError: 'dict' object is not callable

[CRITICAL]2021-03-31 15:44:02,173: agvApi step callback cause a error: 'dict' object is not callable
pid=17948, ppid=10228, tid=16424
Traceback (most recent call last):
  File "E:\安捷利电梯项目\AKMfloor\agvCtrl\agvApi.py", line 261, in _checkFinish
    t.stepCallback(t.params,t.status)
TypeError: 'dict' object is not callable

