[CRITICAL]2021-04-20 17:20:41,985: agvApi step callback cause a error: 'dict' object is not callable
pid=11440, ppid=5756, tid=13308
Traceback (most recent call last):
  File "..\agvCtrl\agvApi.py", line 261, in _checkFinish
    t.stepCallback(t.params,t.status)
TypeError: 'dict' object is not callable

[CRITICAL]2021-04-20 17:20:41,985: agvApi step callback cause a error: 'dict' object is not callable
pid=11440, ppid=5756, tid=13308
Traceback (most recent call last):
  File "..\agvCtrl\agvApi.py", line 261, in _checkFinish
    t.stepCallback(t.params,t.status)
TypeError: 'dict' object is not callable

[CRITICAL]2021-04-20 17:20:44,094: agvApi step callback cause a error: 'dict' object is not callable
pid=11440, ppid=5756, tid=13308
Traceback (most recent call last):
  File "..\agvCtrl\agvApi.py", line 261, in _checkFinish
    t.stepCallback(t.params,t.status)
TypeError: 'dict' object is not callable

[CRITICAL]2021-04-20 17:20:44,094: agvApi step callback cause a error: 'dict' object is not callable
pid=11440, ppid=5756, tid=13308
Traceback (most recent call last):
  File "..\agvCtrl\agvApi.py", line 261, in _checkFinish
    t.stepCallback(t.params,t.status)
TypeError: 'dict' object is not callable

[CRITICAL]2021-04-20 17:20:46,186: agvApi step callback cause a error: 'dict' object is not callable
pid=11440, ppid=5756, tid=13308
Traceback (most recent call last):
  File "..\agvCtrl\agvApi.py", line 261, in _checkFinish
    t.stepCallback(t.params,t.status)
TypeError: 'dict' object is not callable

[CRITICAL]2021-04-20 17:20:46,186: agvApi step callback cause a error: 'dict' object is not callable
pid=11440, ppid=5756, tid=13308
Traceback (most recent call last):
  File "..\agvCtrl\agvApi.py", line 261, in _checkFinish
    t.stepCallback(t.params,t.status)
TypeError: 'dict' object is not callable

[CRITICAL]2021-04-20 17:20:48,284: agvApi step callback cause a error: 'dict' object is not callable
pid=11440, ppid=5756, tid=13308
Traceback (most recent call last):
  File "..\agvCtrl\agvApi.py", line 261, in _checkFinish
    t.stepCallback(t.params,t.status)
TypeError: 'dict' object is not callable

[CRITICAL]2021-04-20 17:20:48,284: agvApi step callback cause a error: 'dict' object is not callable
pid=11440, ppid=5756, tid=13308
Traceback (most recent call last):
  File "..\agvCtrl\agvApi.py", line 261, in _checkFinish
    t.stepCallback(t.params,t.status)
TypeError: 'dict' object is not callable

