[CRITICAL]2021-06-10 23:16:12,351: import main_feed failed, path: feed cause a error: timed out
pid=11852, ppid=18164, tid=22108
Traceback (most recent call last):
  File "run_all.py", line 39, in findModule
    __import__(m[1])
  File "C:\Users\Administrator\Desktop\SVN\√¿Œ¨\MeiWei_back_0421\feed\main_feed.py", line 363, in <module>
    main()
  File "C:\Users\Administrator\Desktop\SVN\√¿Œ¨\MeiWei_back_0421\feed\main_feed.py", line 254, in main
    EasySocket('127.0.0.1', 10001)
  File "C:\Users\Administrator\Desktop\SVN\√¿Œ¨\MeiWei_back_0421\feed\main_feed.py", line 242, in EasySocket
    clientSocket, clientInfo = serverSocket.accept()
  File "C:\Python37\lib\socket.py", line 212, in accept
    fd, addr = self._accept()
socket.timeout: timed out

[CRITICAL]2021-06-10 23:16:12,356: import main_feed failed, path: feed ,cause timed out
