[INFO]2021-03-26 13:09:32,938: log files at D:\python_work\AKMfloor\common\log
[INFO]2021-03-26 13:09:32,939: find module account.main_account
[INFO]2021-03-26 13:09:32,939: find module agvCtrl.main_agv
[INFO]2021-03-26 13:09:32,939: find module agvDevice.main_agvDevice
[INFO]2021-03-26 13:09:32,939: find module alarm.main_alarm
[INFO]2021-03-26 13:09:32,939: find module auth.main_auth
[INFO]2021-03-26 13:09:32,940: find module door.main_door
[INFO]2021-03-26 13:09:32,940: find module elevator.main_elevator
[INFO]2021-03-26 13:09:32,940: find module feed.main_feed
[INFO]2021-03-26 13:09:32,940: find module menu.main_menu
[INFO]2021-03-26 13:09:32,941: find module pharmapackCtrl.main_scadaCtrl
[INFO]2021-03-26 13:09:32,941: find module webFront.main_web
[INFO]2021-03-26 13:09:32,941: find module wmqtt.main_wmqtt
[INFO]2021-03-26 13:09:32,941: import account.main_account
[INFO]2021-03-26 13:09:33,049: import agvCtrl.main_agv
[INFO]2021-03-26 13:09:33,397: create lock <lock name:doorMgr.lock,<unlocked _thread.RLock object owner=0 count=0 at 0x00000210DBD31AE0>>
[INFO]2021-03-26 13:09:33,399: create lock <lock name:door.lock,<unlocked _thread.RLock object owner=0 count=0 at 0x00000210DBD41420>>
[INFO]2021-03-26 13:09:33,496: create lock <lock name:timer.lock_2271434218848,<unlocked _thread.RLock object owner=0 count=0 at 0x00000210DC079EA0>>
[ERROR]2021-03-26 13:09:33,513: mqtt is disabled
[INFO]2021-03-26 13:09:33,513: mqtt: subscribe [alarm/raise/+]
[INFO]2021-03-26 13:09:33,513: mqtt: subscribe [alarm/clear/+]
[INFO]2021-03-26 13:09:36,546: Mongodb connect to 127.0.0.1 port 27017
[INFO]2021-03-26 13:09:36,598: create lock <lock name:elevatorApi.g_lock,<unlocked _thread.RLock object owner=0 count=0 at 0x00000210DC2D94E0>>
[INFO]2021-03-26 13:09:36,599: create lock <lock name:elevatorMgr.lock,<unlocked _thread.RLock object owner=0 count=0 at 0x00000210DC2CD8A0>>
[INFO]2021-03-26 13:09:37,009: create lock <lock name:mapMgr.lock,<unlocked _thread.RLock object owner=0 count=0 at 0x00000210DC2E4480>>
[INFO]2021-03-26 13:09:37,294: create lock <lock name:agvList.g_agvLock,<unlocked _thread.RLock object owner=0 count=0 at 0x00000210DC3C24B0>>
[INFO]2021-03-26 13:09:37,297: create lock <lock name:taskList.lock,<unlocked _thread.RLock object owner=0 count=0 at 0x00000210DC4642D0>>
[INFO]2021-03-26 13:09:37,357: charge policy 1 , fix time
[INFO]2021-03-26 13:09:37,389: create lock <lock name:agvApi.g_lock,<unlocked _thread.RLock object owner=0 count=0 at 0x00000210DC464E70>>
[INFO]2021-03-26 13:09:37,580: start load map D:\python_work\AKMfloor\agvCtrl\projects\AKMfloor\AKM2F.smap
[DEBUG]2021-03-26 13:09:37,722: create aliveObj ELEVATOR01 电梯离线异常 timeout 30
[DEBUG]2021-03-26 13:09:37,723: elevator thread start
[INFO]2021-03-26 13:09:37,764: load map D:\python_work\AKMfloor\agvCtrl\projects\AKMfloor\AKM2F.smap ,used 193 ms
[INFO]2021-03-26 13:09:37,790: start load map D:\python_work\AKMfloor\agvCtrl\projects\AKMfloor\AKM4F.smap
[CRITICAL]2021-03-26 13:09:39,734: elevatorApi cause a error: ('http get', 'http://127.0.0.1:5551/api/elevator/status', {'id': 'ELEVATOR01'}, 'error:', '<urlopen error [WinError 10061] 由于目标计算机积极拒绝，无法连接。>')
pid=25624, ppid=20496, tid=8712
Traceback (most recent call last):
  File "C:\Python38\lib\urllib\request.py", line 1317, in do_open
    h.request(req.get_method(), req.selector, req.data, headers,
  File "C:\Python38\lib\http\client.py", line 1230, in request
    self._send_request(method, url, body, headers, encode_chunked)
  File "C:\Python38\lib\http\client.py", line 1276, in _send_request
    self.endheaders(body, encode_chunked=encode_chunked)
  File "C:\Python38\lib\http\client.py", line 1225, in endheaders
    self._send_output(message_body, encode_chunked=encode_chunked)
  File "C:\Python38\lib\http\client.py", line 1004, in _send_output
    self.send(msg)
  File "C:\Python38\lib\http\client.py", line 944, in send
    self.connect()
  File "C:\Python38\lib\http\client.py", line 915, in connect
    self.sock = self._create_connection(
  File "C:\Python38\lib\socket.py", line 807, in create_connection
    raise err
  File "C:\Python38\lib\socket.py", line 796, in create_connection
    sock.connect(sa)
ConnectionRefusedError: [WinError 10061] 由于目标计算机积极拒绝，无法连接。

During handling of the above exception, another exception occurred:

Traceback (most recent call last):
  File "D:\python_work\AKMfloor\common\webutility.py", line 103, in http_get
    f = urllib.request.urlopen(u,timeout=timeout)
  File "C:\Python38\lib\urllib\request.py", line 222, in urlopen
    return opener.open(url, data, timeout)
  File "C:\Python38\lib\urllib\request.py", line 525, in open
    response = self._open(req, data)
  File "C:\Python38\lib\urllib\request.py", line 542, in _open
    result = self._call_chain(self.handle_open, protocol, protocol +
  File "C:\Python38\lib\urllib\request.py", line 502, in _call_chain
    result = func(*args)
  File "C:\Python38\lib\urllib\request.py", line 1346, in http_open
    return self.do_open(http.client.HTTPConnection, req)
  File "C:\Python38\lib\urllib\request.py", line 1320, in do_open
    raise URLError(err)
urllib.error.URLError: <urlopen error [WinError 10061] 由于目标计算机积极拒绝，无法连接。>

During handling of the above exception, another exception occurred:

Traceback (most recent call last):
  File "D:\python_work\AKMfloor\elevator\elevatorApi.py", line 19, in http_get
    r = webutility.http_get(url, param,timeout=10,writelog=writelog)
  File "D:\python_work\AKMfloor\common\webutility.py", line 105, in http_get
    raise Exception("http get",url,params,"error:",str(e))
Exception: ('http get', 'http://127.0.0.1:5551/api/elevator/status', {'id': 'ELEVATOR01'}, 'error:', '<urlopen error [WinError 10061] 由于目标计算机积极拒绝，无法连接。>')

[INFO]2021-03-26 13:09:40,321: load map D:\python_work\AKMfloor\agvCtrl\projects\AKMfloor\AKM4F.smap ,used 2556 ms
[INFO]2021-03-26 13:09:40,324: import agvDevice.main_agvDevice
[INFO]2021-03-26 13:09:40,325: import alarm.main_alarm
[INFO]2021-03-26 13:09:40,325: import auth.main_auth
[INFO]2021-03-26 13:09:40,336: import door.main_door
[INFO]2021-03-26 13:09:40,339: import elevator.main_elevator
[INFO]2021-03-26 13:09:40,339: import feed.main_feed
[INFO]2021-03-26 13:09:40,349: create lock <lock name:feedTask.g_lock,<unlocked _thread.RLock object owner=0 count=0 at 0x00000210DCBE4660>>
[INFO]2021-03-26 13:09:40,352: create lock <lock name:agvApi.g_lock,<unlocked _thread.RLock object owner=0 count=0 at 0x00000210DCBEF240>>
[INFO]2021-03-26 13:09:40,474: import menu.main_menu
[INFO]2021-03-26 13:09:41,029: import pharmapackCtrl.main_scadaCtrl
[INFO]2021-03-26 13:09:41,140: create lock <lock name:runTasks.g_lock,<unlocked _thread.RLock object owner=0 count=0 at 0x00000210DD163720>>
[INFO]2021-03-26 13:09:41,140: create lock <lock name:runTasks.pre_lock,<unlocked _thread.RLock object owner=0 count=0 at 0x00000210DD163D20>>
[INFO]2021-03-26 13:09:41,148: recover can release agv *task[605c3502e4655fbb4cf35342][AGV03] AP13(LM15) -> AP14(LM16) [finish]
[INFO]2021-03-26 13:09:41,149: import webFront.main_web
[INFO]2021-03-26 13:09:41,153: import wmqtt.main_wmqtt
[SUCC]2021-03-26 13:09:41,164: utility start, pid=25624, ppid=20496
[DEBUG]2021-03-26 13:09:41,164: start timer
[INFO]2021-03-26 13:09:41,173: load agv file: D:\python_work\AKMfloor\agvCtrl/projects/AKMfloor/agv.cfg
[INFO]2021-03-26 13:09:41,174: create lock <lock name:agvList.AGV03.lock,<unlocked _thread.RLock object owner=0 count=0 at 0x00000210DD1FB180>>
[DEBUG]2021-03-26 13:09:41,176: create aliveObj AGV03 AGV离线异常 timeout 300
[INFO]2021-03-26 13:09:41,176: AGV03 start agvList run thread
[INFO]2021-03-26 13:09:41,177: AGV03 start agvList run2 thread
[INFO]2021-03-26 13:09:41,177: create lock <lock name:agv.AGV03.lock_status,<unlocked _thread.RLock object owner=0 count=0 at 0x00000210DD1FBF30>>
[DEBUG]2021-03-26 13:09:41,177: try connect AGV03 192.168.20.183:19204
[INFO]2021-03-26 13:09:41,180: add_ignore: taskStatus
[INFO]2021-03-26 13:09:41,180: add_ignore: api/elevator/status
[INFO]2021-03-26 13:09:41,180: add_ignore: scada/getTask
[INFO]2021-03-26 13:09:41,182: AGV03 connected 192.168.20.183 19204
[INFO]2021-03-26 13:09:41,182: create lock <lock name:agv.AGV03.lock_ctrl,<unlocked _thread.RLock object owner=0 count=0 at 0x00000210DD1FBF60>>
[DEBUG]2021-03-26 13:09:41,183: try connect AGV03 192.168.20.183:19205
[INFO]2021-03-26 13:09:41,187: AGV03 connected 192.168.20.183 19205
[INFO]2021-03-26 13:09:41,187: create lock <lock name:agv.AGV03.lock_task,<unlocked _thread.RLock object owner=0 count=0 at 0x00000210DD1FBF90>>
[DEBUG]2021-03-26 13:09:41,187: try connect AGV03 192.168.20.183:19206
[INFO]2021-03-26 13:09:41,195: AGV03 connected 192.168.20.183 19206
[INFO]2021-03-26 13:09:41,196: create lock <lock name:agv.AGV03.lock_conf,<unlocked _thread.RLock object owner=0 count=0 at 0x00000210DD1FBF00>>
[DEBUG]2021-03-26 13:09:41,197: try connect AGV03 192.168.20.183:19207
[INFO]2021-03-26 13:09:41,202: AGV03 connected 192.168.20.183 19207
[INFO]2021-03-26 13:09:41,203: create lock <lock name:agv.AGV03.lock_core,<unlocked _thread.RLock object owner=0 count=0 at 0x00000210DD1FB5D0>>
[DEBUG]2021-03-26 13:09:41,203: try connect AGV03 192.168.20.183:19208
[INFO]2021-03-26 13:09:41,219: AGV03 connected 192.168.20.183 19208
[INFO]2021-03-26 13:09:41,219: create lock <lock name:agv.AGV03.lock_other,<unlocked _thread.RLock object owner=0 count=0 at 0x00000210DD26FF00>>
[DEBUG]2021-03-26 13:09:41,220: try connect AGV03 192.168.20.183:19210
[INFO]2021-03-26 13:09:41,227: AGV03 connected 192.168.20.183 19210
[INFO]2021-03-26 13:09:41,240: AGV03 current map AKM4F
[INFO]2021-03-26 13:09:41,264: AGV03 is online
[CRITICAL]2021-03-26 13:09:42,815: elevatorApi cause a error: ('http get', 'http://127.0.0.1:5551/api/elevator/status', {'id': 'ELEVATOR01'}, 'error:', '<urlopen error [WinError 10061] 由于目标计算机积极拒绝，无法连接。>')
pid=25624, ppid=20496, tid=8712
Traceback (most recent call last):
  File "C:\Python38\lib\urllib\request.py", line 1317, in do_open
    h.request(req.get_method(), req.selector, req.data, headers,
  File "C:\Python38\lib\http\client.py", line 1230, in request
    self._send_request(method, url, body, headers, encode_chunked)
  File "C:\Python38\lib\http\client.py", line 1276, in _send_request
    self.endheaders(body, encode_chunked=encode_chunked)
  File "C:\Python38\lib\http\client.py", line 1225, in endheaders
    self._send_output(message_body, encode_chunked=encode_chunked)
  File "C:\Python38\lib\http\client.py", line 1004, in _send_output
    self.send(msg)
  File "C:\Python38\lib\http\client.py", line 944, in send
    self.connect()
  File "C:\Python38\lib\http\client.py", line 915, in connect
    self.sock = self._create_connection(
  File "C:\Python38\lib\socket.py", line 807, in create_connection
    raise err
  File "C:\Python38\lib\socket.py", line 796, in create_connection
    sock.connect(sa)
ConnectionRefusedError: [WinError 10061] 由于目标计算机积极拒绝，无法连接。

During handling of the above exception, another exception occurred:

Traceback (most recent call last):
  File "D:\python_work\AKMfloor\common\webutility.py", line 103, in http_get
    f = urllib.request.urlopen(u,timeout=timeout)
  File "C:\Python38\lib\urllib\request.py", line 222, in urlopen
    return opener.open(url, data, timeout)
  File "C:\Python38\lib\urllib\request.py", line 525, in open
    response = self._open(req, data)
  File "C:\Python38\lib\urllib\request.py", line 542, in _open
    result = self._call_chain(self.handle_open, protocol, protocol +
  File "C:\Python38\lib\urllib\request.py", line 502, in _call_chain
    result = func(*args)
  File "C:\Python38\lib\urllib\request.py", line 1346, in http_open
    return self.do_open(http.client.HTTPConnection, req)
  File "C:\Python38\lib\urllib\request.py", line 1320, in do_open
    raise URLError(err)
urllib.error.URLError: <urlopen error [WinError 10061] 由于目标计算机积极拒绝，无法连接。>

During handling of the above exception, another exception occurred:

Traceback (most recent call last):
  File "D:\python_work\AKMfloor\elevator\elevatorApi.py", line 19, in http_get
    r = webutility.http_get(url, param,timeout=10,writelog=writelog)
  File "D:\python_work\AKMfloor\common\webutility.py", line 105, in http_get
    raise Exception("http get",url,params,"error:",str(e))
Exception: ('http get', 'http://127.0.0.1:5551/api/elevator/status', {'id': 'ELEVATOR01'}, 'error:', '<urlopen error [WinError 10061] 由于目标计算机积极拒绝，无法连接。>')

[CRITICAL]2021-03-26 13:09:45,212: agvApi.init cause a error: ('http get', 'http://127.0.0.1:5551/api/agv/init', {'appName': 'scadaTask'}, 'error:', '<urlopen error [WinError 10061] 由于目标计算机积极拒绝，无法连接。>')
pid=25624, ppid=20496, tid=20988
Traceback (most recent call last):
  File "C:\Python38\lib\urllib\request.py", line 1317, in do_open
    h.request(req.get_method(), req.selector, req.data, headers,
  File "C:\Python38\lib\http\client.py", line 1230, in request
    self._send_request(method, url, body, headers, encode_chunked)
  File "C:\Python38\lib\http\client.py", line 1276, in _send_request
    self.endheaders(body, encode_chunked=encode_chunked)
  File "C:\Python38\lib\http\client.py", line 1225, in endheaders
    self._send_output(message_body, encode_chunked=encode_chunked)
  File "C:\Python38\lib\http\client.py", line 1004, in _send_output
    self.send(msg)
  File "C:\Python38\lib\http\client.py", line 944, in send
    self.connect()
  File "C:\Python38\lib\http\client.py", line 915, in connect
    self.sock = self._create_connection(
  File "C:\Python38\lib\socket.py", line 807, in create_connection
    raise err
  File "C:\Python38\lib\socket.py", line 796, in create_connection
    sock.connect(sa)
ConnectionRefusedError: [WinError 10061] 由于目标计算机积极拒绝，无法连接。

During handling of the above exception, another exception occurred:

Traceback (most recent call last):
  File "D:\python_work\AKMfloor\common\webutility.py", line 103, in http_get
    f = urllib.request.urlopen(u,timeout=timeout)
  File "C:\Python38\lib\urllib\request.py", line 222, in urlopen
    return opener.open(url, data, timeout)
  File "C:\Python38\lib\urllib\request.py", line 525, in open
    response = self._open(req, data)
  File "C:\Python38\lib\urllib\request.py", line 542, in _open
    result = self._call_chain(self.handle_open, protocol, protocol +
  File "C:\Python38\lib\urllib\request.py", line 502, in _call_chain
    result = func(*args)
  File "C:\Python38\lib\urllib\request.py", line 1346, in http_open
    return self.do_open(http.client.HTTPConnection, req)
  File "C:\Python38\lib\urllib\request.py", line 1320, in do_open
    raise URLError(err)
urllib.error.URLError: <urlopen error [WinError 10061] 由于目标计算机积极拒绝，无法连接。>

During handling of the above exception, another exception occurred:

Traceback (most recent call last):
  File "D:\python_work\AKMfloor\agvCtrl\agvApi.py", line 40, in init
    _http_get(url + '/api/agv/init', param)
  File "D:\python_work\AKMfloor\agvCtrl\agvApi.py", line 61, in _http_get
    r = webutility.http_get(url, param, timeout=45,writelog=False)
  File "D:\python_work\AKMfloor\common\webutility.py", line 105, in http_get
    raise Exception("http get",url,params,"error:",str(e))
Exception: ('http get', 'http://127.0.0.1:5551/api/agv/init', {'appName': 'scadaTask'}, 'error:', '<urlopen error [WinError 10061] 由于目标计算机积极拒绝，无法连接。>')

[CRITICAL]2021-03-26 13:09:45,863: elevatorApi cause a error: ('http get', 'http://127.0.0.1:5551/api/elevator/status', {'id': 'ELEVATOR01'}, 'error:', '<urlopen error [WinError 10061] 由于目标计算机积极拒绝，无法连接。>')
pid=25624, ppid=20496, tid=8712
Traceback (most recent call last):
  File "C:\Python38\lib\urllib\request.py", line 1317, in do_open
    h.request(req.get_method(), req.selector, req.data, headers,
  File "C:\Python38\lib\http\client.py", line 1230, in request
    self._send_request(method, url, body, headers, encode_chunked)
  File "C:\Python38\lib\http\client.py", line 1276, in _send_request
    self.endheaders(body, encode_chunked=encode_chunked)
  File "C:\Python38\lib\http\client.py", line 1225, in endheaders
    self._send_output(message_body, encode_chunked=encode_chunked)
  File "C:\Python38\lib\http\client.py", line 1004, in _send_output
    self.send(msg)
  File "C:\Python38\lib\http\client.py", line 944, in send
    self.connect()
  File "C:\Python38\lib\http\client.py", line 915, in connect
    self.sock = self._create_connection(
  File "C:\Python38\lib\socket.py", line 807, in create_connection
    raise err
  File "C:\Python38\lib\socket.py", line 796, in create_connection
    sock.connect(sa)
ConnectionRefusedError: [WinError 10061] 由于目标计算机积极拒绝，无法连接。

During handling of the above exception, another exception occurred:

Traceback (most recent call last):
  File "D:\python_work\AKMfloor\common\webutility.py", line 103, in http_get
    f = urllib.request.urlopen(u,timeout=timeout)
  File "C:\Python38\lib\urllib\request.py", line 222, in urlopen
    return opener.open(url, data, timeout)
  File "C:\Python38\lib\urllib\request.py", line 525, in open
    response = self._open(req, data)
  File "C:\Python38\lib\urllib\request.py", line 542, in _open
    result = self._call_chain(self.handle_open, protocol, protocol +
  File "C:\Python38\lib\urllib\request.py", line 502, in _call_chain
    result = func(*args)
  File "C:\Python38\lib\urllib\request.py", line 1346, in http_open
    return self.do_open(http.client.HTTPConnection, req)
  File "C:\Python38\lib\urllib\request.py", line 1320, in do_open
    raise URLError(err)
urllib.error.URLError: <urlopen error [WinError 10061] 由于目标计算机积极拒绝，无法连接。>

During handling of the above exception, another exception occurred:

Traceback (most recent call last):
  File "D:\python_work\AKMfloor\elevator\elevatorApi.py", line 19, in http_get
    r = webutility.http_get(url, param,timeout=10,writelog=writelog)
  File "D:\python_work\AKMfloor\common\webutility.py", line 105, in http_get
    raise Exception("http get",url,params,"error:",str(e))
Exception: ('http get', 'http://127.0.0.1:5551/api/elevator/status', {'id': 'ELEVATOR01'}, 'error:', '<urlopen error [WinError 10061] 由于目标计算机积极拒绝，无法连接。>')

[CRITICAL]2021-03-26 13:09:48,257: agvApi.init cause a error: ('http get', 'http://127.0.0.1:5551/api/agv/init', {'appName': 'scadaTask'}, 'error:', '<urlopen error [WinError 10061] 由于目标计算机积极拒绝，无法连接。>')
pid=25624, ppid=20496, tid=20988
Traceback (most recent call last):
  File "C:\Python38\lib\urllib\request.py", line 1317, in do_open
    h.request(req.get_method(), req.selector, req.data, headers,
  File "C:\Python38\lib\http\client.py", line 1230, in request
    self._send_request(method, url, body, headers, encode_chunked)
  File "C:\Python38\lib\http\client.py", line 1276, in _send_request
    self.endheaders(body, encode_chunked=encode_chunked)
  File "C:\Python38\lib\http\client.py", line 1225, in endheaders
    self._send_output(message_body, encode_chunked=encode_chunked)
  File "C:\Python38\lib\http\client.py", line 1004, in _send_output
    self.send(msg)
  File "C:\Python38\lib\http\client.py", line 944, in send
    self.connect()
  File "C:\Python38\lib\http\client.py", line 915, in connect
    self.sock = self._create_connection(
  File "C:\Python38\lib\socket.py", line 807, in create_connection
    raise err
  File "C:\Python38\lib\socket.py", line 796, in create_connection
    sock.connect(sa)
ConnectionRefusedError: [WinError 10061] 由于目标计算机积极拒绝，无法连接。

During handling of the above exception, another exception occurred:

Traceback (most recent call last):
  File "D:\python_work\AKMfloor\common\webutility.py", line 103, in http_get
    f = urllib.request.urlopen(u,timeout=timeout)
  File "C:\Python38\lib\urllib\request.py", line 222, in urlopen
    return opener.open(url, data, timeout)
  File "C:\Python38\lib\urllib\request.py", line 525, in open
    response = self._open(req, data)
  File "C:\Python38\lib\urllib\request.py", line 542, in _open
    result = self._call_chain(self.handle_open, protocol, protocol +
  File "C:\Python38\lib\urllib\request.py", line 502, in _call_chain
    result = func(*args)
  File "C:\Python38\lib\urllib\request.py", line 1346, in http_open
    return self.do_open(http.client.HTTPConnection, req)
  File "C:\Python38\lib\urllib\request.py", line 1320, in do_open
    raise URLError(err)
urllib.error.URLError: <urlopen error [WinError 10061] 由于目标计算机积极拒绝，无法连接。>

During handling of the above exception, another exception occurred:

Traceback (most recent call last):
  File "D:\python_work\AKMfloor\agvCtrl\agvApi.py", line 40, in init
    _http_get(url + '/api/agv/init', param)
  File "D:\python_work\AKMfloor\agvCtrl\agvApi.py", line 61, in _http_get
    r = webutility.http_get(url, param, timeout=45,writelog=False)
  File "D:\python_work\AKMfloor\common\webutility.py", line 105, in http_get
    raise Exception("http get",url,params,"error:",str(e))
Exception: ('http get', 'http://127.0.0.1:5551/api/agv/init', {'appName': 'scadaTask'}, 'error:', '<urlopen error [WinError 10061] 由于目标计算机积极拒绝，无法连接。>')

[CRITICAL]2021-03-26 13:09:48,895: elevatorApi cause a error: ('http get', 'http://127.0.0.1:5551/api/elevator/status', {'id': 'ELEVATOR01'}, 'error:', '<urlopen error [WinError 10061] 由于目标计算机积极拒绝，无法连接。>')
pid=25624, ppid=20496, tid=8712
Traceback (most recent call last):
  File "C:\Python38\lib\urllib\request.py", line 1317, in do_open
    h.request(req.get_method(), req.selector, req.data, headers,
  File "C:\Python38\lib\http\client.py", line 1230, in request
    self._send_request(method, url, body, headers, encode_chunked)
  File "C:\Python38\lib\http\client.py", line 1276, in _send_request
    self.endheaders(body, encode_chunked=encode_chunked)
  File "C:\Python38\lib\http\client.py", line 1225, in endheaders
    self._send_output(message_body, encode_chunked=encode_chunked)
  File "C:\Python38\lib\http\client.py", line 1004, in _send_output
    self.send(msg)
  File "C:\Python38\lib\http\client.py", line 944, in send
    self.connect()
  File "C:\Python38\lib\http\client.py", line 915, in connect
    self.sock = self._create_connection(
  File "C:\Python38\lib\socket.py", line 807, in create_connection
    raise err
  File "C:\Python38\lib\socket.py", line 796, in create_connection
    sock.connect(sa)
ConnectionRefusedError: [WinError 10061] 由于目标计算机积极拒绝，无法连接。

During handling of the above exception, another exception occurred:

Traceback (most recent call last):
  File "D:\python_work\AKMfloor\common\webutility.py", line 103, in http_get
    f = urllib.request.urlopen(u,timeout=timeout)
  File "C:\Python38\lib\urllib\request.py", line 222, in urlopen
    return opener.open(url, data, timeout)
  File "C:\Python38\lib\urllib\request.py", line 525, in open
    response = self._open(req, data)
  File "C:\Python38\lib\urllib\request.py", line 542, in _open
    result = self._call_chain(self.handle_open, protocol, protocol +
  File "C:\Python38\lib\urllib\request.py", line 502, in _call_chain
    result = func(*args)
  File "C:\Python38\lib\urllib\request.py", line 1346, in http_open
    return self.do_open(http.client.HTTPConnection, req)
  File "C:\Python38\lib\urllib\request.py", line 1320, in do_open
    raise URLError(err)
urllib.error.URLError: <urlopen error [WinError 10061] 由于目标计算机积极拒绝，无法连接。>

During handling of the above exception, another exception occurred:

Traceback (most recent call last):
  File "D:\python_work\AKMfloor\elevator\elevatorApi.py", line 19, in http_get
    r = webutility.http_get(url, param,timeout=10,writelog=writelog)
  File "D:\python_work\AKMfloor\common\webutility.py", line 105, in http_get
    raise Exception("http get",url,params,"error:",str(e))
Exception: ('http get', 'http://127.0.0.1:5551/api/elevator/status', {'id': 'ELEVATOR01'}, 'error:', '<urlopen error [WinError 10061] 由于目标计算机积极拒绝，无法连接。>')

[CRITICAL]2021-03-26 13:09:51,304: agvApi.init cause a error: ('http get', 'http://127.0.0.1:5551/api/agv/init', {'appName': 'scadaTask'}, 'error:', '<urlopen error [WinError 10061] 由于目标计算机积极拒绝，无法连接。>')
pid=25624, ppid=20496, tid=20988
Traceback (most recent call last):
  File "C:\Python38\lib\urllib\request.py", line 1317, in do_open
    h.request(req.get_method(), req.selector, req.data, headers,
  File "C:\Python38\lib\http\client.py", line 1230, in request
    self._send_request(method, url, body, headers, encode_chunked)
  File "C:\Python38\lib\http\client.py", line 1276, in _send_request
    self.endheaders(body, encode_chunked=encode_chunked)
  File "C:\Python38\lib\http\client.py", line 1225, in endheaders
    self._send_output(message_body, encode_chunked=encode_chunked)
  File "C:\Python38\lib\http\client.py", line 1004, in _send_output
    self.send(msg)
  File "C:\Python38\lib\http\client.py", line 944, in send
    self.connect()
  File "C:\Python38\lib\http\client.py", line 915, in connect
    self.sock = self._create_connection(
  File "C:\Python38\lib\socket.py", line 807, in create_connection
    raise err
  File "C:\Python38\lib\socket.py", line 796, in create_connection
    sock.connect(sa)
ConnectionRefusedError: [WinError 10061] 由于目标计算机积极拒绝，无法连接。

During handling of the above exception, another exception occurred:

Traceback (most recent call last):
  File "D:\python_work\AKMfloor\common\webutility.py", line 103, in http_get
    f = urllib.request.urlopen(u,timeout=timeout)
  File "C:\Python38\lib\urllib\request.py", line 222, in urlopen
    return opener.open(url, data, timeout)
  File "C:\Python38\lib\urllib\request.py", line 525, in open
    response = self._open(req, data)
  File "C:\Python38\lib\urllib\request.py", line 542, in _open
    result = self._call_chain(self.handle_open, protocol, protocol +
  File "C:\Python38\lib\urllib\request.py", line 502, in _call_chain
    result = func(*args)
  File "C:\Python38\lib\urllib\request.py", line 1346, in http_open
    return self.do_open(http.client.HTTPConnection, req)
  File "C:\Python38\lib\urllib\request.py", line 1320, in do_open
    raise URLError(err)
urllib.error.URLError: <urlopen error [WinError 10061] 由于目标计算机积极拒绝，无法连接。>

During handling of the above exception, another exception occurred:

Traceback (most recent call last):
  File "D:\python_work\AKMfloor\agvCtrl\agvApi.py", line 40, in init
    _http_get(url + '/api/agv/init', param)
  File "D:\python_work\AKMfloor\agvCtrl\agvApi.py", line 61, in _http_get
    r = webutility.http_get(url, param, timeout=45,writelog=False)
  File "D:\python_work\AKMfloor\common\webutility.py", line 105, in http_get
    raise Exception("http get",url,params,"error:",str(e))
Exception: ('http get', 'http://127.0.0.1:5551/api/agv/init', {'appName': 'scadaTask'}, 'error:', '<urlopen error [WinError 10061] 由于目标计算机积极拒绝，无法连接。>')

[CRITICAL]2021-03-26 13:09:51,925: elevatorApi cause a error: ('http get', 'http://127.0.0.1:5551/api/elevator/status', {'id': 'ELEVATOR01'}, 'error:', '<urlopen error [WinError 10061] 由于目标计算机积极拒绝，无法连接。>')
pid=25624, ppid=20496, tid=8712
Traceback (most recent call last):
  File "C:\Python38\lib\urllib\request.py", line 1317, in do_open
    h.request(req.get_method(), req.selector, req.data, headers,
  File "C:\Python38\lib\http\client.py", line 1230, in request
    self._send_request(method, url, body, headers, encode_chunked)
  File "C:\Python38\lib\http\client.py", line 1276, in _send_request
    self.endheaders(body, encode_chunked=encode_chunked)
  File "C:\Python38\lib\http\client.py", line 1225, in endheaders
    self._send_output(message_body, encode_chunked=encode_chunked)
  File "C:\Python38\lib\http\client.py", line 1004, in _send_output
    self.send(msg)
  File "C:\Python38\lib\http\client.py", line 944, in send
    self.connect()
  File "C:\Python38\lib\http\client.py", line 915, in connect
    self.sock = self._create_connection(
  File "C:\Python38\lib\socket.py", line 807, in create_connection
    raise err
  File "C:\Python38\lib\socket.py", line 796, in create_connection
    sock.connect(sa)
ConnectionRefusedError: [WinError 10061] 由于目标计算机积极拒绝，无法连接。

During handling of the above exception, another exception occurred:

Traceback (most recent call last):
  File "D:\python_work\AKMfloor\common\webutility.py", line 103, in http_get
    f = urllib.request.urlopen(u,timeout=timeout)
  File "C:\Python38\lib\urllib\request.py", line 222, in urlopen
    return opener.open(url, data, timeout)
  File "C:\Python38\lib\urllib\request.py", line 525, in open
    response = self._open(req, data)
  File "C:\Python38\lib\urllib\request.py", line 542, in _open
    result = self._call_chain(self.handle_open, protocol, protocol +
  File "C:\Python38\lib\urllib\request.py", line 502, in _call_chain
    result = func(*args)
  File "C:\Python38\lib\urllib\request.py", line 1346, in http_open
    return self.do_open(http.client.HTTPConnection, req)
  File "C:\Python38\lib\urllib\request.py", line 1320, in do_open
    raise URLError(err)
urllib.error.URLError: <urlopen error [WinError 10061] 由于目标计算机积极拒绝，无法连接。>

During handling of the above exception, another exception occurred:

Traceback (most recent call last):
  File "D:\python_work\AKMfloor\elevator\elevatorApi.py", line 19, in http_get
    r = webutility.http_get(url, param,timeout=10,writelog=writelog)
  File "D:\python_work\AKMfloor\common\webutility.py", line 105, in http_get
    raise Exception("http get",url,params,"error:",str(e))
Exception: ('http get', 'http://127.0.0.1:5551/api/elevator/status', {'id': 'ELEVATOR01'}, 'error:', '<urlopen error [WinError 10061] 由于目标计算机积极拒绝，无法连接。>')

[CRITICAL]2021-03-26 13:09:54,346: agvApi.init cause a error: ('http get', 'http://127.0.0.1:5551/api/agv/init', {'appName': 'scadaTask'}, 'error:', '<urlopen error [WinError 10061] 由于目标计算机积极拒绝，无法连接。>')
pid=25624, ppid=20496, tid=20988
Traceback (most recent call last):
  File "C:\Python38\lib\urllib\request.py", line 1317, in do_open
    h.request(req.get_method(), req.selector, req.data, headers,
  File "C:\Python38\lib\http\client.py", line 1230, in request
    self._send_request(method, url, body, headers, encode_chunked)
  File "C:\Python38\lib\http\client.py", line 1276, in _send_request
    self.endheaders(body, encode_chunked=encode_chunked)
  File "C:\Python38\lib\http\client.py", line 1225, in endheaders
    self._send_output(message_body, encode_chunked=encode_chunked)
  File "C:\Python38\lib\http\client.py", line 1004, in _send_output
    self.send(msg)
  File "C:\Python38\lib\http\client.py", line 944, in send
    self.connect()
  File "C:\Python38\lib\http\client.py", line 915, in connect
    self.sock = self._create_connection(
  File "C:\Python38\lib\socket.py", line 807, in create_connection
    raise err
  File "C:\Python38\lib\socket.py", line 796, in create_connection
    sock.connect(sa)
ConnectionRefusedError: [WinError 10061] 由于目标计算机积极拒绝，无法连接。

During handling of the above exception, another exception occurred:

Traceback (most recent call last):
  File "D:\python_work\AKMfloor\common\webutility.py", line 103, in http_get
    f = urllib.request.urlopen(u,timeout=timeout)
  File "C:\Python38\lib\urllib\request.py", line 222, in urlopen
    return opener.open(url, data, timeout)
  File "C:\Python38\lib\urllib\request.py", line 525, in open
    response = self._open(req, data)
  File "C:\Python38\lib\urllib\request.py", line 542, in _open
    result = self._call_chain(self.handle_open, protocol, protocol +
  File "C:\Python38\lib\urllib\request.py", line 502, in _call_chain
    result = func(*args)
  File "C:\Python38\lib\urllib\request.py", line 1346, in http_open
    return self.do_open(http.client.HTTPConnection, req)
  File "C:\Python38\lib\urllib\request.py", line 1320, in do_open
    raise URLError(err)
urllib.error.URLError: <urlopen error [WinError 10061] 由于目标计算机积极拒绝，无法连接。>

During handling of the above exception, another exception occurred:

Traceback (most recent call last):
  File "D:\python_work\AKMfloor\agvCtrl\agvApi.py", line 40, in init
    _http_get(url + '/api/agv/init', param)
  File "D:\python_work\AKMfloor\agvCtrl\agvApi.py", line 61, in _http_get
    r = webutility.http_get(url, param, timeout=45,writelog=False)
  File "D:\python_work\AKMfloor\common\webutility.py", line 105, in http_get
    raise Exception("http get",url,params,"error:",str(e))
Exception: ('http get', 'http://127.0.0.1:5551/api/agv/init', {'appName': 'scadaTask'}, 'error:', '<urlopen error [WinError 10061] 由于目标计算机积极拒绝，无法连接。>')

[CRITICAL]2021-03-26 13:09:54,950: elevatorApi cause a error: ('http get', 'http://127.0.0.1:5551/api/elevator/status', {'id': 'ELEVATOR01'}, 'error:', '<urlopen error [WinError 10061] 由于目标计算机积极拒绝，无法连接。>')
pid=25624, ppid=20496, tid=8712
Traceback (most recent call last):
  File "C:\Python38\lib\urllib\request.py", line 1317, in do_open
    h.request(req.get_method(), req.selector, req.data, headers,
  File "C:\Python38\lib\http\client.py", line 1230, in request
    self._send_request(method, url, body, headers, encode_chunked)
  File "C:\Python38\lib\http\client.py", line 1276, in _send_request
    self.endheaders(body, encode_chunked=encode_chunked)
  File "C:\Python38\lib\http\client.py", line 1225, in endheaders
    self._send_output(message_body, encode_chunked=encode_chunked)
  File "C:\Python38\lib\http\client.py", line 1004, in _send_output
    self.send(msg)
  File "C:\Python38\lib\http\client.py", line 944, in send
    self.connect()
  File "C:\Python38\lib\http\client.py", line 915, in connect
    self.sock = self._create_connection(
  File "C:\Python38\lib\socket.py", line 807, in create_connection
    raise err
  File "C:\Python38\lib\socket.py", line 796, in create_connection
    sock.connect(sa)
ConnectionRefusedError: [WinError 10061] 由于目标计算机积极拒绝，无法连接。

During handling of the above exception, another exception occurred:

Traceback (most recent call last):
  File "D:\python_work\AKMfloor\common\webutility.py", line 103, in http_get
    f = urllib.request.urlopen(u,timeout=timeout)
  File "C:\Python38\lib\urllib\request.py", line 222, in urlopen
    return opener.open(url, data, timeout)
  File "C:\Python38\lib\urllib\request.py", line 525, in open
    response = self._open(req, data)
  File "C:\Python38\lib\urllib\request.py", line 542, in _open
    result = self._call_chain(self.handle_open, protocol, protocol +
  File "C:\Python38\lib\urllib\request.py", line 502, in _call_chain
    result = func(*args)
  File "C:\Python38\lib\urllib\request.py", line 1346, in http_open
    return self.do_open(http.client.HTTPConnection, req)
  File "C:\Python38\lib\urllib\request.py", line 1320, in do_open
    raise URLError(err)
urllib.error.URLError: <urlopen error [WinError 10061] 由于目标计算机积极拒绝，无法连接。>

During handling of the above exception, another exception occurred:

Traceback (most recent call last):
  File "D:\python_work\AKMfloor\elevator\elevatorApi.py", line 19, in http_get
    r = webutility.http_get(url, param,timeout=10,writelog=writelog)
  File "D:\python_work\AKMfloor\common\webutility.py", line 105, in http_get
    raise Exception("http get",url,params,"error:",str(e))
Exception: ('http get', 'http://127.0.0.1:5551/api/elevator/status', {'id': 'ELEVATOR01'}, 'error:', '<urlopen error [WinError 10061] 由于目标计算机积极拒绝，无法连接。>')

[DEBUG]2021-03-26 13:09:55,855: GET: http://127.0.0.1:5551/api/agv/init?appName=scadaTask addr: 127.0.0.1
[INFO]2021-03-26 13:09:55,856: scadaTask init client agvApi
[DEBUG]2021-03-26 13:09:55,859: used 4ms 200 OK application/json;charset=utf-8, GET: http://127.0.0.1:5551/api/agv/init?appName=scadaTask
[INFO]2021-03-26 13:09:56,075: lift status: {'isMaintain': 'normal', 'isOpening': 0, 'isClosing': 0, 'isFinishOpen': '0', 'inFloor': 6, 'isRunning': 0, 'reachFloorStatus': '1', 'openDoorStatus': None, 'cancelStatus': None, 'reachTargetFloor': None, 'downStatus': '0', 'upStatus': '0'}
[INFO]2021-03-26 13:09:57,246: lift status: {'isMaintain': 'normal', 'isOpening': 0, 'isClosing': 0, 'isFinishOpen': '0', 'inFloor': 6, 'isRunning': 0, 'reachFloorStatus': '1', 'openDoorStatus': None, 'cancelStatus': None, 'reachTargetFloor': None, 'downStatus': '0', 'upStatus': '0'}
[INFO]2021-03-26 13:09:58,462: lift status: {'isMaintain': 'normal', 'isOpening': 0, 'isClosing': 0, 'isFinishOpen': '0', 'inFloor': 6, 'isRunning': 0, 'reachFloorStatus': '1', 'openDoorStatus': None, 'cancelStatus': None, 'reachTargetFloor': None, 'downStatus': '0', 'upStatus': '0'}
[DEBUG]2021-03-26 13:09:58,916: GET: http://127.0.0.1:5551/api/agv/startCharge?appName=scadaTask addr: 127.0.0.1
[DEBUG]2021-03-26 13:09:58,946: used 30ms 200 OK application/json;charset=utf-8, GET: http://127.0.0.1:5551/api/agv/startCharge?appName=scadaTask
[WARNING]2021-03-26 13:09:58,983: timer_thread[tid:20988] <lock name:runTasks.g_lock,<locked _thread.RLock object owner=20988 count=1 at 0x00000210DD163720>> ,hold 15815 ms
[INFO]2021-03-26 13:09:59,040: name=timer_thread, pid=25624, tid=20988
[01] File "C:/Python38/lib/threading.py", line 870, in run() 
[02] File "D:/python_work/AKMfloor/common/mytimer.py", line 113, in _loop() 
[03] File "D:/python_work/AKMfloor/common/lock.py", line 122, in _call() 
[04] File "D:/python_work/AKMfloor/common/lock.py", line 100, in release() 
[05] File "D:/python_work/AKMfloor/common/enhance.py", line 258, in getTrace() 
[06] File "D:/python_work/AKMfloor/common/enhance.py", line 240, in getThreadStack()
[INFO]2021-03-26 13:09:59,647: lift status: {'isMaintain': 'normal', 'isOpening': 0, 'isClosing': 0, 'isFinishOpen': '0', 'inFloor': 6, 'isRunning': 0, 'reachFloorStatus': '1', 'openDoorStatus': None, 'cancelStatus': None, 'reachTargetFloor': None, 'downStatus': '0', 'upStatus': '0'}
[WARNING]2021-03-26 13:10:00,088: AGV03 low battery charge,batteryLevel= 0.472 start charge level= 0.500
[INFO]2021-03-26 13:10:00,089: AGV03 battery 0.472 check success
[WARNING]2021-03-26 13:10:00,102: AGV03 Can't find charge point at AKM4F battery: 0.472
[INFO]2021-03-26 13:10:00,802: lift status: {'isMaintain': 'normal', 'isOpening': 0, 'isClosing': 0, 'isFinishOpen': '0', 'inFloor': 6, 'isRunning': 0, 'reachFloorStatus': '1', 'openDoorStatus': None, 'cancelStatus': None, 'reachTargetFloor': None, 'downStatus': '0', 'upStatus': '0'}
[INFO]2021-03-26 13:10:01,995: lift status: {'isMaintain': 'normal', 'isOpening': 0, 'isClosing': 0, 'isFinishOpen': '0', 'inFloor': 6, 'isRunning': 0, 'reachFloorStatus': '1', 'openDoorStatus': None, 'cancelStatus': None, 'reachTargetFloor': None, 'downStatus': '0', 'upStatus': '0'}
[INFO]2021-03-26 13:10:03,178: lift status: {'isMaintain': 'normal', 'isOpening': 0, 'isClosing': 0, 'isFinishOpen': '0', 'inFloor': 6, 'isRunning': 0, 'reachFloorStatus': '1', 'openDoorStatus': None, 'cancelStatus': None, 'reachTargetFloor': None, 'downStatus': '0', 'upStatus': '0'}
[INFO]2021-03-26 13:10:04,412: lift status: {'isMaintain': 'normal', 'isOpening': 0, 'isClosing': 0, 'isFinishOpen': '0', 'inFloor': 6, 'isRunning': 0, 'reachFloorStatus': '1', 'openDoorStatus': None, 'cancelStatus': None, 'reachTargetFloor': None, 'downStatus': '0', 'upStatus': '0'}
[INFO]2021-03-26 13:10:05,663: lift status: {'isMaintain': 'normal', 'isOpening': 0, 'isClosing': 0, 'isFinishOpen': '0', 'inFloor': 6, 'isRunning': 0, 'reachFloorStatus': '1', 'openDoorStatus': None, 'cancelStatus': None, 'reachTargetFloor': None, 'downStatus': '0', 'upStatus': '0'}
[INFO]2021-03-26 13:10:06,809: lift status: {'isMaintain': 'normal', 'isOpening': 0, 'isClosing': 0, 'isFinishOpen': '0', 'inFloor': 6, 'isRunning': 0, 'reachFloorStatus': '1', 'openDoorStatus': None, 'cancelStatus': None, 'reachTargetFloor': None, 'downStatus': '0', 'upStatus': '0'}
[INFO]2021-03-26 13:10:07,969: lift status: {'isMaintain': 'normal', 'isOpening': 0, 'isClosing': 0, 'isFinishOpen': '0', 'inFloor': 6, 'isRunning': 0, 'reachFloorStatus': '1', 'openDoorStatus': None, 'cancelStatus': None, 'reachTargetFloor': None, 'downStatus': '0', 'upStatus': '0'}
