[CRITICAL]2021-03-26 13:06:11,154: elevatorApi cause a error: ('http get', 'http://127.0.0.1:5551/api/elevator/status', {'id': 'ELEVATOR01'}, 'error:', '<urlopen error [WinError 10061] 由于目标计算机积极拒绝，无法连接。>')
pid=25356, ppid=20496, tid=23380
Traceback (most recent call last):
  File "C:\Python38\lib\urllib\request.py", line 1317, in do_open
    h.request(req.get_method(), req.selector, req.data, headers,
  File "C:\Python38\lib\http\client.py", line 1230, in request
    self._send_request(method, url, body, headers, encode_chunked)
  File "C:\Python38\lib\http\client.py", line 1276, in _send_request
    self.endheaders(body, encode_chunked=encode_chunked)
  File "C:\Python38\lib\http\client.py", line 1225, in endheaders
    self._send_output(message_body, encode_chunked=encode_chunked)
  File "C:\Python38\lib\http\client.py", line 1004, in _send_output
    self.send(msg)
  File "C:\Python38\lib\http\client.py", line 944, in send
    self.connect()
  File "C:\Python38\lib\http\client.py", line 915, in connect
    self.sock = self._create_connection(
  File "C:\Python38\lib\socket.py", line 807, in create_connection
    raise err
  File "C:\Python38\lib\socket.py", line 796, in create_connection
    sock.connect(sa)
ConnectionRefusedError: [WinError 10061] 由于目标计算机积极拒绝，无法连接。

During handling of the above exception, another exception occurred:

Traceback (most recent call last):
  File "D:\python_work\AKMfloor\common\webutility.py", line 103, in http_get
    f = urllib.request.urlopen(u,timeout=timeout)
  File "C:\Python38\lib\urllib\request.py", line 222, in urlopen
    return opener.open(url, data, timeout)
  File "C:\Python38\lib\urllib\request.py", line 525, in open
    response = self._open(req, data)
  File "C:\Python38\lib\urllib\request.py", line 542, in _open
    result = self._call_chain(self.handle_open, protocol, protocol +
  File "C:\Python38\lib\urllib\request.py", line 502, in _call_chain
    result = func(*args)
  File "C:\Python38\lib\urllib\request.py", line 1346, in http_open
    return self.do_open(http.client.HTTPConnection, req)
  File "C:\Python38\lib\urllib\request.py", line 1320, in do_open
    raise URLError(err)
urllib.error.URLError: <urlopen error [WinError 10061] 由于目标计算机积极拒绝，无法连接。>

During handling of the above exception, another exception occurred:

Traceback (most recent call last):
  File "D:\python_work\AKMfloor\elevator\elevatorApi.py", line 19, in http_get
    r = webutility.http_get(url, param,timeout=10,writelog=writelog)
  File "D:\python_work\AKMfloor\common\webutility.py", line 105, in http_get
    raise Exception("http get",url,params,"error:",str(e))
Exception: ('http get', 'http://127.0.0.1:5551/api/elevator/status', {'id': 'ELEVATOR01'}, 'error:', '<urlopen error [WinError 10061] 由于目标计算机积极拒绝，无法连接。>')

[CRITICAL]2021-03-26 13:06:13,942: agvApi.init cause a error: ('http get', 'http://127.0.0.1:5551/api/agv/init', {'appName': 'scadaTask'}, 'error:', '<urlopen error [WinError 10061] 由于目标计算机积极拒绝，无法连接。>')
pid=25356, ppid=20496, tid=24300
Traceback (most recent call last):
  File "C:\Python38\lib\urllib\request.py", line 1317, in do_open
    h.request(req.get_method(), req.selector, req.data, headers,
  File "C:\Python38\lib\http\client.py", line 1230, in request
    self._send_request(method, url, body, headers, encode_chunked)
  File "C:\Python38\lib\http\client.py", line 1276, in _send_request
    self.endheaders(body, encode_chunked=encode_chunked)
  File "C:\Python38\lib\http\client.py", line 1225, in endheaders
    self._send_output(message_body, encode_chunked=encode_chunked)
  File "C:\Python38\lib\http\client.py", line 1004, in _send_output
    self.send(msg)
  File "C:\Python38\lib\http\client.py", line 944, in send
    self.connect()
  File "C:\Python38\lib\http\client.py", line 915, in connect
    self.sock = self._create_connection(
  File "C:\Python38\lib\socket.py", line 807, in create_connection
    raise err
  File "C:\Python38\lib\socket.py", line 796, in create_connection
    sock.connect(sa)
ConnectionRefusedError: [WinError 10061] 由于目标计算机积极拒绝，无法连接。

During handling of the above exception, another exception occurred:

Traceback (most recent call last):
  File "D:\python_work\AKMfloor\common\webutility.py", line 103, in http_get
    f = urllib.request.urlopen(u,timeout=timeout)
  File "C:\Python38\lib\urllib\request.py", line 222, in urlopen
    return opener.open(url, data, timeout)
  File "C:\Python38\lib\urllib\request.py", line 525, in open
    response = self._open(req, data)
  File "C:\Python38\lib\urllib\request.py", line 542, in _open
    result = self._call_chain(self.handle_open, protocol, protocol +
  File "C:\Python38\lib\urllib\request.py", line 502, in _call_chain
    result = func(*args)
  File "C:\Python38\lib\urllib\request.py", line 1346, in http_open
    return self.do_open(http.client.HTTPConnection, req)
  File "C:\Python38\lib\urllib\request.py", line 1320, in do_open
    raise URLError(err)
urllib.error.URLError: <urlopen error [WinError 10061] 由于目标计算机积极拒绝，无法连接。>

During handling of the above exception, another exception occurred:

Traceback (most recent call last):
  File "D:\python_work\AKMfloor\agvCtrl\agvApi.py", line 40, in init
    _http_get(url + '/api/agv/init', param)
  File "D:\python_work\AKMfloor\agvCtrl\agvApi.py", line 61, in _http_get
    r = webutility.http_get(url, param, timeout=45,writelog=False)
  File "D:\python_work\AKMfloor\common\webutility.py", line 105, in http_get
    raise Exception("http get",url,params,"error:",str(e))
Exception: ('http get', 'http://127.0.0.1:5551/api/agv/init', {'appName': 'scadaTask'}, 'error:', '<urlopen error [WinError 10061] 由于目标计算机积极拒绝，无法连接。>')

[CRITICAL]2021-03-26 13:06:14,186: elevatorApi cause a error: ('http get', 'http://127.0.0.1:5551/api/elevator/status', {'id': 'ELEVATOR01'}, 'error:', '<urlopen error [WinError 10061] 由于目标计算机积极拒绝，无法连接。>')
pid=25356, ppid=20496, tid=23380
Traceback (most recent call last):
  File "C:\Python38\lib\urllib\request.py", line 1317, in do_open
    h.request(req.get_method(), req.selector, req.data, headers,
  File "C:\Python38\lib\http\client.py", line 1230, in request
    self._send_request(method, url, body, headers, encode_chunked)
  File "C:\Python38\lib\http\client.py", line 1276, in _send_request
    self.endheaders(body, encode_chunked=encode_chunked)
  File "C:\Python38\lib\http\client.py", line 1225, in endheaders
    self._send_output(message_body, encode_chunked=encode_chunked)
  File "C:\Python38\lib\http\client.py", line 1004, in _send_output
    self.send(msg)
  File "C:\Python38\lib\http\client.py", line 944, in send
    self.connect()
  File "C:\Python38\lib\http\client.py", line 915, in connect
    self.sock = self._create_connection(
  File "C:\Python38\lib\socket.py", line 807, in create_connection
    raise err
  File "C:\Python38\lib\socket.py", line 796, in create_connection
    sock.connect(sa)
ConnectionRefusedError: [WinError 10061] 由于目标计算机积极拒绝，无法连接。

During handling of the above exception, another exception occurred:

Traceback (most recent call last):
  File "D:\python_work\AKMfloor\common\webutility.py", line 103, in http_get
    f = urllib.request.urlopen(u,timeout=timeout)
  File "C:\Python38\lib\urllib\request.py", line 222, in urlopen
    return opener.open(url, data, timeout)
  File "C:\Python38\lib\urllib\request.py", line 525, in open
    response = self._open(req, data)
  File "C:\Python38\lib\urllib\request.py", line 542, in _open
    result = self._call_chain(self.handle_open, protocol, protocol +
  File "C:\Python38\lib\urllib\request.py", line 502, in _call_chain
    result = func(*args)
  File "C:\Python38\lib\urllib\request.py", line 1346, in http_open
    return self.do_open(http.client.HTTPConnection, req)
  File "C:\Python38\lib\urllib\request.py", line 1320, in do_open
    raise URLError(err)
urllib.error.URLError: <urlopen error [WinError 10061] 由于目标计算机积极拒绝，无法连接。>

During handling of the above exception, another exception occurred:

Traceback (most recent call last):
  File "D:\python_work\AKMfloor\elevator\elevatorApi.py", line 19, in http_get
    r = webutility.http_get(url, param,timeout=10,writelog=writelog)
  File "D:\python_work\AKMfloor\common\webutility.py", line 105, in http_get
    raise Exception("http get",url,params,"error:",str(e))
Exception: ('http get', 'http://127.0.0.1:5551/api/elevator/status', {'id': 'ELEVATOR01'}, 'error:', '<urlopen error [WinError 10061] 由于目标计算机积极拒绝，无法连接。>')

[CRITICAL]2021-03-26 13:06:16,971: agvApi.init cause a error: ('http get', 'http://127.0.0.1:5551/api/agv/init', {'appName': 'scadaTask'}, 'error:', '<urlopen error [WinError 10061] 由于目标计算机积极拒绝，无法连接。>')
pid=25356, ppid=20496, tid=24300
Traceback (most recent call last):
  File "C:\Python38\lib\urllib\request.py", line 1317, in do_open
    h.request(req.get_method(), req.selector, req.data, headers,
  File "C:\Python38\lib\http\client.py", line 1230, in request
    self._send_request(method, url, body, headers, encode_chunked)
  File "C:\Python38\lib\http\client.py", line 1276, in _send_request
    self.endheaders(body, encode_chunked=encode_chunked)
  File "C:\Python38\lib\http\client.py", line 1225, in endheaders
    self._send_output(message_body, encode_chunked=encode_chunked)
  File "C:\Python38\lib\http\client.py", line 1004, in _send_output
    self.send(msg)
  File "C:\Python38\lib\http\client.py", line 944, in send
    self.connect()
  File "C:\Python38\lib\http\client.py", line 915, in connect
    self.sock = self._create_connection(
  File "C:\Python38\lib\socket.py", line 807, in create_connection
    raise err
  File "C:\Python38\lib\socket.py", line 796, in create_connection
    sock.connect(sa)
ConnectionRefusedError: [WinError 10061] 由于目标计算机积极拒绝，无法连接。

During handling of the above exception, another exception occurred:

Traceback (most recent call last):
  File "D:\python_work\AKMfloor\common\webutility.py", line 103, in http_get
    f = urllib.request.urlopen(u,timeout=timeout)
  File "C:\Python38\lib\urllib\request.py", line 222, in urlopen
    return opener.open(url, data, timeout)
  File "C:\Python38\lib\urllib\request.py", line 525, in open
    response = self._open(req, data)
  File "C:\Python38\lib\urllib\request.py", line 542, in _open
    result = self._call_chain(self.handle_open, protocol, protocol +
  File "C:\Python38\lib\urllib\request.py", line 502, in _call_chain
    result = func(*args)
  File "C:\Python38\lib\urllib\request.py", line 1346, in http_open
    return self.do_open(http.client.HTTPConnection, req)
  File "C:\Python38\lib\urllib\request.py", line 1320, in do_open
    raise URLError(err)
urllib.error.URLError: <urlopen error [WinError 10061] 由于目标计算机积极拒绝，无法连接。>

During handling of the above exception, another exception occurred:

Traceback (most recent call last):
  File "D:\python_work\AKMfloor\agvCtrl\agvApi.py", line 40, in init
    _http_get(url + '/api/agv/init', param)
  File "D:\python_work\AKMfloor\agvCtrl\agvApi.py", line 61, in _http_get
    r = webutility.http_get(url, param, timeout=45,writelog=False)
  File "D:\python_work\AKMfloor\common\webutility.py", line 105, in http_get
    raise Exception("http get",url,params,"error:",str(e))
Exception: ('http get', 'http://127.0.0.1:5551/api/agv/init', {'appName': 'scadaTask'}, 'error:', '<urlopen error [WinError 10061] 由于目标计算机积极拒绝，无法连接。>')

[CRITICAL]2021-03-26 13:06:17,217: elevatorApi cause a error: ('http get', 'http://127.0.0.1:5551/api/elevator/status', {'id': 'ELEVATOR01'}, 'error:', '<urlopen error [WinError 10061] 由于目标计算机积极拒绝，无法连接。>')
pid=25356, ppid=20496, tid=23380
Traceback (most recent call last):
  File "C:\Python38\lib\urllib\request.py", line 1317, in do_open
    h.request(req.get_method(), req.selector, req.data, headers,
  File "C:\Python38\lib\http\client.py", line 1230, in request
    self._send_request(method, url, body, headers, encode_chunked)
  File "C:\Python38\lib\http\client.py", line 1276, in _send_request
    self.endheaders(body, encode_chunked=encode_chunked)
  File "C:\Python38\lib\http\client.py", line 1225, in endheaders
    self._send_output(message_body, encode_chunked=encode_chunked)
  File "C:\Python38\lib\http\client.py", line 1004, in _send_output
    self.send(msg)
  File "C:\Python38\lib\http\client.py", line 944, in send
    self.connect()
  File "C:\Python38\lib\http\client.py", line 915, in connect
    self.sock = self._create_connection(
  File "C:\Python38\lib\socket.py", line 807, in create_connection
    raise err
  File "C:\Python38\lib\socket.py", line 796, in create_connection
    sock.connect(sa)
ConnectionRefusedError: [WinError 10061] 由于目标计算机积极拒绝，无法连接。

During handling of the above exception, another exception occurred:

Traceback (most recent call last):
  File "D:\python_work\AKMfloor\common\webutility.py", line 103, in http_get
    f = urllib.request.urlopen(u,timeout=timeout)
  File "C:\Python38\lib\urllib\request.py", line 222, in urlopen
    return opener.open(url, data, timeout)
  File "C:\Python38\lib\urllib\request.py", line 525, in open
    response = self._open(req, data)
  File "C:\Python38\lib\urllib\request.py", line 542, in _open
    result = self._call_chain(self.handle_open, protocol, protocol +
  File "C:\Python38\lib\urllib\request.py", line 502, in _call_chain
    result = func(*args)
  File "C:\Python38\lib\urllib\request.py", line 1346, in http_open
    return self.do_open(http.client.HTTPConnection, req)
  File "C:\Python38\lib\urllib\request.py", line 1320, in do_open
    raise URLError(err)
urllib.error.URLError: <urlopen error [WinError 10061] 由于目标计算机积极拒绝，无法连接。>

During handling of the above exception, another exception occurred:

Traceback (most recent call last):
  File "D:\python_work\AKMfloor\elevator\elevatorApi.py", line 19, in http_get
    r = webutility.http_get(url, param,timeout=10,writelog=writelog)
  File "D:\python_work\AKMfloor\common\webutility.py", line 105, in http_get
    raise Exception("http get",url,params,"error:",str(e))
Exception: ('http get', 'http://127.0.0.1:5551/api/elevator/status', {'id': 'ELEVATOR01'}, 'error:', '<urlopen error [WinError 10061] 由于目标计算机积极拒绝，无法连接。>')

[CRITICAL]2021-03-26 13:06:20,012: agvApi.init cause a error: ('http get', 'http://127.0.0.1:5551/api/agv/init', {'appName': 'scadaTask'}, 'error:', '<urlopen error [WinError 10061] 由于目标计算机积极拒绝，无法连接。>')
pid=25356, ppid=20496, tid=24300
Traceback (most recent call last):
  File "C:\Python38\lib\urllib\request.py", line 1317, in do_open
    h.request(req.get_method(), req.selector, req.data, headers,
  File "C:\Python38\lib\http\client.py", line 1230, in request
    self._send_request(method, url, body, headers, encode_chunked)
  File "C:\Python38\lib\http\client.py", line 1276, in _send_request
    self.endheaders(body, encode_chunked=encode_chunked)
  File "C:\Python38\lib\http\client.py", line 1225, in endheaders
    self._send_output(message_body, encode_chunked=encode_chunked)
  File "C:\Python38\lib\http\client.py", line 1004, in _send_output
    self.send(msg)
  File "C:\Python38\lib\http\client.py", line 944, in send
    self.connect()
  File "C:\Python38\lib\http\client.py", line 915, in connect
    self.sock = self._create_connection(
  File "C:\Python38\lib\socket.py", line 807, in create_connection
    raise err
  File "C:\Python38\lib\socket.py", line 796, in create_connection
    sock.connect(sa)
ConnectionRefusedError: [WinError 10061] 由于目标计算机积极拒绝，无法连接。

During handling of the above exception, another exception occurred:

Traceback (most recent call last):
  File "D:\python_work\AKMfloor\common\webutility.py", line 103, in http_get
    f = urllib.request.urlopen(u,timeout=timeout)
  File "C:\Python38\lib\urllib\request.py", line 222, in urlopen
    return opener.open(url, data, timeout)
  File "C:\Python38\lib\urllib\request.py", line 525, in open
    response = self._open(req, data)
  File "C:\Python38\lib\urllib\request.py", line 542, in _open
    result = self._call_chain(self.handle_open, protocol, protocol +
  File "C:\Python38\lib\urllib\request.py", line 502, in _call_chain
    result = func(*args)
  File "C:\Python38\lib\urllib\request.py", line 1346, in http_open
    return self.do_open(http.client.HTTPConnection, req)
  File "C:\Python38\lib\urllib\request.py", line 1320, in do_open
    raise URLError(err)
urllib.error.URLError: <urlopen error [WinError 10061] 由于目标计算机积极拒绝，无法连接。>

During handling of the above exception, another exception occurred:

Traceback (most recent call last):
  File "D:\python_work\AKMfloor\agvCtrl\agvApi.py", line 40, in init
    _http_get(url + '/api/agv/init', param)
  File "D:\python_work\AKMfloor\agvCtrl\agvApi.py", line 61, in _http_get
    r = webutility.http_get(url, param, timeout=45,writelog=False)
  File "D:\python_work\AKMfloor\common\webutility.py", line 105, in http_get
    raise Exception("http get",url,params,"error:",str(e))
Exception: ('http get', 'http://127.0.0.1:5551/api/agv/init', {'appName': 'scadaTask'}, 'error:', '<urlopen error [WinError 10061] 由于目标计算机积极拒绝，无法连接。>')

[CRITICAL]2021-03-26 13:06:20,259: elevatorApi cause a error: ('http get', 'http://127.0.0.1:5551/api/elevator/status', {'id': 'ELEVATOR01'}, 'error:', '<urlopen error [WinError 10061] 由于目标计算机积极拒绝，无法连接。>')
pid=25356, ppid=20496, tid=23380
Traceback (most recent call last):
  File "C:\Python38\lib\urllib\request.py", line 1317, in do_open
    h.request(req.get_method(), req.selector, req.data, headers,
  File "C:\Python38\lib\http\client.py", line 1230, in request
    self._send_request(method, url, body, headers, encode_chunked)
  File "C:\Python38\lib\http\client.py", line 1276, in _send_request
    self.endheaders(body, encode_chunked=encode_chunked)
  File "C:\Python38\lib\http\client.py", line 1225, in endheaders
    self._send_output(message_body, encode_chunked=encode_chunked)
  File "C:\Python38\lib\http\client.py", line 1004, in _send_output
    self.send(msg)
  File "C:\Python38\lib\http\client.py", line 944, in send
    self.connect()
  File "C:\Python38\lib\http\client.py", line 915, in connect
    self.sock = self._create_connection(
  File "C:\Python38\lib\socket.py", line 807, in create_connection
    raise err
  File "C:\Python38\lib\socket.py", line 796, in create_connection
    sock.connect(sa)
ConnectionRefusedError: [WinError 10061] 由于目标计算机积极拒绝，无法连接。

During handling of the above exception, another exception occurred:

Traceback (most recent call last):
  File "D:\python_work\AKMfloor\common\webutility.py", line 103, in http_get
    f = urllib.request.urlopen(u,timeout=timeout)
  File "C:\Python38\lib\urllib\request.py", line 222, in urlopen
    return opener.open(url, data, timeout)
  File "C:\Python38\lib\urllib\request.py", line 525, in open
    response = self._open(req, data)
  File "C:\Python38\lib\urllib\request.py", line 542, in _open
    result = self._call_chain(self.handle_open, protocol, protocol +
  File "C:\Python38\lib\urllib\request.py", line 502, in _call_chain
    result = func(*args)
  File "C:\Python38\lib\urllib\request.py", line 1346, in http_open
    return self.do_open(http.client.HTTPConnection, req)
  File "C:\Python38\lib\urllib\request.py", line 1320, in do_open
    raise URLError(err)
urllib.error.URLError: <urlopen error [WinError 10061] 由于目标计算机积极拒绝，无法连接。>

During handling of the above exception, another exception occurred:

Traceback (most recent call last):
  File "D:\python_work\AKMfloor\elevator\elevatorApi.py", line 19, in http_get
    r = webutility.http_get(url, param,timeout=10,writelog=writelog)
  File "D:\python_work\AKMfloor\common\webutility.py", line 105, in http_get
    raise Exception("http get",url,params,"error:",str(e))
Exception: ('http get', 'http://127.0.0.1:5551/api/elevator/status', {'id': 'ELEVATOR01'}, 'error:', '<urlopen error [WinError 10061] 由于目标计算机积极拒绝，无法连接。>')

[CRITICAL]2021-03-26 13:06:23,056: agvApi.init cause a error: ('http get', 'http://127.0.0.1:5551/api/agv/init', {'appName': 'scadaTask'}, 'error:', '<urlopen error [WinError 10061] 由于目标计算机积极拒绝，无法连接。>')
pid=25356, ppid=20496, tid=24300
Traceback (most recent call last):
  File "C:\Python38\lib\urllib\request.py", line 1317, in do_open
    h.request(req.get_method(), req.selector, req.data, headers,
  File "C:\Python38\lib\http\client.py", line 1230, in request
    self._send_request(method, url, body, headers, encode_chunked)
  File "C:\Python38\lib\http\client.py", line 1276, in _send_request
    self.endheaders(body, encode_chunked=encode_chunked)
  File "C:\Python38\lib\http\client.py", line 1225, in endheaders
    self._send_output(message_body, encode_chunked=encode_chunked)
  File "C:\Python38\lib\http\client.py", line 1004, in _send_output
    self.send(msg)
  File "C:\Python38\lib\http\client.py", line 944, in send
    self.connect()
  File "C:\Python38\lib\http\client.py", line 915, in connect
    self.sock = self._create_connection(
  File "C:\Python38\lib\socket.py", line 807, in create_connection
    raise err
  File "C:\Python38\lib\socket.py", line 796, in create_connection
    sock.connect(sa)
ConnectionRefusedError: [WinError 10061] 由于目标计算机积极拒绝，无法连接。

During handling of the above exception, another exception occurred:

Traceback (most recent call last):
  File "D:\python_work\AKMfloor\common\webutility.py", line 103, in http_get
    f = urllib.request.urlopen(u,timeout=timeout)
  File "C:\Python38\lib\urllib\request.py", line 222, in urlopen
    return opener.open(url, data, timeout)
  File "C:\Python38\lib\urllib\request.py", line 525, in open
    response = self._open(req, data)
  File "C:\Python38\lib\urllib\request.py", line 542, in _open
    result = self._call_chain(self.handle_open, protocol, protocol +
  File "C:\Python38\lib\urllib\request.py", line 502, in _call_chain
    result = func(*args)
  File "C:\Python38\lib\urllib\request.py", line 1346, in http_open
    return self.do_open(http.client.HTTPConnection, req)
  File "C:\Python38\lib\urllib\request.py", line 1320, in do_open
    raise URLError(err)
urllib.error.URLError: <urlopen error [WinError 10061] 由于目标计算机积极拒绝，无法连接。>

During handling of the above exception, another exception occurred:

Traceback (most recent call last):
  File "D:\python_work\AKMfloor\agvCtrl\agvApi.py", line 40, in init
    _http_get(url + '/api/agv/init', param)
  File "D:\python_work\AKMfloor\agvCtrl\agvApi.py", line 61, in _http_get
    r = webutility.http_get(url, param, timeout=45,writelog=False)
  File "D:\python_work\AKMfloor\common\webutility.py", line 105, in http_get
    raise Exception("http get",url,params,"error:",str(e))
Exception: ('http get', 'http://127.0.0.1:5551/api/agv/init', {'appName': 'scadaTask'}, 'error:', '<urlopen error [WinError 10061] 由于目标计算机积极拒绝，无法连接。>')

[CRITICAL]2021-03-26 13:06:23,300: elevatorApi cause a error: ('http get', 'http://127.0.0.1:5551/api/elevator/status', {'id': 'ELEVATOR01'}, 'error:', '<urlopen error [WinError 10061] 由于目标计算机积极拒绝，无法连接。>')
pid=25356, ppid=20496, tid=23380
Traceback (most recent call last):
  File "C:\Python38\lib\urllib\request.py", line 1317, in do_open
    h.request(req.get_method(), req.selector, req.data, headers,
  File "C:\Python38\lib\http\client.py", line 1230, in request
    self._send_request(method, url, body, headers, encode_chunked)
  File "C:\Python38\lib\http\client.py", line 1276, in _send_request
    self.endheaders(body, encode_chunked=encode_chunked)
  File "C:\Python38\lib\http\client.py", line 1225, in endheaders
    self._send_output(message_body, encode_chunked=encode_chunked)
  File "C:\Python38\lib\http\client.py", line 1004, in _send_output
    self.send(msg)
  File "C:\Python38\lib\http\client.py", line 944, in send
    self.connect()
  File "C:\Python38\lib\http\client.py", line 915, in connect
    self.sock = self._create_connection(
  File "C:\Python38\lib\socket.py", line 807, in create_connection
    raise err
  File "C:\Python38\lib\socket.py", line 796, in create_connection
    sock.connect(sa)
ConnectionRefusedError: [WinError 10061] 由于目标计算机积极拒绝，无法连接。

During handling of the above exception, another exception occurred:

Traceback (most recent call last):
  File "D:\python_work\AKMfloor\common\webutility.py", line 103, in http_get
    f = urllib.request.urlopen(u,timeout=timeout)
  File "C:\Python38\lib\urllib\request.py", line 222, in urlopen
    return opener.open(url, data, timeout)
  File "C:\Python38\lib\urllib\request.py", line 525, in open
    response = self._open(req, data)
  File "C:\Python38\lib\urllib\request.py", line 542, in _open
    result = self._call_chain(self.handle_open, protocol, protocol +
  File "C:\Python38\lib\urllib\request.py", line 502, in _call_chain
    result = func(*args)
  File "C:\Python38\lib\urllib\request.py", line 1346, in http_open
    return self.do_open(http.client.HTTPConnection, req)
  File "C:\Python38\lib\urllib\request.py", line 1320, in do_open
    raise URLError(err)
urllib.error.URLError: <urlopen error [WinError 10061] 由于目标计算机积极拒绝，无法连接。>

During handling of the above exception, another exception occurred:

Traceback (most recent call last):
  File "D:\python_work\AKMfloor\elevator\elevatorApi.py", line 19, in http_get
    r = webutility.http_get(url, param,timeout=10,writelog=writelog)
  File "D:\python_work\AKMfloor\common\webutility.py", line 105, in http_get
    raise Exception("http get",url,params,"error:",str(e))
Exception: ('http get', 'http://127.0.0.1:5551/api/elevator/status', {'id': 'ELEVATOR01'}, 'error:', '<urlopen error [WinError 10061] 由于目标计算机积极拒绝，无法连接。>')

