[CRITICAL]2021-03-02 16:20:18,968: [modbusApi: 192.168.20.150] execute fcode=1, addr=0 exception:  cause a error: timed out
pid=10192, ppid=9784, tid=4776
Traceback (most recent call last):
  File "D:\python_lx\akm\common\modbusapi.py", line 35, in __execute
    data = self.master.execute(self.__salveId, fcode, start, quantity_of_x=num, output_value=value)
  File "C:\Python38\lib\site-packages\modbus_tk\utils.py", line 39, in new
    raise excpt
  File "C:\Python38\lib\site-packages\modbus_tk\utils.py", line 37, in new
    ret = fcn(*args, **kwargs)
  File "C:\Python38\lib\site-packages\modbus_tk\modbus.py", line 152, in execute
    self.open()
  File "C:\Python38\lib\site-packages\modbus_tk\modbus.py", line 99, in open
    self._do_open()
  File "C:\Python38\lib\site-packages\modbus_tk\modbus_tcp.py", line 173, in _do_open
    self._sock.connect((self._host, self._port))
socket.timeout: timed out

[CRITICAL]2021-03-02 16:20:18,989: magneticAGV01 readDIList fail cause a error: timed out
pid=10192, ppid=9784, tid=4776
Traceback (most recent call last):
  File "D:\python_lx\akm\virtualDoor\magneticAGV.py", line 192, in readDIList
    return self._read(D0, IO_LENTH)
  File "D:\python_lx\akm\common\lock.py", line 122, in _call
    return func(*p,**pp)
  File "D:\python_lx\akm\virtualDoor\magneticAGV.py", line 226, in _read
    s = self.master.read(mdef.READ_COILS, addr, length)
  File "D:\python_lx\akm\common\modbusapi.py", line 45, in read
    return self.__execute(fcode, start, num)
  File "D:\python_lx\akm\common\modbusapi.py", line 35, in __execute
    data = self.master.execute(self.__salveId, fcode, start, quantity_of_x=num, output_value=value)
  File "C:\Python38\lib\site-packages\modbus_tk\utils.py", line 39, in new
    raise excpt
  File "C:\Python38\lib\site-packages\modbus_tk\utils.py", line 37, in new
    ret = fcn(*args, **kwargs)
  File "C:\Python38\lib\site-packages\modbus_tk\modbus.py", line 152, in execute
    self.open()
  File "C:\Python38\lib\site-packages\modbus_tk\modbus.py", line 99, in open
    self._do_open()
  File "C:\Python38\lib\site-packages\modbus_tk\modbus_tcp.py", line 173, in _do_open
    self._sock.connect((self._host, self._port))
socket.timeout: timed out

[CRITICAL]2021-03-02 16:20:19,000: magneticAGV readDIList error cause a error: timed out
pid=10192, ppid=9784, tid=4776
Traceback (most recent call last):
  File "D:\python_lx\akm\virtualDoor\doorCtrlRunTasks.py", line 81, in _monitorDevices
    s1 = magneticAGV.readDIList(d)["status"]
  File "D:\python_lx\akm\virtualDoor\magneticAGV.py", line 140, in readDIList
    result = remoteioInfo.readDIList()
  File "D:\python_lx\akm\virtualDoor\magneticAGV.py", line 192, in readDIList
    return self._read(D0, IO_LENTH)
  File "D:\python_lx\akm\common\lock.py", line 122, in _call
    return func(*p,**pp)
  File "D:\python_lx\akm\virtualDoor\magneticAGV.py", line 226, in _read
    s = self.master.read(mdef.READ_COILS, addr, length)
  File "D:\python_lx\akm\common\modbusapi.py", line 45, in read
    return self.__execute(fcode, start, num)
  File "D:\python_lx\akm\common\modbusapi.py", line 35, in __execute
    data = self.master.execute(self.__salveId, fcode, start, quantity_of_x=num, output_value=value)
  File "C:\Python38\lib\site-packages\modbus_tk\utils.py", line 39, in new
    raise excpt
  File "C:\Python38\lib\site-packages\modbus_tk\utils.py", line 37, in new
    ret = fcn(*args, **kwargs)
  File "C:\Python38\lib\site-packages\modbus_tk\modbus.py", line 152, in execute
    self.open()
  File "C:\Python38\lib\site-packages\modbus_tk\modbus.py", line 99, in open
    self._do_open()
  File "C:\Python38\lib\site-packages\modbus_tk\modbus_tcp.py", line 173, in _do_open
    self._sock.connect((self._host, self._port))
socket.timeout: timed out

